Workbook

Sheet Global History Jan 2014 MC
A1: Question | B1: Code | C1: Unit | D1: Category | E1: Content | F1: Subcontent/Key Ideas | G1: Additional Code | H1: Notes
A2: 1 | C2: =VLOOKUP(B2,'Global History Standards'!$A:$E,2,false) -> #REF! | D2: =VLOOKUP(B2,'Global History Standards'!$A:$E,3,false) -> #REF! | E2: =VLOOKUP(B2,'Global History Standards'!$A:$E,4,false) -> #REF! | F2: =VLOOKUP(B2,'Global History Standards'!$A:$E,5,false) -> #REF! | H2: Social Studies Methods: Economics
A3: 2 | C3: =VLOOKUP(B3,'Global History Standards'!$A:$E,2,false) -> #REF! | D3: =VLOOKUP(B3,'Global History Standards'!$A:$E,3,false) -> #REF! | E3: =VLOOKUP(B3,'Global History Standards'!$A:$E,4,false) -> #REF! | F3: =VLOOKUP(B3,'Global History Standards'!$A:$E,5,false) -> #REF! | H3: World Geography
A4: 3 | B4: 1.2.1 | C4: =VLOOKUP(B4,'Global History Standards'!$A:$E,2,false) -> #REF! | D4: =VLOOKUP(B4,'Global History Standards'!$A:$E,3,false) -> #REF! | E4: =VLOOKUP(B4,'Global History Standards'!$A:$E,4,false) -> #REF! | F4: =VLOOKUP(B4,'Global History Standards'!$A:$E,5,false) -> #REF!
A5: 4 | B5: 1.3.3 | C5: =VLOOKUP(B5,'Global History Standards'!$A:$E,2,false) -> #REF! | D5: =VLOOKUP(B5,'Global History Standards'!$A:$E,3,false) -> #REF! | E5: =VLOOKUP(B5,'Global History Standards'!$A:$E,4,false) -> #REF! | F5: =VLOOKUP(B5,'Global History Standards'!$A:$E,5,false) -> #REF!
A6: 5 | B6: 1.4.2 | C6: =VLOOKUP(B6,'Global History Standards'!$A:$E,2,false) -> #REF! | D6: =VLOOKUP(B6,'Global History Standards'!$A:$E,3,false) -> #REF! | E6: =VLOOKUP(B6,'Global History Standards'!$A:$E,4,false) -> #REF! | F6: =VLOOKUP(B6,'Global History Standards'!$A:$E,5,false) -> #REF!
A7: 6 | B7: 2.6.2 | C7: =VLOOKUP(B7,'Global History Standards'!$A:$E,2,false) -> #REF! | D7: =VLOOKUP(B7,'Global History Standards'!$A:$E,3,false) -> #REF! | E7: =VLOOKUP(B7,'Global History Standards'!$A:$E,4,false) -> #REF! | F7: =VLOOKUP(B7,'Global History Standards'!$A:$E,5,false) -> #REF!
A8: 7 | B8: 2.5.6 | C8: =VLOOKUP(B8,'Global History Standards'!$A:$E,2,false) -> #REF! | D8: =VLOOKUP(B8,'Global History Standards'!$A:$E,3,false) -> #REF! | E8: =VLOOKUP(B8,'Global History Standards'!$A:$E,4,false) -> #REF! | F8: =VLOOKUP(B8,'Global History Standards'!$A:$E,5,false) -> #REF!
A9: 8 | B9: 2.3.6 | C9: =VLOOKUP(B9,'Global History Standards'!$A:$E,2,false) -> #REF! | D9: =VLOOKUP(B9,'Global History Standards'!$A:$E,3,false) -> #REF! | E9: =VLOOKUP(B9,'Global History Standards'!$A:$E,4,false) -> #REF! | F9: =VLOOKUP(B9,'Global History Standards'!$A:$E,5,false) -> #REF!
A10: 9 | B10: 3.1.3 | C10: =VLOOKUP(B10,'Global History Standards'!$A:$E,2,false) -> #REF! | D10: =VLOOKUP(B10,'Global History Standards'!$A:$E,3,false) -> #REF! | E10: =VLOOKUP(B10,'Global History Standards'!$A:$E,4,false) -> #REF! | F10: =VLOOKUP(B10,'Global History Standards'!$A:$E,5,false) -> #REF!
A11: 10 | B11: 3.3.1 | C11: =VLOOKUP(B11,'Global History Standards'!$A:$E,2,false) -> #REF! | D11: =VLOOKUP(B11,'Global History Standards'!$A:$E,3,false) -> #REF! | E11: =VLOOKUP(B11,'Global History Standards'!$A:$E,4,false) -> #REF! | F11: =VLOOKUP(B11,'Global History Standards'!$A:$E,5,false) -> #REF!
A12: 11 | B12: 2.6.9 | C12: =VLOOKUP(B12,'Global History Standards'!$A:$E,2,false) -> #REF! | D12: =VLOOKUP(B12,'Global History Standards'!$A:$E,3,false) -> #REF! | E12: =VLOOKUP(B12,'Global History Standards'!$A:$E,4,false) -> #REF! | F12: =VLOOKUP(B12,'Global History Standards'!$A:$E,5,false) -> #REF!
A13: 12 | B13: 3.6.2 | C13: =VLOOKUP(B13,'Global History Standards'!$A:$E,2,false) -> #REF! | D13: =VLOOKUP(B13,'Global History Standards'!$A:$E,3,false) -> #REF! | E13: =VLOOKUP(B13,'Global History Standards'!$A:$E,4,false) -> #REF! | F13: =VLOOKUP(B13,'Global History Standards'!$A:$E,5,false) -> #REF!
A14: 13 | B14: 4.2.3 | C14: =VLOOKUP(B14,'Global History Standards'!$A:$E,2,false) -> #REF! | D14: =VLOOKUP(B14,'Global History Standards'!$A:$E,3,false) -> #REF! | E14: =VLOOKUP(B14,'Global History Standards'!$A:$E,4,false) -> #REF! | F14: =VLOOKUP(B14,'Global History Standards'!$A:$E,5,false) -> #REF!
A15: 14 | B15: 1.3.6 | C15: =VLOOKUP(B15,'Global History Standards'!$A:$E,2,false) -> #REF! | D15: =VLOOKUP(B15,'Global History Standards'!$A:$E,3,false) -> #REF! | E15: =VLOOKUP(B15,'Global History Standards'!$A:$E,4,false) -> #REF! | F15: =VLOOKUP(B15,'Global History Standards'!$A:$E,5,false) -> #REF!
... A19: 18 | B19: 4.6.4 | C19: =VLOOKUP(B19,'Global History Standards'!$A:$E,2,false) -> #REF! | D19: =VLOOKUP(B19,'Global History Standards'!$A:$E,3,false) -> #REF! | E19: =VLOOKUP(B19,'Global History Standards'!$A:$E,4,false) -> #REF! | F19: =VLOOKUP(B19,'Global History Standards'!$A:$E,5,false) -> #REF!
A20: 19 | B20: 4.7.4 | C20: =VLOOKUP(B20,'Global History Standards'!$A:$E,2,false) -> #REF! | D20: =VLOOKUP(B20,'Global History Standards'!$A:$E,3,false) -> #REF! | E20: =VLOOKUP(B20,'Global History Standards'!$A:$E,4,false) -> #REF! | F20: =VLOOKUP(B20,'Global History Standards'!$A:$E,5,false) -> #REF! | G20: 4.7.1
A21: 20 | B21: 5.2.2 | C21: =VLOOKUP(B21,'Global History Standards'!$A:$E,2,false) -> #REF! | D21: =VLOOKUP(B21,'Global History Standards'!$A:$E,3,false) -> #REF! | E21: =VLOOKUP(B21,'Global History Standards'!$A:$E,4,false) -> #REF! | F21: =VLOOKUP(B21,'Global History Standards'!$A:$E,5,false) -> #REF!
A22: 21 | B22: 5.3.3 | C22: =VLOOKUP(B22,'Global History Standards'!$A:$E,2,false) -> #REF! | D22: =VLOOKUP(B22,'Global History Standards'!$A:$E,3,false) -> #REF! | E22: =VLOOKUP(B22,'Global History Standards'!$A:$E,4,false) -> #REF! | F22: =VLOOKUP(B22,'Global History Standards'!$A:$E,5,false) -> #REF!
A23: 22 | B23: 5.3.4 | C23: =VLOOKUP(B23,'Global History Standards'!$A:$E,2,false) -> #REF! | D23: =VLOOKUP(B23,'Global History Standards'!$A:$E,3,false) -> #REF! | E23: =VLOOKUP(B23,'Global History Standards'!$A:$E,4,false) -> #REF! | F23: =VLOOKUP(B23,'Global History Standards'!$A:$E,5,false) -> #REF!
A24: 23 | B24: 5.7.1 | C24: =VLOOKUP(B24,'Global History Standards'!$A:$E,2,false) -> #REF! | D24: =VLOOKUP(B24,'Global History Standards'!$A:$E,3,false) -> #REF! | E24: =VLOOKUP(B24,'Global History Standards'!$A:$E,4,false) -> #REF! | F24: =VLOOKUP(B24,'Global History Standards'!$A:$E,5,false) -> #REF!
A25: 24 | B25: 5.7.6 | C25: =VLOOKUP(B25,'Global History Standards'!$A:$E,2,false) -> #REF! | D25: =VLOOKUP(B25,'Global History Standards'!$A:$E,3,false) -> #REF! | E25: =VLOOKUP(B25,'Global History Standards'!$A:$E,4,false) -> #REF! | F25: =VLOOKUP(B25,'Global History Standards'!$A:$E,5,false) -> #REF!
A26: 25 | B26: 5.8.1 | C26: =VLOOKUP(B26,'Global History Standards'!$A:$E,2,false) -> #REF! | D26: =VLOOKUP(B26,'Global History Standards'!$A:$E,3,false) -> #REF! | E26: =VLOOKUP(B26,'Global History Standards'!$A:$E,4,false) -> #REF! | F26: =VLOOKUP(B26,'Global History Standards'!$A:$E,5,false) -> #REF!
A27: 26 | B27: 5.9.3 | C27: =VLOOKUP(B27,'Global History Standards'!$A:$E,2,false) -> #REF! | D27: =VLOOKUP(B27,'Global History Standards'!$A:$E,3,false) -> #REF! | E27: =VLOOKUP(B27,'Global History Standards'!$A:$E,4,false) -> #REF! | F27: =VLOOKUP(B27,'Global History Standards'!$A:$E,5,false) -> #REF! | G27: 6.3.3
A28: 27 | B28: 6.1.7 | C28: =VLOOKUP(B28,'Global History Standards'!$A:$E,2,false) -> #REF! | D28: =VLOOKUP(B28,'Global History Standards'!$A:$E,3,false) -> #REF! | E28: =VLOOKUP(B28,'Global History Standards'!$A:$E,4,false) -> #REF! | F28: =VLOOKUP(B28,'Global History Standards'!$A:$E,5,false) -> #REF!
A29: 28 | B29: 6.3.6 | C29: =VLOOKUP(B29,'Global History Standards'!$A:$E,2,false) -> #REF! | D29: =VLOOKUP(B29,'Global History Standards'!$A:$E,3,false) -> #REF! | E29: =VLOOKUP(B29,'Global History Standards'!$A:$E,4,false) -> #REF! | F29: =VLOOKUP(B29,'Global History Standards'!$A:$E,5,false) -> #REF!
A30: 29 | B30: 7.5.3 | C30: =VLOOKUP(B30,'Global History Standards'!$A:$E,2,false) -> #REF! | D30: =VLOOKUP(B30,'Global History Standards'!$A:$E,3,false) -> #REF! | E30: =VLOOKUP(B30,'Global History Standards'!$A:$E,4,false) -> #REF! | F30: =VLOOKUP(B30,'Global History Standards'!$A:$E,5,false) -> #REF!
A31: 30 | B31: 6.3.1 | C31: =VLOOKUP(B31,'Global History Standards'!$A:$E,2,false) -> #REF! | D31: =VLOOKUP(B31,'Global History Standards'!$A:$E,3,false) -> #REF! | E31: =VLOOKUP(B31,'Global History Standards'!$A:$E,4,false) -> #REF! | F31: =VLOOKUP(B31,'Global History Standards'!$A:$E,5,false) -> #REF!
A32: 31 | B32: 7.5.2 | C32: =VLOOKUP(B32,'Global History Standards'!$A:$E,2,false) -> #REF! | D32: =VLOOKUP(B32,'Global History Standards'!$A:$E,3,false) -> #REF! | E32: =VLOOKUP(B32,'Global History Standards'!$A:$E,4,false) -> #REF! | F32: =VLOOKUP(B32,'Global History Standards'!$A:$E,5,false) -> #REF!
A33: 32 | B33: 6.4.1 | C33: =VLOOKUP(B33,'Global History Standards'!$A:$E,2,false) -> #REF! | D33: =VLOOKUP(B33,'Global History Standards'!$A:$E,3,false) -> #REF! | E33: =VLOOKUP(B33,'Global History Standards'!$A:$E,4,false) -> #REF! | F33: =VLOOKUP(B33,'Global History Standards'!$A:$E,5,false) -> #REF! | G33: 6.4.4
A34: 33 | B34: 7.3.4 | C34: =VLOOKUP(B34,'Global History Standards'!$A:$E,2,false) -> #REF! | D34: =VLOOKUP(B34,'Global History Standards'!$A:$E,3,false) -> #REF! | E34: =VLOOKUP(B34,'Global History Standards'!$A:$E,4,false) -> #REF! | F34: =VLOOKUP(B34,'Global History Standards'!$A:$E,5,false) -> #REF!
A35: 34 | B35: 7.7.4 | C35: =VLOOKUP(B35,'Global History Standards'!$A:$E,2,false) -> #REF! | D35: =VLOOKUP(B35,'Global History Standards'!$A:$E,3,false) -> #REF! | E35: =VLOOKUP(B35,'Global History Standards'!$A:$E,4,false) -> #REF! | F35: =VLOOKUP(B35,'Global History Standards'!$A:$E,5,false) -> #REF! | G35: 7.4.4
A36: 35 | B36: 7.5.3 | C36: =VLOOKUP(B36,'Global History Standards'!$A:$E,2,false) -> #REF! | D36: =VLOOKUP(B36,'Global History Standards'!$A:$E,3,false) -> #REF! | E36: =VLOOKUP(B36,'Global History Standards'!$A:$E,4,false) -> #REF! | F36: =VLOOKUP(B36,'Global History Standards'!$A:$E,5,false) -> #REF!
A37: 36 | B37: 8.2.3 | C37: =VLOOKUP(B37,'Global History Standards'!$A:$E,2,false) -> #REF! | D37: =VLOOKUP(B37,'Global History Standards'!$A:$E,3,false) -> #REF! | E37: =VLOOKUP(B37,'Global History Standards'!$A:$E,4,false) -> #REF! | F37: =VLOOKUP(B37,'Global History Standards'!$A:$E,5,false) -> #REF!
A38: 37 | B38: 7.6.1 | C38: =VLOOKUP(B38,'Global History Standards'!$A:$E,2,false) -> #REF! | D38: =VLOOKUP(B38,'Global History Standards'!$A:$E,3,false) -> #REF! | E38: =VLOOKUP(B38,'Global History Standards'!$A:$E,4,false) -> #REF! | F38: =VLOOKUP(B38,'Global History Standards'!$A:$E,5,false) -> #REF! | G38: 7.6.2, 7.6.3, 7.6.4, 7.5.2
A39: 38 | B39: 8.2.3 | C39: =VLOOKUP(B39,'Global History Standards'!$A:$E,2,false) -> #REF! | D39: =VLOOKUP(B39,'Global History Standards'!$A:$E,3,false) -> #REF! | E39: =VLOOKUP(B39,'Global History Standards'!$A:$E,4,false) -> #REF! | F39: =VLOOKUP(B39,'Global History Standards'!$A:$E,5,false) -> #REF!
A40: 39 | B40: 8.4.7 | C40: =VLOOKUP(B40,'Global History Standards'!$A:$E,2,false) -> #REF! | D40: =VLOOKUP(B40,'Global History Standards'!$A:$E,3,false) -> #REF! | E40: =VLOOKUP(B40,'Global History Standards'!$A:$E,4,false) -> #REF! | F40: =VLOOKUP(B40,'Global History Standards'!$A:$E,5,false) -> #REF!
A41: 40 | B41: 7.1.5 | C41: =VLOOKUP(B41,'Global History Standards'!$A:$E,2,false) -> #REF! | D41: =VLOOKUP(B41,'Global History Standards'!$A:$E,3,false) -> #REF! | E41: =VLOOKUP(B41,'Global History Standards'!$A:$E,4,false) -> #REF! | F41: =VLOOKUP(B41,'Global History Standards'!$A:$E,5,false) -> #REF!
A42: 41 | B42: 8.4.8 | C42: =VLOOKUP(B42,'Global History Standards'!$A:$E,2,false) -> #REF! | D42: =VLOOKUP(B42,'Global History Standards'!$A:$E,3,false) -> #REF! | E42: =VLOOKUP(B42,'Global History Standards'!$A:$E,4,false) -> #REF! | F42: =VLOOKUP(B42,'Global History Standards'!$A:$E,5,false) -> #REF!
A43: 42 | B43: 1.2.1 | C43: =VLOOKUP(B43,'Global History Standards'!$A:$E,2,false) -> #REF! | D43: =VLOOKUP(B43,'Global History Standards'!$A:$E,3,false) -> #REF! | E43: =VLOOKUP(B43,'Global History Standards'!$A:$E,4,false) -> #REF! | F43: =VLOOKUP(B43,'Global History Standards'!$A:$E,5,false) -> #REF!
...

Sheet Cover Sheet
B1: Assessment Data Spreadsheet
B2: Exam: 2023-2025 United States History Regents Exams
B4: This spreadsheet is a sortable version of the information found in the teacher materials for this exam.
B5: Make a copy to see hover text.
B6: Click here for exam resources
B8: Key:
B11: Source | D11: Primary or Secondary
B12: We identify the source of the stimuli and link to it when possible so educators can review the original document and feed confident in its sourcing. | D12: Though an often debated classification, we have tried to categorize documents into primary or secondary texts. Any texts that might be considered tertiary are classified as secondary.
B13: General and Specific Stimuli Types | D13: Framework Unit/Content Specification
B14: To organize stimuli on our exams, we use the following categories: Text-based (i.e.- diary, memoir, letter, monograph, speech, literature, newspaper article) Data-based (i.e.- graph, chart, diagram) Map-based (i.e.- political map, physical map, thematic map) Visual-based (i.e.- political cartoon, photograph, illustration) | D14: The Content Specifications identified in these teacher materials come from the NYS Grades 9-12 Social Studies Framework. In the excerpt of the framework to the right, 11.1 is the Big Idea, 11.1a is the Conceptual Understanding, and the bulleted line below that is the Content Specification. All of our questions are aligned to a content specification.
B15: Task Model | D15: Need OI?
B16: The task models referenced refer to those used to create NYS Social Studies Regents Exam which can be accessed through the link located in the above "Task Model" heading. | D16: This column identifies if outside information is needed to answer the question (yes) or if students can answer the question based solely on the stimuli (no).

Sheet Analysis All Exams
A1: All Exams & Parts Analysis
A2: Stimuli | J2: Question
A3: Primary or Secondary | D3: General Stimuli Type | G3: Framework Unit | J3: Content Specification | M3: Task Model | P3: Need OI?
B4: # | C4: % | E4: # | F4: % | H4: # | I4: % | K4: # | L4: % | N4: # | O4: % | Q4: # | R4: %
A5: Primary | B5: =SUM(COUNTIF('Itemization 202506'!I:I,A5),COUNTIF('Itemization 202501'!I:I,A5),COUNTIF('Itemization 202408'!I:I,A5),COUNTIF('Itemization 202406'!I:I,A5),COUNTIF('Itemization 202401'!I:I,A5),COUNTIF('Itemization 202306'!I:I,A5),COUNTIF('Itemization 202308'!I:I,A5)) -> 210 | C5: =(B5/B8) -> 0.78651685 | D5: Text-based | E5: =SUM(COUNTIF('Itemization 202506'!J:J,D5),COUNTIF('Itemization 202501'!J:J,D5),COUNTIF('Itemization 202408'!J:J,D5),COUNTIF('Itemization 202406'!J:J,D5),COUNTIF('Itemization 202401'!J:J,D5),COUNTIF('Itemization 202308'!J:J,D5),COUNTIF('Itemization 202306'!J:J,D5)) -> 191 | F5: =(E5/E10) -> 0.71535581 | G5: 11.01 | H5: =SUM(COUNTIF('Itemization 202506'!K:K,G5),COUNTIF('Itemization 202501'!K:K,G5),COUNTIF('Itemization 202408'!K:K,G5),COUNTIF('Itemization 202406'!K:K,G5),COUNTIF('Itemization 202401'!K:K,G5),COUNTIF('Itemization 202308'!K:K,G5),COUNTIF('Itemization 202306'!K:K,G5)) -> 11 | I5: =(H5/H16) -> 0.041509434 | J5: 11.01a.1 | K5: =SUM(COUNTIF('Itemization 202506'!L:L,J5),COUNTIF('Itemization 202501'!L:L,J5),COUNTIF('Itemization 202408'!L:L,J5),COUNTIF('Itemization 202406'!L:L,J5),COUNTIF('Itemization 202401'!L:L,J5),COUNTIF('Itemization 202308'!L:L,J5),COUNTIF('Itemization 202306'!L:L,J5)) -> 0 | L5: =(K5/K116) -> 0 | M5: 1 | N5: =SUM(countif('Itemization 202506'!M:M,M5),countif('Itemization 202501'!M:M,M5),countif('Itemization 202408'!M:M,M5),countif('Itemization 202406'!M:M,M5),countif('Itemization 202401'!M:M,M5),countif('Itemization 202308'!M:M,M5),countif('Itemization 202306'!M:M,M5)) -> 23 | O5: =(N5/N23) -> 0.096638655 | P5: Yes | Q5: =SUM(countif('Itemization 202506'!N:N,P5),countif('Itemization 202501'!N:N,P5),countif('Itemization 202408'!N:N,P5),countif('Itemization 202406'!N:N,P5),countif('Itemization 202401'!N:N,P5),countif('Itemization 202308'!N:N,P5),countif('Itemization 202306'!N:N,P5)) -> 179 | R5: =(Q5/Q7) -> 0.68060836
A6: Secondary | B6: =SUM(COUNTIF('Itemization 202506'!I:I,A6),COUNTIF('Itemization 202501'!I:I,A6),COUNTIF('Itemization 202408'!I:I,A6),COUNTIF('Itemization 202406'!I:I,A6),COUNTIF('Itemization 202401'!I:I,A6),COUNTIF('Itemization 202306'!I:I,A6),COUNTIF('Itemization 202308'!I:I,A6)) -> 50 | C6: =(B6/B8) -> 0.18726592 | D6: Visual-based | E6: =SUM(COUNTIF('Itemization 202506'!J:J,D6),COUNTIF('Itemization 202501'!J:J,D6),COUNTIF('Itemization 202408'!J:J,D6),COUNTIF('Itemization 202406'!J:J,D6),COUNTIF('Itemization 202401'!J:J,D6),COUNTIF('Itemization 202308'!J:J,D6),COUNTIF('Itemization 202306'!J:J,D6)) -> 44 | F6: =(E6/E10) -> 0.16479401 | G6: 11.02 | H6: =SUM(COUNTIF('Itemization 202506'!K:K,G6),COUNTIF('Itemization 202501'!K:K,G6),COUNTIF('Itemization 202408'!K:K,G6),COUNTIF('Itemization 202406'!K:K,G6),COUNTIF('Itemization 202401'!K:K,G6),COUNTIF('Itemization 202308'!K:K,G6),COUNTIF('Itemization 202306'!K:K,G6)) -> 38 | I6: =(H6/H16) -> 0.14339623 | J6: 11.01a.2 | K6: =SUM(COUNTIF('Itemization 202506'!L:L,J6),COUNTIF('Itemization 202501'!L:L,J6),COUNTIF('Itemization 202408'!L:L,J6),COUNTIF('Itemization 202406'!L:L,J6),COUNTIF('Itemization 202401'!L:L,J6),COUNTIF('Itemization 202308'!L:L,J6),COUNTIF('Itemization 202306'!L:L,J6)) -> 7 | L6: =(K6/K116) -> 0.026515152 | M6: 2 | N6: =SUM(countif('Itemization 202506'!M:M,M6),countif('Itemization 202501'!M:M,M6),countif('Itemization 202408'!M:M,M6),countif('Itemization 202406'!M:M,M6),countif('Itemization 202401'!M:M,M6),countif('Itemization 202308'!M:M,M6),countif('Itemization 202306'!M:M,M6)) -> 21 | O6: =(N6/N23) -> 0.088235294 | P6: No | Q6: =SUM(countif('Itemization 202506'!N:N,P6),countif('Itemization 202501'!N:N,P6),countif('Itemization 202408'!N:N,P6),countif('Itemization 202406'!N:N,P6),countif('Itemization 202401'!N:N,P6),countif('Itemization 202308'!N:N,P6),countif('Itemization 202306'!N:N,P6)) -> 84 | R6: =(Q6/Q7) -> 0.31939164
A7: Both | B7: =SUM(COUNTIF('Itemization 202506'!I:I,A7),COUNTIF('Itemization 202501'!I:I,A7),COUNTIF('Itemization 202408'!I:I,A7),COUNTIF('Itemization 202406'!I:I,A7),COUNTIF('Itemization 202401'!I:I,A7),COUNTIF('Itemization 202306'!I:I,A7),COUNTIF('Itemization 202308'!I:I,A7)) -> 7 | C7: =(B7/B8) -> 0.026217228 | D7: Data-based | E7: =SUM(COUNTIF('Itemization 202506'!J:J,D7),COUNTIF('Itemization 202501'!J:J,D7),COUNTIF('Itemization 202408'!J:J,D7),COUNTIF('Itemization 202406'!J:J,D7),COUNTIF('Itemization 202401'!J:J,D7),COUNTIF('Itemization 202308'!J:J,D7),COUNTIF('Itemization 202306'!J:J,D7)) -> 6 | F7: =(E7/E10) -> 0.02247191 | G7: 11.03 | H7: =SUM(COUNTIF('Itemization 202506'!K:K,G7),COUNTIF('Itemization 202501'!K:K,G7),COUNTIF('Itemization 202408'!K:K,G7),COUNTIF('Itemization 202406'!K:K,G7),COUNTIF('Itemization 202401'!K:K,G7),COUNTIF('Itemization 202308'!K:K,G7),COUNTIF('Itemization 202306'!K:K,G7)) -> 36 | I7: =(H7/H16) -> 0.13584906 | J7: 11.01b.1 | K7: =SUM(COUNTIF('Itemization 202506'!L:L,J7),COUNTIF('Itemization 202501'!L:L,J7),COUNTIF('Itemization 202408'!L:L,J7),COUNTIF('Itemization 202406'!L:L,J7),COUNTIF('Itemization 202401'!L:L,J7),COUNTIF('Itemization 202308'!L:L,J7),COUNTIF('Itemization 202306'!L:L,J7)) -> 0 | L7: =(K7/K116) -> 0 | M7: 3 | N7: =SUM(countif('Itemization 202506'!M:M,M7),countif('Itemization 202501'!M:M,M7),countif('Itemization 202408'!M:M,M7),countif('Itemization 202406'!M:M,M7),countif('Itemization 202401'!M:M,M7),countif('Itemization 202308'!M:M,M7),countif('Itemization 202306'!M:M,M7)) -> 8 | O7: =(N7/N23) -> 0.033613445 | P7: Total | Q7: =SUM(Q5:Q6) -> 263 | R7: =SUM(R5:R6) -> 1
A8: Total | B8: =SUM(B5:B7) -> 267 | C8: =SUM(C5:C7) -> 1 | D8: Map-based | E8: =SUM(COUNTIF('Itemization 202506'!J:J,D8),COUNTIF('Itemization 202501'!J:J,D8),COUNTIF('Itemization 202408'!J:J,D8),COUNTIF('Itemization 202406'!J:J,D8),COUNTIF('Itemization 202401'!J:J,D8),COUNTIF('Itemization 202308'!J:J,D8),COUNTIF('Itemization 202306'!J:J,D8)) -> 16 | F8: =(E8/E10) -> 0.059925094 | G8: 11.04 | H8: =SUM(COUNTIF('Itemization 202506'!K:K,G8),COUNTIF('Itemization 202501'!K:K,G8),COUNTIF('Itemization 202408'!K:K,G8),COUNTIF('Itemization 202406'!K:K,G8),COUNTIF('Itemization 202401'!K:K,G8),COUNTIF('Itemization 202308'!K:K,G8),COUNTIF('Itemization 202306'!K:K,G8)) -> 18 | I8: =(H8/H16) -> 0.067924528 | J8: 11.01b.2 | K8: =SUM(COUNTIF('Itemization 202506'!L:L,J8),COUNTIF('Itemization 202501'!L:L,J8),COUNTIF('Itemization 202408'!L:L,J8),COUNTIF('Itemization 202406'!L:L,J8),COUNTIF('Itemization 202401'!L:L,J8),COUNTIF('Itemization 202308'!L:L,J8),COUNTIF('Itemization 202306'!L:L,J8)) -> 2 | L8: =(K8/K116) -> 0.0075757576 | M8: 4 | N8: =SUM(countif('Itemization 202506'!M:M,M8),countif('Itemization 202501'!M:M,M8),countif('Itemization 202408'!M:M,M8),countif('Itemization 202406'!M:M,M8),countif('Itemization 202401'!M:M,M8),countif('Itemization 202308'!M:M,M8),countif('Itemization 202306'!M:M,M8)) -> 9 | O8: =(N8/N23) -> 0.037815126
D9: Multiple | E9: =SUM(COUNTIF('Itemization 202506'!J:J,D9),COUNTIF('Itemization 202501'!J:J,D9),COUNTIF('Itemization 202408'!J:J,D9),COUNTIF('Itemization 202406'!J:J,D9),COUNTIF('Itemization 202401'!J:J,D9),COUNTIF('Itemization 202308'!J:J,D9),COUNTIF('Itemization 202306'!J:J,D9)) -> 10 | F9: =(E9/E10) -> 0.037453184 | G9: 11.05 | H9: =SUM(COUNTIF('Itemization 202506'!K:K,G9),COUNTIF('Itemization 202501'!K:K,G9),COUNTIF('Itemization 202408'!K:K,G9),COUNTIF('Itemization 202406'!K:K,G9),COUNTIF('Itemization 202401'!K:K,G9),COUNTIF('Itemization 202308'!K:K,G9),COUNTIF('Itemization 202306'!K:K,G9)) -> 31 | I9: =(H9/H16) -> 0.11698113 | J9: 11.01b.3 | K9: =SUM(COUNTIF('Itemization 202506'!L:L,J9),COUNTIF('Itemization 202501'!L:L,J9),COUNTIF('Itemization 202408'!L:L,J9),COUNTIF('Itemization 202406'!L:L,J9),COUNTIF('Itemization 202401'!L:L,J9),COUNTIF('Itemization 202308'!L:L,J9),COUNTIF('Itemization 202306'!L:L,J9)) -> 0 | L9: =(K9/K116) -> 0 | M9: 5 | N9: =SUM(countif('Itemization 202506'!M:M,M9),countif('Itemization 202501'!M:M,M9),countif('Itemization 202408'!M:M,M9),countif('Itemization 202406'!M:M,M9),countif('Itemization 202401'!M:M,M9),countif('Itemization 202308'!M:M,M9),countif('Itemization 202306'!M:M,M9)) -> 2 | O9: =(N9/N23) -> 0.0084033613
D10: Total | E10: =SUM(E5:E9) -> 267 | F10: =SUM(F5:F9) -> 1 | G10: 11.06 | H10: =SUM(COUNTIF('Itemization 202506'!K:K,G10),COUNTIF('Itemization 202501'!K:K,G10),COUNTIF('Itemization 202408'!K:K,G10),COUNTIF('Itemization 202406'!K:K,G10),COUNTIF('Itemization 202401'!K:K,G10),COUNTIF('Itemization 202308'!K:K,G10),COUNTIF('Itemization 202306'!K:K,G10)) -> 34 | I10: =(H10/H16) -> 0.12830189 | J10: 11.01c.1 | K10: =SUM(COUNTIF('Itemization 202506'!L:L,J10),COUNTIF('Itemization 202501'!L:L,J10),COUNTIF('Itemization 202408'!L:L,J10),COUNTIF('Itemization 202406'!L:L,J10),COUNTIF('Itemization 202401'!L:L,J10),COUNTIF('Itemization 202308'!L:L,J10),COUNTIF('Itemization 202306'!L:L,J10)) -> 0 | L10: =(K10/K116) -> 0 | M10: 6 | N10: =SUM(countif('Itemization 202506'!M:M,M10),countif('Itemization 202501'!M:M,M10),countif('Itemization 202408'!M:M,M10),countif('Itemization 202406'!M:M,M10),countif('Itemization 202401'!M:M,M10),countif('Itemization 202308'!M:M,M10),countif('Itemization 202306'!M:M,M10)) -> 6 | O10: =(N10/N23) -> 0.025210084
G11: 11.07 | H11: =SUM(COUNTIF('Itemization 202506'!K:K,G11),COUNTIF('Itemization 202501'!K:K,G11),COUNTIF('Itemization 202408'!K:K,G11),COUNTIF('Itemization 202406'!K:K,G11),COUNTIF('Itemization 202401'!K:K,G11),COUNTIF('Itemization 202308'!K:K,G11),COUNTIF('Itemization 202306'!K:K,G11)) -> 24 | I11: =(H11/H16) -> 0.090566038 | J11: 11.01c.2 | K11: =SUM(COUNTIF('Itemization 202506'!L:L,J11),COUNTIF('Itemization 202501'!L:L,J11),COUNTIF('Itemization 202408'!L:L,J11),COUNTIF('Itemization 202406'!L:L,J11),COUNTIF('Itemization 202401'!L:L,J11),COUNTIF('Itemization 202308'!L:L,J11),COUNTIF('Itemization 202306'!L:L,J11)) -> 2 | L11: =(K11/K116) -> 0.0075757576 | M11: 7 | N11: =SUM(countif('Itemization 202506'!M:M,M11),countif('Itemization 202501'!M:M,M11),countif('Itemization 202408'!M:M,M11),countif('Itemization 202406'!M:M,M11),countif('Itemization 202401'!M:M,M11),countif('Itemization 202308'!M:M,M11),countif('Itemization 202306'!M:M,M11)) -> 24 | O11: =(N11/N23) -> 0.10084034
G12: 11.08 | H12: =SUM(COUNTIF('Itemization 202506'!K:K,G12),COUNTIF('Itemization 202501'!K:K,G12),COUNTIF('Itemization 202408'!K:K,G12),COUNTIF('Itemization 202406'!K:K,G12),COUNTIF('Itemization 202401'!K:K,G12),COUNTIF('Itemization 202308'!K:K,G12),COUNTIF('Itemization 202306'!K:K,G12)) -> 14 | I12: =(H12/H16) -> 0.052830189 | J12: 11.02a.1 | K12: =SUM(COUNTIF('Itemization 202506'!L:L,J12),COUNTIF('Itemization 202501'!L:L,J12),COUNTIF('Itemization 202408'!L:L,J12),COUNTIF('Itemization 202406'!L:L,J12),COUNTIF('Itemization 202401'!L:L,J12),COUNTIF('Itemization 202308'!L:L,J12),COUNTIF('Itemization 202306'!L:L,J12)) -> 10 | L12: =(K12/K116) -> 0.037878788 | M12: 8 | N12: =SUM(countif('Itemization 202506'!M:M,M12),countif('Itemization 202501'!M:M,M12),countif('Itemization 202408'!M:M,M12),countif('Itemization 202406'!M:M,M12),countif('Itemization 202401'!M:M,M12),countif('Itemization 202308'!M:M,M12),countif('Itemization 202306'!M:M,M12)) -> 38 | O12: =(N12/N23) -> 0.15966387
G13: 11.09 | H13: =SUM(COUNTIF('Itemization 202506'!K:K,G13),COUNTIF('Itemization 202501'!K:K,G13),COUNTIF('Itemization 202408'!K:K,G13),COUNTIF('Itemization 202406'!K:K,G13),COUNTIF('Itemization 202401'!K:K,G13),COUNTIF('Itemization 202308'!K:K,G13),COUNTIF('Itemization 202306'!K:K,G13)) -> 27 | I13: =(H13/H16) -> 0.10188679 | J13: 11.02b.1 | K13: =SUM(COUNTIF('Itemization 202506'!L:L,J13),COUNTIF('Itemization 202501'!L:L,J13),COUNTIF('Itemization 202408'!L:L,J13),COUNTIF('Itemization 202406'!L:L,J13),COUNTIF('Itemization 202401'!L:L,J13),COUNTIF('Itemization 202308'!L:L,J13),COUNTIF('Itemization 202306'!L:L,J13)) -> 2 | L13: =(K13/K116) -> 0.0075757576 | M13: 9 | N13: =SUM(countif('Itemization 202506'!M:M,M13),countif('Itemization 202501'!M:M,M13),countif('Itemization 202408'!M:M,M13),countif('Itemization 202406'!M:M,M13),countif('Itemization 202401'!M:M,M13),countif('Itemization 202308'!M:M,M13),countif('Itemization 202306'!M:M,M13)) -> 12 | O13: =(N13/N23) -> 0.050420168
G14: 11.10 | H14: =SUM(COUNTIF('Itemization 202506'!K:K,G14),COUNTIF('Itemization 202501'!K:K,G14),COUNTIF('Itemization 202408'!K:K,G14),COUNTIF('Itemization 202406'!K:K,G14),COUNTIF('Itemization 202401'!K:K,G14),COUNTIF('Itemization 202308'!K:K,G14),COUNTIF('Itemization 202306'!K:K,G14)) -> 26 | I14: =(H14/H16) -> 0.098113208 | J14: 11.02b.2 | K14: =SUM(COUNTIF('Itemization 202506'!L:L,J14),COUNTIF('Itemization 202501'!L:L,J14),COUNTIF('Itemization 202408'!L:L,J14),COUNTIF('Itemization 202406'!L:L,J14),COUNTIF('Itemization 202401'!L:L,J14),COUNTIF('Itemization 202308'!L:L,J14),COUNTIF('Itemization 202306'!L:L,J14)) -> 0 | L14: =(K14/K116) -> 0 | M14: 10 | N14: =SUM(countif('Itemization 202506'!M:M,M14),countif('Itemization 202501'!M:M,M14),countif('Itemization 202408'!M:M,M14),countif('Itemization 202406'!M:M,M14),countif('Itemization 202401'!M:M,M14),countif('Itemization 202308'!M:M,M14),countif('Itemization 202306'!M:M,M14)) -> 6 | O14: =(N14/N23) -> 0.025210084
G15: 11.11 | H15: =SUM(COUNTIF('Itemization 202506'!K:K,G15),COUNTIF('Itemization 202501'!K:K,G15),COUNTIF('Itemization 202408'!K:K,G15),COUNTIF('Itemization 202406'!K:K,G15),COUNTIF('Itemization 202401'!K:K,G15),COUNTIF('Itemization 202308'!K:K,G15),COUNTIF('Itemization 202306'!K:K,G15)) -> 6 | I15: =(H15/H16) -> 0.022641509 | J15: 11.02c.1 | K15: =SUM(COUNTIF('Itemization 202506'!L:L,J15),COUNTIF('Itemization 202501'!L:L,J15),COUNTIF('Itemization 202408'!L:L,J15),COUNTIF('Itemization 202406'!L:L,J15),COUNTIF('Itemization 202401'!L:L,J15),COUNTIF('Itemization 202308'!L:L,J15),COUNTIF('Itemization 202306'!L:L,J15)) -> 0 | L15: =(K15/K116) -> 0 | M15: 11 | N15: =SUM(countif('Itemization 202506'!M:M,M15),countif('Itemization 202501'!M:M,M15),countif('Itemization 202408'!M:M,M15),countif('Itemization 202406'!M:M,M15),countif('Itemization 202401'!M:M,M15),countif('Itemization 202308'!M:M,M15),countif('Itemization 202306'!M:M,M15)) -> 2 | O15: =(N15/N23) -> 0.0084033613
G16: Total | H16: =SUM(H5:H15) -> 265 | I16: =sum(I5:I15) -> 1 | J16: 11.02c.2 | K16: =SUM(COUNTIF('Itemization 202506'!L:L,J16),COUNTIF('Itemization 202501'!L:L,J16),COUNTIF('Itemization 202408'!L:L,J16),COUNTIF('Itemization 202406'!L:L,J16),COUNTIF('Itemization 202401'!L:L,J16),COUNTIF('Itemization 202308'!L:L,J16),COUNTIF('Itemization 202306'!L:L,J16)) -> 2 | L16: =(K16/K116) -> 0.0075757576 | M16: 12 | N16: =SUM(countif('Itemization 202506'!M:M,M16),countif('Itemization 202501'!M:M,M16),countif('Itemization 202408'!M:M,M16),countif('Itemization 202406'!M:M,M16),countif('Itemization 202401'!M:M,M16),countif('Itemization 202308'!M:M,M16),countif('Itemization 202306'!M:M,M16)) -> 16 | O16: =(N16/N23) -> 0.067226891
J17: 11.02c.3 | K17: =SUM(COUNTIF('Itemization 202506'!L:L,J17),COUNTIF('Itemization 202501'!L:L,J17),COUNTIF('Itemization 202408'!L:L,J17),COUNTIF('Itemization 202406'!L:L,J17),COUNTIF('Itemization 202401'!L:L,J17),COUNTIF('Itemization 202308'!L:L,J17),COUNTIF('Itemization 202306'!L:L,J17)) -> 3 | L17: =(K17/K116) -> 0.011363636 | M17: 13 | N17: =SUM(countif('Itemization 202506'!M:M,M17),countif('Itemization 202501'!M:M,M17),countif('Itemization 202408'!M:M,M17),countif('Itemization 202406'!M:M,M17),countif('Itemization 202401'!M:M,M17),countif('Itemization 202308'!M:M,M17),countif('Itemization 202306'!M:M,M17)) -> 11 | O17: =(N17/N23) -> 0.046218487
J18: 11.02c.4 | K18: =SUM(COUNTIF('Itemization 202506'!L:L,J18),COUNTIF('Itemization 202501'!L:L,J18),COUNTIF('Itemization 202408'!L:L,J18),COUNTIF('Itemization 202406'!L:L,J18),COUNTIF('Itemization 202401'!L:L,J18),COUNTIF('Itemization 202308'!L:L,J18),COUNTIF('Itemization 202306'!L:L,J18)) -> 8 | L18: =(K18/K116) -> 0.03030303 | M18: 14 | N18: =SUM(countif('Itemization 202506'!M:M,M18),countif('Itemization 202501'!M:M,M18),countif('Itemization 202408'!M:M,M18),countif('Itemization 202406'!M:M,M18),countif('Itemization 202401'!M:M,M18),countif('Itemization 202308'!M:M,M18),countif('Itemization 202306'!M:M,M18)) -> 14 | O18: =(N18/N23) -> 0.058823529
A19: Color Code | J19: 11.02c.5 | K19: =SUM(COUNTIF('Itemization 202506'!L:L,J19),COUNTIF('Itemization 202501'!L:L,J19),COUNTIF('Itemization 202408'!L:L,J19),COUNTIF('Itemization 202406'!L:L,J19),COUNTIF('Itemization 202401'!L:L,J19),COUNTIF('Itemization 202308'!L:L,J19),COUNTIF('Itemization 202306'!L:L,J19)) -> 1 | L19: =(K19/K116) -> 0.0037878788 | M19: 15 | N19: =SUM(countif('Itemization 202506'!M:M,M19),countif('Itemization 202501'!M:M,M19),countif('Itemization 202408'!M:M,M19),countif('Itemization 202406'!M:M,M19),countif('Itemization 202401'!M:M,M19),countif('Itemization 202308'!M:M,M19),countif('Itemization 202306'!M:M,M19)) -> 10 | O19: =(N19/N23) -> 0.042016807
A20: Blue: Most common | J20: 11.02d.1 | K20: =SUM(COUNTIF('Itemization 202506'!L:L,J20),COUNTIF('Itemization 202501'!L:L,J20),COUNTIF('Itemization 202408'!L:L,J20),COUNTIF('Itemization 202406'!L:L,J20),COUNTIF('Itemization 202401'!L:L,J20),COUNTIF('Itemization 202308'!L:L,J20),COUNTIF('Itemization 202306'!L:L,J20)) -> 5 | L20: =(K20/K116) -> 0.018939394 | M20: 16 | N20: =SUM(countif('Itemization 202506'!M:M,M20),countif('Itemization 202501'!M:M,M20),countif('Itemization 202408'!M:M,M20),countif('Itemization 202406'!M:M,M20),countif('Itemization 202401'!M:M,M20),countif('Itemization 202308'!M:M,M20),countif('Itemization 202306'!M:M,M20)) -> 1 | O20: =(N20/N23) -> 0.0042016807
A21: Green: 2nd most common | J21: 11.02d.2 | K21: =SUM(COUNTIF('Itemization 202506'!L:L,J21),COUNTIF('Itemization 202501'!L:L,J21),COUNTIF('Itemization 202408'!L:L,J21),COUNTIF('Itemization 202406'!L:L,J21),COUNTIF('Itemization 202401'!L:L,J21),COUNTIF('Itemization 202308'!L:L,J21),COUNTIF('Itemization 202306'!L:L,J21)) -> 0 | L21: =(K21/K116) -> 0 | M21: 17 | N21: =SUM(countif('Itemization 202506'!M:M,M21),countif('Itemization 202501'!M:M,M21),countif('Itemization 202408'!M:M,M21),countif('Itemization 202406'!M:M,M21),countif('Itemization 202401'!M:M,M21),countif('Itemization 202308'!M:M,M21),countif('Itemization 202306'!M:M,M21)) -> 13 | O21: =(N21/N23) -> 0.054621849
A22: Yellow: 3rd most common | J22: 11.02d.3 | K22: =SUM(COUNTIF('Itemization 202506'!L:L,J22),COUNTIF('Itemization 202501'!L:L,J22),COUNTIF('Itemization 202408'!L:L,J22),COUNTIF('Itemization 202406'!L:L,J22),COUNTIF('Itemization 202401'!L:L,J22),COUNTIF('Itemization 202308'!L:L,J22),COUNTIF('Itemization 202306'!L:L,J22)) -> 3 | L22: =(K22/K116) -> 0.011363636 | M22: 18 | N22: =SUM(countif('Itemization 202506'!M:M,M22),countif('Itemization 202501'!M:M,M22),countif('Itemization 202408'!M:M,M22),countif('Itemization 202406'!M:M,M22),countif('Itemization 202401'!M:M,M22),countif('Itemization 202308'!M:M,M22),countif('Itemization 202306'!M:M,M22)) -> 22 | O22: =(N22/N23) -> 0.092436975
A23: Clear: Less than 3rd | J23: 11.02d.4 | K23: =SUM(COUNTIF('Itemization 202506'!L:L,J23),COUNTIF('Itemization 202501'!L:L,J23),COUNTIF('Itemization 202408'!L:L,J23),COUNTIF('Itemization 202406'!L:L,J23),COUNTIF('Itemization 202401'!L:L,J23),COUNTIF('Itemization 202308'!L:L,J23),COUNTIF('Itemization 202306'!L:L,J23)) -> 6 | L23: =(K23/K116) -> 0.022727273 | M23: Total | N23: =SUM(N5:N22) -> 238 | O23: =SUM(O4:O22) -> 1
A24: Red: Unused | J24: 11.03a.1 | K24: =SUM(COUNTIF('Itemization 202506'!L:L,J24),COUNTIF('Itemization 202501'!L:L,J24),COUNTIF('Itemization 202408'!L:L,J24),COUNTIF('Itemization 202406'!L:L,J24),COUNTIF('Itemization 202401'!L:L,J24),COUNTIF('Itemization 202308'!L:L,J24),COUNTIF('Itemization 202306'!L:L,J24)) -> 15 | L24: =(K24/K116) -> 0.056818182
J25: 11.03a.2 | K25: =SUM(COUNTIF('Itemization 202506'!L:L,J25),COUNTIF('Itemization 202501'!L:L,J25),COUNTIF('Itemization 202408'!L:L,J25),COUNTIF('Itemization 202406'!L:L,J25),COUNTIF('Itemization 202401'!L:L,J25),COUNTIF('Itemization 202308'!L:L,J25),COUNTIF('Itemization 202306'!L:L,J25)) -> 0 | L25: =(K25/K116) -> 0
J26: 11.03a.3 | K26: =SUM(COUNTIF('Itemization 202506'!L:L,J26),COUNTIF('Itemization 202501'!L:L,J26),COUNTIF('Itemization 202408'!L:L,J26),COUNTIF('Itemization 202406'!L:L,J26),COUNTIF('Itemization 202401'!L:L,J26),COUNTIF('Itemization 202308'!L:L,J26),COUNTIF('Itemization 202306'!L:L,J26)) -> 2 | L26: =(K26/K116) -> 0.0075757576
J27: 11.03b.1 | K27: =SUM(COUNTIF('Itemization 202506'!L:L,J27),COUNTIF('Itemization 202501'!L:L,J27),COUNTIF('Itemization 202408'!L:L,J27),COUNTIF('Itemization 202406'!L:L,J27),COUNTIF('Itemization 202401'!L:L,J27),COUNTIF('Itemization 202308'!L:L,J27),COUNTIF('Itemization 202306'!L:L,J27)) -> 0 | L27: =(K27/K116) -> 0
J28: 11.03b.2 | K28: =SUM(COUNTIF('Itemization 202506'!L:L,J28),COUNTIF('Itemization 202501'!L:L,J28),COUNTIF('Itemization 202408'!L:L,J28),COUNTIF('Itemization 202406'!L:L,J28),COUNTIF('Itemization 202401'!L:L,J28),COUNTIF('Itemization 202308'!L:L,J28),COUNTIF('Itemization 202306'!L:L,J28)) -> 4 | L28: =(K28/K116) -> 0.015151515
J29: 11.03b.3 | K29: =SUM(COUNTIF('Itemization 202506'!L:L,J29),COUNTIF('Itemization 202501'!L:L,J29),COUNTIF('Itemization 202408'!L:L,J29),COUNTIF('Itemization 202406'!L:L,J29),COUNTIF('Itemization 202401'!L:L,J29),COUNTIF('Itemization 202308'!L:L,J29),COUNTIF('Itemization 202306'!L:L,J29)) -> 3 | L29: =(K29/K116) -> 0.011363636
J30: 11.03b.4 | K30: =SUM(COUNTIF('Itemization 202506'!L:L,J30),COUNTIF('Itemization 202501'!L:L,J30),COUNTIF('Itemization 202408'!L:L,J30),COUNTIF('Itemization 202406'!L:L,J30),COUNTIF('Itemization 202401'!L:L,J30),COUNTIF('Itemization 202308'!L:L,J30),COUNTIF('Itemization 202306'!L:L,J30)) -> 5 | L30: =(K30/K116) -> 0.018939394
J31: 11.03c.1 | K31: =SUM(COUNTIF('Itemization 202506'!L:L,J31),COUNTIF('Itemization 202501'!L:L,J31),COUNTIF('Itemization 202408'!L:L,J31),COUNTIF('Itemization 202406'!L:L,J31),COUNTIF('Itemization 202401'!L:L,J31),COUNTIF('Itemization 202308'!L:L,J31),COUNTIF('Itemization 202306'!L:L,J31)) -> 1 | L31: =(K31/K116) -> 0.0037878788
J32: 11.03c.2 | K32: =SUM(COUNTIF('Itemization 202506'!L:L,J32),COUNTIF('Itemization 202501'!L:L,J32),COUNTIF('Itemization 202408'!L:L,J32),COUNTIF('Itemization 202406'!L:L,J32),COUNTIF('Itemization 202401'!L:L,J32),COUNTIF('Itemization 202308'!L:L,J32),COUNTIF('Itemization 202306'!L:L,J32)) -> 6 | L32: =(K32/K116) -> 0.022727273
J33: 11.03c.3 | K33: =SUM(COUNTIF('Itemization 202506'!L:L,J33),COUNTIF('Itemization 202501'!L:L,J33),COUNTIF('Itemization 202408'!L:L,J33),COUNTIF('Itemization 202406'!L:L,J33),COUNTIF('Itemization 202401'!L:L,J33),COUNTIF('Itemization 202308'!L:L,J33),COUNTIF('Itemization 202306'!L:L,J33)) -> 0 | L33: =(K33/K116) -> 0
J34: 11.04a.1 | K34: =SUM(COUNTIF('Itemization 202506'!L:L,J34),COUNTIF('Itemization 202501'!L:L,J34),COUNTIF('Itemization 202408'!L:L,J34),COUNTIF('Itemization 202406'!L:L,J34),COUNTIF('Itemization 202401'!L:L,J34),COUNTIF('Itemization 202308'!L:L,J34),COUNTIF('Itemization 202306'!L:L,J34)) -> 2 | L34: =(K34/K116) -> 0.0075757576
J35: 11.04a.2 | K35: =SUM(COUNTIF('Itemization 202506'!L:L,J35),COUNTIF('Itemization 202501'!L:L,J35),COUNTIF('Itemization 202408'!L:L,J35),COUNTIF('Itemization 202406'!L:L,J35),COUNTIF('Itemization 202401'!L:L,J35),COUNTIF('Itemization 202308'!L:L,J35),COUNTIF('Itemization 202306'!L:L,J35)) -> 3 | L35: =(K35/K116) -> 0.011363636
J36: 11.04a.3 | K36: =SUM(COUNTIF('Itemization 202506'!L:L,J36),COUNTIF('Itemization 202501'!L:L,J36),COUNTIF('Itemization 202408'!L:L,J36),COUNTIF('Itemization 202406'!L:L,J36),COUNTIF('Itemization 202401'!L:L,J36),COUNTIF('Itemization 202308'!L:L,J36),COUNTIF('Itemization 202306'!L:L,J36)) -> 0 | L36: =(K36/K116) -> 0
J37: 11.04a.4 | K37: =SUM(COUNTIF('Itemization 202506'!L:L,J37),COUNTIF('Itemization 202501'!L:L,J37),COUNTIF('Itemization 202408'!L:L,J37),COUNTIF('Itemization 202406'!L:L,J37),COUNTIF('Itemization 202401'!L:L,J37),COUNTIF('Itemization 202308'!L:L,J37),COUNTIF('Itemization 202306'!L:L,J37)) -> 4 | L37: =(K37/K116) -> 0.015151515
J38: 11.04b.1 | K38: =SUM(COUNTIF('Itemization 202506'!L:L,J38),COUNTIF('Itemization 202501'!L:L,J38),COUNTIF('Itemization 202408'!L:L,J38),COUNTIF('Itemization 202406'!L:L,J38),COUNTIF('Itemization 202401'!L:L,J38),COUNTIF('Itemization 202308'!L:L,J38),COUNTIF('Itemization 202306'!L:L,J38)) -> 4 | L38: =(K38/K116) -> 0.015151515
J39: 11.04c.1 | K39: =SUM(COUNTIF('Itemization 202506'!L:L,J39),COUNTIF('Itemization 202501'!L:L,J39),COUNTIF('Itemization 202408'!L:L,J39),COUNTIF('Itemization 202406'!L:L,J39),COUNTIF('Itemization 202401'!L:L,J39),COUNTIF('Itemization 202308'!L:L,J39),COUNTIF('Itemization 202306'!L:L,J39)) -> 3 | L39: =(K39/K116) -> 0.011363636
J40: 11.04c.2 | K40: =SUM(COUNTIF('Itemization 202506'!L:L,J40),COUNTIF('Itemization 202501'!L:L,J40),COUNTIF('Itemization 202408'!L:L,J40),COUNTIF('Itemization 202406'!L:L,J40),COUNTIF('Itemization 202401'!L:L,J40),COUNTIF('Itemization 202308'!L:L,J40),COUNTIF('Itemization 202306'!L:L,J40)) -> 1 | L40: =(K40/K116) -> 0.0037878788
...

Sheet Visualization All Exams
A63: Primary or Secondary | B63: 45809 | C63: 45658 | D63: 45505 | E63: 45444 | F63: 45292 | G63: 45139 | H63: 45078
A64: Primary | B64: =COUNTIF('Itemization 202506'!I:I,A64) -> 26 | C64: =COUNTIF('Itemization 202501'!I:I,A64) -> 36 | D64: =COUNTIF('Itemization 202408'!I:I,A64) -> 26 | E64: =COUNTIF('Itemization 202406'!I:I,A64) -> 36 | F64: 34 | G64: 26 | H64: 26
A65: Secondary | B65: =COUNTIF('Itemization 202506'!I:I,A65) -> 12 | C65: =COUNTIF('Itemization 202501'!I:I,A65) -> 0 | D65: =COUNTIF('Itemization 202408'!I:I,A65) -> 11 | E65: =COUNTIF('Itemization 202406'!I:I,A65) -> 2 | F65: 5 | G65: 11 | H65: 9
A66: Both | B66: =COUNTIF('Itemization 202506'!I:I,A66) -> 0 | C66: =COUNTIF('Itemization 202501'!I:I,A66) -> 2 | D66: =COUNTIF('Itemization 202408'!I:I,A66) -> 1 | E66: =COUNTIF('Itemization 202406'!I:I,A66) -> 0 | F66: 0 | G66: 1 | H66: 3
A68: General Stimuli Type | B68: 45809 | C68: 45658 | D68: 45505 | E68: 45444 | F68: 45292 | G68: 45139 | H68: 45078 | J68: Color Code
A69: Text-based | B69: 26 | C69: 33 | D69: 28 | E69: 25 | F69: 27 | G69: 26 | H69: 26 | J69: Blue: Most common
A70: Visual-based | B70: 7 | C70: 3 | D70: 4 | E70: 11 | F70: 8 | G70: 4 | H70: 7 | J70: Green: 2nd most common
A71: Data-based | B71: 0 | C71: 0 | D71: 5 | E71: 0 | F71: 1 | G71: 0 | H71: 0 | J71: Yellow: 3rd most common
A72: Map-based | B72: 4 | C72: 0 | D72: 0 | E72: 0 | F72: 3 | G72: 7 | H72: 2 | J72: Orange: Less than 3rd
A73: Multiple | B73: 1 | C73: 2 | D73: 1 | E73: 2 | F73: 0 | G73: 1 | H73: 3 | J73: Red: Unused
A75: Framework Unit | B75: 45809 | C75: 45658 | D75: 45505 | E75: 45444 | F75: 45292 | G75: 45139 | H75: 45078
A76: 11.01 | B76: 2 | C76: 2 | D76: 4 | E76: 1 | F76: 2 | G76: 0 | H76: 2
A77: 11.02 | B77: 6 | C77: 6 | D77: 6 | E77: 5 | F77: 3 | G77: 6 | H77: 4
A78: 11.03 | B78: 8 | C78: 4 | D78: 4 | E78: 4 | F78: 5 | G78: 6 | H78: 5
A79: 11.04 | B79: 2 | C79: 2 | D79: 0 | E79: 3 | F79: 4 | G79: 4 | H79: 2
A80: 11.05 | B80: 5 | C80: 4 | D80: 4 | E80: 6 | F80: 3 | G80: 1 | H80: 6
A81: 11.06 | B81: 4 | C81: 8 | D81: 7 | E81: 6 | F81: 1 | G81: 3 | H81: 6
A82: 11.07 | B82: 2 | C82: 2 | D82: 2 | E82: 3 | F82: 8 | G82: 4 | H82: 2
A83: 11.08 | B83: 1 | C83: 2 | D83: 1 | E83: 6 | F83: 0 | G83: 2 | H83: 2
A84: 11.09 | B84: 6 | C84: 4 | D84: 4 | E84: 3 | F84: 3 | G84: 3 | H84: 4
A85: 11.10 | B85: 2 | C85: 2 | D85: 4 | E85: 1 | F85: 9 | G85: 6 | H85: 5
A86: 11.11 | B86: 0 | C86: 2 | D86: 2 | E86: 0 | F86: 0 | G86: 2 | H86: 0
A88: Task Model | B88: 45809 | C88: 45658 | D88: 45505 | E88: 45444 | F88: 45292 | G88: 45139 | H88: 45078
A89: 1 | B89: 2 | C89: =countif('Itemization 202501'!$M$3:$M$41,A89) -> 3 | D89: 4 | E89: 3 | F89: 7 | G89: 2 | H89: 2
A90: 2 | B90: 5 | C90: =countif('Itemization 202501'!$M$3:$M$41,A90) -> 4 | D90: 0 | E90: 3 | F90: 3 | G90: 2 | H90: 4
A91: 3 | B91: 0 | C91: =countif('Itemization 202501'!$M$3:$M$41,A91) -> 1 | D91: 2 | E91: 1 | F91: 0 | G91: 3 | H91: 0
A92: 4 | B92: 0 | C92: =countif('Itemization 202501'!$M$3:$M$41,A92) -> 1 | D92: 2 | E92: 3 | F92: 1 | G92: 1 | H92: 1
A93: 5 | B93: 0 | C93: =countif('Itemization 202501'!$M$3:$M$41,A93) -> 0 | D93: 1 | E93: 0 | F93: 0 | G93: 1 | H93: 0
A94: 6 | B94: 1 | C94: =countif('Itemization 202501'!$M$3:$M$41,A94) -> 1 | D94: 1 | E94: 0 | F94: 0 | G94: 1 | H94: 2
A95: 7 | B95: 4 | C95: =countif('Itemization 202501'!$M$3:$M$41,A95) -> 1 | D95: 8 | E95: 2 | F95: 2 | G95: 4 | H95: 3
A96: 8 | B96: 5 | C96: =countif('Itemization 202501'!$M$3:$M$41,A96) -> 4 | D96: 7 | E96: 3 | F96: 4 | G96: 6 | H96: 9
A97: 9 | B97: 1 | C97: =countif('Itemization 202501'!$M$3:$M$41,A97) -> 2 | D97: 1 | E97: 1 | F97: 2 | G97: 2 | H97: 3
A98: 10 | B98: 0 | C98: =countif('Itemization 202501'!$M$3:$M$41,A98) -> 4 | D98: 0 | E98: 0 | F98: 1 | G98: 0 | H98: 1
A99: 11 | B99: 0 | C99: =countif('Itemization 202501'!$M$3:$M$41,A99) -> 1 | D99: 0 | E99: 0 | F99: 0 | G99: 0 | H99: 1
A100: 12 | B100: 1 | C100: =countif('Itemization 202501'!$M$3:$M$41,A100) -> 0 | D100: 1 | E100: 4 | F100: 3 | G100: 5 | H100: 2
... A106: 18 | B106: 4 | C106: =countif('Itemization 202501'!$M$3:$M$41,A106) -> 6 | D106: 2 | E106: 4 | F106: 4 | G106: 0 | H106: 2
A108: Needs Outside Information | B108: 45809 | C108: 45658 | D108: 45505 | E108: 45444 | F108: 45292 | G108: 45139 | H108: 45078
A109: Yes | B109: 21 | C109: 27 | D109: 29 | E109: 25 | F109: 29 | G109: 22 | H109: 26
A110: No | B110: 14 | C110: 8 | D110: 10 | E110: 14 | F110: 9 | G110: 16 | H110: 13

Sheet Analysis All Part 1
A1: All Exams Part 1 Analysis
A2: Stimuli | J2: Question
A3: Primary or Secondary | D3: General Stimuli Type | G3: Framework Unit | J3: Content Specification | M3: Task Model | P3: Need OI?
B4: # | C4: % | E4: # | F4: % | H4: # | I4: % | K4: # | L4: % | N4: # | O4: % | Q4: # | R4: %
A5: Primary | B5: =SUM(COUNTIF('Itemization 202506'!I3:I30,A5),COUNTIF('Itemization 202501'!I3:I30,A5),COUNTIF('Itemization 202408'!I3:I30,A5),COUNTIF('Itemization 202406'!I3:I30,A5),COUNTIF('Itemization 202401'!I3:I30,A5),COUNTIF('Itemization 202306'!I3:I30,A5),COUNTIF('Itemization 202308'!I3:I30,A5)) -> 164 | C5: =(B5/B8) -> 0.83673469 | D5: Text-based | E5: =SUM(COUNTIF('Itemization 202506'!J3:J30,D5),COUNTIF('Itemization 202501'!J3:J30,D5),COUNTIF('Itemization 202408'!J3:J30,D5),COUNTIF('Itemization 202406'!J3:J30,D5),COUNTIF('Itemization 202401'!J3:J30,D5),COUNTIF('Itemization 202308'!J3:J30,D5),COUNTIF('Itemization 202306'!J3:J30,D5)) -> 137 | F5: =(E5/E10) -> 0.69897959 | G5: 11.01 | H5: =SUM(COUNTIF('Itemization 202506'!K3:K30,G5),COUNTIF('Itemization 202501'!K3:K30,G5),COUNTIF('Itemization 202408'!K3:K30,G5),COUNTIF('Itemization 202406'!K3:K30,G5),COUNTIF('Itemization 202401'!K3:K30,G5),COUNTIF('Itemization 202308'!K3:K30,G5),COUNTIF('Itemization 202306'!K3:K30,G5)) -> 11 | I5: =(H5/H16) -> 0.056122449 | J5: 11.01a.1 | K5: =SUM(COUNTIF('Itemization 202506'!L3:L30,J5),COUNTIF('Itemization 202501'!L3:L30,J5),COUNTIF('Itemization 202408'!L3:L30,J5),COUNTIF('Itemization 202406'!L3:L30,J5),COUNTIF('Itemization 202401'!L3:L30,J5),COUNTIF('Itemization 202308'!L3:L30,J5),COUNTIF('Itemization 202306'!L3:L30,J5)) -> 0 | L5: =(K5/K116) -> 0 | M5: 1 | N5: =SUM(countif('Itemization 202506'!M3:M30,M5),countif('Itemization 202501'!M3:M30,M5),countif('Itemization 202408'!M3:M30,M5),countif('Itemization 202406'!M3:M30,M5),countif('Itemization 202401'!M3:M30,M5),countif('Itemization 202308'!M3:M30,M5),countif('Itemization 202306'!M3:M30,M5)) -> 23 | O5: =(N5/N23) -> 0.11734694 | P5: Yes | Q5: =SUM(countif('Itemization 202506'!N3:N30,P5),countif('Itemization 202501'!N3:N30,P5),countif('Itemization 202408'!N3:N30,P5),countif('Itemization 202406'!N3:N30,P5),countif('Itemization 202401'!N3:N30,P5),countif('Itemization 202308'!N3:N30,P5),countif('Itemization 202306'!N3:N30,P5)) -> 150 | R5: =(Q5/Q7) -> 0.76530612
A6: Secondary | B6: =SUM(COUNTIF('Itemization 202506'!I3:I30,A6),COUNTIF('Itemization 202501'!I3:I30,A6),COUNTIF('Itemization 202408'!I3:I30,A6),COUNTIF('Itemization 202406'!I3:I30,A6),COUNTIF('Itemization 202401'!I3:I30,A6),COUNTIF('Itemization 202306'!I3:I30,A6),COUNTIF('Itemization 202308'!I3:I30,A6)) -> 30 | C6: =(B6/B8) -> 0.15306122 | D6: Visual-based | E6: =SUM(COUNTIF('Itemization 202506'!J3:J30,D6),COUNTIF('Itemization 202501'!J3:J30,D6),COUNTIF('Itemization 202408'!J3:J30,D6),COUNTIF('Itemization 202406'!J3:J30,D6),COUNTIF('Itemization 202401'!J3:J30,D6),COUNTIF('Itemization 202308'!J3:J30,D6),COUNTIF('Itemization 202306'!J3:J30,D6)) -> 39 | F6: =(E6/E10) -> 0.19897959 | G6: 11.02 | H6: =SUM(COUNTIF('Itemization 202506'!K3:K30,G6),COUNTIF('Itemization 202501'!K3:K30,G6),COUNTIF('Itemization 202408'!K3:K30,G6),COUNTIF('Itemization 202406'!K3:K30,G6),COUNTIF('Itemization 202401'!K3:K30,G6),COUNTIF('Itemization 202308'!K3:K30,G6),COUNTIF('Itemization 202306'!K3:K30,G6)) -> 33 | I6: =(H6/H16) -> 0.16836735 | J6: 11.01a.2 | K6: =SUM(COUNTIF('Itemization 202506'!L3:L30,J6),COUNTIF('Itemization 202501'!L3:L30,J6),COUNTIF('Itemization 202408'!L3:L30,J6),COUNTIF('Itemization 202406'!L3:L30,J6),COUNTIF('Itemization 202401'!L3:L30,J6),COUNTIF('Itemization 202308'!L3:L30,J6),COUNTIF('Itemization 202306'!L3:L30,J6)) -> 7 | L6: =(K6/K116) -> 0.035714286 | M6: 2 | N6: =SUM(countif('Itemization 202506'!M3:M30,M6),countif('Itemization 202501'!M3:M30,M6),countif('Itemization 202408'!M3:M30,M6),countif('Itemization 202406'!M3:M30,M6),countif('Itemization 202401'!M3:M30,M6),countif('Itemization 202308'!M3:M30,M6),countif('Itemization 202306'!M3:M30,M6)) -> 19 | O6: =(N6/N23) -> 0.096938776 | P6: No | Q6: =SUM(countif('Itemization 202506'!N3:N30,P6),countif('Itemization 202501'!N3:N30,P6),countif('Itemization 202408'!N3:N30,P6),countif('Itemization 202406'!N3:N30,P6),countif('Itemization 202401'!N3:N30,P6),countif('Itemization 202308'!N3:N30,P6),countif('Itemization 202306'!N3:N30,P6)) -> 46 | R6: =(Q6/Q7) -> 0.23469388
A7: Both | B7: =SUM(COUNTIF('Itemization 202506'!I3:I30,A7),COUNTIF('Itemization 202501'!I3:I30,A7),COUNTIF('Itemization 202408'!I3:I30,A7),COUNTIF('Itemization 202406'!I3:I30,A7),COUNTIF('Itemization 202401'!I3:I30,A7),COUNTIF('Itemization 202306'!I3:I30,A7),COUNTIF('Itemization 202308'!I3:I30,A7)) -> 2 | C7: =(B7/B8) -> 0.010204082 | D7: Data-based | E7: =SUM(COUNTIF('Itemization 202506'!J3:J30,D7),COUNTIF('Itemization 202501'!J3:J30,D7),COUNTIF('Itemization 202408'!J3:J30,D7),COUNTIF('Itemization 202406'!J3:J30,D7),COUNTIF('Itemization 202401'!J3:J30,D7),COUNTIF('Itemization 202308'!J3:J30,D7),COUNTIF('Itemization 202306'!J3:J30,D7)) -> 4 | F7: =(E7/E10) -> 0.020408163 | G7: 11.03 | H7: =SUM(COUNTIF('Itemization 202506'!K3:K30,G7),COUNTIF('Itemization 202501'!K3:K30,G7),COUNTIF('Itemization 202408'!K3:K30,G7),COUNTIF('Itemization 202406'!K3:K30,G7),COUNTIF('Itemization 202401'!K3:K30,G7),COUNTIF('Itemization 202308'!K3:K30,G7),COUNTIF('Itemization 202306'!K3:K30,G7)) -> 26 | I7: =(H7/H16) -> 0.13265306 | J7: 11.01b.1 | K7: =SUM(COUNTIF('Itemization 202506'!L3:L30,J7),COUNTIF('Itemization 202501'!L3:L30,J7),COUNTIF('Itemization 202408'!L3:L30,J7),COUNTIF('Itemization 202406'!L3:L30,J7),COUNTIF('Itemization 202401'!L3:L30,J7),COUNTIF('Itemization 202308'!L3:L30,J7),COUNTIF('Itemization 202306'!L3:L30,J7)) -> 0 | L7: =(K7/K116) -> 0 | M7: 3 | N7: =SUM(countif('Itemization 202506'!M3:M30,M7),countif('Itemization 202501'!M3:M30,M7),countif('Itemization 202408'!M3:M30,M7),countif('Itemization 202406'!M3:M30,M7),countif('Itemization 202401'!M3:M30,M7),countif('Itemization 202308'!M3:M30,M7),countif('Itemization 202306'!M3:M30,M7)) -> 8 | O7: =(N7/N23) -> 0.040816327 | P7: Total | Q7: =SUM(Q5:Q6) -> 196 | R7: =SUM(R5:R6) -> 1
A8: Total | B8: =SUM(B5:B7) -> 196 | C8: =SUM(C5:C7) -> 1 | D8: Map-based | E8: =SUM(COUNTIF('Itemization 202506'!J3:J30,D8),COUNTIF('Itemization 202501'!J3:J30,D8),COUNTIF('Itemization 202408'!J3:J30,D8),COUNTIF('Itemization 202406'!J3:J30,D8),COUNTIF('Itemization 202401'!J3:J30,D8),COUNTIF('Itemization 202308'!J3:J30,D8),COUNTIF('Itemization 202306'!J3:J30,D8)) -> 14 | F8: =(E8/E10) -> 0.071428571 | G8: 11.04 | H8: =SUM(COUNTIF('Itemization 202506'!K3:K30,G8),COUNTIF('Itemization 202501'!K3:K30,G8),COUNTIF('Itemization 202408'!K3:K30,G8),COUNTIF('Itemization 202406'!K3:K30,G8),COUNTIF('Itemization 202401'!K3:K30,G8),COUNTIF('Itemization 202308'!K3:K30,G8),COUNTIF('Itemization 202306'!K3:K30,G8)) -> 10 | I8: =(H8/H16) -> 0.051020408 | J8: 11.01b.2 | K8: =SUM(COUNTIF('Itemization 202506'!L3:L30,J8),COUNTIF('Itemization 202501'!L3:L30,J8),COUNTIF('Itemization 202408'!L3:L30,J8),COUNTIF('Itemization 202406'!L3:L30,J8),COUNTIF('Itemization 202401'!L3:L30,J8),COUNTIF('Itemization 202308'!L3:L30,J8),COUNTIF('Itemization 202306'!L3:L30,J8)) -> 2 | L8: =(K8/K116) -> 0.010204082 | M8: 4 | N8: =SUM(countif('Itemization 202506'!M3:M30,M8),countif('Itemization 202501'!M3:M30,M8),countif('Itemization 202408'!M3:M30,M8),countif('Itemization 202406'!M3:M30,M8),countif('Itemization 202401'!M3:M30,M8),countif('Itemization 202308'!M3:M30,M8),countif('Itemization 202306'!M3:M30,M8)) -> 8 | O8: =(N8/N23) -> 0.040816327
D9: Multiple | E9: =SUM(COUNTIF('Itemization 202506'!J3:J30,D9),COUNTIF('Itemization 202501'!J3:J30,D9),COUNTIF('Itemization 202408'!J3:J30,D9),COUNTIF('Itemization 202406'!J3:J30,D9),COUNTIF('Itemization 202401'!J3:J30,D9),COUNTIF('Itemization 202308'!J3:J30,D9),COUNTIF('Itemization 202306'!J3:J30,D9)) -> 2 | F9: =(E9/E10) -> 0.010204082 | G9: 11.05 | H9: =SUM(COUNTIF('Itemization 202506'!K3:K30,G9),COUNTIF('Itemization 202501'!K3:K30,G9),COUNTIF('Itemization 202408'!K3:K30,G9),COUNTIF('Itemization 202406'!K3:K30,G9),COUNTIF('Itemization 202401'!K3:K30,G9),COUNTIF('Itemization 202308'!K3:K30,G9),COUNTIF('Itemization 202306'!K3:K30,G9)) -> 22 | I9: =(H9/H16) -> 0.1122449 | J9: 11.01b.3 | K9: =SUM(COUNTIF('Itemization 202506'!L3:L30,J9),COUNTIF('Itemization 202501'!L3:L30,J9),COUNTIF('Itemization 202408'!L3:L30,J9),COUNTIF('Itemization 202406'!L3:L30,J9),COUNTIF('Itemization 202401'!L3:L30,J9),COUNTIF('Itemization 202308'!L3:L30,J9),COUNTIF('Itemization 202306'!L3:L30,J9)) -> 0 | L9: =(K9/K116) -> 0 | M9: 5 | N9: =SUM(countif('Itemization 202506'!M3:M30,M9),countif('Itemization 202501'!M3:M30,M9),countif('Itemization 202408'!M3:M30,M9),countif('Itemization 202406'!M3:M30,M9),countif('Itemization 202401'!M3:M30,M9),countif('Itemization 202308'!M3:M30,M9),countif('Itemization 202306'!M3:M30,M9)) -> 2 | O9: =(N9/N23) -> 0.010204082
D10: Total | E10: =SUM(E5:E9) -> 196 | F10: =SUM(F5:F9) -> 1 | G10: 11.06 | H10: =SUM(COUNTIF('Itemization 202506'!K3:K30,G10),COUNTIF('Itemization 202501'!K3:K30,G10),COUNTIF('Itemization 202408'!K3:K30,G10),COUNTIF('Itemization 202406'!K3:K30,G10),COUNTIF('Itemization 202401'!K3:K30,G10),COUNTIF('Itemization 202308'!K3:K30,G10),COUNTIF('Itemization 202306'!K3:K30,G10)) -> 21 | I10: =(H10/H16) -> 0.10714286 | J10: 11.01c.1 | K10: =SUM(COUNTIF('Itemization 202506'!L3:L30,J10),COUNTIF('Itemization 202501'!L3:L30,J10),COUNTIF('Itemization 202408'!L3:L30,J10),COUNTIF('Itemization 202406'!L3:L30,J10),COUNTIF('Itemization 202401'!L3:L30,J10),COUNTIF('Itemization 202308'!L3:L30,J10),COUNTIF('Itemization 202306'!L3:L30,J10)) -> 0 | L10: =(K10/K116) -> 0 | M10: 6 | N10: =SUM(countif('Itemization 202506'!M3:M30,M10),countif('Itemization 202501'!M3:M30,M10),countif('Itemization 202408'!M3:M30,M10),countif('Itemization 202406'!M3:M30,M10),countif('Itemization 202401'!M3:M30,M10),countif('Itemization 202308'!M3:M30,M10),countif('Itemization 202306'!M3:M30,M10)) -> 6 | O10: =(N10/N23) -> 0.030612245
G11: 11.07 | H11: =SUM(COUNTIF('Itemization 202506'!K3:K30,G11),COUNTIF('Itemization 202501'!K3:K30,G11),COUNTIF('Itemization 202408'!K3:K30,G11),COUNTIF('Itemization 202406'!K3:K30,G11),COUNTIF('Itemization 202401'!K3:K30,G11),COUNTIF('Itemization 202308'!K3:K30,G11),COUNTIF('Itemization 202306'!K3:K30,G11)) -> 22 | I11: =(H11/H16) -> 0.1122449 | J11: 11.01c.2 | K11: =SUM(COUNTIF('Itemization 202506'!L3:L30,J11),COUNTIF('Itemization 202501'!L3:L30,J11),COUNTIF('Itemization 202408'!L3:L30,J11),COUNTIF('Itemization 202406'!L3:L30,J11),COUNTIF('Itemization 202401'!L3:L30,J11),COUNTIF('Itemization 202308'!L3:L30,J11),COUNTIF('Itemization 202306'!L3:L30,J11)) -> 2 | L11: =(K11/K116) -> 0.010204082 | M11: 7 | N11: =SUM(countif('Itemization 202506'!M3:M30,M11),countif('Itemization 202501'!M3:M30,M11),countif('Itemization 202408'!M3:M30,M11),countif('Itemization 202406'!M3:M30,M11),countif('Itemization 202401'!M3:M30,M11),countif('Itemization 202308'!M3:M30,M11),countif('Itemization 202306'!M3:M30,M11)) -> 20 | O11: =(N11/N23) -> 0.10204082
G12: 11.08 | H12: =SUM(COUNTIF('Itemization 202506'!K3:K30,G12),COUNTIF('Itemization 202501'!K3:K30,G12),COUNTIF('Itemization 202408'!K3:K30,G12),COUNTIF('Itemization 202406'!K3:K30,G12),COUNTIF('Itemization 202401'!K3:K30,G12),COUNTIF('Itemization 202308'!K3:K30,G12),COUNTIF('Itemization 202306'!K3:K30,G12)) -> 7 | I12: =(H12/H16) -> 0.035714286 | J12: 11.02a.1 | K12: =SUM(COUNTIF('Itemization 202506'!L3:L30,J12),COUNTIF('Itemization 202501'!L3:L30,J12),COUNTIF('Itemization 202408'!L3:L30,J12),COUNTIF('Itemization 202406'!L3:L30,J12),COUNTIF('Itemization 202401'!L3:L30,J12),COUNTIF('Itemization 202308'!L3:L30,J12),COUNTIF('Itemization 202306'!L3:L30,J12)) -> 6 | L12: =(K12/K116) -> 0.030612245 | M12: 8 | N12: =SUM(countif('Itemization 202506'!M3:M30,M12),countif('Itemization 202501'!M3:M30,M12),countif('Itemization 202408'!M3:M30,M12),countif('Itemization 202406'!M3:M30,M12),countif('Itemization 202401'!M3:M30,M12),countif('Itemization 202308'!M3:M30,M12),countif('Itemization 202306'!M3:M30,M12)) -> 25 | O12: =(N12/N23) -> 0.12755102
G13: 11.09 | H13: =SUM(COUNTIF('Itemization 202506'!K3:K30,G13),COUNTIF('Itemization 202501'!K3:K30,G13),COUNTIF('Itemization 202408'!K3:K30,G13),COUNTIF('Itemization 202406'!K3:K30,G13),COUNTIF('Itemization 202401'!K3:K30,G13),COUNTIF('Itemization 202308'!K3:K30,G13),COUNTIF('Itemization 202306'!K3:K30,G13)) -> 22 | I13: =(H13/H16) -> 0.1122449 | J13: 11.02b.1 | K13: =SUM(COUNTIF('Itemization 202506'!L3:L30,J13),COUNTIF('Itemization 202501'!L3:L30,J13),COUNTIF('Itemization 202408'!L3:L30,J13),COUNTIF('Itemization 202406'!L3:L30,J13),COUNTIF('Itemization 202401'!L3:L30,J13),COUNTIF('Itemization 202308'!L3:L30,J13),COUNTIF('Itemization 202306'!L3:L30,J13)) -> 2 | L13: =(K13/K116) -> 0.010204082 | M13: 9 | N13: =SUM(countif('Itemization 202506'!M3:M30,M13),countif('Itemization 202501'!M3:M30,M13),countif('Itemization 202408'!M3:M30,M13),countif('Itemization 202406'!M3:M30,M13),countif('Itemization 202401'!M3:M30,M13),countif('Itemization 202308'!M3:M30,M13),countif('Itemization 202306'!M3:M30,M13)) -> 8 | O13: =(N13/N23) -> 0.040816327
G14: 11.10 | H14: =SUM(COUNTIF('Itemization 202506'!K3:K30,G14),COUNTIF('Itemization 202501'!K3:K30,G14),COUNTIF('Itemization 202408'!K3:K30,G14),COUNTIF('Itemization 202406'!K3:K30,G14),COUNTIF('Itemization 202401'!K3:K30,G14),COUNTIF('Itemization 202308'!K3:K30,G14),COUNTIF('Itemization 202306'!K3:K30,G14)) -> 16 | I14: =(H14/H16) -> 0.081632653 | J14: 11.02b.2 | K14: =SUM(COUNTIF('Itemization 202506'!L3:L30,J14),COUNTIF('Itemization 202501'!L3:L30,J14),COUNTIF('Itemization 202408'!L3:L30,J14),COUNTIF('Itemization 202406'!L3:L30,J14),COUNTIF('Itemization 202401'!L3:L30,J14),COUNTIF('Itemization 202308'!L3:L30,J14),COUNTIF('Itemization 202306'!L3:L30,J14)) -> 0 | L14: =(K14/K116) -> 0 | M14: 10 | N14: =SUM(countif('Itemization 202506'!M3:M30,M14),countif('Itemization 202501'!M3:M30,M14),countif('Itemization 202408'!M3:M30,M14),countif('Itemization 202406'!M3:M30,M14),countif('Itemization 202401'!M3:M30,M14),countif('Itemization 202308'!M3:M30,M14),countif('Itemization 202306'!M3:M30,M14)) -> 6 | O14: =(N14/N23) -> 0.030612245
G15: 11.11 | H15: =SUM(COUNTIF('Itemization 202506'!K3:K30,G15),COUNTIF('Itemization 202501'!K3:K30,G15),COUNTIF('Itemization 202408'!K3:K30,G15),COUNTIF('Itemization 202406'!K3:K30,G15),COUNTIF('Itemization 202401'!K3:K30,G15),COUNTIF('Itemization 202308'!K3:K30,G15),COUNTIF('Itemization 202306'!K3:K30,G15)) -> 6 | I15: =(H15/H16) -> 0.030612245 | J15: 11.02c.1 | K15: =SUM(COUNTIF('Itemization 202506'!L3:L30,J15),COUNTIF('Itemization 202501'!L3:L30,J15),COUNTIF('Itemization 202408'!L3:L30,J15),COUNTIF('Itemization 202406'!L3:L30,J15),COUNTIF('Itemization 202401'!L3:L30,J15),COUNTIF('Itemization 202308'!L3:L30,J15),COUNTIF('Itemization 202306'!L3:L30,J15)) -> 0 | L15: =(K15/K116) -> 0 | M15: 11 | N15: =SUM(countif('Itemization 202506'!M3:M30,M15),countif('Itemization 202501'!M3:M30,M15),countif('Itemization 202408'!M3:M30,M15),countif('Itemization 202406'!M3:M30,M15),countif('Itemization 202401'!M3:M30,M15),countif('Itemization 202308'!M3:M30,M15),countif('Itemization 202306'!M3:M30,M15)) -> 2 | O15: =(N15/N23) -> 0.010204082
G16: Total | H16: =SUM(H5:H15) -> 196 | I16: =sum(I5:I15) -> 1 | J16: 11.02c.2 | K16: =SUM(COUNTIF('Itemization 202506'!L3:L30,J16),COUNTIF('Itemization 202501'!L3:L30,J16),COUNTIF('Itemization 202408'!L3:L30,J16),COUNTIF('Itemization 202406'!L3:L30,J16),COUNTIF('Itemization 202401'!L3:L30,J16),COUNTIF('Itemization 202308'!L3:L30,J16),COUNTIF('Itemization 202306'!L3:L30,J16)) -> 2 | L16: =(K16/K116) -> 0.010204082 | M16: 12 | N16: =SUM(countif('Itemization 202506'!M3:M30,M16),countif('Itemization 202501'!M3:M30,M16),countif('Itemization 202408'!M3:M30,M16),countif('Itemization 202406'!M3:M30,M16),countif('Itemization 202401'!M3:M30,M16),countif('Itemization 202308'!M3:M30,M16),countif('Itemization 202306'!M3:M30,M16)) -> 12 | O16: =(N16/N23) -> 0.06122449
