Workbook

Sheet Scores
A1: ID | B1: ELL | C1: IEP | D1: MC | E1: CRQ | F1: EIE | G1: Final | H1: 1 | I1: 2 | J1: 3 | K1: 4 | L1: 5 | M1: 6 | N1: 7 | O1: 8 | P1: 9 | Q1: 10 | R1: 11 | S1: 12 | T1: 13 | U1: 14 | V1: 15 | W1: 16 | X1: 17 | Y1: 18 | Z1: 19 | AA1: 20 | AB1: 21 | AC1: 22 | AD1: 23 | AE1: 24 | AF1: 25 | AG1: 26 | AH1: 27 | AI1: 28 | AJ1: 29 | AK1: 30 | AL1: 31 | AM1: 32 | AN1: 33 | AO1: 34a | AP1: 34b | AQ1: 35 | AR1: Q1 | AS1: Q2 | AT1: Q3 | AU1: Q4 | AV1: Q5 | AW1: Q6 | AX1: Q7 | AY1: Q8 | AZ1: Q9 | BA1: Q10 | BB1: Q11 | BC1: Q12 | BD1: Q13 | BE1: Q14 | BF1: Q15 | BG1: Q16 | BH1: Q17 | BI1: Q18 | BJ1: Q19 | BK1: Q20 | BL1: Q21 | BM1: Q22 | BN1: Q23 | BO1: Q24 | BP1: Q25 | BQ1: Q26 | BR1: Q27 | BS1: Q28
A2: 1 | B2: FALSE | C2: FALSE | D2: =SUM(Scores[[#This Row],[Q1]:[Q28]]) -> 22 | E2: =SUM(Scores[[#This Row],[29]:[34b]]) -> 0 | F2: =Scores[[#This Row],[35]] -> 0 | G2: =INDEX('Conversion Chart'!$C$3:$M$38,MATCH(SUM(Scores[[#This Row],[MC]:[CRQ]]),'Conversion Chart'!$B$3:$B$38,0),MATCH(Scores[[#This Row],[EIE]],'Conversion Chart'!$C$2:$M$2,0)) -> 57 | H2: 4 | I2: 3 | J2: 1 | K2: 3 | L2: 2 | M2: 3 | N2: 3 | O2: 4 | P2: 1 | Q2: 1 | R2: 4 | S2: 3 | T2: 1 | U2: 4 | V2: 1 | W2: 4 | X2: 2 | Y2: 3 | Z2: 2 | AA2: 1 | AB2: 2 | AC2: 1 | AD2: 3 | AE2: 2 | AF2: 4 | AG2: 3 | AH2: 1 | AI2: 1 | AR2: =IF(H2=VLOOKUP(VALUE(H$1),Questions!$A:$E,5,FALSE),1,0) -> 1 | AS2: =IF(I2=VLOOKUP(VALUE(I$1),Questions!$A:$E,5,FALSE),1,0) -> 1 | AT2: =IF(J2=VLOOKUP(VALUE(J$1),Questions!$A:$E,5,FALSE),1,0) -> 1 | AU2: =IF(K2=VLOOKUP(VALUE(K$1),Questions!$A:$E,5,FALSE),1,0) -> 0 | AV2: =IF(L2=VLOOKUP(VALUE(L$1),Questions!$A:$E,5,FALSE),1,0) -> 1 | AW2: =IF(M2=VLOOKUP(VALUE(M$1),Questions!$A:$E,5,FALSE),1,0) -> 0 | AX2: =IF(N2=VLOOKUP(VALUE(N$1),Questions!$A:$E,5,FALSE),1,0) -> 1 | AY2: =IF(O2=VLOOKUP(VALUE(O$1),Questions!$A:$E,5,FALSE),1,0) -> 0 | ... BS2: =IF(AI2=VLOOKUP(VALUE(AI$1),Questions!$A:$E,5,FALSE),1,0) -> 1
A3: 2 | B3: FALSE | C3: FALSE | D3: =SUM(Scores[[#This Row],[Q1]:[Q28]]) -> 24 | E3: =SUM(Scores[[#This Row],[29]:[34b]]) -> 0 | F3: =Scores[[#This Row],[35]] -> 0 | G3: =INDEX('Conversion Chart'!$C$3:$M$38,MATCH(SUM(Scores[[#This Row],[MC]:[CRQ]]),'Conversion Chart'!$B$3:$B$38,0),MATCH(Scores[[#This Row],[EIE]],'Conversion Chart'!$C$2:$M$2,0)) -> 61 | H3: 4 | I3: 3 | J3: 1 | K3: 2 | L3: 4 | M3: 4 | N3: 3 | O3: 4 | P3: 1 | Q3: 1 | R3: 4 | S3: 2 | T3: 1 | U3: 4 | V3: 3 | W3: 4 | X3: 2 | Y3: 3 | Z3: 2 | AA3: 3 | AB3: 2 | AC3: 3 | AD3: 3 | AE3: 4 | AF3: 4 | AG3: 3 | AH3: 1 | AI3: 1 | AR3: =IF(H3=VLOOKUP(VALUE(H$1),Questions!$A:$E,5,FALSE),1,0) -> 1 | AS3: =IF(I3=VLOOKUP(VALUE(I$1),Questions!$A:$E,5,FALSE),1,0) -> 1 | AT3: =IF(J3=VLOOKUP(VALUE(J$1),Questions!$A:$E,5,FALSE),1,0) -> 1 | AU3: =IF(K3=VLOOKUP(VALUE(K$1),Questions!$A:$E,5,FALSE),1,0) -> 1 | AV3: =IF(L3=VLOOKUP(VALUE(L$1),Questions!$A:$E,5,FALSE),1,0) -> 0 | AW3: =IF(M3=VLOOKUP(VALUE(M$1),Questions!$A:$E,5,FALSE),1,0) -> 1 | AX3: =IF(N3=VLOOKUP(VALUE(N$1),Questions!$A:$E,5,FALSE),1,0) -> 1 | AY3: =IF(O3=VLOOKUP(VALUE(O$1),Questions!$A:$E,5,FALSE),1,0) -> 0 | ... BS3: =IF(AI3=VLOOKUP(VALUE(AI$1),Questions!$A:$E,5,FALSE),1,0) -> 1
A4: 3 | B4: FALSE | C4: FALSE | D4: =SUM(Scores[[#This Row],[Q1]:[Q28]]) -> 15 | E4: =SUM(Scores[[#This Row],[29]:[34b]]) -> 0 | F4: =Scores[[#This Row],[35]] -> 0 | G4: =INDEX('Conversion Chart'!$C$3:$M$38,MATCH(SUM(Scores[[#This Row],[MC]:[CRQ]]),'Conversion Chart'!$B$3:$B$38,0),MATCH(Scores[[#This Row],[EIE]],'Conversion Chart'!$C$2:$M$2,0)) -> 42 | H4: 4 | I4: 3 | J4: 1 | K4: 2 | L4: 1 | M4: 4 | N4: 3 | O4: 3 | P4: 2 | Q4: 3 | R4: 4 | S4: 3 | T4: 2 | U4: 1 | V4: 1 | W4: 4 | X4: 2 | Y4: 3 | Z4: 2 | AA4: 1 | AB4: 2 | AC4: 4 | AD4: 3 | AE4: 4 | AF4: 4 | AG4: 2 | AH4: 3 | AI4: 1 | AR4: =IF(H4=VLOOKUP(VALUE(H$1),Questions!$A:$E,5,FALSE),1,0) -> 1 | AS4: =IF(I4=VLOOKUP(VALUE(I$1),Questions!$A:$E,5,FALSE),1,0) -> 1 | AT4: =IF(J4=VLOOKUP(VALUE(J$1),Questions!$A:$E,5,FALSE),1,0) -> 1 | AU4: =IF(K4=VLOOKUP(VALUE(K$1),Questions!$A:$E,5,FALSE),1,0) -> 1 | AV4: =IF(L4=VLOOKUP(VALUE(L$1),Questions!$A:$E,5,FALSE),1,0) -> 0 | AW4: =IF(M4=VLOOKUP(VALUE(M$1),Questions!$A:$E,5,FALSE),1,0) -> 1 | AX4: =IF(N4=VLOOKUP(VALUE(N$1),Questions!$A:$E,5,FALSE),1,0) -> 1 | AY4: =IF(O4=VLOOKUP(VALUE(O$1),Questions!$A:$E,5,FALSE),1,0) -> 0 | ... BS4: =IF(AI4=VLOOKUP(VALUE(AI$1),Questions!$A:$E,5,FALSE),1,0) -> 1
A5: 4 | B5: FALSE | C5: FALSE | D5: =SUM(Scores[[#This Row],[Q1]:[Q28]]) -> 19 | E5: =SUM(Scores[[#This Row],[29]:[34b]]) -> 0 | F5: =Scores[[#This Row],[35]] -> 0 | G5: =INDEX('Conversion Chart'!$C$3:$M$38,MATCH(SUM(Scores[[#This Row],[MC]:[CRQ]]),'Conversion Chart'!$B$3:$B$38,0),MATCH(Scores[[#This Row],[EIE]],'Conversion Chart'!$C$2:$M$2,0)) -> 51 | H5: 4 | I5: 3 | J5: 1 | K5: 4 | L5: 2 | M5: 4 | N5: 3 | O5: 4 | P5: 1 | Q5: 1 | R5: 4 | S5: 4 | T5: 1 | U5: 4 | V5: 1 | W5: 4 | X5: 2 | Y5: 2 | Z5: 1 | AA5: 3 | AB5: 2 | AC5: 3 | AD5: 3 | AE5: 4 | AF5: 4 | AG5: 2 | AH5: 1 | AI5: 1 | AR5: =IF(H5=VLOOKUP(VALUE(H$1),Questions!$A:$E,5,FALSE),1,0) -> 1 | AS5: =IF(I5=VLOOKUP(VALUE(I$1),Questions!$A:$E,5,FALSE),1,0) -> 1 | AT5: =IF(J5=VLOOKUP(VALUE(J$1),Questions!$A:$E,5,FALSE),1,0) -> 1 | AU5: =IF(K5=VLOOKUP(VALUE(K$1),Questions!$A:$E,5,FALSE),1,0) -> 0 | AV5: =IF(L5=VLOOKUP(VALUE(L$1),Questions!$A:$E,5,FALSE),1,0) -> 1 | AW5: =IF(M5=VLOOKUP(VALUE(M$1),Questions!$A:$E,5,FALSE),1,0) -> 1 | AX5: =IF(N5=VLOOKUP(VALUE(N$1),Questions!$A:$E,5,FALSE),1,0) -> 1 | AY5: =IF(O5=VLOOKUP(VALUE(O$1),Questions!$A:$E,5,FALSE),1,0) -> 0 | ... BS5: =IF(AI5=VLOOKUP(VALUE(AI$1),Questions!$A:$E,5,FALSE),1,0) -> 1
A6: 5 | B6: FALSE | C6: FALSE | D6: =SUM(Scores[[#This Row],[Q1]:[Q28]]) -> 20 | E6: =SUM(Scores[[#This Row],[29]:[34b]]) -> 0 | F6: =Scores[[#This Row],[35]] -> 0 | G6: =INDEX('Conversion Chart'!$C$3:$M$38,MATCH(SUM(Scores[[#This Row],[MC]:[CRQ]]),'Conversion Chart'!$B$3:$B$38,0),MATCH(Scores[[#This Row],[EIE]],'Conversion Chart'!$C$2:$M$2,0)) -> 53 | H6: 4 | I6: 3 | J6: 1 | K6: 2 | L6: 4 | M6: 4 | N6: 3 | O6: 4 | P6: 1 | Q6: 1 | R6: 4 | S6: 2 | T6: 1 | U6: 4 | V6: 1 | W6: 4 | X6: 2 | Y6: 2 | Z6: 1 | AA6: 3 | AB6: 2 | AC6: 3 | AD6: 3 | AE6: 4 | AF6: 4 | AG6: 2 | AH6: 1 | AI6: 1 | AR6: =IF(H6=VLOOKUP(VALUE(H$1),Questions!$A:$E,5,FALSE),1,0) -> 1 | AS6: =IF(I6=VLOOKUP(VALUE(I$1),Questions!$A:$E,5,FALSE),1,0) -> 1 | AT6: =IF(J6=VLOOKUP(VALUE(J$1),Questions!$A:$E,5,FALSE),1,0) -> 1 | AU6: =IF(K6=VLOOKUP(VALUE(K$1),Questions!$A:$E,5,FALSE),1,0) -> 1 | AV6: =IF(L6=VLOOKUP(VALUE(L$1),Questions!$A:$E,5,FALSE),1,0) -> 0 | AW6: =IF(M6=VLOOKUP(VALUE(M$1),Questions!$A:$E,5,FALSE),1,0) -> 1 | AX6: =IF(N6=VLOOKUP(VALUE(N$1),Questions!$A:$E,5,FALSE),1,0) -> 1 | AY6: =IF(O6=VLOOKUP(VALUE(O$1),Questions!$A:$E,5,FALSE),1,0) -> 0 | ... BS6: =IF(AI6=VLOOKUP(VALUE(AI$1),Questions!$A:$E,5,FALSE),1,0) -> 1
A7: 6 | B7: FALSE | C7: FALSE | D7: =SUM(Scores[[#This Row],[Q1]:[Q28]]) -> 15 | E7: =SUM(Scores[[#This Row],[29]:[34b]]) -> 0 | F7: =Scores[[#This Row],[35]] -> 0 | G7: =INDEX('Conversion Chart'!$C$3:$M$38,MATCH(SUM(Scores[[#This Row],[MC]:[CRQ]]),'Conversion Chart'!$B$3:$B$38,0),MATCH(Scores[[#This Row],[EIE]],'Conversion Chart'!$C$2:$M$2,0)) -> 42 | H7: 3 | I7: 3 | J7: 1 | K7: 2 | L7: 4 | M7: 4 | N7: 3 | O7: 2 | P7: 2 | Q7: 2 | R7: 4 | S7: 4 | T7: 1 | U7: 2 | V7: 3 | W7: 1 | X7: 3 | Y7: 3 | Z7: 1 | AA7: 1 | AB7: 2 | AC7: 1 | AD7: 3 | AE7: 2 | AF7: 4 | AI7: 1 | AR7: =IF(H7=VLOOKUP(VALUE(H$1),Questions!$A:$E,5,FALSE),1,0) -> 0 | AS7: =IF(I7=VLOOKUP(VALUE(I$1),Questions!$A:$E,5,FALSE),1,0) -> 1 | AT7: =IF(J7=VLOOKUP(VALUE(J$1),Questions!$A:$E,5,FALSE),1,0) -> 1 | AU7: =IF(K7=VLOOKUP(VALUE(K$1),Questions!$A:$E,5,FALSE),1,0) -> 1 | AV7: =IF(L7=VLOOKUP(VALUE(L$1),Questions!$A:$E,5,FALSE),1,0) -> 0 | AW7: =IF(M7=VLOOKUP(VALUE(M$1),Questions!$A:$E,5,FALSE),1,0) -> 1 | AX7: =IF(N7=VLOOKUP(VALUE(N$1),Questions!$A:$E,5,FALSE),1,0) -> 1 | AY7: =IF(O7=VLOOKUP(VALUE(O$1),Questions!$A:$E,5,FALSE),1,0) -> 0 | ... BS7: =IF(AI7=VLOOKUP(VALUE(AI$1),Questions!$A:$E,5,FALSE),1,0) -> 1
A8: 7 | B8: FALSE | C8: FALSE | D8: =SUM(Scores[[#This Row],[Q1]:[Q28]]) -> 17 | E8: =SUM(Scores[[#This Row],[29]:[34b]]) -> 0 | F8: =Scores[[#This Row],[35]] -> 0 | G8: =INDEX('Conversion Chart'!$C$3:$M$38,MATCH(SUM(Scores[[#This Row],[MC]:[CRQ]]),'Conversion Chart'!$B$3:$B$38,0),MATCH(Scores[[#This Row],[EIE]],'Conversion Chart'!$C$2:$M$2,0)) -> 47 | H8: 4 | I8: 3 | J8: 1 | K8: 2 | L8: 3 | M8: 2 | N8: 3 | O8: 1 | P8: 2 | Q8: 2 | R8: 4 | S8: 3 | T8: 2 | U8: 4 | V8: 3 | W8: 1 | X8: 2 | Y8: 2 | Z8: 2 | AA8: 3 | AB8: 2 | AC8: 1 | AD8: 2 | AE8: 4 | AF8: 4 | AG8: 2 | AH8: 1 | AI8: 1 | AR8: =IF(H8=VLOOKUP(VALUE(H$1),Questions!$A:$E,5,FALSE),1,0) -> 1 | AS8: =IF(I8=VLOOKUP(VALUE(I$1),Questions!$A:$E,5,FALSE),1,0) -> 1 | AT8: =IF(J8=VLOOKUP(VALUE(J$1),Questions!$A:$E,5,FALSE),1,0) -> 1 | AU8: =IF(K8=VLOOKUP(VALUE(K$1),Questions!$A:$E,5,FALSE),1,0) -> 1 | AV8: =IF(L8=VLOOKUP(VALUE(L$1),Questions!$A:$E,5,FALSE),1,0) -> 0 | AW8: =IF(M8=VLOOKUP(VALUE(M$1),Questions!$A:$E,5,FALSE),1,0) -> 0 | AX8: =IF(N8=VLOOKUP(VALUE(N$1),Questions!$A:$E,5,FALSE),1,0) -> 1 | AY8: =IF(O8=VLOOKUP(VALUE(O$1),Questions!$A:$E,5,FALSE),1,0) -> 1 | ... BS8: =IF(AI8=VLOOKUP(VALUE(AI$1),Questions!$A:$E,5,FALSE),1,0) -> 1
A9: 8 | B9: FALSE | C9: FALSE | D9: =SUM(Scores[[#This Row],[Q1]:[Q28]]) -> 16 | E9: =SUM(Scores[[#This Row],[29]:[34b]]) -> 0 | F9: =Scores[[#This Row],[35]] -> 0 | G9: =INDEX('Conversion Chart'!$C$3:$M$38,MATCH(SUM(Scores[[#This Row],[MC]:[CRQ]]),'Conversion Chart'!$B$3:$B$38,0),MATCH(Scores[[#This Row],[EIE]],'Conversion Chart'!$C$2:$M$2,0)) -> 45 | H9: 3 | I9: 3 | J9: 1 | K9: 2 | L9: 1 | M9: 4 | N9: 4 | O9: 1 | P9: 4 | Q9: 2 | R9: 4 | S9: 2 | T9: 1 | U9: 4 | V9: 1 | W9: 4 | X9: 2 | Y9: 2 | Z9: 1 | AA9: 4 | AB9: 4 | AC9: 2 | AD9: 3 | AE9: 4 | AF9: 4 | AG9: 3 | AH9: 1 | AI9: 1 | AR9: =IF(H9=VLOOKUP(VALUE(H$1),Questions!$A:$E,5,FALSE),1,0) -> 0 | AS9: =IF(I9=VLOOKUP(VALUE(I$1),Questions!$A:$E,5,FALSE),1,0) -> 1 | AT9: =IF(J9=VLOOKUP(VALUE(J$1),Questions!$A:$E,5,FALSE),1,0) -> 1 | AU9: =IF(K9=VLOOKUP(VALUE(K$1),Questions!$A:$E,5,FALSE),1,0) -> 1 | AV9: =IF(L9=VLOOKUP(VALUE(L$1),Questions!$A:$E,5,FALSE),1,0) -> 0 | AW9: =IF(M9=VLOOKUP(VALUE(M$1),Questions!$A:$E,5,FALSE),1,0) -> 1 | AX9: =IF(N9=VLOOKUP(VALUE(N$1),Questions!$A:$E,5,FALSE),1,0) -> 0 | AY9: =IF(O9=VLOOKUP(VALUE(O$1),Questions!$A:$E,5,FALSE),1,0) -> 1 | ... BS9: =IF(AI9=VLOOKUP(VALUE(AI$1),Questions!$A:$E,5,FALSE),1,0) -> 1
A10: 9 | B10: FALSE | C10: FALSE | D10: =SUM(Scores[[#This Row],[Q1]:[Q28]]) -> 25 | E10: =SUM(Scores[[#This Row],[29]:[34b]]) -> 0 | F10: =Scores[[#This Row],[35]] -> 0 | G10: =INDEX('Conversion Chart'!$C$3:$M$38,MATCH(SUM(Scores[[#This Row],[MC]:[CRQ]]),'Conversion Chart'!$B$3:$B$38,0),MATCH(Scores[[#This Row],[EIE]],'Conversion Chart'!$C$2:$M$2,0)) -> 63 | H10: 4 | I10: 3 | J10: 1 | K10: 2 | L10: 2 | M10: 4 | N10: 3 | O10: 1 | P10: 1 | Q10: 1 | R10: 4 | S10: 2 | T10: 1 | U10: 4 | V10: 3 | W10: 1 | X10: 2 | Y10: 3 | Z10: 4 | AA10: 3 | AB10: 2 | AC10: 1 | AD10: 3 | AE10: 2 | AF10: 4 | AG10: 2 | AH10: 1 | AI10: 1 | AR10: =IF(H10=VLOOKUP(VALUE(H$1),Questions!$A:$E,5,FALSE),1,0) -> 1 | AS10: =IF(I10=VLOOKUP(VALUE(I$1),Questions!$A:$E,5,FALSE),1,0) -> 1 | AT10: =IF(J10=VLOOKUP(VALUE(J$1),Questions!$A:$E,5,FALSE),1,0) -> 1 | AU10: =IF(K10=VLOOKUP(VALUE(K$1),Questions!$A:$E,5,FALSE),1,0) -> 1 | AV10: =IF(L10=VLOOKUP(VALUE(L$1),Questions!$A:$E,5,FALSE),1,0) -> 1 | AW10: =IF(M10=VLOOKUP(VALUE(M$1),Questions!$A:$E,5,FALSE),1,0) -> 1 | AX10: =IF(N10=VLOOKUP(VALUE(N$1),Questions!$A:$E,5,FALSE),1,0) -> 1 | AY10: =IF(O10=VLOOKUP(VALUE(O$1),Questions!$A:$E,5,FALSE),1,0) -> 1 | ... BS10: =IF(AI10=VLOOKUP(VALUE(AI$1),Questions!$A:$E,5,FALSE),1,0) -> 1
A11: 10 | B11: FALSE | C11: FALSE | D11: =SUM(Scores[[#This Row],[Q1]:[Q28]]) -> 22 | E11: =SUM(Scores[[#This Row],[29]:[34b]]) -> 0 | F11: =Scores[[#This Row],[35]] -> 0 | G11: =INDEX('Conversion Chart'!$C$3:$M$38,MATCH(SUM(Scores[[#This Row],[MC]:[CRQ]]),'Conversion Chart'!$B$3:$B$38,0),MATCH(Scores[[#This Row],[EIE]],'Conversion Chart'!$C$2:$M$2,0)) -> 57 | H11: 4 | I11: 3 | J11: 1 | K11: 2 | L11: 2 | M11: 4 | N11: 3 | O11: 1 | P11: 1 | Q11: 4 | R11: 4 | S11: 4 | T11: 1 | U11: 3 | V11: 3 | W11: 4 | X11: 2 | Y11: 3 | Z11: 3 | AA11: 3 | AB11: 2 | AC11: 3 | AD11: 3 | AE11: 2 | AF11: 4 | AG11: 1 | AH11: 1 | AI11: 1 | AR11: =IF(H11=VLOOKUP(VALUE(H$1),Questions!$A:$E,5,FALSE),1,0) -> 1 | AS11: =IF(I11=VLOOKUP(VALUE(I$1),Questions!$A:$E,5,FALSE),1,0) -> 1 | AT11: =IF(J11=VLOOKUP(VALUE(J$1),Questions!$A:$E,5,FALSE),1,0) -> 1 | AU11: =IF(K11=VLOOKUP(VALUE(K$1),Questions!$A:$E,5,FALSE),1,0) -> 1 | AV11: =IF(L11=VLOOKUP(VALUE(L$1),Questions!$A:$E,5,FALSE),1,0) -> 1 | AW11: =IF(M11=VLOOKUP(VALUE(M$1),Questions!$A:$E,5,FALSE),1,0) -> 1 | AX11: =IF(N11=VLOOKUP(VALUE(N$1),Questions!$A:$E,5,FALSE),1,0) -> 1 | AY11: =IF(O11=VLOOKUP(VALUE(O$1),Questions!$A:$E,5,FALSE),1,0) -> 1 | ... BS11: =IF(AI11=VLOOKUP(VALUE(AI$1),Questions!$A:$E,5,FALSE),1,0) -> 1
A12: 11 | B12: FALSE | C12: FALSE | D12: =SUM(Scores[[#This Row],[Q1]:[Q28]]) -> 12 | E12: =SUM(Scores[[#This Row],[29]:[34b]]) -> 0 | F12: =Scores[[#This Row],[35]] -> 0 | G12: =INDEX('Conversion Chart'!$C$3:$M$38,MATCH(SUM(Scores[[#This Row],[MC]:[CRQ]]),'Conversion Chart'!$B$3:$B$38,0),MATCH(Scores[[#This Row],[EIE]],'Conversion Chart'!$C$2:$M$2,0)) -> 35 | H12: 4 | I12: 3 | J12: 3 | K12: 2 | L12: 1 | M12: 4 | N12: 3 | O12: 4 | P12: 1 | Q12: 3 | R12: 2 | S12: 4 | T12: 4 | U12: 3 | V12: 1 | W12: 3 | X12: 3 | Y12: 2 | Z12: 2 | AA12: 3 | AB12: 2 | AC12: 1 | AD12: 3 | AE12: 3 | AF12: 2 | AG12: 4 | AH12: 1 | AI12: 3 | AR12: =IF(H12=VLOOKUP(VALUE(H$1),Questions!$A:$E,5,FALSE),1,0) -> 1 | AS12: =IF(I12=VLOOKUP(VALUE(I$1),Questions!$A:$E,5,FALSE),1,0) -> 1 | AT12: =IF(J12=VLOOKUP(VALUE(J$1),Questions!$A:$E,5,FALSE),1,0) -> 0 | AU12: =IF(K12=VLOOKUP(VALUE(K$1),Questions!$A:$E,5,FALSE),1,0) -> 1 | AV12: =IF(L12=VLOOKUP(VALUE(L$1),Questions!$A:$E,5,FALSE),1,0) -> 0 | AW12: =IF(M12=VLOOKUP(VALUE(M$1),Questions!$A:$E,5,FALSE),1,0) -> 1 | AX12: =IF(N12=VLOOKUP(VALUE(N$1),Questions!$A:$E,5,FALSE),1,0) -> 1 | AY12: =IF(O12=VLOOKUP(VALUE(O$1),Questions!$A:$E,5,FALSE),1,0) -> 0 | ... BS12: =IF(AI12=VLOOKUP(VALUE(AI$1),Questions!$A:$E,5,FALSE),1,0) -> 0
A13: 12 | B13: FALSE | C13: FALSE | D13: =SUM(Scores[[#This Row],[Q1]:[Q28]]) -> 22 | E13: =SUM(Scores[[#This Row],[29]:[34b]]) -> 0 | F13: =Scores[[#This Row],[35]] -> 0 | G13: =INDEX('Conversion Chart'!$C$3:$M$38,MATCH(SUM(Scores[[#This Row],[MC]:[CRQ]]),'Conversion Chart'!$B$3:$B$38,0),MATCH(Scores[[#This Row],[EIE]],'Conversion Chart'!$C$2:$M$2,0)) -> 57 | H13: 3 | I13: 3 | J13: 1 | K13: 2 | L13: 2 | M13: 4 | N13: 4 | O13: 1 | P13: 1 | Q13: 1 | R13: 4 | S13: 2 | T13: 1 | U13: 4 | V13: 3 | W13: 4 | X13: 2 | Y13: 3 | Z13: 1 | AA13: 1 | AB13: 4 | AC13: 1 | AD13: 3 | AE13: 2 | AF13: 4 | AG13: 3 | AH13: 1 | AI13: 4 | AR13: =IF(H13=VLOOKUP(VALUE(H$1),Questions!$A:$E,5,FALSE),1,0) -> 0 | AS13: =IF(I13=VLOOKUP(VALUE(I$1),Questions!$A:$E,5,FALSE),1,0) -> 1 | AT13: =IF(J13=VLOOKUP(VALUE(J$1),Questions!$A:$E,5,FALSE),1,0) -> 1 | AU13: =IF(K13=VLOOKUP(VALUE(K$1),Questions!$A:$E,5,FALSE),1,0) -> 1 | AV13: =IF(L13=VLOOKUP(VALUE(L$1),Questions!$A:$E,5,FALSE),1,0) -> 1 | AW13: =IF(M13=VLOOKUP(VALUE(M$1),Questions!$A:$E,5,FALSE),1,0) -> 1 | AX13: =IF(N13=VLOOKUP(VALUE(N$1),Questions!$A:$E,5,FALSE),1,0) -> 0 | AY13: =IF(O13=VLOOKUP(VALUE(O$1),Questions!$A:$E,5,FALSE),1,0) -> 1 | ... BS13: =IF(AI13=VLOOKUP(VALUE(AI$1),Questions!$A:$E,5,FALSE),1,0) -> 0
A14: 13 | B14: FALSE | C14: FALSE | D14: =SUM(Scores[[#This Row],[Q1]:[Q28]]) -> 24 | E14: =SUM(Scores[[#This Row],[29]:[34b]]) -> 0 | F14: =Scores[[#This Row],[35]] -> 0 | G14: =INDEX('Conversion Chart'!$C$3:$M$38,MATCH(SUM(Scores[[#This Row],[MC]:[CRQ]]),'Conversion Chart'!$B$3:$B$38,0),MATCH(Scores[[#This Row],[EIE]],'Conversion Chart'!$C$2:$M$2,0)) -> 61 | H14: 3 | I14: 3 | J14: 1 | K14: 2 | L14: 2 | M14: 4 | N14: 3 | O14: 4 | P14: 1 | Q14: 1 | R14: 4 | S14: 2 | T14: 1 | U14: 4 | V14: 3 | W14: 3 | X14: 2 | Y14: 3 | AA14: 3 | AB14: 2 | AC14: 1 | AD14: 3 | AE14: 2 | AF14: 4 | AG14: 3 | AH14: 1 | AI14: 1 | AR14: =IF(H14=VLOOKUP(VALUE(H$1),Questions!$A:$E,5,FALSE),1,0) -> 0 | AS14: =IF(I14=VLOOKUP(VALUE(I$1),Questions!$A:$E,5,FALSE),1,0) -> 1 | AT14: =IF(J14=VLOOKUP(VALUE(J$1),Questions!$A:$E,5,FALSE),1,0) -> 1 | AU14: =IF(K14=VLOOKUP(VALUE(K$1),Questions!$A:$E,5,FALSE),1,0) -> 1 | AV14: =IF(L14=VLOOKUP(VALUE(L$1),Questions!$A:$E,5,FALSE),1,0) -> 1 | AW14: =IF(M14=VLOOKUP(VALUE(M$1),Questions!$A:$E,5,FALSE),1,0) -> 1 | AX14: =IF(N14=VLOOKUP(VALUE(N$1),Questions!$A:$E,5,FALSE),1,0) -> 1 | AY14: =IF(O14=VLOOKUP(VALUE(O$1),Questions!$A:$E,5,FALSE),1,0) -> 0 | ... BS14: =IF(AI14=VLOOKUP(VALUE(AI$1),Questions!$A:$E,5,FALSE),1,0) -> 1
A15: 14 | B15: FALSE | C15: FALSE | D15: =SUM(Scores[[#This Row],[Q1]:[Q28]]) -> 10 | E15: =SUM(Scores[[#This Row],[29]:[34b]]) -> 0 | F15: =Scores[[#This Row],[35]] -> 0 | G15: =INDEX('Conversion Chart'!$C$3:$M$38,MATCH(SUM(Scores[[#This Row],[MC]:[CRQ]]),'Conversion Chart'!$B$3:$B$38,0),MATCH(Scores[[#This Row],[EIE]],'Conversion Chart'!$C$2:$M$2,0)) -> 30 | H15: 1 | I15: 3 | J15: 1 | K15: 2 | L15: 1 | M15: 2 | N15: 3 | O15: 3 | P15: 4 | Q15: 3 | R15: 4 | S15: 4 | T15: 4 | U15: 1 | V15: 4 | W15: 3 | X15: 1 | Y15: 2 | Z15: 4 | AA15: 1 | AB15: 2 | AC15: 4 | AD15: 3 | AE15: 4 | AF15: 4 | AG15: 1 | AH15: 1 | AI15: 1 | AR15: =IF(H15=VLOOKUP(VALUE(H$1),Questions!$A:$E,5,FALSE),1,0) -> 0 | AS15: =IF(I15=VLOOKUP(VALUE(I$1),Questions!$A:$E,5,FALSE),1,0) -> 1 | AT15: =IF(J15=VLOOKUP(VALUE(J$1),Questions!$A:$E,5,FALSE),1,0) -> 1 | AU15: =IF(K15=VLOOKUP(VALUE(K$1),Questions!$A:$E,5,FALSE),1,0) -> 1 | AV15: =IF(L15=VLOOKUP(VALUE(L$1),Questions!$A:$E,5,FALSE),1,0) -> 0 | AW15: =IF(M15=VLOOKUP(VALUE(M$1),Questions!$A:$E,5,FALSE),1,0) -> 0 | AX15: =IF(N15=VLOOKUP(VALUE(N$1),Questions!$A:$E,5,FALSE),1,0) -> 1 | AY15: =IF(O15=VLOOKUP(VALUE(O$1),Questions!$A:$E,5,FALSE),1,0) -> 0 | ... BS15: =IF(AI15=VLOOKUP(VALUE(AI$1),Questions!$A:$E,5,FALSE),1,0) -> 1
A16: 15 | B16: FALSE | C16: FALSE | D16: =SUM(Scores[[#This Row],[Q1]:[Q28]]) -> 25 | E16: =SUM(Scores[[#This Row],[29]:[34b]]) -> 0 | F16: =Scores[[#This Row],[35]] -> 0 | G16: =INDEX('Conversion Chart'!$C$3:$M$38,MATCH(SUM(Scores[[#This Row],[MC]:[CRQ]]),'Conversion Chart'!$B$3:$B$38,0),MATCH(Scores[[#This Row],[EIE]],'Conversion Chart'!$C$2:$M$2,0)) -> 63 | H16: 4 | I16: 3 | J16: 1 | K16: 2 | L16: 2 | M16: 4 | N16: 1 | O16: 4 | P16: 1 | Q16: 1 | R16: 4 | S16: 2 | T16: 1 | U16: 4 | V16: 3 | W16: 4 | X16: 2 | Y16: 3 | Z16: 1 | AA16: 3 | AB16: 2 | AC16: 1 | AD16: 3 | AE16: 2 | AF16: 4 | AG16: 3 | AH16: 1 | AI16: 1 | AR16: =IF(H16=VLOOKUP(VALUE(H$1),Questions!$A:$E,5,FALSE),1,0) -> 1 | AS16: =IF(I16=VLOOKUP(VALUE(I$1),Questions!$A:$E,5,FALSE),1,0) -> 1 | AT16: =IF(J16=VLOOKUP(VALUE(J$1),Questions!$A:$E,5,FALSE),1,0) -> 1 | AU16: =IF(K16=VLOOKUP(VALUE(K$1),Questions!$A:$E,5,FALSE),1,0) -> 1 | AV16: =IF(L16=VLOOKUP(VALUE(L$1),Questions!$A:$E,5,FALSE),1,0) -> 1 | AW16: =IF(M16=VLOOKUP(VALUE(M$1),Questions!$A:$E,5,FALSE),1,0) -> 1 | AX16: =IF(N16=VLOOKUP(VALUE(N$1),Questions!$A:$E,5,FALSE),1,0) -> 0 | AY16: =IF(O16=VLOOKUP(VALUE(O$1),Questions!$A:$E,5,FALSE),1,0) -> 0 | ... BS16: =IF(AI16=VLOOKUP(VALUE(AI$1),Questions!$A:$E,5,FALSE),1,0) -> 1
A17: 16 | B17: FALSE | C17: FALSE | D17: =SUM(Scores[[#This Row],[Q1]:[Q28]]) -> 27 | E17: =SUM(Scores[[#This Row],[29]:[34b]]) -> 0 | F17: =Scores[[#This Row],[35]] -> 0 | G17: =INDEX('Conversion Chart'!$C$3:$M$38,MATCH(SUM(Scores[[#This Row],[MC]:[CRQ]]),'Conversion Chart'!$B$3:$B$38,0),MATCH(Scores[[#This Row],[EIE]],'Conversion Chart'!$C$2:$M$2,0)) -> 66 | H17: 4 | I17: 3 | J17: 1 | K17: 2 | L17: 2 | M17: 4 | N17: 3 | O17: 4 | P17: 1 | Q17: 1 | R17: 4 | S17: 2 | T17: 1 | U17: 4 | V17: 3 | W17: 4 | X17: 2 | Y17: 3 | Z17: 2 | AA17: 3 | AB17: 2 | AC17: 1 | AD17: 3 | AE17: 2 | AF17: 4 | AG17: 3 | AH17: 1 | AI17: 1 | AR17: =IF(H17=VLOOKUP(VALUE(H$1),Questions!$A:$E,5,FALSE),1,0) -> 1 | AS17: =IF(I17=VLOOKUP(VALUE(I$1),Questions!$A:$E,5,FALSE),1,0) -> 1 | AT17: =IF(J17=VLOOKUP(VALUE(J$1),Questions!$A:$E,5,FALSE),1,0) -> 1 | AU17: =IF(K17=VLOOKUP(VALUE(K$1),Questions!$A:$E,5,FALSE),1,0) -> 1 | AV17: =IF(L17=VLOOKUP(VALUE(L$1),Questions!$A:$E,5,FALSE),1,0) -> 1 | AW17: =IF(M17=VLOOKUP(VALUE(M$1),Questions!$A:$E,5,FALSE),1,0) -> 1 | AX17: =IF(N17=VLOOKUP(VALUE(N$1),Questions!$A:$E,5,FALSE),1,0) -> 1 | AY17: =IF(O17=VLOOKUP(VALUE(O$1),Questions!$A:$E,5,FALSE),1,0) -> 0 | ... BS17: =IF(AI17=VLOOKUP(VALUE(AI$1),Questions!$A:$E,5,FALSE),1,0) -> 1
A18: 17 | B18: FALSE | C18: FALSE | D18: =SUM(Scores[[#This Row],[Q1]:[Q28]]) -> 24 | E18: =SUM(Scores[[#This Row],[29]:[34b]]) -> 0 | F18: =Scores[[#This Row],[35]] -> 0 | G18: =INDEX('Conversion Chart'!$C$3:$M$38,MATCH(SUM(Scores[[#This Row],[MC]:[CRQ]]),'Conversion Chart'!$B$3:$B$38,0),MATCH(Scores[[#This Row],[EIE]],'Conversion Chart'!$C$2:$M$2,0)) -> 61 | H18: 4 | I18: 3 | J18: 1 | K18: 2 | L18: 2 | M18: 4 | N18: 3 | O18: 1 | P18: 3 | Q18: 1 | R18: 4 | S18: 2 | T18: 1 | U18: 3 | V18: 3 | W18: 4 | X18: 2 | Y18: 3 | Z18: 2 | AA18: 3 | AB18: 2 | AC18: 1 | AD18: 2 | AE18: 2 | AF18: 4 | AG18: 3 | AH18: 1 | AI18: 4 | AR18: =IF(H18=VLOOKUP(VALUE(H$1),Questions!$A:$E,5,FALSE),1,0) -> 1 | AS18: =IF(I18=VLOOKUP(VALUE(I$1),Questions!$A:$E,5,FALSE),1,0) -> 1 | AT18: =IF(J18=VLOOKUP(VALUE(J$1),Questions!$A:$E,5,FALSE),1,0) -> 1 | AU18: =IF(K18=VLOOKUP(VALUE(K$1),Questions!$A:$E,5,FALSE),1,0) -> 1 | AV18: =IF(L18=VLOOKUP(VALUE(L$1),Questions!$A:$E,5,FALSE),1,0) -> 1 | AW18: =IF(M18=VLOOKUP(VALUE(M$1),Questions!$A:$E,5,FALSE),1,0) -> 1 | AX18: =IF(N18=VLOOKUP(VALUE(N$1),Questions!$A:$E,5,FALSE),1,0) -> 1 | AY18: =IF(O18=VLOOKUP(VALUE(O$1),Questions!$A:$E,5,FALSE),1,0) -> 1 | ... BS18: =IF(AI18=VLOOKUP(VALUE(AI$1),Questions!$A:$E,5,FALSE),1,0) -> 0
A19: 18 | B19: FALSE | C19: FALSE | D19: =SUM(Scores[[#This Row],[Q1]:[Q28]]) -> 24 | E19: =SUM(Scores[[#This Row],[29]:[34b]]) -> 0 | F19: =Scores[[#This Row],[35]] -> 0 | G19: =INDEX('Conversion Chart'!$C$3:$M$38,MATCH(SUM(Scores[[#This Row],[MC]:[CRQ]]),'Conversion Chart'!$B$3:$B$38,0),MATCH(Scores[[#This Row],[EIE]],'Conversion Chart'!$C$2:$M$2,0)) -> 61 | H19: 4 | I19: 3 | J19: 3 | K19: 2 | L19: 2 | M19: 4 | N19: 1 | O19: 4 | P19: 1 | Q19: 1 | R19: 4 | S19: 2 | T19: 1 | U19: 4 | V19: 3 | W19: 4 | X19: 2 | Y19: 3 | Z19: 1 | AA19: 3 | AB19: 2 | AC19: 1 | AD19: 3 | AE19: 2 | AF19: 4 | AG19: 3 | AH19: 1 | AI19: 1 | AR19: =IF(H19=VLOOKUP(VALUE(H$1),Questions!$A:$E,5,FALSE),1,0) -> 1 | AS19: =IF(I19=VLOOKUP(VALUE(I$1),Questions!$A:$E,5,FALSE),1,0) -> 1 | AT19: =IF(J19=VLOOKUP(VALUE(J$1),Questions!$A:$E,5,FALSE),1,0) -> 0 | AU19: =IF(K19=VLOOKUP(VALUE(K$1),Questions!$A:$E,5,FALSE),1,0) -> 1 | AV19: =IF(L19=VLOOKUP(VALUE(L$1),Questions!$A:$E,5,FALSE),1,0) -> 1 | AW19: =IF(M19=VLOOKUP(VALUE(M$1),Questions!$A:$E,5,FALSE),1,0) -> 1 | AX19: =IF(N19=VLOOKUP(VALUE(N$1),Questions!$A:$E,5,FALSE),1,0) -> 0 | AY19: =IF(O19=VLOOKUP(VALUE(O$1),Questions!$A:$E,5,FALSE),1,0) -> 0 | ... BS19: =IF(AI19=VLOOKUP(VALUE(AI$1),Questions!$A:$E,5,FALSE),1,0) -> 1
A20: 19 | B20: FALSE | C20: FALSE | D20: =SUM(Scores[[#This Row],[Q1]:[Q28]]) -> 28 | E20: =SUM(Scores[[#This Row],[29]:[34b]]) -> 0 | F20: =Scores[[#This Row],[35]] -> 0 | G20: =INDEX('Conversion Chart'!$C$3:$M$38,MATCH(SUM(Scores[[#This Row],[MC]:[CRQ]]),'Conversion Chart'!$B$3:$B$38,0),MATCH(Scores[[#This Row],[EIE]],'Conversion Chart'!$C$2:$M$2,0)) -> 68 | H20: 4 | I20: 3 | J20: 1 | K20: 2 | L20: 2 | M20: 4 | N20: 3 | O20: 1 | P20: 1 | Q20: 1 | R20: 4 | S20: 2 | T20: 1 | U20: 4 | V20: 3 | W20: 4 | X20: 2 | Y20: 3 | Z20: 2 | AA20: 3 | AB20: 2 | AC20: 1 | AD20: 3 | AE20: 2 | AF20: 4 | AG20: 3 | AH20: 1 | AI20: 1 | AR20: =IF(H20=VLOOKUP(VALUE(H$1),Questions!$A:$E,5,FALSE),1,0) -> 1 | AS20: =IF(I20=VLOOKUP(VALUE(I$1),Questions!$A:$E,5,FALSE),1,0) -> 1 | AT20: =IF(J20=VLOOKUP(VALUE(J$1),Questions!$A:$E,5,FALSE),1,0) -> 1 | AU20: =IF(K20=VLOOKUP(VALUE(K$1),Questions!$A:$E,5,FALSE),1,0) -> 1 | AV20: =IF(L20=VLOOKUP(VALUE(L$1),Questions!$A:$E,5,FALSE),1,0) -> 1 | AW20: =IF(M20=VLOOKUP(VALUE(M$1),Questions!$A:$E,5,FALSE),1,0) -> 1 | AX20: =IF(N20=VLOOKUP(VALUE(N$1),Questions!$A:$E,5,FALSE),1,0) -> 1 | AY20: =IF(O20=VLOOKUP(VALUE(O$1),Questions!$A:$E,5,FALSE),1,0) -> 1 | ... BS20: =IF(AI20=VLOOKUP(VALUE(AI$1),Questions!$A:$E,5,FALSE),1,0) -> 1
A21: 20 | B21: FALSE | C21: FALSE | D21: =SUM(Scores[[#This Row],[Q1]:[Q28]]) -> 20 | E21: =SUM(Scores[[#This Row],[29]:[34b]]) -> 0 | F21: =Scores[[#This Row],[35]] -> 0 | G21: =INDEX('Conversion Chart'!$C$3:$M$38,MATCH(SUM(Scores[[#This Row],[MC]:[CRQ]]),'Conversion Chart'!$B$3:$B$38,0),MATCH(Scores[[#This Row],[EIE]],'Conversion Chart'!$C$2:$M$2,0)) -> 53 | H21: 4 | I21: 3 | J21: 1 | K21: 2 | L21: 1 | M21: 4 | N21: 3 | O21: 1 | P21: 1 | Q21: 4 | R21: 1 | S21: 2 | T21: 1 | U21: 2 | V21: 3 | W21: 4 | X21: 2 | Y21: 2 | Z21: 4 | AA21: 3 | AB21: 4 | AC21: 1 | AD21: 2 | AE21: 2 | AF21: 4 | AG21: 3 | AH21: 1 | AI21: 1 | AR21: =IF(H21=VLOOKUP(VALUE(H$1),Questions!$A:$E,5,FALSE),1,0) -> 1 | AS21: =IF(I21=VLOOKUP(VALUE(I$1),Questions!$A:$E,5,FALSE),1,0) -> 1 | AT21: =IF(J21=VLOOKUP(VALUE(J$1),Questions!$A:$E,5,FALSE),1,0) -> 1 | AU21: =IF(K21=VLOOKUP(VALUE(K$1),Questions!$A:$E,5,FALSE),1,0) -> 1 | AV21: =IF(L21=VLOOKUP(VALUE(L$1),Questions!$A:$E,5,FALSE),1,0) -> 0 | AW21: =IF(M21=VLOOKUP(VALUE(M$1),Questions!$A:$E,5,FALSE),1,0) -> 1 | AX21: =IF(N21=VLOOKUP(VALUE(N$1),Questions!$A:$E,5,FALSE),1,0) -> 1 | AY21: =IF(O21=VLOOKUP(VALUE(O$1),Questions!$A:$E,5,FALSE),1,0) -> 1 | ... BS21: =IF(AI21=VLOOKUP(VALUE(AI$1),Questions!$A:$E,5,FALSE),1,0) -> 1
A22: 21 | B22: FALSE | C22: FALSE | D22: =SUM(Scores[[#This Row],[Q1]:[Q28]]) -> 16 | E22: =SUM(Scores[[#This Row],[29]:[34b]]) -> 0 | F22: =Scores[[#This Row],[35]] -> 0 | G22: =INDEX('Conversion Chart'!$C$3:$M$38,MATCH(SUM(Scores[[#This Row],[MC]:[CRQ]]),'Conversion Chart'!$B$3:$B$38,0),MATCH(Scores[[#This Row],[EIE]],'Conversion Chart'!$C$2:$M$2,0)) -> 45 | H22: 4 | I22: 3 | J22: 1 | K22: 2 | L22: 3 | M22: 4 | N22: 3 | O22: 1 | P22: 3 | Q22: 1 | R22: 4 | S22: 3 | T22: 1 | U22: 3 | V22: 3 | W22: 4 | X22: 3 | Y22: 3 | Z22: 4 | AA22: 2 | AB22: 2 | AC22: 3 | AD22: 4 | AE22: 2 | AF22: 1 | AG22: 3 | AH22: 3 | AI22: 2 | AR22: =IF(H22=VLOOKUP(VALUE(H$1),Questions!$A:$E,5,FALSE),1,0) -> 1 | AS22: =IF(I22=VLOOKUP(VALUE(I$1),Questions!$A:$E,5,FALSE),1,0) -> 1 | AT22: =IF(J22=VLOOKUP(VALUE(J$1),Questions!$A:$E,5,FALSE),1,0) -> 1 | AU22: =IF(K22=VLOOKUP(VALUE(K$1),Questions!$A:$E,5,FALSE),1,0) -> 1 | AV22: =IF(L22=VLOOKUP(VALUE(L$1),Questions!$A:$E,5,FALSE),1,0) -> 0 | AW22: =IF(M22=VLOOKUP(VALUE(M$1),Questions!$A:$E,5,FALSE),1,0) -> 1 | AX22: =IF(N22=VLOOKUP(VALUE(N$1),Questions!$A:$E,5,FALSE),1,0) -> 1 | AY22: =IF(O22=VLOOKUP(VALUE(O$1),Questions!$A:$E,5,FALSE),1,0) -> 1 | ... BS22: =IF(AI22=VLOOKUP(VALUE(AI$1),Questions!$A:$E,5,FALSE),1,0) -> 0
A23: 22 | B23: FALSE | C23: FALSE | D23: =SUM(Scores[[#This Row],[Q1]:[Q28]]) -> 19 | E23: =SUM(Scores[[#This Row],[29]:[34b]]) -> 0 | F23: =Scores[[#This Row],[35]] -> 0 | G23: =INDEX('Conversion Chart'!$C$3:$M$38,MATCH(SUM(Scores[[#This Row],[MC]:[CRQ]]),'Conversion Chart'!$B$3:$B$38,0),MATCH(Scores[[#This Row],[EIE]],'Conversion Chart'!$C$2:$M$2,0)) -> 51 | H23: 4 | I23: 3 | J23: 1 | K23: 2 | L23: 2 | M23: 4 | N23: 3 | O23: 3 | P23: 1 | Q23: 1 | R23: 4 | S23: 2 | T23: 4 | U23: 2 | V23: 3 | W23: 4 | X23: 2 | Y23: 2 | Z23: 1 | AA23: 2 | AB23: 2 | AC23: 3 | AD23: 3 | AE23: 4 | AF23: 4 | AG23: 2 | AH23: 1 | AI23: 1 | AR23: =IF(H23=VLOOKUP(VALUE(H$1),Questions!$A:$E,5,FALSE),1,0) -> 1 | AS23: =IF(I23=VLOOKUP(VALUE(I$1),Questions!$A:$E,5,FALSE),1,0) -> 1 | AT23: =IF(J23=VLOOKUP(VALUE(J$1),Questions!$A:$E,5,FALSE),1,0) -> 1 | AU23: =IF(K23=VLOOKUP(VALUE(K$1),Questions!$A:$E,5,FALSE),1,0) -> 1 | AV23: =IF(L23=VLOOKUP(VALUE(L$1),Questions!$A:$E,5,FALSE),1,0) -> 1 | AW23: =IF(M23=VLOOKUP(VALUE(M$1),Questions!$A:$E,5,FALSE),1,0) -> 1 | AX23: =IF(N23=VLOOKUP(VALUE(N$1),Questions!$A:$E,5,FALSE),1,0) -> 1 | AY23: =IF(O23=VLOOKUP(VALUE(O$1),Questions!$A:$E,5,FALSE),1,0) -> 0 | ... BS23: =IF(AI23=VLOOKUP(VALUE(AI$1),Questions!$A:$E,5,FALSE),1,0) -> 1
A24: 23 | B24: FALSE | C24: FALSE | D24: =SUM(Scores[[#This Row],[Q1]:[Q28]]) -> 15 | E24: =SUM(Scores[[#This Row],[29]:[34b]]) -> 0 | F24: =Scores[[#This Row],[35]] -> 0 | G24: =INDEX('Conversion Chart'!$C$3:$M$38,MATCH(SUM(Scores[[#This Row],[MC]:[CRQ]]),'Conversion Chart'!$B$3:$B$38,0),MATCH(Scores[[#This Row],[EIE]],'Conversion Chart'!$C$2:$M$2,0)) -> 42 | H24: 3 | I24: 3 | J24: 1 | K24: 3 | L24: 2 | M24: 4 | N24: 1 | O24: 1 | P24: 1 | Q24: 1 | R24: 4 | S24: 4 | T24: 2 | U24: 1 | V24: 4 | W24: 1 | X24: 2 | Y24: 1 | Z24: 1 | AA24: 3 | AB24: 4 | AC24: 1 | AD24: 4 | AE24: 2 | AF24: 4 | AG24: 1 | AH24: 1 | AI24: 1 | AR24: =IF(H24=VLOOKUP(VALUE(H$1),Questions!$A:$E,5,FALSE),1,0) -> 0 | AS24: =IF(I24=VLOOKUP(VALUE(I$1),Questions!$A:$E,5,FALSE),1,0) -> 1 | AT24: =IF(J24=VLOOKUP(VALUE(J$1),Questions!$A:$E,5,FALSE),1,0) -> 1 | AU24: =IF(K24=VLOOKUP(VALUE(K$1),Questions!$A:$E,5,FALSE),1,0) -> 0 | AV24: =IF(L24=VLOOKUP(VALUE(L$1),Questions!$A:$E,5,FALSE),1,0) -> 1 | AW24: =IF(M24=VLOOKUP(VALUE(M$1),Questions!$A:$E,5,FALSE),1,0) -> 1 | AX24: =IF(N24=VLOOKUP(VALUE(N$1),Questions!$A:$E,5,FALSE),1,0) -> 0 | AY24: =IF(O24=VLOOKUP(VALUE(O$1),Questions!$A:$E,5,FALSE),1,0) -> 1 | ... BS24: =IF(AI24=VLOOKUP(VALUE(AI$1),Questions!$A:$E,5,FALSE),1,0) -> 1
A25: 24 | B25: FALSE | C25: FALSE | D25: =SUM(Scores[[#This Row],[Q1]:[Q28]]) -> 0 | E25: =SUM(Scores[[#This Row],[29]:[34b]]) -> 0 | F25: =Scores[[#This Row],[35]] -> 0 | G25: =INDEX('Conversion Chart'!$C$3:$M$38,MATCH(SUM(Scores[[#This Row],[MC]:[CRQ]]),'Conversion Chart'!$B$3:$B$38,0),MATCH(Scores[[#This Row],[EIE]],'Conversion Chart'!$C$2:$M$2,0)) -> 0 | AR25: =IF(H25=VLOOKUP(VALUE(H$1),Questions!$A:$E,5,FALSE),1,0) -> 0 | AS25: =IF(I25=VLOOKUP(VALUE(I$1),Questions!$A:$E,5,FALSE),1,0) -> 0 | AT25: =IF(J25=VLOOKUP(VALUE(J$1),Questions!$A:$E,5,FALSE),1,0) -> 0 | AU25: =IF(K25=VLOOKUP(VALUE(K$1),Questions!$A:$E,5,FALSE),1,0) -> 0 | AV25: =IF(L25=VLOOKUP(VALUE(L$1),Questions!$A:$E,5,FALSE),1,0) -> 0 | AW25: =IF(M25=VLOOKUP(VALUE(M$1),Questions!$A:$E,5,FALSE),1,0) -> 0 | AX25: =IF(N25=VLOOKUP(VALUE(N$1),Questions!$A:$E,5,FALSE),1,0) -> 0 | AY25: =IF(O25=VLOOKUP(VALUE(O$1),Questions!$A:$E,5,FALSE),1,0) -> 0 | ... BS25: =IF(AI25=VLOOKUP(VALUE(AI$1),Questions!$A:$E,5,FALSE),1,0) -> 0
A26: 25 | B26: FALSE | C26: FALSE | D26: =SUM(Scores[[#This Row],[Q1]:[Q28]]) -> 17 | E26: =SUM(Scores[[#This Row],[29]:[34b]]) -> 0 | F26: =Scores[[#This Row],[35]] -> 0 | G26: =INDEX('Conversion Chart'!$C$3:$M$38,MATCH(SUM(Scores[[#This Row],[MC]:[CRQ]]),'Conversion Chart'!$B$3:$B$38,0),MATCH(Scores[[#This Row],[EIE]],'Conversion Chart'!$C$2:$M$2,0)) -> 47 | H26: 4 | I26: 3 | J26: 1 | K26: 2 | L26: 3 | M26: 2 | N26: 2 | O26: 1 | P26: 2 | Q26: 1 | R26: 4 | S26: 2 | T26: 1 | U26: 4 | V26: 3 | W26: 1 | X26: 2 | Y26: 2 | Z26: 4 | AA26: 3 | AB26: 2 | AC26: 1 | AD26: 2 | AE26: 2 | AF26: 1 | AG26: 3 | AH26: 4 | AI26: 4 | AR26: =IF(H26=VLOOKUP(VALUE(H$1),Questions!$A:$E,5,FALSE),1,0) -> 1 | AS26: =IF(I26=VLOOKUP(VALUE(I$1),Questions!$A:$E,5,FALSE),1,0) -> 1 | AT26: =IF(J26=VLOOKUP(VALUE(J$1),Questions!$A:$E,5,FALSE),1,0) -> 1 | AU26: =IF(K26=VLOOKUP(VALUE(K$1),Questions!$A:$E,5,FALSE),1,0) -> 1 | AV26: =IF(L26=VLOOKUP(VALUE(L$1),Questions!$A:$E,5,FALSE),1,0) -> 0 | AW26: =IF(M26=VLOOKUP(VALUE(M$1),Questions!$A:$E,5,FALSE),1,0) -> 0 | AX26: =IF(N26=VLOOKUP(VALUE(N$1),Questions!$A:$E,5,FALSE),1,0) -> 0 | AY26: =IF(O26=VLOOKUP(VALUE(O$1),Questions!$A:$E,5,FALSE),1,0) -> 1 | ... BS26: =IF(AI26=VLOOKUP(VALUE(AI$1),Questions!$A:$E,5,FALSE),1,0) -> 0
A27: 26 | B27: FALSE | C27: FALSE | D27: =SUM(Scores[[#This Row],[Q1]:[Q28]]) -> 12 | E27: =SUM(Scores[[#This Row],[29]:[34b]]) -> 0 | F27: =Scores[[#This Row],[35]] -> 0 | G27: =INDEX('Conversion Chart'!$C$3:$M$38,MATCH(SUM(Scores[[#This Row],[MC]:[CRQ]]),'Conversion Chart'!$B$3:$B$38,0),MATCH(Scores[[#This Row],[EIE]],'Conversion Chart'!$C$2:$M$2,0)) -> 35 | H27: 1 | I27: 3 | J27: 1 | K27: 2 | L27: 1 | M27: 4 | N27: 2 | O27: 3 | P27: 4 | Q27: 1 | R27: 4 | S27: 4 | T27: 1 | U27: 2 | V27: 1 | W27: 1 | X27: 2 | Y27: 2 | Z27: 2 | AA27: 3 | AB27: 1 | AC27: 3 | AD27: 2 | AE27: 2 | AF27: 1 | AG27: 4 | AH27: 1 | AI27: 4 | AR27: =IF(H27=VLOOKUP(VALUE(H$1),Questions!$A:$E,5,FALSE),1,0) -> 0 | AS27: =IF(I27=VLOOKUP(VALUE(I$1),Questions!$A:$E,5,FALSE),1,0) -> 1 | AT27: =IF(J27=VLOOKUP(VALUE(J$1),Questions!$A:$E,5,FALSE),1,0) -> 1 | AU27: =IF(K27=VLOOKUP(VALUE(K$1),Questions!$A:$E,5,FALSE),1,0) -> 1 | AV27: =IF(L27=VLOOKUP(VALUE(L$1),Questions!$A:$E,5,FALSE),1,0) -> 0 | AW27: =IF(M27=VLOOKUP(VALUE(M$1),Questions!$A:$E,5,FALSE),1,0) -> 1 | AX27: =IF(N27=VLOOKUP(VALUE(N$1),Questions!$A:$E,5,FALSE),1,0) -> 0 | AY27: =IF(O27=VLOOKUP(VALUE(O$1),Questions!$A:$E,5,FALSE),1,0) -> 0 | ... BS27: =IF(AI27=VLOOKUP(VALUE(AI$1),Questions!$A:$E,5,FALSE),1,0) -> 0
A28: 27 | B28: FALSE | C28: FALSE | D28: =SUM(Scores[[#This Row],[Q1]:[Q28]]) -> 24 | E28: =SUM(Scores[[#This Row],[29]:[34b]]) -> 0 | F28: =Scores[[#This Row],[35]] -> 0 | G28: =INDEX('Conversion Chart'!$C$3:$M$38,MATCH(SUM(Scores[[#This Row],[MC]:[CRQ]]),'Conversion Chart'!$B$3:$B$38,0),MATCH(Scores[[#This Row],[EIE]],'Conversion Chart'!$C$2:$M$2,0)) -> 61 | H28: 4 | I28: 3 | J28: 1 | K28: 2 | L28: 2 | M28: 4 | N28: 3 | O28: 4 | P28: 1 | Q28: 1 | R28: 4 | S28: 3 | T28: 1 | U28: 4 | V28: 3 | W28: 4 | X28: 2 | Y28: 3 | Z28: 2 | AA28: 2 | AB28: 3 | AC28: 1 | AD28: 3 | AE28: 2 | AF28: 4 | AG28: 3 | AH28: 1 | AI28: 1 | AR28: =IF(H28=VLOOKUP(VALUE(H$1),Questions!$A:$E,5,FALSE),1,0) -> 1 | AS28: =IF(I28=VLOOKUP(VALUE(I$1),Questions!$A:$E,5,FALSE),1,0) -> 1 | AT28: =IF(J28=VLOOKUP(VALUE(J$1),Questions!$A:$E,5,FALSE),1,0) -> 1 | AU28: =IF(K28=VLOOKUP(VALUE(K$1),Questions!$A:$E,5,FALSE),1,0) -> 1 | AV28: =IF(L28=VLOOKUP(VALUE(L$1),Questions!$A:$E,5,FALSE),1,0) -> 1 | AW28: =IF(M28=VLOOKUP(VALUE(M$1),Questions!$A:$E,5,FALSE),1,0) -> 1 | AX28: =IF(N28=VLOOKUP(VALUE(N$1),Questions!$A:$E,5,FALSE),1,0) -> 1 | AY28: =IF(O28=VLOOKUP(VALUE(O$1),Questions!$A:$E,5,FALSE),1,0) -> 0 | ... BS28: =IF(AI28=VLOOKUP(VALUE(AI$1),Questions!$A:$E,5,FALSE),1,0) -> 1
A29: 28 | B29: FALSE | C29: FALSE | D29: =SUM(Scores[[#This Row],[Q1]:[Q28]]) -> 12 | E29: =SUM(Scores[[#This Row],[29]:[34b]]) -> 0 | F29: =Scores[[#This Row],[35]] -> 0 | G29: =INDEX('Conversion Chart'!$C$3:$M$38,MATCH(SUM(Scores[[#This Row],[MC]:[CRQ]]),'Conversion Chart'!$B$3:$B$38,0),MATCH(Scores[[#This Row],[EIE]],'Conversion Chart'!$C$2:$M$2,0)) -> 35 | H29: 4 | I29: 3 | J29: 1 | K29: 4 | L29: 1 | M29: 4 | N29: 1 | O29: 3 | P29: 2 | Q29: 1 | R29: 4 | S29: 4 | T29: 1 | U29: 3 | V29: 1 | W29: 2 | X29: 3 | Y29: 1 | Z29: 1 | AA29: 3 | AB29: 4 | AC29: 4 | AD29: 3 | AE29: 2 | AF29: 4 | AG29: 3 | AH29: 4 | AI29: 3 | AR29: =IF(H29=VLOOKUP(VALUE(H$1),Questions!$A:$E,5,FALSE),1,0) -> 1 | AS29: =IF(I29=VLOOKUP(VALUE(I$1),Questions!$A:$E,5,FALSE),1,0) -> 1 | AT29: =IF(J29=VLOOKUP(VALUE(J$1),Questions!$A:$E,5,FALSE),1,0) -> 1 | AU29: =IF(K29=VLOOKUP(VALUE(K$1),Questions!$A:$E,5,FALSE),1,0) -> 0 | AV29: =IF(L29=VLOOKUP(VALUE(L$1),Questions!$A:$E,5,FALSE),1,0) -> 0 | AW29: =IF(M29=VLOOKUP(VALUE(M$1),Questions!$A:$E,5,FALSE),1,0) -> 1 | AX29: =IF(N29=VLOOKUP(VALUE(N$1),Questions!$A:$E,5,FALSE),1,0) -> 0 | AY29: =IF(O29=VLOOKUP(VALUE(O$1),Questions!$A:$E,5,FALSE),1,0) -> 0 | ... BS29: =IF(AI29=VLOOKUP(VALUE(AI$1),Questions!$A:$E,5,FALSE),1,0) -> 0
A30: 29 | B30: FALSE | C30: FALSE | D30: =SUM(Scores[[#This Row],[Q1]:[Q28]]) -> 21 | E30: =SUM(Scores[[#This Row],[29]:[34b]]) -> 0 | F30: =Scores[[#This Row],[35]] -> 0 | G30: =INDEX('Conversion Chart'!$C$3:$M$38,MATCH(SUM(Scores[[#This Row],[MC]:[CRQ]]),'Conversion Chart'!$B$3:$B$38,0),MATCH(Scores[[#This Row],[EIE]],'Conversion Chart'!$C$2:$M$2,0)) -> 55 | H30: 4 | I30: 3 | J30: 1 | K30: 2 | L30: 1 | M30: 4 | N30: 3 | O30: 3 | P30: 1 | Q30: 4 | R30: 4 | S30: 4 | T30: 3 | U30: 4 | V30: 3 | W30: 4 | X30: 2 | Y30: 3 | Z30: 4 | AA30: 3 | AB30: 2 | AC30: 1 | AD30: 3 | AE30: 4 | AF30: 4 | AG30: 3 | AH30: 1 | AI30: 1 | AR30: =IF(H30=VLOOKUP(VALUE(H$1),Questions!$A:$E,5,FALSE),1,0) -> 1 | AS30: =IF(I30=VLOOKUP(VALUE(I$1),Questions!$A:$E,5,FALSE),1,0) -> 1 | AT30: =IF(J30=VLOOKUP(VALUE(J$1),Questions!$A:$E,5,FALSE),1,0) -> 1 | AU30: =IF(K30=VLOOKUP(VALUE(K$1),Questions!$A:$E,5,FALSE),1,0) -> 1 | AV30: =IF(L30=VLOOKUP(VALUE(L$1),Questions!$A:$E,5,FALSE),1,0) -> 0 | AW30: =IF(M30=VLOOKUP(VALUE(M$1),Questions!$A:$E,5,FALSE),1,0) -> 1 | AX30: =IF(N30=VLOOKUP(VALUE(N$1),Questions!$A:$E,5,FALSE),1,0) -> 1 | AY30: =IF(O30=VLOOKUP(VALUE(O$1),Questions!$A:$E,5,FALSE),1,0) -> 0 | ... BS30: =IF(AI30=VLOOKUP(VALUE(AI$1),Questions!$A:$E,5,FALSE),1,0) -> 1
A31: 30 | B31: FALSE | C31: FALSE | D31: =SUM(Scores[[#This Row],[Q1]:[Q28]]) -> 23 | E31: =SUM(Scores[[#This Row],[29]:[34b]]) -> 0 | F31: =Scores[[#This Row],[35]] -> 0 | G31: =INDEX('Conversion Chart'!$C$3:$M$38,MATCH(SUM(Scores[[#This Row],[MC]:[CRQ]]),'Conversion Chart'!$B$3:$B$38,0),MATCH(Scores[[#This Row],[EIE]],'Conversion Chart'!$C$2:$M$2,0)) -> 59 | H31: 4 | I31: 3 | J31: 1 | K31: 2 | L31: 2 | M31: 4 | N31: 3 | O31: 1 | P31: 1 | Q31: 1 | R31: 4 | S31: 2 | T31: 1 | U31: 4 | V31: 1 | W31: 1 | X31: 1 | Y31: 3 | Z31: 4 | AA31: 3 | AB31: 2 | AC31: 1 | AD31: 3 | AE31: 2 | AF31: 4 | AG31: 3 | AH31: 4 | AI31: 1 | AR31: =IF(H31=VLOOKUP(VALUE(H$1),Questions!$A:$E,5,FALSE),1,0) -> 1 | AS31: =IF(I31=VLOOKUP(VALUE(I$1),Questions!$A:$E,5,FALSE),1,0) -> 1 | AT31: =IF(J31=VLOOKUP(VALUE(J$1),Questions!$A:$E,5,FALSE),1,0) -> 1 | AU31: =IF(K31=VLOOKUP(VALUE(K$1),Questions!$A:$E,5,FALSE),1,0) -> 1 | AV31: =IF(L31=VLOOKUP(VALUE(L$1),Questions!$A:$E,5,FALSE),1,0) -> 1 | AW31: =IF(M31=VLOOKUP(VALUE(M$1),Questions!$A:$E,5,FALSE),1,0) -> 1 | AX31: =IF(N31=VLOOKUP(VALUE(N$1),Questions!$A:$E,5,FALSE),1,0) -> 1 | AY31: =IF(O31=VLOOKUP(VALUE(O$1),Questions!$A:$E,5,FALSE),1,0) -> 1 | ... BS31: =IF(AI31=VLOOKUP(VALUE(AI$1),Questions!$A:$E,5,FALSE),1,0) -> 1
A32: 31 | B32: FALSE | C32: FALSE | D32: =SUM(Scores[[#This Row],[Q1]:[Q28]]) -> 27 | E32: =SUM(Scores[[#This Row],[29]:[34b]]) -> 0 | F32: =Scores[[#This Row],[35]] -> 0 | G32: =INDEX('Conversion Chart'!$C$3:$M$38,MATCH(SUM(Scores[[#This Row],[MC]:[CRQ]]),'Conversion Chart'!$B$3:$B$38,0),MATCH(Scores[[#This Row],[EIE]],'Conversion Chart'!$C$2:$M$2,0)) -> 66 | H32: 4 | I32: 3 | J32: 1 | K32: 2 | L32: 2 | M32: 4 | N32: 3 | O32: 3 | P32: 1 | Q32: 1 | R32: 4 | S32: 2 | T32: 1 | U32: 4 | V32: 3 | W32: 4 | X32: 2 | Y32: 3 | Z32: 2 | AA32: 3 | AB32: 2 | AC32: 1 | AD32: 3 | AE32: 2 | AF32: 4 | AG32: 3 | AH32: 1 | AI32: 1 | AR32: =IF(H32=VLOOKUP(VALUE(H$1),Questions!$A:$E,5,FALSE),1,0) -> 1 | AS32: =IF(I32=VLOOKUP(VALUE(I$1),Questions!$A:$E,5,FALSE),1,0) -> 1 | AT32: =IF(J32=VLOOKUP(VALUE(J$1),Questions!$A:$E,5,FALSE),1,0) -> 1 | AU32: =IF(K32=VLOOKUP(VALUE(K$1),Questions!$A:$E,5,FALSE),1,0) -> 1 | AV32: =IF(L32=VLOOKUP(VALUE(L$1),Questions!$A:$E,5,FALSE),1,0) -> 1 | AW32: =IF(M32=VLOOKUP(VALUE(M$1),Questions!$A:$E,5,FALSE),1,0) -> 1 | AX32: =IF(N32=VLOOKUP(VALUE(N$1),Questions!$A:$E,5,FALSE),1,0) -> 1 | AY32: =IF(O32=VLOOKUP(VALUE(O$1),Questions!$A:$E,5,FALSE),1,0) -> 0 | ... BS32: =IF(AI32=VLOOKUP(VALUE(AI$1),Questions!$A:$E,5,FALSE),1,0) -> 1
A33: 32 | B33: FALSE | C33: FALSE | D33: =SUM(Scores[[#This Row],[Q1]:[Q28]]) -> 21 | E33: =SUM(Scores[[#This Row],[29]:[34b]]) -> 0 | F33: =Scores[[#This Row],[35]] -> 0 | G33: =INDEX('Conversion Chart'!$C$3:$M$38,MATCH(SUM(Scores[[#This Row],[MC]:[CRQ]]),'Conversion Chart'!$B$3:$B$38,0),MATCH(Scores[[#This Row],[EIE]],'Conversion Chart'!$C$2:$M$2,0)) -> 55 | H33: 4 | I33: 3 | J33: 1 | K33: 2 | L33: 2 | M33: 4 | N33: 3 | O33: 2 | P33: 1 | Q33: 3 | R33: 1 | S33: 4 | T33: 1 | U33: 4 | V33: 1 | W33: 3 | X33: 1 | Y33: 3 | Z33: 2 | AA33: 3 | AB33: 2 | AC33: 1 | AD33: 3 | AE33: 2 | AF33: 4 | AG33: 3 | AH33: 1 | AI33: 1 | AR33: =IF(H33=VLOOKUP(VALUE(H$1),Questions!$A:$E,5,FALSE),1,0) -> 1 | AS33: =IF(I33=VLOOKUP(VALUE(I$1),Questions!$A:$E,5,FALSE),1,0) -> 1 | AT33: =IF(J33=VLOOKUP(VALUE(J$1),Questions!$A:$E,5,FALSE),1,0) -> 1 | AU33: =IF(K33=VLOOKUP(VALUE(K$1),Questions!$A:$E,5,FALSE),1,0) -> 1 | AV33: =IF(L33=VLOOKUP(VALUE(L$1),Questions!$A:$E,5,FALSE),1,0) -> 1 | AW33: =IF(M33=VLOOKUP(VALUE(M$1),Questions!$A:$E,5,FALSE),1,0) -> 1 | AX33: =IF(N33=VLOOKUP(VALUE(N$1),Questions!$A:$E,5,FALSE),1,0) -> 1 | AY33: =IF(O33=VLOOKUP(VALUE(O$1),Questions!$A:$E,5,FALSE),1,0) -> 0 | ... BS33: =IF(AI33=VLOOKUP(VALUE(AI$1),Questions!$A:$E,5,FALSE),1,0) -> 1
A34: 33 | B34: FALSE | C34: FALSE | D34: =SUM(Scores[[#This Row],[Q1]:[Q28]]) -> 16 | E34: =SUM(Scores[[#This Row],[29]:[34b]]) -> 0 | F34: =Scores[[#This Row],[35]] -> 0 | G34: =INDEX('Conversion Chart'!$C$3:$M$38,MATCH(SUM(Scores[[#This Row],[MC]:[CRQ]]),'Conversion Chart'!$B$3:$B$38,0),MATCH(Scores[[#This Row],[EIE]],'Conversion Chart'!$C$2:$M$2,0)) -> 45 | H34: 4 | I34: 1 | J34: 1 | K34: 2 | L34: 1 | M34: 2 | N34: 3 | O34: 4 | P34: 1 | Q34: 1 | R34: 3 | S34: 4 | T34: 4 | U34: 3 | V34: 1 | W34: 4 | X34: 2 | Y34: 1 | Z34: 2 | AA34: 4 | AB34: 2 | AC34: 1 | AD34: 3 | AE34: 2 | AF34: 4 | AG34: 3 | AH34: 4 | AI34: 1 | AR34: =IF(H34=VLOOKUP(VALUE(H$1),Questions!$A:$E,5,FALSE),1,0) -> 1 | AS34: =IF(I34=VLOOKUP(VALUE(I$1),Questions!$A:$E,5,FALSE),1,0) -> 0 | AT34: =IF(J34=VLOOKUP(VALUE(J$1),Questions!$A:$E,5,FALSE),1,0) -> 1 | AU34: =IF(K34=VLOOKUP(VALUE(K$1),Questions!$A:$E,5,FALSE),1,0) -> 1 | AV34: =IF(L34=VLOOKUP(VALUE(L$1),Questions!$A:$E,5,FALSE),1,0) -> 0 | AW34: =IF(M34=VLOOKUP(VALUE(M$1),Questions!$A:$E,5,FALSE),1,0) -> 0 | AX34: =IF(N34=VLOOKUP(VALUE(N$1),Questions!$A:$E,5,FALSE),1,0) -> 1 | AY34: =IF(O34=VLOOKUP(VALUE(O$1),Questions!$A:$E,5,FALSE),1,0) -> 0 | ... BS34: =IF(AI34=VLOOKUP(VALUE(AI$1),Questions!$A:$E,5,FALSE),1,0) -> 1
A35: 34 | B35: FALSE | C35: FALSE | D35: =SUM(Scores[[#This Row],[Q1]:[Q28]]) -> 26 | E35: =SUM(Scores[[#This Row],[29]:[34b]]) -> 0 | F35: =Scores[[#This Row],[35]] -> 0 | G35: =INDEX('Conversion Chart'!$C$3:$M$38,MATCH(SUM(Scores[[#This Row],[MC]:[CRQ]]),'Conversion Chart'!$B$3:$B$38,0),MATCH(Scores[[#This Row],[EIE]],'Conversion Chart'!$C$2:$M$2,0)) -> 64 | H35: 4 | I35: 3 | J35: 1 | K35: 2 | L35: 2 | M35: 4 | N35: 3 | O35: 3 | P35: 1 | Q35: 1 | R35: 4 | S35: 2 | T35: 1 | U35: 4 | V35: 3 | W35: 4 | X35: 2 | Y35: 3 | Z35: 2 | AA35: 4 | AB35: 2 | AC35: 1 | AD35: 3 | AE35: 2 | AF35: 4 | AG35: 3 | AH35: 1 | AI35: 1 | AR35: =IF(H35=VLOOKUP(VALUE(H$1),Questions!$A:$E,5,FALSE),1,0) -> 1 | AS35: =IF(I35=VLOOKUP(VALUE(I$1),Questions!$A:$E,5,FALSE),1,0) -> 1 | AT35: =IF(J35=VLOOKUP(VALUE(J$1),Questions!$A:$E,5,FALSE),1,0) -> 1 | AU35: =IF(K35=VLOOKUP(VALUE(K$1),Questions!$A:$E,5,FALSE),1,0) -> 1 | AV35: =IF(L35=VLOOKUP(VALUE(L$1),Questions!$A:$E,5,FALSE),1,0) -> 1 | AW35: =IF(M35=VLOOKUP(VALUE(M$1),Questions!$A:$E,5,FALSE),1,0) -> 1 | AX35: =IF(N35=VLOOKUP(VALUE(N$1),Questions!$A:$E,5,FALSE),1,0) -> 1 | AY35: =IF(O35=VLOOKUP(VALUE(O$1),Questions!$A:$E,5,FALSE),1,0) -> 0 | ... BS35: =IF(AI35=VLOOKUP(VALUE(AI$1),Questions!$A:$E,5,FALSE),1,0) -> 1
A36: 35 | B36: FALSE | C36: FALSE | D36: =SUM(Scores[[#This Row],[Q1]:[Q28]]) -> 20 | E36: =SUM(Scores[[#This Row],[29]:[34b]]) -> 0 | F36: =Scores[[#This Row],[35]] -> 0 | G36: =INDEX('Conversion Chart'!$C$3:$M$38,MATCH(SUM(Scores[[#This Row],[MC]:[CRQ]]),'Conversion Chart'!$B$3:$B$38,0),MATCH(Scores[[#This Row],[EIE]],'Conversion Chart'!$C$2:$M$2,0)) -> 53 | H36: 4 | I36: 3 | J36: 1 | K36: 3 | L36: 4 | M36: 4 | N36: 3 | O36: 1 | P36: 4 | Q36: 1 | R36: 4 | S36: 3 | T36: 1 | U36: 4 | V36: 3 | W36: 1 | X36: 2 | Y36: 1 | Z36: 2 | AA36: 1 | AB36: 2 | AC36: 1 | AD36: 3 | AE36: 4 | AF36: 4 | AG36: 3 | AH36: 1 | AI36: 1 | AR36: =IF(H36=VLOOKUP(VALUE(H$1),Questions!$A:$E,5,FALSE),1,0) -> 1 | AS36: =IF(I36=VLOOKUP(VALUE(I$1),Questions!$A:$E,5,FALSE),1,0) -> 1 | AT36: =IF(J36=VLOOKUP(VALUE(J$1),Questions!$A:$E,5,FALSE),1,0) -> 1 | AU36: =IF(K36=VLOOKUP(VALUE(K$1),Questions!$A:$E,5,FALSE),1,0) -> 0 | AV36: =IF(L36=VLOOKUP(VALUE(L$1),Questions!$A:$E,5,FALSE),1,0) -> 0 | AW36: =IF(M36=VLOOKUP(VALUE(M$1),Questions!$A:$E,5,FALSE),1,0) -> 1 | AX36: =IF(N36=VLOOKUP(VALUE(N$1),Questions!$A:$E,5,FALSE),1,0) -> 1 | AY36: =IF(O36=VLOOKUP(VALUE(O$1),Questions!$A:$E,5,FALSE),1,0) -> 1 | ... BS36: =IF(AI36=VLOOKUP(VALUE(AI$1),Questions!$A:$E,5,FALSE),1,0) -> 1
A37: 36 | B37: FALSE | C37: FALSE | D37: =SUM(Scores[[#This Row],[Q1]:[Q28]]) -> 20 | E37: =SUM(Scores[[#This Row],[29]:[34b]]) -> 0 | F37: =Scores[[#This Row],[35]] -> 0 | G37: =INDEX('Conversion Chart'!$C$3:$M$38,MATCH(SUM(Scores[[#This Row],[MC]:[CRQ]]),'Conversion Chart'!$B$3:$B$38,0),MATCH(Scores[[#This Row],[EIE]],'Conversion Chart'!$C$2:$M$2,0)) -> 53 | H37: 4 | I37: 3 | J37: 1 | K37: 3 | L37: 2 | M37: 3 | N37: 1 | O37: 4 | P37: 1 | Q37: 1 | R37: 4 | S37: 3 | T37: 1 | U37: 4 | V37: 1 | W37: 4 | X37: 1 | Y37: 3 | Z37: 2 | AA37: 1 | AB37: 2 | AC37: 1 | AD37: 3 | AE37: 2 | AF37: 4 | AG37: 3 | AH37: 1 | AI37: 1 | AR37: =IF(H37=VLOOKUP(VALUE(H$1),Questions!$A:$E,5,FALSE),1,0) -> 1 | AS37: =IF(I37=VLOOKUP(VALUE(I$1),Questions!$A:$E,5,FALSE),1,0) -> 1 | AT37: =IF(J37=VLOOKUP(VALUE(J$1),Questions!$A:$E,5,FALSE),1,0) -> 1 | AU37: =IF(K37=VLOOKUP(VALUE(K$1),Questions!$A:$E,5,FALSE),1,0) -> 0 | AV37: =IF(L37=VLOOKUP(VALUE(L$1),Questions!$A:$E,5,FALSE),1,0) -> 1 | AW37: =IF(M37=VLOOKUP(VALUE(M$1),Questions!$A:$E,5,FALSE),1,0) -> 0 | AX37: =IF(N37=VLOOKUP(VALUE(N$1),Questions!$A:$E,5,FALSE),1,0) -> 0 | AY37: =IF(O37=VLOOKUP(VALUE(O$1),Questions!$A:$E,5,FALSE),1,0) -> 0 | ... BS37: =IF(AI37=VLOOKUP(VALUE(AI$1),Questions!$A:$E,5,FALSE),1,0) -> 1
... A43: 42 | B43: FALSE | C43: FALSE | D43: =SUM(Scores[[#This Row],[Q1]:[Q28]]) -> 23 | E43: =SUM(Scores[[#This Row],[29]:[34b]]) -> 0 | F43: =Scores[[#This Row],[35]] -> 0 | G43: =INDEX('Conversion Chart'!$C$3:$M$38,MATCH(SUM(Scores[[#This Row],[MC]:[CRQ]]),'Conversion Chart'!$B$3:$B$38,0),MATCH(Scores[[#This Row],[EIE]],'Conversion Chart'!$C$2:$M$2,0)) -> 59 | H43: 4 | I43: 3 | J43: 1 | K43: 3 | L43: 2 | M43: 4 | N43: 3 | O43: 1 | P43: 2 | Q43: 1 | R43: 4 | S43: 4 | T43: 1 | U43: 4 | V43: 4 | W43: 4 | X43: 2 | Y43: 3 | Z43: 4 | AA43: 3 | AB43: 2 | AC43: 1 | AD43: 3 | AE43: 2 | AF43: 4 | AG43: 3 | AH43: 1 | AI43: 1 | AR43: =IF(H43=VLOOKUP(VALUE(H$1),Questions!$A:$E,5,FALSE),1,0) -> 1 | AS43: =IF(I43=VLOOKUP(VALUE(I$1),Questions!$A:$E,5,FALSE),1,0) -> 1 | AT43: =IF(J43=VLOOKUP(VALUE(J$1),Questions!$A:$E,5,FALSE),1,0) -> 1 | AU43: =IF(K43=VLOOKUP(VALUE(K$1),Questions!$A:$E,5,FALSE),1,0) -> 0 | AV43: =IF(L43=VLOOKUP(VALUE(L$1),Questions!$A:$E,5,FALSE),1,0) -> 1 | AW43: =IF(M43=VLOOKUP(VALUE(M$1),Questions!$A:$E,5,FALSE),1,0) -> 1 | AX43: =IF(N43=VLOOKUP(VALUE(N$1),Questions!$A:$E,5,FALSE),1,0) -> 1 | AY43: =IF(O43=VLOOKUP(VALUE(O$1),Questions!$A:$E,5,FALSE),1,0) -> 1 | ... BS43: =IF(AI43=VLOOKUP(VALUE(AI$1),Questions!$A:$E,5,FALSE),1,0) -> 1
A44: 43 | B44: FALSE | C44: FALSE | D44: =SUM(Scores[[#This Row],[Q1]:[Q28]]) -> 0 | E44: =SUM(Scores[[#This Row],[29]:[34b]]) -> 0 | F44: =Scores[[#This Row],[35]] -> 0 | G44: =INDEX('Conversion Chart'!$C$3:$M$38,MATCH(SUM(Scores[[#This Row],[MC]:[CRQ]]),'Conversion Chart'!$B$3:$B$38,0),MATCH(Scores[[#This Row],[EIE]],'Conversion Chart'!$C$2:$M$2,0)) -> 0 | AR44: =IF(H44=VLOOKUP(VALUE(H$1),Questions!$A:$E,5,FALSE),1,0) -> 0 | AS44: =IF(I44=VLOOKUP(VALUE(I$1),Questions!$A:$E,5,FALSE),1,0) -> 0 | AT44: =IF(J44=VLOOKUP(VALUE(J$1),Questions!$A:$E,5,FALSE),1,0) -> 0 | AU44: =IF(K44=VLOOKUP(VALUE(K$1),Questions!$A:$E,5,FALSE),1,0) -> 0 | AV44: =IF(L44=VLOOKUP(VALUE(L$1),Questions!$A:$E,5,FALSE),1,0) -> 0 | AW44: =IF(M44=VLOOKUP(VALUE(M$1),Questions!$A:$E,5,FALSE),1,0) -> 0 | AX44: =IF(N44=VLOOKUP(VALUE(N$1),Questions!$A:$E,5,FALSE),1,0) -> 0 | AY44: =IF(O44=VLOOKUP(VALUE(O$1),Questions!$A:$E,5,FALSE),1,0) -> 0 | ... BS44: =IF(AI44=VLOOKUP(VALUE(AI$1),Questions!$A:$E,5,FALSE),1,0) -> 0
A45: 44 | B45: FALSE | C45: FALSE | D45: =SUM(Scores[[#This Row],[Q1]:[Q28]]) -> 22 | E45: =SUM(Scores[[#This Row],[29]:[34b]]) -> 0 | F45: =Scores[[#This Row],[35]] -> 0 | G45: =INDEX('Conversion Chart'!$C$3:$M$38,MATCH(SUM(Scores[[#This Row],[MC]:[CRQ]]),'Conversion Chart'!$B$3:$B$38,0),MATCH(Scores[[#This Row],[EIE]],'Conversion Chart'!$C$2:$M$2,0)) -> 57 | H45: 4 | I45: 3 | J45: 1 | K45: 2 | L45: 2 | M45: 4 | N45: 3 | O45: 4 | P45: 1 | Q45: 1 | R45: 4 | S45: 3 | T45: 1 | U45: 2 | V45: 1 | W45: 3 | X45: 2 | Y45: 2 | Z45: 2 | AA45: 3 | AB45: 2 | AC45: 1 | AD45: 3 | AE45: 2 | AF45: 4 | AG45: 3 | AH45: 1 | AI45: 1 | AR45: =IF(H45=VLOOKUP(VALUE(H$1),Questions!$A:$E,5,FALSE),1,0) -> 1 | AS45: =IF(I45=VLOOKUP(VALUE(I$1),Questions!$A:$E,5,FALSE),1,0) -> 1 | AT45: =IF(J45=VLOOKUP(VALUE(J$1),Questions!$A:$E,5,FALSE),1,0) -> 1 | AU45: =IF(K45=VLOOKUP(VALUE(K$1),Questions!$A:$E,5,FALSE),1,0) -> 1 | AV45: =IF(L45=VLOOKUP(VALUE(L$1),Questions!$A:$E,5,FALSE),1,0) -> 1 | AW45: =IF(M45=VLOOKUP(VALUE(M$1),Questions!$A:$E,5,FALSE),1,0) -> 1 | AX45: =IF(N45=VLOOKUP(VALUE(N$1),Questions!$A:$E,5,FALSE),1,0) -> 1 | AY45: =IF(O45=VLOOKUP(VALUE(O$1),Questions!$A:$E,5,FALSE),1,0) -> 0 | ... BS45: =IF(AI45=VLOOKUP(VALUE(AI$1),Questions!$A:$E,5,FALSE),1,0) -> 1
...

Sheet Questions
A1: # | B1: Part | C1: Stimulus | D1: Question | E1: Answer | F1: Option_1 | G1: Option_2 | H1: Option_3 | I1: Option_4 | J1: Stimulus_type | K1: Source_type | L1: Task_model | M1: Skill_standard | N1: Need_OI? | O1: Content_standard | P1: Content_specification | Q1: Pct_correct | R1: Pt_biserial
A2: 1 | B2: Part I | C2: Passage on the Kingdom of Benin | D2: Which claim about Benin is best supported by this passage? | E2: 4 | F2: Its artisans produced goods for domestic use only | G2: It was fighting a war with Portugal | H2: Its wealth came from plantation agriculture | I2: It was engaged in vast trade networks | J2: Text-based | K2: Secondary | L2: 4. Claim Validity (Without Outside Information) | M2: A.5: Inferences & Conclusions | N2: No | O2: 10.01b.3 | P2: =IFERROR(VLOOKUP(Questions[[#This Row],[Content_standard]],Content[#All],2),"") -> Comparing Empire's Geography & Power | Q2: =AVERAGE(INDEX(Scores[#Data],0,MATCH("Q"&$A2,Scores[#Headers],0))) -> 0.79259259 | R2: =IFERROR(CORREL(INDEX(Scores[#Data],0,MATCH("Q"&$A2,Scores[#Headers],0)),Scores[MC]),"") -> 0.48014997
A3: 2 | B3: Part I | C3: Passage on Mughal religious intolerance | D3: Which claim is best supported by this passage? | E3: 3 | F3: The threat of the British unified Hindus and Muslims in the 1700s | G3: The military campaigns of Aurangzeb led to prosperity for Muslims in India | H3: Aurangzeb's rule was characterized by intolerance and oppression of Hindus | I3: The end of the Mughal Dynasty was marked by advances in learning and scholarship | J3: Text-based | K3: Secondary | L3: 4. Claim Validity (Without Outside Information) | M3: A.5: Inferences & Conclusions | N3: No | O3: 10.01a.1 | P3: =IFERROR(VLOOKUP(Questions[[#This Row],[Content_standard]],Content[#All],2),"") -> Mughal & Ottoman (c. 1750) | Q3: =AVERAGE(INDEX(Scores[#Data],0,MATCH("Q"&$A3,Scores[#Headers],0))) -> 0.85185185 | R3: =IFERROR(CORREL(INDEX(Scores[#Data],0,MATCH("Q"&$A3,Scores[#Headers],0)),Scores[MC]),"") -> 0.63750929
A4: 3 | B4: Part I | C4: Passage on Mughal religious intolerance | D4: Based on this passage, which situation was a result of Aurangzeb's actions in India? | E4: 1 | F4: The British seized the opportunity to increase their power in Mughal India | G4: The Puritans of India rebelled against the Muslims | H4: The Mughal rulers limited European trade to a single port | I4: The Mughal dynasty remained strong in India | J4: Text-based | K4: Secondary | L4: 8. Effect | M4: B.2: Cause & Effect | N4: No | O4: 10.01a.1 | P4: =IFERROR(VLOOKUP(Questions[[#This Row],[Content_standard]],Content[#All],2),"") -> Mughal & Ottoman (c. 1750) | Q4: =AVERAGE(INDEX(Scores[#Data],0,MATCH("Q"&$A4,Scores[#Headers],0))) -> 0.82962963 | R4: =IFERROR(CORREL(INDEX(Scores[#Data],0,MATCH("Q"&$A4,Scores[#Headers],0)),Scores[MC]),"") -> 0.5695502
A5: 4 | B5: Part I | C5: Passage on John Locke | D5: This passage would be most useful to a person attempting to prove the | E5: 2 | F5: importance of Enlightenment thought in supporting the divine right of kings | G5: effect of Enlightenment ideas on future political and economic movements | H5: influence of the Enlightenment on the strengthening of absolutism | I5: rejection of Enlightenment ideas such as natural rights | J5: Text-based | K5: Secondary | L5: 1. Best Use | M5: A.2: Evaluating Sources | N5: No | O5: 10.02a.1 | P5: =IFERROR(VLOOKUP(Questions[[#This Row],[Content_standard]],Content[#All],2),"") -> Political Philosophies | Q5: =AVERAGE(INDEX(Scores[#Data],0,MATCH("Q"&$A5,Scores[#Headers],0))) -> 0.68888889 | R5: =IFERROR(CORREL(INDEX(Scores[#Data],0,MATCH("Q"&$A5,Scores[#Headers],0)),Scores[MC]),"") -> 0.50053948
A6: 5 | B6: Part I | C6: Passage on Tokugawa Japan | D6: One major change in Japan that resulted from the events described in this passage was | E6: 2 | F6: the development of equal treaties | G6: an increase in the efforts to modernize | H6: an increase in the power of the samurai class | I6: the strengthening of isolationist policies | J6: Text-based | K6: Secondary | L6: 8. Effect | M6: B.2: Cause & Effect | N6: Yes | O6: 10.04b.2 | P6: =IFERROR(VLOOKUP(Questions[[#This Row],[Content_standard]],Content[#All],2),"") -> Japanese Reaction to Western Imperialism | Q6: =AVERAGE(INDEX(Scores[#Data],0,MATCH("Q"&$A6,Scores[#Headers],0))) -> 0.58518519 | R6: =IFERROR(CORREL(INDEX(Scores[#Data],0,MATCH("Q"&$A6,Scores[#Headers],0)),Scores[MC]),"") -> 0.59583828
A7: 6 | B7: Part I | C7: Passage on Tokugawa Japan | D7: This passage is most useful for studying | E7: 4 | F7: ways to end peasant protests | G7: the reasons why the Shogunate gained power | H7: ways the Qing conducted military campaigns | I7: the impact of Western imperialism | J7: Text-based | K7: Secondary | L7: 1. Best Use | M7: A.2: Evaluating Sources | N7: No | O7: 10.04b.2 | P7: =IFERROR(VLOOKUP(Questions[[#This Row],[Content_standard]],Content[#All],2),"") -> Japanese Reaction to Western Imperialism | Q7: =AVERAGE(INDEX(Scores[#Data],0,MATCH("Q"&$A7,Scores[#Headers],0))) -> 0.71851852 | R7: =IFERROR(CORREL(INDEX(Scores[#Data],0,MATCH("Q"&$A7,Scores[#Headers],0)),Scores[MC]),"") -> 0.63205205
A8: 7 | B8: Part I | C8: Queen Victoria, Speech to Parliament | D8: Who was most harmed by the circumstances described in this speech? | E8: 3 | F8: government leaders | G8: merchant sailors | H8: tenant farmers | I8: business owners | J8: Text-based | K8: Primary | L8: 14. Stakeholder Issue | M8: A.5: Inferences & Conclusions | N8: Yes | O8: 10.03d.2 | P8: =IFERROR(VLOOKUP(Questions[[#This Row],[Content_standard]],Content[#All],2),"") -> Irish Potato Famine | Q8: =AVERAGE(INDEX(Scores[#Data],0,MATCH("Q"&$A8,Scores[#Headers],0))) -> 0.77037037 | R8: =IFERROR(CORREL(INDEX(Scores[#Data],0,MATCH("Q"&$A8,Scores[#Headers],0)),Scores[MC]),"") -> 0.46030037
A9: 8 | B9: Part I | C9: Queen Victoria, Speech to Parliament | D9: The situation described in this speech resulted in | E9: 1 | F9: mass emigration | G9: a unified global response | H9: a shift to communal farming | I9: implementation of major political reforms | J9: Text-based | K9: Primary | L9: 8. Effect | M9: B.2: Cause & Effect | N9: Yes | O9: 10.03d.2 | P9: =IFERROR(VLOOKUP(Questions[[#This Row],[Content_standard]],Content[#All],2),"") -> Irish Potato Famine | Q9: =AVERAGE(INDEX(Scores[#Data],0,MATCH("Q"&$A9,Scores[#Headers],0))) -> 0.42222222 | R9: =IFERROR(CORREL(INDEX(Scores[#Data],0,MATCH("Q"&$A9,Scores[#Headers],0)),Scores[MC]),"") -> 0.34716625
A10: 9 | B10: Part I | C10: "The Real Trouble Will Come With the Wake" cartoon | D10: Which key event influenced the creation of this image? | E10: 1 | F10: the signing of a series of unequal treaties between China and Western powers | G10: the creation of a multinational intervention to protect Chinese interests | H10: the founding of the Republic of China with Sun Yixian [Sun Yat-sen] as president | I10: The establishment of an alliance between China, the United States, and Britain | J10: Visual-based | K10: Primary | L10: 7. Cause | M10: B.2: Cause & Effect | N10: Yes | O10: 10.04a.2 | P10: =IFERROR(VLOOKUP(Questions[[#This Row],[Content_standard]],Content[#All],2),"") -> Control & Spheres of Influence in Africa & China | Q10: =AVERAGE(INDEX(Scores[#Data],0,MATCH("Q"&$A10,Scores[#Headers],0))) -> 0.68888889 | R10: =IFERROR(CORREL(INDEX(Scores[#Data],0,MATCH("Q"&$A10,Scores[#Headers],0)),Scores[MC]),"") -> 0.53218496
A11: 10 | B11: Part I | C11: "The Real Trouble Will Come With the Wake" cartoon | D11: What do the animals surrounding China symbolize in this cartoon? | E11: 1 | F11: nations seeking economic advantages | G11: allies offering aid to the Qing dynasty | H11: rival countries during World War II | I11: opium-importing countries | J11: Visual-based | K11: Primary | L11: 13. Interpret Visual Data | M11: A.3: Sourcing & Point of View | N11: No | O11: 10.04a.2 | P11: =IFERROR(VLOOKUP(Questions[[#This Row],[Content_standard]],Content[#All],2),"") -> Control & Spheres of Influence in Africa & China | Q11: =AVERAGE(INDEX(Scores[#Data],0,MATCH("Q"&$A11,Scores[#Headers],0))) -> 0.62222222 | R11: =IFERROR(CORREL(INDEX(Scores[#Data],0,MATCH("Q"&$A11,Scores[#Headers],0)),Scores[MC]),"") -> 0.47360812
A12: 11 | B12: Part I | C12: The Treaty of Versailles | D12: For which purpose was this document written? | E12: 4 | F12: to grant independence to former German overseas possessions | G12: to support the rebuilding of the German military | H12: to form a permanent alliance with Germany | I12: to punish Germany for its role in World War I | J12: Text-based | K12: Primary | L12: 2. POV | M12: A.3: Sourcing & Point of View | N12: Yes | O12: 10.05c.1 | P12: =IFERROR(VLOOKUP(Questions[[#This Row],[Content_standard]],Content[#All],2),"") -> Fourteen Points, the Treaty of Versailles, League of Nations, & United Nations | Q12: =AVERAGE(INDEX(Scores[#Data],0,MATCH("Q"&$A12,Scores[#Headers],0))) -> 0.81481481 | R12: =IFERROR(CORREL(INDEX(Scores[#Data],0,MATCH("Q"&$A12,Scores[#Headers],0)),Scores[MC]),"") -> 0.61708233
A13: 12 | B13: Part I | C13: The Treaty of Versailles | D13: Which situation was the result of these articles? | E13: 2 | F13: People in France demanded the right to vote in democratic elections. | G13: Resentment led to the rise of the Nazi Party. | H13: Coal mines were given to Germany to pay for damages. | I13: Allied governments were held responsible for World War I. | J13: Text-based | K13: Primary | L13: 8. Effect | M13: B.2: Cause & Effect | N13: Yes | O13: 10.05c.1 | P13: =IFERROR(VLOOKUP(Questions[[#This Row],[Content_standard]],Content[#All],2),"") -> Fourteen Points, the Treaty of Versailles, League of Nations, & United Nations | Q13: =AVERAGE(INDEX(Scores[#Data],0,MATCH("Q"&$A13,Scores[#Headers],0))) -> 0.46666667 | R13: =IFERROR(CORREL(INDEX(Scores[#Data],0,MATCH("Q"&$A13,Scores[#Headers],0)),Scores[MC]),"") -> 0.51292193
... A29: 28 | B29: Part I | C29: Article on Taliban Afghanistan | D29: Based on this passage, which statement described Khaled Hosseini's point of view? | E29: 1 | F29: Years of working to implement democracy in Afghanistan have been reversed quickly. | G29: The Afghan government needed minimal outside support to function effectively. | H29: The majority of Afghans do not want to change their political institutions. | I29: NATO partners did not do enough to root out corruption in the elected government. | J29: Text-based | K29: Primary | L29: 2. POV | M29: A.3: Sourcing & Point of View | N29: No | O29: 10.08b.2 | P29: =IFERROR(VLOOKUP(Questions[[#This Row],[Content_standard]],Content[#All],2),"") -> Advancements in Communications & Transportation Effect on Authority | Q29: =AVERAGE(INDEX(Scores[#Data],0,MATCH("Q"&$A29,Scores[#Headers],0))) -> 0.71111111 | R29: =IFERROR(CORREL(INDEX(Scores[#Data],0,MATCH("Q"&$A29,Scores[#Headers],0)),Scores[MC]),"") -> 0.58324813
