Workbook

Sheet Scores
A1: Key | B1: Class | C1: Period | D1: ELL | E1: IEP | F1: MC | G1: CRQ | H1: Final | I1: 1 | J1: 2 | K1: 3 | L1: 4 | M1: 5 | N1: 6 | O1: 7 | P1: 8 | Q1: 9 | R1: 10 | S1: 11a | T1: 11b | U1: Q1 | V1: Q2 | W1: Q3 | X1: Q4 | Y1: Q5 | Z1: Q6 | AA1: Q7 | AB1: Q8
A2: IRV37104 | B2: Sourial | C2: 8 | D2: FALSE | E2: FALSE | F2: =SUM(U2:AB2) -> 8 | G2: =SUM(Q2:T2) -> 0 | H2: =SUM(F2:G2)/12 -> 0.66666667 | I2: 2 | J2: 2 | K2: 1 | L2: 3 | M2: 2 | N2: 3 | O2: 3 | P2: 3 | U2: =IF(I2=VLOOKUP(VALUE(I$1),Questions[#All],5,FALSE),1,0) -> 1 | V2: =IF(J2=VLOOKUP(VALUE(J$1),Questions[#All],5,FALSE),1,0) -> 1 | W2: =IF(K2=VLOOKUP(VALUE(K$1),Questions[#All],5,FALSE),1,0) -> 1 | X2: =IF(L2=VLOOKUP(VALUE(L$1),Questions[#All],5,FALSE),1,0) -> 1 | Y2: =IF(M2=VLOOKUP(VALUE(M$1),Questions[#All],5,FALSE),1,0) -> 1 | Z2: =IF(N2=VLOOKUP(VALUE(N$1),Questions[#All],5,FALSE),1,0) -> 1 | AA2: =IF(O2=VLOOKUP(VALUE(O$1),Questions[#All],5,FALSE),1,0) -> 1 | AB2: =IF(P2=VLOOKUP(VALUE(P$1),Questions[#All],5,FALSE),1,0) -> 1
A3: JUA27367 | B3: Sourial | C3: 8 | D3: FALSE | E3: FALSE | F3: =SUM(U3:AB3) -> 3 | G3: =SUM(Q3:T3) -> 0 | H3: =SUM(F3:G3)/12 -> 0.25 | I3: 2 | J3: 2 | K3: 3 | L3: 1 | M3: 4 | N3: 2 | O3: 3 | P3: 1 | U3: =IF(I3=VLOOKUP(VALUE(I$1),Questions[#All],5,FALSE),1,0) -> 1 | V3: =IF(J3=VLOOKUP(VALUE(J$1),Questions[#All],5,FALSE),1,0) -> 1 | W3: =IF(K3=VLOOKUP(VALUE(K$1),Questions[#All],5,FALSE),1,0) -> 0 | X3: =IF(L3=VLOOKUP(VALUE(L$1),Questions[#All],5,FALSE),1,0) -> 0 | Y3: =IF(M3=VLOOKUP(VALUE(M$1),Questions[#All],5,FALSE),1,0) -> 0 | Z3: =IF(N3=VLOOKUP(VALUE(N$1),Questions[#All],5,FALSE),1,0) -> 0 | AA3: =IF(O3=VLOOKUP(VALUE(O$1),Questions[#All],5,FALSE),1,0) -> 1 | AB3: =IF(P3=VLOOKUP(VALUE(P$1),Questions[#All],5,FALSE),1,0) -> 0
A4: HMJ88128 | B4: Sourial | C4: 8 | D4: FALSE | E4: FALSE | F4: =SUM(U4:AB4) -> 4 | G4: =SUM(Q4:T4) -> 0 | H4: =SUM(F4:G4)/12 -> 0.33333333 | I4: 1 | J4: 2 | K4: 3 | L4: 3 | M4: 2 | N4: 4 | O4: 1 | P4: 3 | U4: =IF(I4=VLOOKUP(VALUE(I$1),Questions[#All],5,FALSE),1,0) -> 0 | V4: =IF(J4=VLOOKUP(VALUE(J$1),Questions[#All],5,FALSE),1,0) -> 1 | W4: =IF(K4=VLOOKUP(VALUE(K$1),Questions[#All],5,FALSE),1,0) -> 0 | X4: =IF(L4=VLOOKUP(VALUE(L$1),Questions[#All],5,FALSE),1,0) -> 1 | Y4: =IF(M4=VLOOKUP(VALUE(M$1),Questions[#All],5,FALSE),1,0) -> 1 | Z4: =IF(N4=VLOOKUP(VALUE(N$1),Questions[#All],5,FALSE),1,0) -> 0 | AA4: =IF(O4=VLOOKUP(VALUE(O$1),Questions[#All],5,FALSE),1,0) -> 0 | AB4: =IF(P4=VLOOKUP(VALUE(P$1),Questions[#All],5,FALSE),1,0) -> 1
A5: VIM36434 | B5: Sourial | C5: 8 | D5: FALSE | E5: FALSE | F5: =SUM(U5:AB5) -> 7 | G5: =SUM(Q5:T5) -> 0 | H5: =SUM(F5:G5)/12 -> 0.58333333 | I5: 1 | J5: 2 | K5: 1 | L5: 3 | M5: 2 | N5: 3 | O5: 3 | P5: 3 | U5: =IF(I5=VLOOKUP(VALUE(I$1),Questions[#All],5,FALSE),1,0) -> 0 | V5: =IF(J5=VLOOKUP(VALUE(J$1),Questions[#All],5,FALSE),1,0) -> 1 | W5: =IF(K5=VLOOKUP(VALUE(K$1),Questions[#All],5,FALSE),1,0) -> 1 | X5: =IF(L5=VLOOKUP(VALUE(L$1),Questions[#All],5,FALSE),1,0) -> 1 | Y5: =IF(M5=VLOOKUP(VALUE(M$1),Questions[#All],5,FALSE),1,0) -> 1 | Z5: =IF(N5=VLOOKUP(VALUE(N$1),Questions[#All],5,FALSE),1,0) -> 1 | AA5: =IF(O5=VLOOKUP(VALUE(O$1),Questions[#All],5,FALSE),1,0) -> 1 | AB5: =IF(P5=VLOOKUP(VALUE(P$1),Questions[#All],5,FALSE),1,0) -> 1
A6: GEY89112 | B6: Sourial | C6: 8 | D6: FALSE | E6: FALSE | F6: =SUM(U6:AB6) -> 7 | G6: =SUM(Q6:T6) -> 0 | H6: =SUM(F6:G6)/12 -> 0.58333333 | I6: 2 | J6: 2 | K6: 1 | L6: 3 | M6: 2 | N6: 3 | O6: 3 | P6: 1 | U6: =IF(I6=VLOOKUP(VALUE(I$1),Questions[#All],5,FALSE),1,0) -> 1 | V6: =IF(J6=VLOOKUP(VALUE(J$1),Questions[#All],5,FALSE),1,0) -> 1 | W6: =IF(K6=VLOOKUP(VALUE(K$1),Questions[#All],5,FALSE),1,0) -> 1 | X6: =IF(L6=VLOOKUP(VALUE(L$1),Questions[#All],5,FALSE),1,0) -> 1 | Y6: =IF(M6=VLOOKUP(VALUE(M$1),Questions[#All],5,FALSE),1,0) -> 1 | Z6: =IF(N6=VLOOKUP(VALUE(N$1),Questions[#All],5,FALSE),1,0) -> 1 | AA6: =IF(O6=VLOOKUP(VALUE(O$1),Questions[#All],5,FALSE),1,0) -> 1 | AB6: =IF(P6=VLOOKUP(VALUE(P$1),Questions[#All],5,FALSE),1,0) -> 0
A7: XJA95792 | B7: Sourial | C7: 8 | D7: FALSE | E7: FALSE | F7: =SUM(U7:AB7) -> 2 | G7: =SUM(Q7:T7) -> 0 | H7: =SUM(F7:G7)/12 -> 0.16666667 | I7: 4 | J7: 2 | K7: 3 | L7: 1 | M7: 3 | N7: 1 | O7: 3 | U7: =IF(I7=VLOOKUP(VALUE(I$1),Questions[#All],5,FALSE),1,0) -> 0 | V7: =IF(J7=VLOOKUP(VALUE(J$1),Questions[#All],5,FALSE),1,0) -> 1 | W7: =IF(K7=VLOOKUP(VALUE(K$1),Questions[#All],5,FALSE),1,0) -> 0 | X7: =IF(L7=VLOOKUP(VALUE(L$1),Questions[#All],5,FALSE),1,0) -> 0 | Y7: =IF(M7=VLOOKUP(VALUE(M$1),Questions[#All],5,FALSE),1,0) -> 0 | Z7: =IF(N7=VLOOKUP(VALUE(N$1),Questions[#All],5,FALSE),1,0) -> 0 | AA7: =IF(O7=VLOOKUP(VALUE(O$1),Questions[#All],5,FALSE),1,0) -> 1 | AB7: =IF(P7=VLOOKUP(VALUE(P$1),Questions[#All],5,FALSE),1,0) -> 0
A8: NPE95670 | B8: Sourial | C8: 8 | D8: FALSE | E8: FALSE | F8: =SUM(U8:AB8) -> 8 | G8: =SUM(Q8:T8) -> 0 | H8: =SUM(F8:G8)/12 -> 0.66666667 | I8: 2 | J8: 2 | K8: 1 | L8: 3 | M8: 2 | N8: 3 | O8: 3 | P8: 3 | U8: =IF(I8=VLOOKUP(VALUE(I$1),Questions[#All],5,FALSE),1,0) -> 1 | V8: =IF(J8=VLOOKUP(VALUE(J$1),Questions[#All],5,FALSE),1,0) -> 1 | W8: =IF(K8=VLOOKUP(VALUE(K$1),Questions[#All],5,FALSE),1,0) -> 1 | X8: =IF(L8=VLOOKUP(VALUE(L$1),Questions[#All],5,FALSE),1,0) -> 1 | Y8: =IF(M8=VLOOKUP(VALUE(M$1),Questions[#All],5,FALSE),1,0) -> 1 | Z8: =IF(N8=VLOOKUP(VALUE(N$1),Questions[#All],5,FALSE),1,0) -> 1 | AA8: =IF(O8=VLOOKUP(VALUE(O$1),Questions[#All],5,FALSE),1,0) -> 1 | AB8: =IF(P8=VLOOKUP(VALUE(P$1),Questions[#All],5,FALSE),1,0) -> 1
A9: TYB40461 | B9: Sourial | C9: 8 | D9: FALSE | E9: FALSE | F9: =SUM(U9:AB9) -> 4 | G9: =SUM(Q9:T9) -> 0 | H9: =SUM(F9:G9)/12 -> 0.33333333 | I9: 2 | J9: 4 | K9: 4 | L9: 1 | M9: 2 | N9: 4 | O9: 3 | P9: 3 | U9: =IF(I9=VLOOKUP(VALUE(I$1),Questions[#All],5,FALSE),1,0) -> 1 | V9: =IF(J9=VLOOKUP(VALUE(J$1),Questions[#All],5,FALSE),1,0) -> 0 | W9: =IF(K9=VLOOKUP(VALUE(K$1),Questions[#All],5,FALSE),1,0) -> 0 | X9: =IF(L9=VLOOKUP(VALUE(L$1),Questions[#All],5,FALSE),1,0) -> 0 | Y9: =IF(M9=VLOOKUP(VALUE(M$1),Questions[#All],5,FALSE),1,0) -> 1 | Z9: =IF(N9=VLOOKUP(VALUE(N$1),Questions[#All],5,FALSE),1,0) -> 0 | AA9: =IF(O9=VLOOKUP(VALUE(O$1),Questions[#All],5,FALSE),1,0) -> 1 | AB9: =IF(P9=VLOOKUP(VALUE(P$1),Questions[#All],5,FALSE),1,0) -> 1
A10: KYF53977 | B10: Sourial | C10: 8 | D10: FALSE | E10: FALSE | F10: =SUM(U10:AB10) -> 5 | G10: =SUM(Q10:T10) -> 0 | H10: =SUM(F10:G10)/12 -> 0.41666667 | I10: 2 | J10: 2 | K10: 1 | L10: 1 | M10: 2 | N10: 2 | O10: 1 | P10: 3 | U10: =IF(I10=VLOOKUP(VALUE(I$1),Questions[#All],5,FALSE),1,0) -> 1 | V10: =IF(J10=VLOOKUP(VALUE(J$1),Questions[#All],5,FALSE),1,0) -> 1 | W10: =IF(K10=VLOOKUP(VALUE(K$1),Questions[#All],5,FALSE),1,0) -> 1 | X10: =IF(L10=VLOOKUP(VALUE(L$1),Questions[#All],5,FALSE),1,0) -> 0 | Y10: =IF(M10=VLOOKUP(VALUE(M$1),Questions[#All],5,FALSE),1,0) -> 1 | Z10: =IF(N10=VLOOKUP(VALUE(N$1),Questions[#All],5,FALSE),1,0) -> 0 | AA10: =IF(O10=VLOOKUP(VALUE(O$1),Questions[#All],5,FALSE),1,0) -> 0 | AB10: =IF(P10=VLOOKUP(VALUE(P$1),Questions[#All],5,FALSE),1,0) -> 1
A11: KOQ20864 | B11: Sourial | C11: 8 | D11: FALSE | E11: FALSE | F11: =SUM(U11:AB11) -> 3 | G11: =SUM(Q11:T11) -> 0 | H11: =SUM(F11:G11)/12 -> 0.25 | I11: 1 | J11: 2 | K11: 1 | L11: 1 | M11: 1 | N11: 2 | O11: 3 | P11: 2 | U11: =IF(I11=VLOOKUP(VALUE(I$1),Questions[#All],5,FALSE),1,0) -> 0 | V11: =IF(J11=VLOOKUP(VALUE(J$1),Questions[#All],5,FALSE),1,0) -> 1 | W11: =IF(K11=VLOOKUP(VALUE(K$1),Questions[#All],5,FALSE),1,0) -> 1 | X11: =IF(L11=VLOOKUP(VALUE(L$1),Questions[#All],5,FALSE),1,0) -> 0 | Y11: =IF(M11=VLOOKUP(VALUE(M$1),Questions[#All],5,FALSE),1,0) -> 0 | Z11: =IF(N11=VLOOKUP(VALUE(N$1),Questions[#All],5,FALSE),1,0) -> 0 | AA11: =IF(O11=VLOOKUP(VALUE(O$1),Questions[#All],5,FALSE),1,0) -> 1 | AB11: =IF(P11=VLOOKUP(VALUE(P$1),Questions[#All],5,FALSE),1,0) -> 0
A12: YJL43166 | B12: Sourial | C12: 8 | D12: FALSE | E12: FALSE | F12: =SUM(U12:AB12) -> 7 | G12: =SUM(Q12:T12) -> 0 | H12: =SUM(F12:G12)/12 -> 0.58333333 | I12: 2 | J12: 2 | K12: 1 | L12: 3 | M12: 2 | N12: 3 | O12: 2 | P12: 3 | U12: =IF(I12=VLOOKUP(VALUE(I$1),Questions[#All],5,FALSE),1,0) -> 1 | V12: =IF(J12=VLOOKUP(VALUE(J$1),Questions[#All],5,FALSE),1,0) -> 1 | W12: =IF(K12=VLOOKUP(VALUE(K$1),Questions[#All],5,FALSE),1,0) -> 1 | X12: =IF(L12=VLOOKUP(VALUE(L$1),Questions[#All],5,FALSE),1,0) -> 1 | Y12: =IF(M12=VLOOKUP(VALUE(M$1),Questions[#All],5,FALSE),1,0) -> 1 | Z12: =IF(N12=VLOOKUP(VALUE(N$1),Questions[#All],5,FALSE),1,0) -> 1 | AA12: =IF(O12=VLOOKUP(VALUE(O$1),Questions[#All],5,FALSE),1,0) -> 0 | AB12: =IF(P12=VLOOKUP(VALUE(P$1),Questions[#All],5,FALSE),1,0) -> 1
A13: NBB33601 | B13: Sourial | C13: 8 | D13: FALSE | E13: FALSE | F13: =SUM(U13:AB13) -> 8 | G13: =SUM(Q13:T13) -> 0 | H13: =SUM(F13:G13)/12 -> 0.66666667 | I13: 2 | J13: 2 | K13: 1 | L13: 3 | M13: 2 | N13: 3 | O13: 3 | P13: 3 | U13: =IF(I13=VLOOKUP(VALUE(I$1),Questions[#All],5,FALSE),1,0) -> 1 | V13: =IF(J13=VLOOKUP(VALUE(J$1),Questions[#All],5,FALSE),1,0) -> 1 | W13: =IF(K13=VLOOKUP(VALUE(K$1),Questions[#All],5,FALSE),1,0) -> 1 | X13: =IF(L13=VLOOKUP(VALUE(L$1),Questions[#All],5,FALSE),1,0) -> 1 | Y13: =IF(M13=VLOOKUP(VALUE(M$1),Questions[#All],5,FALSE),1,0) -> 1 | Z13: =IF(N13=VLOOKUP(VALUE(N$1),Questions[#All],5,FALSE),1,0) -> 1 | AA13: =IF(O13=VLOOKUP(VALUE(O$1),Questions[#All],5,FALSE),1,0) -> 1 | AB13: =IF(P13=VLOOKUP(VALUE(P$1),Questions[#All],5,FALSE),1,0) -> 1
A14: PRY28676 | B14: Sourial | C14: 8 | D14: FALSE | E14: FALSE | F14: =SUM(U14:AB14) -> 8 | G14: =SUM(Q14:T14) -> 0 | H14: =SUM(F14:G14)/12 -> 0.66666667 | I14: 2 | J14: 2 | K14: 1 | L14: 3 | M14: 2 | N14: 3 | O14: 3 | P14: 3 | U14: =IF(I14=VLOOKUP(VALUE(I$1),Questions[#All],5,FALSE),1,0) -> 1 | V14: =IF(J14=VLOOKUP(VALUE(J$1),Questions[#All],5,FALSE),1,0) -> 1 | W14: =IF(K14=VLOOKUP(VALUE(K$1),Questions[#All],5,FALSE),1,0) -> 1 | X14: =IF(L14=VLOOKUP(VALUE(L$1),Questions[#All],5,FALSE),1,0) -> 1 | Y14: =IF(M14=VLOOKUP(VALUE(M$1),Questions[#All],5,FALSE),1,0) -> 1 | Z14: =IF(N14=VLOOKUP(VALUE(N$1),Questions[#All],5,FALSE),1,0) -> 1 | AA14: =IF(O14=VLOOKUP(VALUE(O$1),Questions[#All],5,FALSE),1,0) -> 1 | AB14: =IF(P14=VLOOKUP(VALUE(P$1),Questions[#All],5,FALSE),1,0) -> 1
A15: CUA13132 | B15: Sourial | C15: 8 | D15: FALSE | E15: FALSE | F15: =SUM(U15:AB15) -> 5 | G15: =SUM(Q15:T15) -> 0 | H15: =SUM(F15:G15)/12 -> 0.41666667 | I15: 2 | J15: 3 | K15: 4 | L15: 3 | M15: 2 | N15: 1 | O15: 3 | P15: 3 | U15: =IF(I15=VLOOKUP(VALUE(I$1),Questions[#All],5,FALSE),1,0) -> 1 | V15: =IF(J15=VLOOKUP(VALUE(J$1),Questions[#All],5,FALSE),1,0) -> 0 | W15: =IF(K15=VLOOKUP(VALUE(K$1),Questions[#All],5,FALSE),1,0) -> 0 | X15: =IF(L15=VLOOKUP(VALUE(L$1),Questions[#All],5,FALSE),1,0) -> 1 | Y15: =IF(M15=VLOOKUP(VALUE(M$1),Questions[#All],5,FALSE),1,0) -> 1 | Z15: =IF(N15=VLOOKUP(VALUE(N$1),Questions[#All],5,FALSE),1,0) -> 0 | AA15: =IF(O15=VLOOKUP(VALUE(O$1),Questions[#All],5,FALSE),1,0) -> 1 | AB15: =IF(P15=VLOOKUP(VALUE(P$1),Questions[#All],5,FALSE),1,0) -> 1
A16: BSC39574 | B16: Sourial | C16: 8 | D16: FALSE | E16: FALSE | F16: =SUM(U16:AB16) -> 7 | G16: =SUM(Q16:T16) -> 0 | H16: =SUM(F16:G16)/12 -> 0.58333333 | I16: 2 | J16: 1 | K16: 1 | L16: 3 | M16: 2 | N16: 3 | O16: 3 | P16: 3 | U16: =IF(I16=VLOOKUP(VALUE(I$1),Questions[#All],5,FALSE),1,0) -> 1 | V16: =IF(J16=VLOOKUP(VALUE(J$1),Questions[#All],5,FALSE),1,0) -> 0 | W16: =IF(K16=VLOOKUP(VALUE(K$1),Questions[#All],5,FALSE),1,0) -> 1 | X16: =IF(L16=VLOOKUP(VALUE(L$1),Questions[#All],5,FALSE),1,0) -> 1 | Y16: =IF(M16=VLOOKUP(VALUE(M$1),Questions[#All],5,FALSE),1,0) -> 1 | Z16: =IF(N16=VLOOKUP(VALUE(N$1),Questions[#All],5,FALSE),1,0) -> 1 | AA16: =IF(O16=VLOOKUP(VALUE(O$1),Questions[#All],5,FALSE),1,0) -> 1 | AB16: =IF(P16=VLOOKUP(VALUE(P$1),Questions[#All],5,FALSE),1,0) -> 1
A17: WQP13614 | B17: Sourial | C17: 8 | D17: FALSE | E17: FALSE | F17: =SUM(U17:AB17) -> 3 | G17: =SUM(Q17:T17) -> 0 | H17: =SUM(F17:G17)/12 -> 0.25 | I17: 3 | J17: 2 | K17: 1 | L17: 2 | M17: 3 | N17: 1 | O17: 1 | P17: 3 | U17: =IF(I17=VLOOKUP(VALUE(I$1),Questions[#All],5,FALSE),1,0) -> 0 | V17: =IF(J17=VLOOKUP(VALUE(J$1),Questions[#All],5,FALSE),1,0) -> 1 | W17: =IF(K17=VLOOKUP(VALUE(K$1),Questions[#All],5,FALSE),1,0) -> 1 | X17: =IF(L17=VLOOKUP(VALUE(L$1),Questions[#All],5,FALSE),1,0) -> 0 | Y17: =IF(M17=VLOOKUP(VALUE(M$1),Questions[#All],5,FALSE),1,0) -> 0 | Z17: =IF(N17=VLOOKUP(VALUE(N$1),Questions[#All],5,FALSE),1,0) -> 0 | AA17: =IF(O17=VLOOKUP(VALUE(O$1),Questions[#All],5,FALSE),1,0) -> 0 | AB17: =IF(P17=VLOOKUP(VALUE(P$1),Questions[#All],5,FALSE),1,0) -> 1
A18: QZX85356 | B18: Sourial | C18: 6 | D18: FALSE | E18: FALSE | F18: =SUM(U18:AB18) -> 6 | G18: =SUM(Q18:T18) -> 0 | H18: =SUM(F18:G18)/12 -> 0.5 | I18: 2 | J18: 2 | K18: 3 | L18: 1 | M18: 2 | N18: 3 | O18: 3 | P18: 3 | U18: =IF(I18=VLOOKUP(VALUE(I$1),Questions[#All],5,FALSE),1,0) -> 1 | V18: =IF(J18=VLOOKUP(VALUE(J$1),Questions[#All],5,FALSE),1,0) -> 1 | W18: =IF(K18=VLOOKUP(VALUE(K$1),Questions[#All],5,FALSE),1,0) -> 0 | X18: =IF(L18=VLOOKUP(VALUE(L$1),Questions[#All],5,FALSE),1,0) -> 0 | Y18: =IF(M18=VLOOKUP(VALUE(M$1),Questions[#All],5,FALSE),1,0) -> 1 | Z18: =IF(N18=VLOOKUP(VALUE(N$1),Questions[#All],5,FALSE),1,0) -> 1 | AA18: =IF(O18=VLOOKUP(VALUE(O$1),Questions[#All],5,FALSE),1,0) -> 1 | AB18: =IF(P18=VLOOKUP(VALUE(P$1),Questions[#All],5,FALSE),1,0) -> 1
A19: YMW32660 | B19: Sourial | C19: 6 | D19: FALSE | E19: FALSE | F19: =SUM(U19:AB19) -> 5 | G19: =SUM(Q19:T19) -> 0 | H19: =SUM(F19:G19)/12 -> 0.41666667 | I19: 1 | J19: 2 | K19: 1 | L19: 3 | M19: 1 | N19: 3 | O19: 3 | P19: 4 | U19: =IF(I19=VLOOKUP(VALUE(I$1),Questions[#All],5,FALSE),1,0) -> 0 | V19: =IF(J19=VLOOKUP(VALUE(J$1),Questions[#All],5,FALSE),1,0) -> 1 | W19: =IF(K19=VLOOKUP(VALUE(K$1),Questions[#All],5,FALSE),1,0) -> 1 | X19: =IF(L19=VLOOKUP(VALUE(L$1),Questions[#All],5,FALSE),1,0) -> 1 | Y19: =IF(M19=VLOOKUP(VALUE(M$1),Questions[#All],5,FALSE),1,0) -> 0 | Z19: =IF(N19=VLOOKUP(VALUE(N$1),Questions[#All],5,FALSE),1,0) -> 1 | AA19: =IF(O19=VLOOKUP(VALUE(O$1),Questions[#All],5,FALSE),1,0) -> 1 | AB19: =IF(P19=VLOOKUP(VALUE(P$1),Questions[#All],5,FALSE),1,0) -> 0
... A45: OGV62307 | B45: Dushin | C45: 8 | D45: FALSE | E45: TRUE | F45: =SUM(U45:AB45) -> 2 | G45: =SUM(Q45:T45) -> 0 | H45: =SUM(F45:G45)/12 -> 0.16666667 | I45: 3 | J45: 2 | K45: 3 | L45: 3 | M45: 1 | N45: 2 | O45: 1 | P45: 2 | U45: =IF(I45=VLOOKUP(VALUE(I$1),Questions[#All],5,FALSE),1,0) -> 0 | V45: =IF(J45=VLOOKUP(VALUE(J$1),Questions[#All],5,FALSE),1,0) -> 1 | W45: =IF(K45=VLOOKUP(VALUE(K$1),Questions[#All],5,FALSE),1,0) -> 0 | X45: =IF(L45=VLOOKUP(VALUE(L$1),Questions[#All],5,FALSE),1,0) -> 1 | Y45: =IF(M45=VLOOKUP(VALUE(M$1),Questions[#All],5,FALSE),1,0) -> 0 | Z45: =IF(N45=VLOOKUP(VALUE(N$1),Questions[#All],5,FALSE),1,0) -> 0 | AA45: =IF(O45=VLOOKUP(VALUE(O$1),Questions[#All],5,FALSE),1,0) -> 0 | AB45: =IF(P45=VLOOKUP(VALUE(P$1),Questions[#All],5,FALSE),1,0) -> 0
A46: GGY41496 | B46: Dushin | C46: 8 | D46: FALSE | E46: FALSE | F46: =SUM(U46:AB46) -> 3 | G46: =SUM(Q46:T46) -> 0 | H46: =SUM(F46:G46)/12 -> 0.25 | I46: 1 | J46: 2 | K46: 1 | L46: 1 | M46: 1 | N46: 3 | U46: =IF(I46=VLOOKUP(VALUE(I$1),Questions[#All],5,FALSE),1,0) -> 0 | V46: =IF(J46=VLOOKUP(VALUE(J$1),Questions[#All],5,FALSE),1,0) -> 1 | W46: =IF(K46=VLOOKUP(VALUE(K$1),Questions[#All],5,FALSE),1,0) -> 1 | X46: =IF(L46=VLOOKUP(VALUE(L$1),Questions[#All],5,FALSE),1,0) -> 0 | Y46: =IF(M46=VLOOKUP(VALUE(M$1),Questions[#All],5,FALSE),1,0) -> 0 | Z46: =IF(N46=VLOOKUP(VALUE(N$1),Questions[#All],5,FALSE),1,0) -> 1 | AA46: =IF(O46=VLOOKUP(VALUE(O$1),Questions[#All],5,FALSE),1,0) -> 0 | AB46: =IF(P46=VLOOKUP(VALUE(P$1),Questions[#All],5,FALSE),1,0) -> 0
A47: ZRM84184 | B47: Dushin | C47: 8 | D47: FALSE | E47: FALSE | F47: =SUM(U47:AB47) -> 5 | G47: =SUM(Q47:T47) -> 0 | H47: =SUM(F47:G47)/12 -> 0.41666667 | I47: 1 | J47: 2 | K47: 1 | L47: 3 | M47: 2 | N47: 3 | O47: 1 | P47: 2 | U47: =IF(I47=VLOOKUP(VALUE(I$1),Questions[#All],5,FALSE),1,0) -> 0 | V47: =IF(J47=VLOOKUP(VALUE(J$1),Questions[#All],5,FALSE),1,0) -> 1 | W47: =IF(K47=VLOOKUP(VALUE(K$1),Questions[#All],5,FALSE),1,0) -> 1 | X47: =IF(L47=VLOOKUP(VALUE(L$1),Questions[#All],5,FALSE),1,0) -> 1 | Y47: =IF(M47=VLOOKUP(VALUE(M$1),Questions[#All],5,FALSE),1,0) -> 1 | Z47: =IF(N47=VLOOKUP(VALUE(N$1),Questions[#All],5,FALSE),1,0) -> 1 | AA47: =IF(O47=VLOOKUP(VALUE(O$1),Questions[#All],5,FALSE),1,0) -> 0 | AB47: =IF(P47=VLOOKUP(VALUE(P$1),Questions[#All],5,FALSE),1,0) -> 0
A48: ZVY84429 | B48: Dushin | C48: 8 | D48: FALSE | E48: TRUE | F48: =SUM(U48:AB48) -> 3 | G48: =SUM(Q48:T48) -> 0 | H48: =SUM(F48:G48)/12 -> 0.25 | I48: 3 | J48: 2 | K48: 1 | L48: 2 | M48: 1 | N48: 1 | O48: 4 | P48: 3 | U48: =IF(I48=VLOOKUP(VALUE(I$1),Questions[#All],5,FALSE),1,0) -> 0 | V48: =IF(J48=VLOOKUP(VALUE(J$1),Questions[#All],5,FALSE),1,0) -> 1 | W48: =IF(K48=VLOOKUP(VALUE(K$1),Questions[#All],5,FALSE),1,0) -> 1 | X48: =IF(L48=VLOOKUP(VALUE(L$1),Questions[#All],5,FALSE),1,0) -> 0 | Y48: =IF(M48=VLOOKUP(VALUE(M$1),Questions[#All],5,FALSE),1,0) -> 0 | Z48: =IF(N48=VLOOKUP(VALUE(N$1),Questions[#All],5,FALSE),1,0) -> 0 | AA48: =IF(O48=VLOOKUP(VALUE(O$1),Questions[#All],5,FALSE),1,0) -> 0 | AB48: =IF(P48=VLOOKUP(VALUE(P$1),Questions[#All],5,FALSE),1,0) -> 1
A49: QFF23928 | B49: Dushin | C49: 8 | D49: FALSE | E49: FALSE | F49: =SUM(U49:AB49) -> 7 | G49: =SUM(Q49:T49) -> 0 | H49: =SUM(F49:G49)/12 -> 0.58333333 | I49: 1 | J49: 2 | K49: 1 | L49: 3 | M49: 2 | N49: 3 | O49: 3 | P49: 3 | U49: =IF(I49=VLOOKUP(VALUE(I$1),Questions[#All],5,FALSE),1,0) -> 0 | V49: =IF(J49=VLOOKUP(VALUE(J$1),Questions[#All],5,FALSE),1,0) -> 1 | W49: =IF(K49=VLOOKUP(VALUE(K$1),Questions[#All],5,FALSE),1,0) -> 1 | X49: =IF(L49=VLOOKUP(VALUE(L$1),Questions[#All],5,FALSE),1,0) -> 1 | Y49: =IF(M49=VLOOKUP(VALUE(M$1),Questions[#All],5,FALSE),1,0) -> 1 | Z49: =IF(N49=VLOOKUP(VALUE(N$1),Questions[#All],5,FALSE),1,0) -> 1 | AA49: =IF(O49=VLOOKUP(VALUE(O$1),Questions[#All],5,FALSE),1,0) -> 1 | AB49: =IF(P49=VLOOKUP(VALUE(P$1),Questions[#All],5,FALSE),1,0) -> 1
A50: ZFI39321 | B50: Dushin | C50: 8 | D50: FALSE | E50: FALSE | F50: =SUM(U50:AB50) -> 7 | G50: =SUM(Q50:T50) -> 0 | H50: =SUM(F50:G50)/12 -> 0.58333333 | I50: 2 | J50: 2 | K50: 1 | L50: 3 | M50: 2 | N50: 3 | O50: 1 | P50: 3 | U50: =IF(I50=VLOOKUP(VALUE(I$1),Questions[#All],5,FALSE),1,0) -> 1 | V50: =IF(J50=VLOOKUP(VALUE(J$1),Questions[#All],5,FALSE),1,0) -> 1 | W50: =IF(K50=VLOOKUP(VALUE(K$1),Questions[#All],5,FALSE),1,0) -> 1 | X50: =IF(L50=VLOOKUP(VALUE(L$1),Questions[#All],5,FALSE),1,0) -> 1 | Y50: =IF(M50=VLOOKUP(VALUE(M$1),Questions[#All],5,FALSE),1,0) -> 1 | Z50: =IF(N50=VLOOKUP(VALUE(N$1),Questions[#All],5,FALSE),1,0) -> 1 | AA50: =IF(O50=VLOOKUP(VALUE(O$1),Questions[#All],5,FALSE),1,0) -> 0 | AB50: =IF(P50=VLOOKUP(VALUE(P$1),Questions[#All],5,FALSE),1,0) -> 1
A51: SAK32940 | B51: Dushin | C51: 8 | D51: FALSE | E51: FALSE | F51: =SUM(U51:AB51) -> 4 | G51: =SUM(Q51:T51) -> 0 | H51: =SUM(F51:G51)/12 -> 0.33333333 | I51: 1 | J51: 2 | K51: 2 | L51: 1 | M51: 2 | N51: 4 | O51: 3 | P51: 3 | U51: =IF(I51=VLOOKUP(VALUE(I$1),Questions[#All],5,FALSE),1,0) -> 0 | V51: =IF(J51=VLOOKUP(VALUE(J$1),Questions[#All],5,FALSE),1,0) -> 1 | W51: =IF(K51=VLOOKUP(VALUE(K$1),Questions[#All],5,FALSE),1,0) -> 0 | X51: =IF(L51=VLOOKUP(VALUE(L$1),Questions[#All],5,FALSE),1,0) -> 0 | Y51: =IF(M51=VLOOKUP(VALUE(M$1),Questions[#All],5,FALSE),1,0) -> 1 | Z51: =IF(N51=VLOOKUP(VALUE(N$1),Questions[#All],5,FALSE),1,0) -> 0 | AA51: =IF(O51=VLOOKUP(VALUE(O$1),Questions[#All],5,FALSE),1,0) -> 1 | AB51: =IF(P51=VLOOKUP(VALUE(P$1),Questions[#All],5,FALSE),1,0) -> 1
A52: CCY62645 | B52: Dushin | C52: 8 | D52: FALSE | E52: TRUE | F52: =SUM(U52:AB52) -> 7 | G52: =SUM(Q52:T52) -> 0 | H52: =SUM(F52:G52)/12 -> 0.58333333 | I52: 2 | J52: 2 | K52: 1 | L52: 3 | M52: 2 | N52: 3 | O52: 1 | P52: 3 | U52: =IF(I52=VLOOKUP(VALUE(I$1),Questions[#All],5,FALSE),1,0) -> 1 | V52: =IF(J52=VLOOKUP(VALUE(J$1),Questions[#All],5,FALSE),1,0) -> 1 | W52: =IF(K52=VLOOKUP(VALUE(K$1),Questions[#All],5,FALSE),1,0) -> 1 | X52: =IF(L52=VLOOKUP(VALUE(L$1),Questions[#All],5,FALSE),1,0) -> 1 | Y52: =IF(M52=VLOOKUP(VALUE(M$1),Questions[#All],5,FALSE),1,0) -> 1 | Z52: =IF(N52=VLOOKUP(VALUE(N$1),Questions[#All],5,FALSE),1,0) -> 1 | AA52: =IF(O52=VLOOKUP(VALUE(O$1),Questions[#All],5,FALSE),1,0) -> 0 | AB52: =IF(P52=VLOOKUP(VALUE(P$1),Questions[#All],5,FALSE),1,0) -> 1
A53: LRD39073 | B53: Dushin | C53: 8 | D53: FALSE | E53: FALSE | F53: =SUM(U53:AB53) -> 5 | G53: =SUM(Q53:T53) -> 0 | H53: =SUM(F53:G53)/12 -> 0.41666667 | I53: 2 | J53: 2 | K53: 2 | L53: 3 | M53: 2 | N53: 3 | O53: 2 | P53: 2 | U53: =IF(I53=VLOOKUP(VALUE(I$1),Questions[#All],5,FALSE),1,0) -> 1 | V53: =IF(J53=VLOOKUP(VALUE(J$1),Questions[#All],5,FALSE),1,0) -> 1 | W53: =IF(K53=VLOOKUP(VALUE(K$1),Questions[#All],5,FALSE),1,0) -> 0 | X53: =IF(L53=VLOOKUP(VALUE(L$1),Questions[#All],5,FALSE),1,0) -> 1 | Y53: =IF(M53=VLOOKUP(VALUE(M$1),Questions[#All],5,FALSE),1,0) -> 1 | Z53: =IF(N53=VLOOKUP(VALUE(N$1),Questions[#All],5,FALSE),1,0) -> 1 | AA53: =IF(O53=VLOOKUP(VALUE(O$1),Questions[#All],5,FALSE),1,0) -> 0 | AB53: =IF(P53=VLOOKUP(VALUE(P$1),Questions[#All],5,FALSE),1,0) -> 0
A54: ZFW55392 | B54: Dushin | C54: 8 | D54: FALSE | E54: TRUE | F54: =SUM(U54:AB54) -> 6 | G54: =SUM(Q54:T54) -> 0 | H54: =SUM(F54:G54)/12 -> 0.5 | I54: 1 | J54: 2 | K54: 1 | L54: 3 | M54: 2 | N54: 4 | O54: 3 | P54: 3 | U54: =IF(I54=VLOOKUP(VALUE(I$1),Questions[#All],5,FALSE),1,0) -> 0 | V54: =IF(J54=VLOOKUP(VALUE(J$1),Questions[#All],5,FALSE),1,0) -> 1 | W54: =IF(K54=VLOOKUP(VALUE(K$1),Questions[#All],5,FALSE),1,0) -> 1 | X54: =IF(L54=VLOOKUP(VALUE(L$1),Questions[#All],5,FALSE),1,0) -> 1 | Y54: =IF(M54=VLOOKUP(VALUE(M$1),Questions[#All],5,FALSE),1,0) -> 1 | Z54: =IF(N54=VLOOKUP(VALUE(N$1),Questions[#All],5,FALSE),1,0) -> 0 | AA54: =IF(O54=VLOOKUP(VALUE(O$1),Questions[#All],5,FALSE),1,0) -> 1 | AB54: =IF(P54=VLOOKUP(VALUE(P$1),Questions[#All],5,FALSE),1,0) -> 1
A55: ZUZ85484 | B55: Dushin | C55: 8 | D55: FALSE | E55: FALSE | F55: =SUM(U55:AB55) -> 1 | G55: =SUM(Q55:T55) -> 0 | H55: =SUM(F55:G55)/12 -> 0.083333333 | I55: 3 | J55: 4 | K55: 4 | L55: 3 | M55: 3 | N55: 1 | O55: 2 | P55: 4 | U55: =IF(I55=VLOOKUP(VALUE(I$1),Questions[#All],5,FALSE),1,0) -> 0 | V55: =IF(J55=VLOOKUP(VALUE(J$1),Questions[#All],5,FALSE),1,0) -> 0 | W55: =IF(K55=VLOOKUP(VALUE(K$1),Questions[#All],5,FALSE),1,0) -> 0 | X55: =IF(L55=VLOOKUP(VALUE(L$1),Questions[#All],5,FALSE),1,0) -> 1 | Y55: =IF(M55=VLOOKUP(VALUE(M$1),Questions[#All],5,FALSE),1,0) -> 0 | Z55: =IF(N55=VLOOKUP(VALUE(N$1),Questions[#All],5,FALSE),1,0) -> 0 | AA55: =IF(O55=VLOOKUP(VALUE(O$1),Questions[#All],5,FALSE),1,0) -> 0 | AB55: =IF(P55=VLOOKUP(VALUE(P$1),Questions[#All],5,FALSE),1,0) -> 0
A56: GGF71395 | B56: Dushin | C56: 8 | D56: FALSE | E56: TRUE | F56: =SUM(U56:AB56) -> 3 | G56: =SUM(Q56:T56) -> 0 | H56: =SUM(F56:G56)/12 -> 0.25 | I56: 3 | J56: 4 | K56: 1 | L56: 2 | M56: 4 | N56: 3 | O56: 3 | P56: 1 | U56: =IF(I56=VLOOKUP(VALUE(I$1),Questions[#All],5,FALSE),1,0) -> 0 | V56: =IF(J56=VLOOKUP(VALUE(J$1),Questions[#All],5,FALSE),1,0) -> 0 | W56: =IF(K56=VLOOKUP(VALUE(K$1),Questions[#All],5,FALSE),1,0) -> 1 | X56: =IF(L56=VLOOKUP(VALUE(L$1),Questions[#All],5,FALSE),1,0) -> 0 | Y56: =IF(M56=VLOOKUP(VALUE(M$1),Questions[#All],5,FALSE),1,0) -> 0 | Z56: =IF(N56=VLOOKUP(VALUE(N$1),Questions[#All],5,FALSE),1,0) -> 1 | AA56: =IF(O56=VLOOKUP(VALUE(O$1),Questions[#All],5,FALSE),1,0) -> 1 | AB56: =IF(P56=VLOOKUP(VALUE(P$1),Questions[#All],5,FALSE),1,0) -> 0
A57: BAX29796 | B57: Dushin | C57: 4 | D57: FALSE | E57: FALSE | F57: =SUM(U57:AB57) -> 4 | G57: =SUM(Q57:T57) -> 0 | H57: =SUM(F57:G57)/12 -> 0.33333333 | I57: 2 | J57: 2 | K57: 3 | L57: 3 | M57: 2 | U57: =IF(I57=VLOOKUP(VALUE(I$1),Questions[#All],5,FALSE),1,0) -> 1 | V57: =IF(J57=VLOOKUP(VALUE(J$1),Questions[#All],5,FALSE),1,0) -> 1 | W57: =IF(K57=VLOOKUP(VALUE(K$1),Questions[#All],5,FALSE),1,0) -> 0 | X57: =IF(L57=VLOOKUP(VALUE(L$1),Questions[#All],5,FALSE),1,0) -> 1 | Y57: =IF(M57=VLOOKUP(VALUE(M$1),Questions[#All],5,FALSE),1,0) -> 1 | Z57: =IF(N57=VLOOKUP(VALUE(N$1),Questions[#All],5,FALSE),1,0) -> 0 | AA57: =IF(O57=VLOOKUP(VALUE(O$1),Questions[#All],5,FALSE),1,0) -> 0 | AB57: =IF(P57=VLOOKUP(VALUE(P$1),Questions[#All],5,FALSE),1,0) -> 0
A58: TWL50281 | B58: Dushin | C58: 4 | D58: FALSE | E58: FALSE | F58: =SUM(U58:AB58) -> 6 | G58: =SUM(Q58:T58) -> 0 | H58: =SUM(F58:G58)/12 -> 0.5 | I58: 2 | J58: 2 | K58: 3 | L58: 3 | M58: 2 | N58: 3 | O58: 4 | P58: 3 | U58: =IF(I58=VLOOKUP(VALUE(I$1),Questions[#All],5,FALSE),1,0) -> 1 | V58: =IF(J58=VLOOKUP(VALUE(J$1),Questions[#All],5,FALSE),1,0) -> 1 | W58: =IF(K58=VLOOKUP(VALUE(K$1),Questions[#All],5,FALSE),1,0) -> 0 | X58: =IF(L58=VLOOKUP(VALUE(L$1),Questions[#All],5,FALSE),1,0) -> 1 | Y58: =IF(M58=VLOOKUP(VALUE(M$1),Questions[#All],5,FALSE),1,0) -> 1 | Z58: =IF(N58=VLOOKUP(VALUE(N$1),Questions[#All],5,FALSE),1,0) -> 1 | AA58: =IF(O58=VLOOKUP(VALUE(O$1),Questions[#All],5,FALSE),1,0) -> 0 | AB58: =IF(P58=VLOOKUP(VALUE(P$1),Questions[#All],5,FALSE),1,0) -> 1
A59: IHP45341 | B59: Dushin | C59: 4 | D59: FALSE | E59: TRUE | F59: =SUM(U59:AB59) -> 4 | G59: =SUM(Q59:T59) -> 0 | H59: =SUM(F59:G59)/12 -> 0.33333333 | I59: 3 | J59: 4 | K59: 3 | L59: 1 | M59: 2 | N59: 3 | O59: 3 | P59: 3 | U59: =IF(I59=VLOOKUP(VALUE(I$1),Questions[#All],5,FALSE),1,0) -> 0 | V59: =IF(J59=VLOOKUP(VALUE(J$1),Questions[#All],5,FALSE),1,0) -> 0 | W59: =IF(K59=VLOOKUP(VALUE(K$1),Questions[#All],5,FALSE),1,0) -> 0 | X59: =IF(L59=VLOOKUP(VALUE(L$1),Questions[#All],5,FALSE),1,0) -> 0 | Y59: =IF(M59=VLOOKUP(VALUE(M$1),Questions[#All],5,FALSE),1,0) -> 1 | Z59: =IF(N59=VLOOKUP(VALUE(N$1),Questions[#All],5,FALSE),1,0) -> 1 | AA59: =IF(O59=VLOOKUP(VALUE(O$1),Questions[#All],5,FALSE),1,0) -> 1 | AB59: =IF(P59=VLOOKUP(VALUE(P$1),Questions[#All],5,FALSE),1,0) -> 1
A60: QFF13061 | B60: Dushin | C60: 4 | D60: FALSE | E60: FALSE | F60: =SUM(U60:AB60) -> 6 | G60: =SUM(Q60:T60) -> 0 | H60: =SUM(F60:G60)/12 -> 0.5 | I60: 2 | J60: 2 | K60: 1 | L60: 3 | M60: 2 | N60: 3 | O60: 4 | P60: 1 | U60: =IF(I60=VLOOKUP(VALUE(I$1),Questions[#All],5,FALSE),1,0) -> 1 | V60: =IF(J60=VLOOKUP(VALUE(J$1),Questions[#All],5,FALSE),1,0) -> 1 | W60: =IF(K60=VLOOKUP(VALUE(K$1),Questions[#All],5,FALSE),1,0) -> 1 | X60: =IF(L60=VLOOKUP(VALUE(L$1),Questions[#All],5,FALSE),1,0) -> 1 | Y60: =IF(M60=VLOOKUP(VALUE(M$1),Questions[#All],5,FALSE),1,0) -> 1 | Z60: =IF(N60=VLOOKUP(VALUE(N$1),Questions[#All],5,FALSE),1,0) -> 1 | AA60: =IF(O60=VLOOKUP(VALUE(O$1),Questions[#All],5,FALSE),1,0) -> 0 | AB60: =IF(P60=VLOOKUP(VALUE(P$1),Questions[#All],5,FALSE),1,0) -> 0
A61: LND58729 | B61: Dushin | C61: 4 | D61: FALSE | E61: FALSE | F61: =SUM(U61:AB61) -> 7 | G61: =SUM(Q61:T61) -> 0 | H61: =SUM(F61:G61)/12 -> 0.58333333 | I61: 2 | J61: 2 | K61: 1 | L61: 3 | M61: 2 | N61: 3 | O61: 2 | P61: 3 | U61: =IF(I61=VLOOKUP(VALUE(I$1),Questions[#All],5,FALSE),1,0) -> 1 | V61: =IF(J61=VLOOKUP(VALUE(J$1),Questions[#All],5,FALSE),1,0) -> 1 | W61: =IF(K61=VLOOKUP(VALUE(K$1),Questions[#All],5,FALSE),1,0) -> 1 | X61: =IF(L61=VLOOKUP(VALUE(L$1),Questions[#All],5,FALSE),1,0) -> 1 | Y61: =IF(M61=VLOOKUP(VALUE(M$1),Questions[#All],5,FALSE),1,0) -> 1 | Z61: =IF(N61=VLOOKUP(VALUE(N$1),Questions[#All],5,FALSE),1,0) -> 1 | AA61: =IF(O61=VLOOKUP(VALUE(O$1),Questions[#All],5,FALSE),1,0) -> 0 | AB61: =IF(P61=VLOOKUP(VALUE(P$1),Questions[#All],5,FALSE),1,0) -> 1
A62: OGD80870 | B62: Dushin | C62: 4 | D62: FALSE | E62: FALSE | F62: =SUM(U62:AB62) -> 4 | G62: =SUM(Q62:T62) -> 0 | H62: =SUM(F62:G62)/12 -> 0.33333333 | I62: 1 | J62: 2 | K62: 3 | L62: 3 | M62: 2 | N62: 3 | O62: 4 | P62: 4 | U62: =IF(I62=VLOOKUP(VALUE(I$1),Questions[#All],5,FALSE),1,0) -> 0 | V62: =IF(J62=VLOOKUP(VALUE(J$1),Questions[#All],5,FALSE),1,0) -> 1 | W62: =IF(K62=VLOOKUP(VALUE(K$1),Questions[#All],5,FALSE),1,0) -> 0 | X62: =IF(L62=VLOOKUP(VALUE(L$1),Questions[#All],5,FALSE),1,0) -> 1 | Y62: =IF(M62=VLOOKUP(VALUE(M$1),Questions[#All],5,FALSE),1,0) -> 1 | Z62: =IF(N62=VLOOKUP(VALUE(N$1),Questions[#All],5,FALSE),1,0) -> 1 | AA62: =IF(O62=VLOOKUP(VALUE(O$1),Questions[#All],5,FALSE),1,0) -> 0 | AB62: =IF(P62=VLOOKUP(VALUE(P$1),Questions[#All],5,FALSE),1,0) -> 0
A63: UCF60506 | B63: Dushin | C63: 4 | D63: FALSE | E63: FALSE | F63: =SUM(U63:AB63) -> 6 | G63: =SUM(Q63:T63) -> 0 | H63: =SUM(F63:G63)/12 -> 0.5 | I63: 1 | J63: 2 | K63: 1 | L63: 3 | M63: 2 | N63: 3 | O63: 1 | P63: 3 | U63: =IF(I63=VLOOKUP(VALUE(I$1),Questions[#All],5,FALSE),1,0) -> 0 | V63: =IF(J63=VLOOKUP(VALUE(J$1),Questions[#All],5,FALSE),1,0) -> 1 | W63: =IF(K63=VLOOKUP(VALUE(K$1),Questions[#All],5,FALSE),1,0) -> 1 | X63: =IF(L63=VLOOKUP(VALUE(L$1),Questions[#All],5,FALSE),1,0) -> 1 | Y63: =IF(M63=VLOOKUP(VALUE(M$1),Questions[#All],5,FALSE),1,0) -> 1 | Z63: =IF(N63=VLOOKUP(VALUE(N$1),Questions[#All],5,FALSE),1,0) -> 1 | AA63: =IF(O63=VLOOKUP(VALUE(O$1),Questions[#All],5,FALSE),1,0) -> 0 | AB63: =IF(P63=VLOOKUP(VALUE(P$1),Questions[#All],5,FALSE),1,0) -> 1
A64: OFB59860 | B64: Dushin | C64: 4 | D64: FALSE | E64: FALSE | F64: =SUM(U64:AB64) -> 6 | G64: =SUM(Q64:T64) -> 0 | H64: =SUM(F64:G64)/12 -> 0.5 | I64: 4 | J64: 2 | K64: 1 | L64: 1 | M64: 2 | N64: 3 | O64: 3 | P64: 3 | U64: =IF(I64=VLOOKUP(VALUE(I$1),Questions[#All],5,FALSE),1,0) -> 0 | V64: =IF(J64=VLOOKUP(VALUE(J$1),Questions[#All],5,FALSE),1,0) -> 1 | W64: =IF(K64=VLOOKUP(VALUE(K$1),Questions[#All],5,FALSE),1,0) -> 1 | X64: =IF(L64=VLOOKUP(VALUE(L$1),Questions[#All],5,FALSE),1,0) -> 0 | Y64: =IF(M64=VLOOKUP(VALUE(M$1),Questions[#All],5,FALSE),1,0) -> 1 | Z64: =IF(N64=VLOOKUP(VALUE(N$1),Questions[#All],5,FALSE),1,0) -> 1 | AA64: =IF(O64=VLOOKUP(VALUE(O$1),Questions[#All],5,FALSE),1,0) -> 1 | AB64: =IF(P64=VLOOKUP(VALUE(P$1),Questions[#All],5,FALSE),1,0) -> 1
A65: PKU98163 | B65: Dushin | C65: 4 | D65: FALSE | E65: FALSE | F65: =SUM(U65:AB65) -> 7 | G65: =SUM(Q65:T65) -> 0 | H65: =SUM(F65:G65)/12 -> 0.58333333 | I65: 2 | J65: 2 | K65: 1 | L65: 3 | M65: 2 | N65: 3 | O65: 2 | P65: 3 | U65: =IF(I65=VLOOKUP(VALUE(I$1),Questions[#All],5,FALSE),1,0) -> 1 | V65: =IF(J65=VLOOKUP(VALUE(J$1),Questions[#All],5,FALSE),1,0) -> 1 | W65: =IF(K65=VLOOKUP(VALUE(K$1),Questions[#All],5,FALSE),1,0) -> 1 | X65: =IF(L65=VLOOKUP(VALUE(L$1),Questions[#All],5,FALSE),1,0) -> 1 | Y65: =IF(M65=VLOOKUP(VALUE(M$1),Questions[#All],5,FALSE),1,0) -> 1 | Z65: =IF(N65=VLOOKUP(VALUE(N$1),Questions[#All],5,FALSE),1,0) -> 1 | AA65: =IF(O65=VLOOKUP(VALUE(O$1),Questions[#All],5,FALSE),1,0) -> 0 | AB65: =IF(P65=VLOOKUP(VALUE(P$1),Questions[#All],5,FALSE),1,0) -> 1
...

Sheet Questions
A1: # | B1: Part | C1: Stimulus | D1: Question | E1: Key | F1: Option_1 | G1: Option_2 | H1: Option_3 | I1: Option_4 | J1: Stimulus_type | K1: Source_type | L1: Task_model | M1: Skill_standard | N1: Need_OI? | O1: Content_standard | P1: Pct_Correct | Q1: Point_Biserial
A2: 1 | B2: Part I | C2: BBC passage on factors in the Ottoman Empire's decline | D2: Based on the passage, identify an issue faced by the Ottoman Empire in the 1600s. | E2: 2 | F2: The empire became too large to govern. | G2: Global trade routes shifted. | H2: Rulers were responsive to the needs of people living in the empire. | I2: Trade increased in the empire. | J2: Text-based | K2: Secondary | L2: 17. Problem | M2: A.5: Inferences & Conclusions | N2: No | O2: 10.01a.1: Mughal & Ottoman (c. 1750) | P2: =AVERAGE(INDEX(Scores!$U$2:$AB$82,0,Questions[[#This Row],['#]])) -> 0.64197531 | Q2: {=_xlfn.LET(_xlpm.item,INDEX(Scores!$U$2:$AB$82,0,Questions[[#This Row],['#]]),CORREL(_xlpm.item,Scores!$F$2:$F$82-_xlpm.item))} -> 0.40059982
A3: 2 | B3: Part I | C3: Ansary excerpts on Aurangzeb's Mughal rule and Ottoman society | D3: Based on these passages, what is a primary similarity between the Mughal and Ottoman Empires? | E3: 2 | F3: Social conflict did not exist in either empire. | G3: Each empire experienced a period of success. | H3: Each empire lasted less than a century. | I3: Hinduism had little influence in their development. | J3: Text-based | K3: Secondary | L3: 10. Compare | M3: C.4: Comparing Societies | N3: No | O3: 10.01a.1: Mughal & Ottoman (c. 1750) | P3: =AVERAGE(INDEX(Scores!$U$2:$AB$82,0,Questions[[#This Row],['#]])) -> 0.81481481 | Q3: {=_xlfn.LET(_xlpm.item,INDEX(Scores!$U$2:$AB$82,0,Questions[[#This Row],['#]]),CORREL(_xlpm.item,Scores!$F$2:$F$82-_xlpm.item))} -> 0.23810932
A4: 3 | B4: Part I | C4: Ansary excerpts on Aurangzeb's Mughal rule and Ottoman society | D4: Which statement best explains a reason the Mughal Empire declined and a reason the Ottoman Empire declined? | E4: 1 | F4: Mughal leaders were ineffective; Ottoman society was too interconnected. | G4: Mughal society was too secular; policies of Ottoman sultans were inconsistent. | H4: Religious diversity in the Mughal Empire was lacking; the Ottoman Empire never worked efficiently. | I4: Mughal society paid little attention to the government; Ottoman social groups were too isolated. | J4: Text-based | K4: Secondary | L4: 7. Cause | M4: B.3: Multiple Causes & Effects | N4: No | O4: 10.01a.1: Mughal & Ottoman (c. 1750) | P4: =AVERAGE(INDEX(Scores!$U$2:$AB$82,0,Questions[[#This Row],['#]])) -> 0.59259259 | Q4: {=_xlfn.LET(_xlpm.item,INDEX(Scores!$U$2:$AB$82,0,Questions[[#This Row],['#]]),CORREL(_xlpm.item,Scores!$F$2:$F$82-_xlpm.item))} -> 0.28398456
A5: 4 | B5: Part I | C5: Tokugawa Edict of 1635 closing Japan | D5: Identify the best use of this document for a historian. | E5: 3 | F5: To determine the effects of the Edict of 1635 Ordering the Closing of Japan on merchants | G5: To find out how Japanese Christians felt about the Tokugawa shogunate | H5: To explore the views of the Japanese government towards outsiders in 1635 | I5: To identify the goods exported by Japanese merchants | J5: Text-based | K5: Primary | L5: 1. Best Use | M5: A.2: Evaluating Sources | N5: No | O5: 10.01b.1: Tokugawa & Mughal Responses to Outsiders | P5: =AVERAGE(INDEX(Scores!$U$2:$AB$82,0,Questions[[#This Row],['#]])) -> 0.71604938 | Q5: {=_xlfn.LET(_xlpm.item,INDEX(Scores!$U$2:$AB$82,0,Questions[[#This Row],['#]]),CORREL(_xlpm.item,Scores!$F$2:$F$82-_xlpm.item))} -> 0.42338068
A6: 5 | B6: Part I | C6: Britannica passage on the sankin kōtai system | D6: One effect of the policy described in this passage was that it | E6: 2 | F6: promoted local resistance | G6: strengthened the power of the shogun | H6: renewed trade agreements | I6: increased the wealth of the samurai | J6: Text-based | K6: Secondary | L6: 8. Effect | M6: B.2: Cause & Effect | N6: No | O6: 10.01a.2: Tokugawa Shogunate | P6: =AVERAGE(INDEX(Scores!$U$2:$AB$82,0,Questions[[#This Row],['#]])) -> 0.79012346 | Q6: {=_xlfn.LET(_xlpm.item,INDEX(Scores!$U$2:$AB$82,0,Questions[[#This Row],['#]]),CORREL(_xlpm.item,Scores!$F$2:$F$82-_xlpm.item))} -> 0.6229702
A7: 6 | B7: Part I | C7: Map of the Ottoman Empire at its height | D7: This map shows that at the height of the Ottoman Empire, the empire | E7: 3 | F7: controlled the port cities of Barcelona and Marseille | G7: governed the Persian Empire | H7: included territory in Europe, Africa, and Asia | I7: completely surrounded the Red Sea | J7: Map-based | K7: Secondary | L7: 13. Interpret Visual Data | M7: D.2: Spatial Relationships | N7: No | O7: 10.01b.2: Eurasia World Map | P7: =AVERAGE(INDEX(Scores!$U$2:$AB$82,0,Questions[[#This Row],['#]])) -> 0.72839506 | Q7: {=_xlfn.LET(_xlpm.item,INDEX(Scores!$U$2:$AB$82,0,Questions[[#This Row],['#]]),CORREL(_xlpm.item,Scores!$F$2:$F$82-_xlpm.item))} -> 0.39200434
A8: 7 | B8: Part I | C8: Saint-Simon memoir on Louis XIV's court at Versailles | D8: A historian would find this passage most useful for understanding the | E8: 3 | F8: rules of diplomacy followed by Louis XIV | G8: effectiveness of Louis XIV's reign | H8: methods Louis XIV used to control the nobility | I8: divine right beliefs of Louis XIV | J8: Text-based | K8: Primary | L8: 1. Best Use | M8: A.2: Evaluating Sources | N8: No | O8: 10.01a.3: Comparing Tokugawa Shogunate & Bourbon Dynasty | P8: =AVERAGE(INDEX(Scores!$U$2:$AB$82,0,Questions[[#This Row],['#]])) -> 0.58024691 | Q8: {=_xlfn.LET(_xlpm.item,INDEX(Scores!$U$2:$AB$82,0,Questions[[#This Row],['#]]),CORREL(_xlpm.item,Scores!$F$2:$F$82-_xlpm.item))} -> 0.14094468
A9: 8 | B9: Part I | C9: Saint-Simon memoir on Louis XIV's court at Versailles | D9: Which historical situation is most similar to the one described in this passage? | E9: 3 | F9: the rebellions in Cuba led by Fidel Castro | G9: the emancipation of serfs in Russia under Catherine the Great | H9: the implementation of an alternative attendance system in Tokugawa Japan | I9: the mobilization of the Red Guard to remove corrupt officials under Mao Zedong | J9: Text-based | K9: Primary | L9: 10. Compare | M9: C.3: Comparing Developments | N9: Yes | O9: 10.01a.3: Comparing Tokugawa Shogunate & Bourbon Dynasty | P9: =AVERAGE(INDEX(Scores!$U$2:$AB$82,0,Questions[[#This Row],['#]])) -> 0.66666667 | Q9: {=_xlfn.LET(_xlpm.item,INDEX(Scores!$U$2:$AB$82,0,Questions[[#This Row],['#]]),CORREL(_xlpm.item,Scores!$F$2:$F$82-_xlpm.item))} -> 0.31706488
A10: 9 | B10: Part II | C10: Jahangir's 1617 letter to King James I granting English trade rights | D10: Explain the historical circumstances that led to the developments shown in this passage. | E10: 1 | J10: Text-based | K10: Primary | L10: 9. Impact of Setting | M10: C.6: Historical Context | N10: Yes | O10: 10.01b.1: Tokugawa & Mughal Responses to Outsiders
A11: 10 | B11: Part II | C11: Tokugawa Edict of 1635 closing Japan | D11: Based on the excerpt, explain the author's point of view regarding Europeans in the Tokugawa Shogunate. | E11: 1 | J11: Text-based | K11: Primary | L11: 2. POV | M11: A.3: Sourcing & Point of View | N11: Yes | O11: 10.01b.1: Tokugawa & Mughal Responses to Outsiders
A12: 11a | B12: Part II | C12: Jahangir's letter to James I and Tokugawa Edict of 1635 | D12: Identify a similarity or a difference between the treatment of outsiders in the Mughal Empire in the 1750s and the Tokugawa Shogunate in 1635. | E12: 1 | J12: Multiple | K12: Primary | L12: 11. Contrast | M12: C.4: Comparing Societies | N12: No | O12: 10.01b.1: Tokugawa & Mughal Responses to Outsiders
A13: 11b | B13: Part II | C13: Jahangir's letter to James I and Tokugawa Edict of 1635 | D13: Explain the similarity or difference you identified using evidence from both documents. | E13: 1 | J13: Multiple | K13: Primary | L13: 11. Contrast | M13: A.7: Synthesizing Evidence | N13: No | O13: 10.01b.1: Tokugawa & Mughal Responses to Outsiders

Sheet Task Models
A1: Model | B1: Detail
A2: 1. Best Use | B2: Students are given a stimulus and asked to evaluate and classify (identify) best use.
A3: 2. POV | B3: Students are given a stimulus and asked to identify point of view, purpose, context, bias, format of source, location of source in time and/or place, and/or intended audience of sources using background knowledge.
A4: 3. Claim Validity (With Outside Information) | B4: Students are given a stimulus and asked to identify support for a claim found in the stimulus (bound in the same timeframe/event/space). It must require students to draw on their knowledge rather than on straight comprehension of text.
A5: 4. Claim Validity (Without Outside Information) | B5: Students are given a stimulus and asked to select a plausible claim that logically follows from evidence presented.
A6: 5. Turning Point | B6: Students are given a stimulus and asked to identify the significance of a turning point in history.
A7: 6. Change Over Time | B7: Students are given a stimulus and asked to identify significance of an event, action, idea, or development as part of change or part of continuity in history.
A8: 7. Cause | B8: Students are given a stimulus and asked to identify a central cause of the described phenomenon.
A9: 8. Effect | B9: Students are given a stimulus and asked to identify a central effect of the described phenomenon.
A10: 9. Impact of Setting | B10: Students are given a stimulus and asked to identify the impact of time and place on an issue or event linked to that stimulus.
A11: 10. Compare | B11: Students are given one stimulus or two stimuli and asked to identify a similarity in the described phenomenon (historical development, historical event, geographic setting, economic situation, individual’s action/belief) (implicit comparison).
A12: 11. Contrast | B12: Students are given one/two stimuli and asked to identify a difference in the described phenomenon (historical development, historical event, geographic setting, economic situation, individual’s action/belief) (implicit comparison).
... A19: 18. Response to Problem | B19: Students are given one stimulus or two stimuli and asked to identify a response to a problem (issue).

Sheet Skill Standards
A1: Standard | B1: Concept | C1: Specification
A2: A. Gathering, Interpreting, and Using Evidence | B2: A.1: Framing Questions & Hypotheses | C2: Define and frame questions about events and the world in which we live, form hypotheses as potential answers to these questions, use evidence to answer these questions, and consider and analyze counter-hypotheses.
A3: A. Gathering, Interpreting, and Using Evidence | B3: A.2: Evaluating Sources | C3: Identify, describe, and evaluate evidence about events from diverse sources (including written documents, works of art, photographs, charts and graphs, artifacts, oral traditions, and other primary and secondary sources).
A4: A. Gathering, Interpreting, and Using Evidence | B4: A.3: Sourcing & Point of View | C4: Analyze evidence in terms of content, authorship, point of view, bias, purpose, format, and audience.
A5: A. Gathering, Interpreting, and Using Evidence | B5: A.4: Evaluating Arguments | C5: Describe, analyze, and evaluate arguments of others.
A6: A. Gathering, Interpreting, and Using Evidence | B6: A.5: Inferences & Conclusions | C6: Make inferences and draw conclusions from evidence.
A7: A. Gathering, Interpreting, and Using Evidence | B7: A.6: Constructing Arguments | C7: Deconstruct and construct plausible and persuasive arguments, using evidence.
A8: A. Gathering, Interpreting, and Using Evidence | B8: A.7: Synthesizing Evidence | C8: Create meaningful and persuasive understandings of the past by fusing disparate and relevant evidence from primary and secondary sources and drawing connections to the present.
A9: B. Chronological Reasoning and Causation | B9: B.1: Chronological Relationships | C9: Articulate how events are related chronologically to one another in time and explain the ways in which earlier ideas and events may influence subsequent ideas and events.
A10: B. Chronological Reasoning and Causation | B10: B.2: Cause & Effect | C10: Identify causes and effects using examples from different time periods and courses of study across several grade levels.
A11: B. Chronological Reasoning and Causation | B11: B.3: Multiple Causes & Effects | C11: Identify, analyze, and evaluate the relationship between multiple causes and effects
A12: B. Chronological Reasoning and Causation | B12: B.4: Long-Term vs. Immediate Causes | C12: Distinguish between long-term and immediate causes and multiple effects (time, continuity, and change).
... A42: F. Civic Participation | B42: F.8: Civic Responsibility | C42: Fulfill social and political responsibilities associated with citizenship in a democratic society and interdependent global community by developing awareness of and/or engaging in the political process.

Sheet Content Standards
A1: # | B1: Framework | C1: Specifications | D1: Concatenated
A2: 10.01a.1 | B2: Mughal & Ottoman (c. 1750) | C2: Students will compare and contrast the Mughal Empire and the Ottoman Empire in 1750 in terms of religious and ethnic tolerance, political organization, and commercial activity. | D2: =_xlfn.CONCAT(Table3[[#This Row],['#]],": ",Table3[[#This Row],[Framework]]) -> 10.01a.1: Mughal & Ottoman (c. 1750)
A3: 10.01a.2 | B3: Tokugawa Shogunate | C3: Students will examine efforts to unify, stabilize, and centralize Japan under the rule of the Tokugawa Shogunate. | D3: =_xlfn.CONCAT(Table3[[#This Row],['#]],": ",Table3[[#This Row],[Framework]]) -> 10.01a.2: Tokugawa Shogunate
A4: 10.01a.3 | B4: Comparing Tokugawa Shogunate & Bourbon Dynasty | C4: Students will compare and contrast the Tokugawa Shogunate in Japan with France under the rule of the Bourbon Dynasty, looking at the role of Edo and Paris/Versailles, attempts to control the daimyo and nobles, and the development of bureaucracies. | D4: =_xlfn.CONCAT(Table3[[#This Row],['#]],": ",Table3[[#This Row],[Framework]]) -> 10.01a.3: Comparing Tokugawa Shogunate & Bourbon Dynasty
A5: 10.01b.1 | B5: Tokugawa & Mughal Responses to Outsiders | C5: Students will compare and contrast the Tokugawa and Mughal responses to outsiders, with attention to the impacts of those decisions. | D5: =_xlfn.CONCAT(Table3[[#This Row],['#]],": ",Table3[[#This Row],[Framework]]) -> 10.01b.1: Tokugawa & Mughal Responses to Outsiders
A6: 10.01b.2 | B6: Eurasia World Map | C6: Students will create a world map showing the extent of European maritime empires, the Russian Empire, the Ottoman Empire, Mughal Empire, China under the Qing Dynasty, Japan under the Tokugawa Shogunate, Ashanti, Benin, and Dahomey ca. 1750. | D6: =_xlfn.CONCAT(Table3[[#This Row],['#]],": ",Table3[[#This Row],[Framework]]) -> 10.01b.2: Eurasia World Map
A7: 10.01b.3 | B7: Comparing Empire's Geography & Power | C7: Students will compare the size of these states, empires, and kingdoms relative to the power they wielded in their regions and in the world. | D7: =_xlfn.CONCAT(Table3[[#This Row],['#]],": ",Table3[[#This Row],[Framework]]) -> 10.01b.3: Comparing Empire's Geography & Power
A8: 10.02a.1 | B8: Political Philosophies | C8: Students will examine at least three Enlightenment thinkers, including John Locke, Baron de Montesquieu, and Jean-Jacques Rousseau, and key ideas from their written works. | D8: =_xlfn.CONCAT(Table3[[#This Row],['#]],": ",Table3[[#This Row],[Framework]]) -> 10.02a.1: Political Philosophies
A9: 10.02b.1 | B9: Gender & Abolition | C9: Students will explore the influence of Enlightenment ideals on issues of gender and abolition by examining the ideas of individuals such as Mary Wollstonecraft and William Wilberforce. | D9: =_xlfn.CONCAT(Table3[[#This Row],['#]],": ",Table3[[#This Row],[Framework]]) -> 10.02b.1: Gender & Abolition
A10: 10.02b.2 | B10: Enlightened Despots | C10: Students will examine enlightened despots including Catherine the Great. | D10: =_xlfn.CONCAT(Table3[[#This Row],['#]],": ",Table3[[#This Row],[Framework]]) -> 10.02b.2: Enlightened Despots
A11: 10.02c.1 | B11: French Revolutions | C11: Students will examine evidence related to the preconditions of the French Revolution and the course of the revolution, noting the roles of Olympe de Gouges, Maximilien Robespierre, and Napoleon Bonaparte. | D11: =_xlfn.CONCAT(Table3[[#This Row],['#]],": ",Table3[[#This Row],[Framework]]) -> 10.02c.1: French Revolutions
A12: 10.02c.2 | B12: Latin American Revolutions | C12: Students will examine the evidence related to the impacts of the French Revolution on resistance and revolutionary movements, noting the roles of Toussaint L'Ouverture and Simon Bolivar. | D12: =_xlfn.CONCAT(Table3[[#This Row],['#]],": ",Table3[[#This Row],[Framework]]) -> 10.02c.2: Latin American Revolutions
A13: 10.02d.1 | B13: Italy, Germany & Ottoman, Austrian | C13: Students will investigate the role of cultural identity and nationalism in the unification of Italy and Germany and in the dissolution of the Ottoman and Austrian Empires. | D13: =_xlfn.CONCAT(Table3[[#This Row],['#]],": ",Table3[[#This Row],[Framework]]) -> 10.02d.1: Italy, Germany & Ottoman, Austrian
... A178: 11.11c.3 | B178: US vs China Rivalry | C178: Students will examine the economic relationship and the strategic rivalry between the United States and China. | D178: =_xlfn.CONCAT(Table3[[#This Row],['#]],": ",Table3[[#This Row],[Framework]]) -> 11.11c.3: US vs China Rivalry
