Workbook

Sheet Scores
A1: Class | B1: Grade | C1: Period | D1: Student Name | E1: ELL? | F1: IEP? | G1: 1 | H1: 2 | I1: 3 | J1: 4 | K1: 5 | L1: 6 | M1: 7 | N1: 8 | O1: 9 | P1: 10 | Q1: 11 | R1: 12 | S1: 13 | T1: 14 | U1: 15 | V1: 16 | W1: 17 | X1: 18 | Y1: 19 | Z1: 20 | AA1: 21 | AB1: 22 | AC1: 23 | AD1: 24 | AE1: 25 | AF1: 26 | AG1: 27 | AH1: 28 | AI1: 29 | AJ1: 30 | AK1: 31 | AL1: 32 | AM1: 33 | AN1: 34a | AO1: 34b | AP1: Q1 | AQ1: Q2 | AR1: Q3 | AS1: Q4 | AT1: Q5 | AU1: Q6 | AV1: Q7 | AW1: Q8 | AX1: Q9 | AY1: Q10 | AZ1: Q11 | BA1: Q12 | BB1: Q13 | BC1: Q14 | BD1: Q15 | BE1: Q16 | BF1: Q17 | BG1: Q18 | BH1: Q19 | BI1: Q20 | BJ1: Q21 | BK1: Q22 | BL1: Q23 | BM1: Q24 | BN1: Q25 | BO1: Q26 | BP1: Q27 | BQ1: Q28
A2: Kovelsky | B2: 10 | C2: 4 | D2: 1 | G2: 4 | H2: 1 | I2: 3 | J2: 2 | K2: 4 | L2: 4 | M2: 2 | N2: 4 | O2: 1 | P2: 2 | Q2: 1 | R2: 4 | S2: 3 | T2: 4 | U2: 4 | V2: 2 | W2: 3 | X2: 4 | Y2: 1 | Z2: 2 | AA2: 4 | AB2: 2 | AC2: 2 | AD2: 3 | AE2: 3 | AF2: 4 | AG2: 2 | AH2: 2 | AI2: 1 | AJ2: 0 | AK2: 1 | AL2: 1 | AM2: 1 | AN2: 1 | AO2: 1 | AP2: =IF(G2=VLOOKUP(VALUE(G$1),Questions!$A:$E,5,FALSE),1,0) -> 1 | AQ2: =IF(H2=VLOOKUP(VALUE(H$1),Questions!$A:$E,5,FALSE),1,0) -> 1 | AR2: =IF(I2=VLOOKUP(VALUE(I$1),Questions!$A:$E,5,FALSE),1,0) -> 1 | AS2: =IF(J2=VLOOKUP(VALUE(J$1),Questions!$A:$E,5,FALSE),1,0) -> 1 | AT2: =IF(K2=VLOOKUP(VALUE(K$1),Questions!$A:$E,5,FALSE),1,0) -> 0 | AU2: =IF(L2=VLOOKUP(VALUE(L$1),Questions!$A:$E,5,FALSE),1,0) -> 0 | AV2: =IF(M2=VLOOKUP(VALUE(M$1),Questions!$A:$E,5,FALSE),1,0) -> 1 | AW2: =IF(N2=VLOOKUP(VALUE(N$1),Questions!$A:$E,5,FALSE),1,0) -> 0 | ... BQ2: =IF(AH2=VLOOKUP(VALUE(AH$1),Questions!$A:$E,5,FALSE),1,0) -> 1
A3: Kovelsky | B3: 10 | C3: 4 | D3: 2 | G3: 4 | H3: 1 | I3: 3 | J3: 4 | K3: 1 | L3: 2 | M3: 2 | N3: 3 | O3: 1 | P3: 1 | R3: 4 | S3: 2 | T3: 2 | U3: 3 | V3: 1 | W3: 4 | X3: 4 | Y3: 3 | Z3: 4 | AA3: 3 | AB3: 4 | AC3: 3 | AD3: 1 | AE3: 4 | AF3: 3 | AG3: 3 | AH3: 3 | AI3: 1 | AJ3: 0 | AK3: 1 | AL3: 1 | AM3: 1 | AN3: 1 | AO3: 1 | AP3: =IF(G3=VLOOKUP(VALUE(G$1),Questions!$A:$E,5,FALSE),1,0) -> 1 | AQ3: =IF(H3=VLOOKUP(VALUE(H$1),Questions!$A:$E,5,FALSE),1,0) -> 1 | AR3: =IF(I3=VLOOKUP(VALUE(I$1),Questions!$A:$E,5,FALSE),1,0) -> 1 | AS3: =IF(J3=VLOOKUP(VALUE(J$1),Questions!$A:$E,5,FALSE),1,0) -> 0 | AT3: =IF(K3=VLOOKUP(VALUE(K$1),Questions!$A:$E,5,FALSE),1,0) -> 1 | AU3: =IF(L3=VLOOKUP(VALUE(L$1),Questions!$A:$E,5,FALSE),1,0) -> 0 | AV3: =IF(M3=VLOOKUP(VALUE(M$1),Questions!$A:$E,5,FALSE),1,0) -> 1 | AW3: =IF(N3=VLOOKUP(VALUE(N$1),Questions!$A:$E,5,FALSE),1,0) -> 1 | ... BQ3: =IF(AH3=VLOOKUP(VALUE(AH$1),Questions!$A:$E,5,FALSE),1,0) -> 0
A4: Kovelsky | B4: 10 | C4: 4 | D4: 3 | G4: 4 | H4: 1 | I4: 3 | J4: 2 | K4: 1 | L4: 3 | M4: 4 | N4: 3 | O4: 1 | P4: 4 | Q4: 1 | R4: 4 | S4: 2 | T4: 3 | U4: 4 | V4: 3 | W4: 4 | X4: 4 | Y4: 1 | Z4: 3 | AA4: 4 | AB4: 1 | AC4: 2 | AD4: 4 | AE4: 2 | AF4: 4 | AG4: 1 | AH4: 3 | AP4: =IF(G4=VLOOKUP(VALUE(G$1),Questions!$A:$E,5,FALSE),1,0) -> 1 | AQ4: =IF(H4=VLOOKUP(VALUE(H$1),Questions!$A:$E,5,FALSE),1,0) -> 1 | AR4: =IF(I4=VLOOKUP(VALUE(I$1),Questions!$A:$E,5,FALSE),1,0) -> 1 | AS4: =IF(J4=VLOOKUP(VALUE(J$1),Questions!$A:$E,5,FALSE),1,0) -> 1 | AT4: =IF(K4=VLOOKUP(VALUE(K$1),Questions!$A:$E,5,FALSE),1,0) -> 1 | AU4: =IF(L4=VLOOKUP(VALUE(L$1),Questions!$A:$E,5,FALSE),1,0) -> 1 | AV4: =IF(M4=VLOOKUP(VALUE(M$1),Questions!$A:$E,5,FALSE),1,0) -> 0 | AW4: =IF(N4=VLOOKUP(VALUE(N$1),Questions!$A:$E,5,FALSE),1,0) -> 1 | ... BQ4: =IF(AH4=VLOOKUP(VALUE(AH$1),Questions!$A:$E,5,FALSE),1,0) -> 0
A5: Kovelsky | B5: 10 | C5: 4 | D5: 4 | G5: 4 | H5: 1 | I5: 3 | J5: 2 | K5: 1 | L5: 2 | M5: 4 | N5: 2 | O5: 1 | P5: 4 | Q5: 2 | R5: 2 | S5: 3 | T5: 2 | U5: 1 | V5: 2 | W5: 1 | X5: 3 | Y5: 4 | Z5: 1 | AA5: 3 | AB5: 2 | AC5: 1 | AD5: 3 | AE5: 1 | AF5: 3 | AG5: 2 | AH5: 2 | AI5: 1 | AJ5: 1 | AK5: 1 | AL5: 0 | AM5: 0 | AN5: 0 | AO5: 0 | AP5: =IF(G5=VLOOKUP(VALUE(G$1),Questions!$A:$E,5,FALSE),1,0) -> 1 | AQ5: =IF(H5=VLOOKUP(VALUE(H$1),Questions!$A:$E,5,FALSE),1,0) -> 1 | AR5: =IF(I5=VLOOKUP(VALUE(I$1),Questions!$A:$E,5,FALSE),1,0) -> 1 | AS5: =IF(J5=VLOOKUP(VALUE(J$1),Questions!$A:$E,5,FALSE),1,0) -> 1 | AT5: =IF(K5=VLOOKUP(VALUE(K$1),Questions!$A:$E,5,FALSE),1,0) -> 1 | AU5: =IF(L5=VLOOKUP(VALUE(L$1),Questions!$A:$E,5,FALSE),1,0) -> 0 | AV5: =IF(M5=VLOOKUP(VALUE(M$1),Questions!$A:$E,5,FALSE),1,0) -> 0 | AW5: =IF(N5=VLOOKUP(VALUE(N$1),Questions!$A:$E,5,FALSE),1,0) -> 0 | ... BQ5: =IF(AH5=VLOOKUP(VALUE(AH$1),Questions!$A:$E,5,FALSE),1,0) -> 1
A6: Kovelsky | B6: 10 | C6: 4 | D6: 5 | G6: 4 | H6: 1 | I6: 3 | J6: 2 | K6: 3 | L6: 3 | M6: 2 | N6: 3 | O6: 3 | P6: 4 | Q6: 1 | R6: 4 | S6: 2 | T6: 3 | U6: 4 | V6: 3 | W6: 4 | X6: 4 | Y6: 1 | Z6: 3 | AA6: 3 | AB6: 2 | AC6: 1 | AD6: 3 | AE6: 2 | AF6: 1 | AI6: 1 | AJ6: 1 | AK6: 1 | AL6: 1 | AM6: 1 | AN6: 1 | AO6: 0 | AP6: =IF(G6=VLOOKUP(VALUE(G$1),Questions!$A:$E,5,FALSE),1,0) -> 1 | AQ6: =IF(H6=VLOOKUP(VALUE(H$1),Questions!$A:$E,5,FALSE),1,0) -> 1 | AR6: =IF(I6=VLOOKUP(VALUE(I$1),Questions!$A:$E,5,FALSE),1,0) -> 1 | AS6: =IF(J6=VLOOKUP(VALUE(J$1),Questions!$A:$E,5,FALSE),1,0) -> 1 | AT6: =IF(K6=VLOOKUP(VALUE(K$1),Questions!$A:$E,5,FALSE),1,0) -> 0 | AU6: =IF(L6=VLOOKUP(VALUE(L$1),Questions!$A:$E,5,FALSE),1,0) -> 1 | AV6: =IF(M6=VLOOKUP(VALUE(M$1),Questions!$A:$E,5,FALSE),1,0) -> 1 | AW6: =IF(N6=VLOOKUP(VALUE(N$1),Questions!$A:$E,5,FALSE),1,0) -> 1 | ... BQ6: =IF(AH6=VLOOKUP(VALUE(AH$1),Questions!$A:$E,5,FALSE),1,0) -> 0
A7: Kovelsky | B7: 10 | C7: 4 | D7: 6 | G7: 2 | H7: 3 | I7: 3 | J7: 2 | K7: 3 | L7: 3 | M7: 2 | N7: 3 | O7: 1 | P7: 3 | Q7: 1 | R7: 4 | S7: 3 | T7: 3 | U7: 4 | V7: 3 | W7: 4 | X7: 3 | Y7: 1 | Z7: 3 | AA7: 4 | AB7: 2 | AC7: 3 | AD7: 4 | AE7: 2 | AF7: 4 | AG7: 2 | AH7: 2 | AP7: =IF(G7=VLOOKUP(VALUE(G$1),Questions!$A:$E,5,FALSE),1,0) -> 0 | AQ7: =IF(H7=VLOOKUP(VALUE(H$1),Questions!$A:$E,5,FALSE),1,0) -> 0 | AR7: =IF(I7=VLOOKUP(VALUE(I$1),Questions!$A:$E,5,FALSE),1,0) -> 1 | AS7: =IF(J7=VLOOKUP(VALUE(J$1),Questions!$A:$E,5,FALSE),1,0) -> 1 | AT7: =IF(K7=VLOOKUP(VALUE(K$1),Questions!$A:$E,5,FALSE),1,0) -> 0 | AU7: =IF(L7=VLOOKUP(VALUE(L$1),Questions!$A:$E,5,FALSE),1,0) -> 1 | AV7: =IF(M7=VLOOKUP(VALUE(M$1),Questions!$A:$E,5,FALSE),1,0) -> 1 | AW7: =IF(N7=VLOOKUP(VALUE(N$1),Questions!$A:$E,5,FALSE),1,0) -> 1 | ... BQ7: =IF(AH7=VLOOKUP(VALUE(AH$1),Questions!$A:$E,5,FALSE),1,0) -> 1
A8: Kovelsky | B8: 10 | C8: 4 | D8: 7 | G8: 4 | H8: 1 | I8: 3 | J8: 2 | K8: 1 | L8: 1 | M8: 2 | N8: 4 | O8: 1 | P8: 3 | Q8: 1 | R8: 4 | S8: 1 | T8: 2 | U8: 4 | V8: 3 | W8: 4 | X8: 4 | Y8: 1 | Z8: 3 | AA8: 4 | AB8: 2 | AC8: 2 | AD8: 1 | AE8: 3 | AF8: 1 | AG8: 2 | AH8: 2 | AI8: 1 | AJ8: 0 | AK8: 1 | AL8: 1 | AM8: 1 | AN8: 1 | AO8: 1 | AP8: =IF(G8=VLOOKUP(VALUE(G$1),Questions!$A:$E,5,FALSE),1,0) -> 1 | AQ8: =IF(H8=VLOOKUP(VALUE(H$1),Questions!$A:$E,5,FALSE),1,0) -> 1 | AR8: =IF(I8=VLOOKUP(VALUE(I$1),Questions!$A:$E,5,FALSE),1,0) -> 1 | AS8: =IF(J8=VLOOKUP(VALUE(J$1),Questions!$A:$E,5,FALSE),1,0) -> 1 | AT8: =IF(K8=VLOOKUP(VALUE(K$1),Questions!$A:$E,5,FALSE),1,0) -> 1 | AU8: =IF(L8=VLOOKUP(VALUE(L$1),Questions!$A:$E,5,FALSE),1,0) -> 0 | AV8: =IF(M8=VLOOKUP(VALUE(M$1),Questions!$A:$E,5,FALSE),1,0) -> 1 | AW8: =IF(N8=VLOOKUP(VALUE(N$1),Questions!$A:$E,5,FALSE),1,0) -> 0 | ... BQ8: =IF(AH8=VLOOKUP(VALUE(AH$1),Questions!$A:$E,5,FALSE),1,0) -> 1
A9: Kovelsky | B9: 10 | C9: 4 | D9: 8 | G9: 4 | H9: 1 | I9: 3 | J9: 2 | K9: 1 | L9: 3 | M9: 2 | N9: 3 | O9: 3 | P9: 4 | Q9: 1 | R9: 1 | S9: 2 | T9: 3 | U9: 4 | V9: 2 | W9: 1 | X9: 3 | Y9: 2 | Z9: 4 | AA9: 1 | AB9: 3 | AC9: 4 | AD9: 3 | AE9: 2 | AF9: 1 | AG9: 1 | AH9: 3 | AI9: 0 | AJ9: 1 | AK9: 1 | AL9: 1 | AM9: 1 | AN9: 1 | AO9: 0 | AP9: =IF(G9=VLOOKUP(VALUE(G$1),Questions!$A:$E,5,FALSE),1,0) -> 1 | AQ9: =IF(H9=VLOOKUP(VALUE(H$1),Questions!$A:$E,5,FALSE),1,0) -> 1 | AR9: =IF(I9=VLOOKUP(VALUE(I$1),Questions!$A:$E,5,FALSE),1,0) -> 1 | AS9: =IF(J9=VLOOKUP(VALUE(J$1),Questions!$A:$E,5,FALSE),1,0) -> 1 | AT9: =IF(K9=VLOOKUP(VALUE(K$1),Questions!$A:$E,5,FALSE),1,0) -> 1 | AU9: =IF(L9=VLOOKUP(VALUE(L$1),Questions!$A:$E,5,FALSE),1,0) -> 1 | AV9: =IF(M9=VLOOKUP(VALUE(M$1),Questions!$A:$E,5,FALSE),1,0) -> 1 | AW9: =IF(N9=VLOOKUP(VALUE(N$1),Questions!$A:$E,5,FALSE),1,0) -> 1 | ... BQ9: =IF(AH9=VLOOKUP(VALUE(AH$1),Questions!$A:$E,5,FALSE),1,0) -> 0
A10: Kovelsky | B10: 10 | C10: 4 | D10: 9 | AI10: 0 | AP10: =IF(G10=VLOOKUP(VALUE(G$1),Questions!$A:$E,5,FALSE),1,0) -> 0 | AQ10: =IF(H10=VLOOKUP(VALUE(H$1),Questions!$A:$E,5,FALSE),1,0) -> 0 | AR10: =IF(I10=VLOOKUP(VALUE(I$1),Questions!$A:$E,5,FALSE),1,0) -> 0 | AS10: =IF(J10=VLOOKUP(VALUE(J$1),Questions!$A:$E,5,FALSE),1,0) -> 0 | AT10: =IF(K10=VLOOKUP(VALUE(K$1),Questions!$A:$E,5,FALSE),1,0) -> 0 | AU10: =IF(L10=VLOOKUP(VALUE(L$1),Questions!$A:$E,5,FALSE),1,0) -> 0 | AV10: =IF(M10=VLOOKUP(VALUE(M$1),Questions!$A:$E,5,FALSE),1,0) -> 0 | AW10: =IF(N10=VLOOKUP(VALUE(N$1),Questions!$A:$E,5,FALSE),1,0) -> 0 | ... BQ10: =IF(AH10=VLOOKUP(VALUE(AH$1),Questions!$A:$E,5,FALSE),1,0) -> 0
A11: Kovelsky | B11: 10 | C11: 4 | D11: 10 | G11: 4 | H11: 1 | I11: 3 | J11: 2 | K11: 1 | L11: 3 | M11: 2 | N11: 3 | O11: 1 | P11: 4 | Q11: 1 | R11: 4 | S11: 2 | T11: 2 | U11: 4 | V11: 3 | W11: 4 | X11: 4 | Y11: 1 | Z11: 3 | AA11: 4 | AB11: 2 | AC11: 3 | AD11: 3 | AE11: 2 | AF11: 4 | AG11: 1 | AH11: 2 | AI11: 1 | AJ11: 1 | AK11: 1 | AL11: 1 | AM11: 1 | AN11: 1 | AO11: 1 | AP11: =IF(G11=VLOOKUP(VALUE(G$1),Questions!$A:$E,5,FALSE),1,0) -> 1 | AQ11: =IF(H11=VLOOKUP(VALUE(H$1),Questions!$A:$E,5,FALSE),1,0) -> 1 | AR11: =IF(I11=VLOOKUP(VALUE(I$1),Questions!$A:$E,5,FALSE),1,0) -> 1 | AS11: =IF(J11=VLOOKUP(VALUE(J$1),Questions!$A:$E,5,FALSE),1,0) -> 1 | AT11: =IF(K11=VLOOKUP(VALUE(K$1),Questions!$A:$E,5,FALSE),1,0) -> 1 | AU11: =IF(L11=VLOOKUP(VALUE(L$1),Questions!$A:$E,5,FALSE),1,0) -> 1 | AV11: =IF(M11=VLOOKUP(VALUE(M$1),Questions!$A:$E,5,FALSE),1,0) -> 1 | AW11: =IF(N11=VLOOKUP(VALUE(N$1),Questions!$A:$E,5,FALSE),1,0) -> 1 | ... BQ11: =IF(AH11=VLOOKUP(VALUE(AH$1),Questions!$A:$E,5,FALSE),1,0) -> 1
A12: Kovelsky | B12: 10 | C12: 4 | D12: 11 | G12: 4 | H12: 1 | I12: 3 | J12: 2 | K12: 3 | L12: 1 | M12: 2 | N12: 1 | O12: 1 | P12: 4 | Q12: 1 | R12: 4 | S12: 3 | T12: 2 | U12: 4 | V12: 3 | W12: 4 | X12: 4 | Y12: 1 | Z12: 3 | AA12: 4 | AB12: 2 | AC12: 4 | AD12: 3 | AI12: 0 | AJ12: 1 | AK12: 1 | AL12: 0 | AM12: 1 | AN12: 1 | AO12: 1 | AP12: =IF(G12=VLOOKUP(VALUE(G$1),Questions!$A:$E,5,FALSE),1,0) -> 1 | AQ12: =IF(H12=VLOOKUP(VALUE(H$1),Questions!$A:$E,5,FALSE),1,0) -> 1 | AR12: =IF(I12=VLOOKUP(VALUE(I$1),Questions!$A:$E,5,FALSE),1,0) -> 1 | AS12: =IF(J12=VLOOKUP(VALUE(J$1),Questions!$A:$E,5,FALSE),1,0) -> 1 | AT12: =IF(K12=VLOOKUP(VALUE(K$1),Questions!$A:$E,5,FALSE),1,0) -> 0 | AU12: =IF(L12=VLOOKUP(VALUE(L$1),Questions!$A:$E,5,FALSE),1,0) -> 0 | AV12: =IF(M12=VLOOKUP(VALUE(M$1),Questions!$A:$E,5,FALSE),1,0) -> 1 | AW12: =IF(N12=VLOOKUP(VALUE(N$1),Questions!$A:$E,5,FALSE),1,0) -> 0 | ... BQ12: =IF(AH12=VLOOKUP(VALUE(AH$1),Questions!$A:$E,5,FALSE),1,0) -> 0
A13: Kovelsky | B13: 10 | C13: 4 | D13: 12 | G13: 2 | H13: 4 | I13: 3 | J13: 1 | K13: 3 | L13: 1 | M13: 2 | N13: 3 | O13: 3 | P13: 4 | Q13: 3 | R13: 1 | S13: 2 | T13: 3 | U13: 2 | V13: 3 | W13: 1 | X13: 2 | Y13: 3 | Z13: 3 | AA13: 3 | AB13: 3 | AD13: 3 | AE13: 4 | AF13: 2 | AG13: 3 | AI13: 0 | AJ13: 0 | AK13: 0 | AL13: 1 | AM13: 0 | AN13: 0 | AO13: 1 | AP13: =IF(G13=VLOOKUP(VALUE(G$1),Questions!$A:$E,5,FALSE),1,0) -> 0 | AQ13: =IF(H13=VLOOKUP(VALUE(H$1),Questions!$A:$E,5,FALSE),1,0) -> 0 | AR13: =IF(I13=VLOOKUP(VALUE(I$1),Questions!$A:$E,5,FALSE),1,0) -> 1 | AS13: =IF(J13=VLOOKUP(VALUE(J$1),Questions!$A:$E,5,FALSE),1,0) -> 0 | AT13: =IF(K13=VLOOKUP(VALUE(K$1),Questions!$A:$E,5,FALSE),1,0) -> 0 | AU13: =IF(L13=VLOOKUP(VALUE(L$1),Questions!$A:$E,5,FALSE),1,0) -> 0 | AV13: =IF(M13=VLOOKUP(VALUE(M$1),Questions!$A:$E,5,FALSE),1,0) -> 1 | AW13: =IF(N13=VLOOKUP(VALUE(N$1),Questions!$A:$E,5,FALSE),1,0) -> 1 | ... BQ13: =IF(AH13=VLOOKUP(VALUE(AH$1),Questions!$A:$E,5,FALSE),1,0) -> 0
A14: Kovelsky | B14: 10 | C14: 4 | D14: 13 | G14: 3 | H14: 3 | I14: 3 | J14: 2 | K14: 4 | L14: 4 | M14: 1 | N14: 4 | O14: 1 | P14: 2 | Q14: 2 | R14: 1 | S14: 3 | T14: 3 | U14: 1 | V14: 1 | W14: 1 | X14: 1 | Y14: 1 | Z14: 2 | AA14: 1 | AB14: 2 | AC14: 2 | AD14: 3 | AE14: 3 | AF14: 1 | AG14: 3 | AH14: 1 | AP14: =IF(G14=VLOOKUP(VALUE(G$1),Questions!$A:$E,5,FALSE),1,0) -> 0 | AQ14: =IF(H14=VLOOKUP(VALUE(H$1),Questions!$A:$E,5,FALSE),1,0) -> 0 | AR14: =IF(I14=VLOOKUP(VALUE(I$1),Questions!$A:$E,5,FALSE),1,0) -> 1 | AS14: =IF(J14=VLOOKUP(VALUE(J$1),Questions!$A:$E,5,FALSE),1,0) -> 1 | AT14: =IF(K14=VLOOKUP(VALUE(K$1),Questions!$A:$E,5,FALSE),1,0) -> 0 | AU14: =IF(L14=VLOOKUP(VALUE(L$1),Questions!$A:$E,5,FALSE),1,0) -> 0 | AV14: =IF(M14=VLOOKUP(VALUE(M$1),Questions!$A:$E,5,FALSE),1,0) -> 0 | AW14: =IF(N14=VLOOKUP(VALUE(N$1),Questions!$A:$E,5,FALSE),1,0) -> 0 | ... BQ14: =IF(AH14=VLOOKUP(VALUE(AH$1),Questions!$A:$E,5,FALSE),1,0) -> 0
A15: Kovelsky | B15: 10 | C15: 4 | D15: 14 | G15: 4 | H15: 3 | I15: 3 | J15: 2 | K15: 1 | L15: 1 | M15: 4 | N15: 2 | O15: 3 | P15: 4 | Q15: 1 | R15: 1 | S15: 3 | T15: 3 | U15: 4 | V15: 3 | W15: 4 | X15: 3 | Y15: 1 | Z15: 3 | AA15: 4 | AB15: 3 | AD15: 3 | AE15: 2 | AF15: 4 | AG15: 1 | AH15: 2 | AI15: 0 | AJ15: 1 | AK15: 1 | AL15: 1 | AM15: 1 | AN15: 1 | AO15: 1 | AP15: =IF(G15=VLOOKUP(VALUE(G$1),Questions!$A:$E,5,FALSE),1,0) -> 1 | AQ15: =IF(H15=VLOOKUP(VALUE(H$1),Questions!$A:$E,5,FALSE),1,0) -> 0 | AR15: =IF(I15=VLOOKUP(VALUE(I$1),Questions!$A:$E,5,FALSE),1,0) -> 1 | AS15: =IF(J15=VLOOKUP(VALUE(J$1),Questions!$A:$E,5,FALSE),1,0) -> 1 | AT15: =IF(K15=VLOOKUP(VALUE(K$1),Questions!$A:$E,5,FALSE),1,0) -> 1 | AU15: =IF(L15=VLOOKUP(VALUE(L$1),Questions!$A:$E,5,FALSE),1,0) -> 0 | AV15: =IF(M15=VLOOKUP(VALUE(M$1),Questions!$A:$E,5,FALSE),1,0) -> 0 | AW15: =IF(N15=VLOOKUP(VALUE(N$1),Questions!$A:$E,5,FALSE),1,0) -> 0 | ... BQ15: =IF(AH15=VLOOKUP(VALUE(AH$1),Questions!$A:$E,5,FALSE),1,0) -> 1
A16: Kovelsky | B16: 10 | C16: 4 | D16: 15 | G16: 4 | H16: 1 | I16: 3 | J16: 2 | K16: 1 | L16: 2 | M16: 2 | N16: 3 | O16: 1 | P16: 3 | Q16: 1 | R16: 4 | S16: 2 | T16: 1 | U16: 4 | V16: 3 | W16: 4 | X16: 3 | Y16: 1 | Z16: 3 | AA16: 4 | AB16: 2 | AC16: 4 | AD16: 3 | AE16: 2 | AF16: 1 | AG16: 1 | AH16: 1 | AI16: 1 | AJ16: 1 | AK16: 1 | AL16: 1 | AM16: 1 | AN16: 1 | AO16: 1 | AP16: =IF(G16=VLOOKUP(VALUE(G$1),Questions!$A:$E,5,FALSE),1,0) -> 1 | AQ16: =IF(H16=VLOOKUP(VALUE(H$1),Questions!$A:$E,5,FALSE),1,0) -> 1 | AR16: =IF(I16=VLOOKUP(VALUE(I$1),Questions!$A:$E,5,FALSE),1,0) -> 1 | AS16: =IF(J16=VLOOKUP(VALUE(J$1),Questions!$A:$E,5,FALSE),1,0) -> 1 | AT16: =IF(K16=VLOOKUP(VALUE(K$1),Questions!$A:$E,5,FALSE),1,0) -> 1 | AU16: =IF(L16=VLOOKUP(VALUE(L$1),Questions!$A:$E,5,FALSE),1,0) -> 0 | AV16: =IF(M16=VLOOKUP(VALUE(M$1),Questions!$A:$E,5,FALSE),1,0) -> 1 | AW16: =IF(N16=VLOOKUP(VALUE(N$1),Questions!$A:$E,5,FALSE),1,0) -> 1 | ... BQ16: =IF(AH16=VLOOKUP(VALUE(AH$1),Questions!$A:$E,5,FALSE),1,0) -> 0
A17: Kovelsky | B17: 10 | C17: 4 | D17: 16 | G17: 4 | H17: 1 | I17: 3 | J17: 2 | K17: 1 | L17: 2 | M17: 1 | N17: 4 | O17: 3 | P17: 4 | Q17: 1 | R17: 1 | S17: 3 | T17: 2 | U17: 3 | V17: 3 | W17: 1 | X17: 3 | Y17: 1 | Z17: 2 | AA17: 3 | AB17: 2 | AC17: 4 | AD17: 3 | AE17: 1 | AF17: 3 | AG17: 2 | AH17: 2 | AP17: =IF(G17=VLOOKUP(VALUE(G$1),Questions!$A:$E,5,FALSE),1,0) -> 1 | AQ17: =IF(H17=VLOOKUP(VALUE(H$1),Questions!$A:$E,5,FALSE),1,0) -> 1 | AR17: =IF(I17=VLOOKUP(VALUE(I$1),Questions!$A:$E,5,FALSE),1,0) -> 1 | AS17: =IF(J17=VLOOKUP(VALUE(J$1),Questions!$A:$E,5,FALSE),1,0) -> 1 | AT17: =IF(K17=VLOOKUP(VALUE(K$1),Questions!$A:$E,5,FALSE),1,0) -> 1 | AU17: =IF(L17=VLOOKUP(VALUE(L$1),Questions!$A:$E,5,FALSE),1,0) -> 0 | AV17: =IF(M17=VLOOKUP(VALUE(M$1),Questions!$A:$E,5,FALSE),1,0) -> 0 | AW17: =IF(N17=VLOOKUP(VALUE(N$1),Questions!$A:$E,5,FALSE),1,0) -> 0 | ... BQ17: =IF(AH17=VLOOKUP(VALUE(AH$1),Questions!$A:$E,5,FALSE),1,0) -> 1
A18: Kovelsky | B18: 10 | C18: 4 | D18: 17 | AP18: =IF(G18=VLOOKUP(VALUE(G$1),Questions!$A:$E,5,FALSE),1,0) -> 0 | AQ18: =IF(H18=VLOOKUP(VALUE(H$1),Questions!$A:$E,5,FALSE),1,0) -> 0 | AR18: =IF(I18=VLOOKUP(VALUE(I$1),Questions!$A:$E,5,FALSE),1,0) -> 0 | AS18: =IF(J18=VLOOKUP(VALUE(J$1),Questions!$A:$E,5,FALSE),1,0) -> 0 | AT18: =IF(K18=VLOOKUP(VALUE(K$1),Questions!$A:$E,5,FALSE),1,0) -> 0 | AU18: =IF(L18=VLOOKUP(VALUE(L$1),Questions!$A:$E,5,FALSE),1,0) -> 0 | AV18: =IF(M18=VLOOKUP(VALUE(M$1),Questions!$A:$E,5,FALSE),1,0) -> 0 | AW18: =IF(N18=VLOOKUP(VALUE(N$1),Questions!$A:$E,5,FALSE),1,0) -> 0 | ... BQ18: =IF(AH18=VLOOKUP(VALUE(AH$1),Questions!$A:$E,5,FALSE),1,0) -> 0
A19: Kovelsky | B19: 10 | C19: 4 | D19: 18 | G19: 4 | H19: 1 | I19: 3 | J19: 1 | K19: 1 | L19: 4 | M19: 2 | N19: 4 | O19: 3 | P19: 3 | Q19: 1 | R19: 4 | S19: 2 | T19: 4 | U19: 1 | V19: 3 | W19: 1 | X19: 3 | Y19: 3 | Z19: 1 | AA19: 2 | AB19: 3 | AC19: 1 | AD19: 3 | AE19: 4 | AF19: 2 | AG19: 1 | AH19: 3 | AI19: 0 | AJ19: 1 | AK19: 1 | AL19: 1 | AM19: 1 | AN19: 1 | AO19: 0 | AP19: =IF(G19=VLOOKUP(VALUE(G$1),Questions!$A:$E,5,FALSE),1,0) -> 1 | AQ19: =IF(H19=VLOOKUP(VALUE(H$1),Questions!$A:$E,5,FALSE),1,0) -> 1 | AR19: =IF(I19=VLOOKUP(VALUE(I$1),Questions!$A:$E,5,FALSE),1,0) -> 1 | AS19: =IF(J19=VLOOKUP(VALUE(J$1),Questions!$A:$E,5,FALSE),1,0) -> 0 | AT19: =IF(K19=VLOOKUP(VALUE(K$1),Questions!$A:$E,5,FALSE),1,0) -> 1 | AU19: =IF(L19=VLOOKUP(VALUE(L$1),Questions!$A:$E,5,FALSE),1,0) -> 0 | AV19: =IF(M19=VLOOKUP(VALUE(M$1),Questions!$A:$E,5,FALSE),1,0) -> 1 | AW19: =IF(N19=VLOOKUP(VALUE(N$1),Questions!$A:$E,5,FALSE),1,0) -> 0 | ... BQ19: =IF(AH19=VLOOKUP(VALUE(AH$1),Questions!$A:$E,5,FALSE),1,0) -> 0
A20: Kovelsky | B20: 10 | C20: 4 | D20: 19 | G20: 4 | H20: 1 | I20: 3 | J20: 2 | K20: 1 | L20: 2 | M20: 2 | N20: 3 | O20: 1 | P20: 2 | Q20: 1 | R20: 4 | S20: 3 | T20: 2 | U20: 4 | V20: 3 | W20: 4 | X20: 3 | Y20: 1 | Z20: 3 | AA20: 3 | AB20: 2 | AC20: 3 | AD20: 3 | AE20: 3 | AF20: 4 | AG20: 2 | AH20: 3 | AI20: 1 | AJ20: 1 | AK20: 1 | AL20: 1 | AM20: 1 | AN20: 1 | AO20: 1 | AP20: =IF(G20=VLOOKUP(VALUE(G$1),Questions!$A:$E,5,FALSE),1,0) -> 1 | AQ20: =IF(H20=VLOOKUP(VALUE(H$1),Questions!$A:$E,5,FALSE),1,0) -> 1 | AR20: =IF(I20=VLOOKUP(VALUE(I$1),Questions!$A:$E,5,FALSE),1,0) -> 1 | AS20: =IF(J20=VLOOKUP(VALUE(J$1),Questions!$A:$E,5,FALSE),1,0) -> 1 | AT20: =IF(K20=VLOOKUP(VALUE(K$1),Questions!$A:$E,5,FALSE),1,0) -> 1 | AU20: =IF(L20=VLOOKUP(VALUE(L$1),Questions!$A:$E,5,FALSE),1,0) -> 0 | AV20: =IF(M20=VLOOKUP(VALUE(M$1),Questions!$A:$E,5,FALSE),1,0) -> 1 | AW20: =IF(N20=VLOOKUP(VALUE(N$1),Questions!$A:$E,5,FALSE),1,0) -> 1 | ... BQ20: =IF(AH20=VLOOKUP(VALUE(AH$1),Questions!$A:$E,5,FALSE),1,0) -> 0
A21: Kovelsky | B21: 10 | C21: 4 | D21: 20 | G21: 3 | H21: 3 | I21: 1 | J21: 2 | K21: 3 | L21: 2 | M21: 2 | N21: 4 | O21: 1 | P21: 4 | Q21: 1 | R21: 2 | S21: 3 | T21: 1 | U21: 1 | V21: 4 | W21: 2 | X21: 1 | Y21: 1 | Z21: 3 | AA21: 4 | AB21: 3 | AC21: 3 | AD21: 1 | AE21: 1 | AF21: 4 | AG21: 2 | AH21: 3 | AP21: =IF(G21=VLOOKUP(VALUE(G$1),Questions!$A:$E,5,FALSE),1,0) -> 0 | AQ21: =IF(H21=VLOOKUP(VALUE(H$1),Questions!$A:$E,5,FALSE),1,0) -> 0 | AR21: =IF(I21=VLOOKUP(VALUE(I$1),Questions!$A:$E,5,FALSE),1,0) -> 0 | AS21: =IF(J21=VLOOKUP(VALUE(J$1),Questions!$A:$E,5,FALSE),1,0) -> 1 | AT21: =IF(K21=VLOOKUP(VALUE(K$1),Questions!$A:$E,5,FALSE),1,0) -> 0 | AU21: =IF(L21=VLOOKUP(VALUE(L$1),Questions!$A:$E,5,FALSE),1,0) -> 0 | AV21: =IF(M21=VLOOKUP(VALUE(M$1),Questions!$A:$E,5,FALSE),1,0) -> 1 | AW21: =IF(N21=VLOOKUP(VALUE(N$1),Questions!$A:$E,5,FALSE),1,0) -> 0 | ... BQ21: =IF(AH21=VLOOKUP(VALUE(AH$1),Questions!$A:$E,5,FALSE),1,0) -> 0
A22: Kovelsky | B22: 10 | C22: 4 | D22: 21 | G22: 4 | H22: 1 | I22: 3 | J22: 2 | K22: 3 | L22: 1 | M22: 2 | N22: 1 | O22: 1 | P22: 3 | Q22: 1 | R22: 4 | S22: 2 | T22: 2 | U22: 3 | V22: 1 | W22: 2 | X22: 4 | Y22: 1 | Z22: 3 | AA22: 4 | AB22: 2 | AC22: 2 | AD22: 3 | AE22: 4 | AF22: 4 | AG22: 3 | AH22: 2 | AI22: 0 | AJ22: 1 | AK22: 1 | AL22: 1 | AM22: 1 | AN22: 1 | AO22: 1 | AP22: =IF(G22=VLOOKUP(VALUE(G$1),Questions!$A:$E,5,FALSE),1,0) -> 1 | AQ22: =IF(H22=VLOOKUP(VALUE(H$1),Questions!$A:$E,5,FALSE),1,0) -> 1 | AR22: =IF(I22=VLOOKUP(VALUE(I$1),Questions!$A:$E,5,FALSE),1,0) -> 1 | AS22: =IF(J22=VLOOKUP(VALUE(J$1),Questions!$A:$E,5,FALSE),1,0) -> 1 | AT22: =IF(K22=VLOOKUP(VALUE(K$1),Questions!$A:$E,5,FALSE),1,0) -> 0 | AU22: =IF(L22=VLOOKUP(VALUE(L$1),Questions!$A:$E,5,FALSE),1,0) -> 0 | AV22: =IF(M22=VLOOKUP(VALUE(M$1),Questions!$A:$E,5,FALSE),1,0) -> 1 | AW22: =IF(N22=VLOOKUP(VALUE(N$1),Questions!$A:$E,5,FALSE),1,0) -> 0 | ... BQ22: =IF(AH22=VLOOKUP(VALUE(AH$1),Questions!$A:$E,5,FALSE),1,0) -> 1
A23: Kovelsky | B23: 10 | C23: 4 | D23: 22 | G23: 4 | H23: 1 | I23: 3 | J23: 2 | K23: 3 | L23: 1 | M23: 2 | N23: 1 | O23: 1 | P23: 3 | Q23: 1 | R23: 4 | S23: 2 | T23: 2 | U23: 3 | V23: 1 | W23: 2 | X23: 4 | Y23: 1 | Z23: 3 | AA23: 4 | AB23: 2 | AC23: 2 | AD23: 3 | AE23: 4 | AF23: 4 | AG23: 3 | AH23: 2 | AI23: 1 | AJ23: 0 | AK23: 1 | AL23: 0 | AM23: 1 | AN23: 1 | AO23: 1 | AP23: =IF(G23=VLOOKUP(VALUE(G$1),Questions!$A:$E,5,FALSE),1,0) -> 1 | AQ23: =IF(H23=VLOOKUP(VALUE(H$1),Questions!$A:$E,5,FALSE),1,0) -> 1 | AR23: =IF(I23=VLOOKUP(VALUE(I$1),Questions!$A:$E,5,FALSE),1,0) -> 1 | AS23: =IF(J23=VLOOKUP(VALUE(J$1),Questions!$A:$E,5,FALSE),1,0) -> 1 | AT23: =IF(K23=VLOOKUP(VALUE(K$1),Questions!$A:$E,5,FALSE),1,0) -> 0 | AU23: =IF(L23=VLOOKUP(VALUE(L$1),Questions!$A:$E,5,FALSE),1,0) -> 0 | AV23: =IF(M23=VLOOKUP(VALUE(M$1),Questions!$A:$E,5,FALSE),1,0) -> 1 | AW23: =IF(N23=VLOOKUP(VALUE(N$1),Questions!$A:$E,5,FALSE),1,0) -> 0 | ... BQ23: =IF(AH23=VLOOKUP(VALUE(AH$1),Questions!$A:$E,5,FALSE),1,0) -> 1
A24: Kovelsky | B24: 10 | C24: 4 | D24: 23 | AI24: 0 | AJ24: 0 | AK24: 1 | AL24: 0 | AM24: 1 | AN24: 1 | AO24: 1 | AP24: =IF(G24=VLOOKUP(VALUE(G$1),Questions!$A:$E,5,FALSE),1,0) -> 0 | AQ24: =IF(H24=VLOOKUP(VALUE(H$1),Questions!$A:$E,5,FALSE),1,0) -> 0 | AR24: =IF(I24=VLOOKUP(VALUE(I$1),Questions!$A:$E,5,FALSE),1,0) -> 0 | AS24: =IF(J24=VLOOKUP(VALUE(J$1),Questions!$A:$E,5,FALSE),1,0) -> 0 | AT24: =IF(K24=VLOOKUP(VALUE(K$1),Questions!$A:$E,5,FALSE),1,0) -> 0 | AU24: =IF(L24=VLOOKUP(VALUE(L$1),Questions!$A:$E,5,FALSE),1,0) -> 0 | AV24: =IF(M24=VLOOKUP(VALUE(M$1),Questions!$A:$E,5,FALSE),1,0) -> 0 | AW24: =IF(N24=VLOOKUP(VALUE(N$1),Questions!$A:$E,5,FALSE),1,0) -> 0 | ... BQ24: =IF(AH24=VLOOKUP(VALUE(AH$1),Questions!$A:$E,5,FALSE),1,0) -> 0
A25: Kovelsky | B25: 10 | C25: 4 | D25: 24 | G25: 4 | H25: 1 | I25: 3 | J25: 2 | K25: 4 | L25: 1 | M25: 2 | N25: 1 | O25: 1 | P25: 4 | Q25: 1 | R25: 4 | S25: 3 | T25: 2 | U25: 4 | V25: 3 | W25: 4 | X25: 4 | Y25: 1 | Z25: 3 | AA25: 4 | AB25: 2 | AC25: 4 | AD25: 3 | AE25: 2 | AF25: 4 | AG25: 2 | AH25: 2 | AI25: 0 | AJ25: 1 | AK25: 1 | AL25: 1 | AM25: 1 | AN25: 1 | AO25: 1 | AP25: =IF(G25=VLOOKUP(VALUE(G$1),Questions!$A:$E,5,FALSE),1,0) -> 1 | AQ25: =IF(H25=VLOOKUP(VALUE(H$1),Questions!$A:$E,5,FALSE),1,0) -> 1 | AR25: =IF(I25=VLOOKUP(VALUE(I$1),Questions!$A:$E,5,FALSE),1,0) -> 1 | AS25: =IF(J25=VLOOKUP(VALUE(J$1),Questions!$A:$E,5,FALSE),1,0) -> 1 | AT25: =IF(K25=VLOOKUP(VALUE(K$1),Questions!$A:$E,5,FALSE),1,0) -> 0 | AU25: =IF(L25=VLOOKUP(VALUE(L$1),Questions!$A:$E,5,FALSE),1,0) -> 0 | AV25: =IF(M25=VLOOKUP(VALUE(M$1),Questions!$A:$E,5,FALSE),1,0) -> 1 | AW25: =IF(N25=VLOOKUP(VALUE(N$1),Questions!$A:$E,5,FALSE),1,0) -> 0 | ... BQ25: =IF(AH25=VLOOKUP(VALUE(AH$1),Questions!$A:$E,5,FALSE),1,0) -> 1
A26: Kovelsky | B26: 10 | C26: 4 | D26: 25 | G26: 4 | H26: 1 | I26: 3 | J26: 2 | K26: 1 | L26: 3 | M26: 2 | N26: 2 | O26: 3 | P26: 3 | Q26: 1 | R26: 4 | S26: 3 | T26: 3 | U26: 4 | V26: 3 | W26: 4 | X26: 3 | Y26: 1 | Z26: 3 | AA26: 1 | AB26: 3 | AC26: 4 | AD26: 4 | AE26: 1 | AF26: 2 | AG26: 2 | AH26: 3 | AI26: 1 | AJ26: 1 | AK26: 1 | AL26: 1 | AM26: 0 | AN26: 1 | AO26: 1 | AP26: =IF(G26=VLOOKUP(VALUE(G$1),Questions!$A:$E,5,FALSE),1,0) -> 1 | AQ26: =IF(H26=VLOOKUP(VALUE(H$1),Questions!$A:$E,5,FALSE),1,0) -> 1 | AR26: =IF(I26=VLOOKUP(VALUE(I$1),Questions!$A:$E,5,FALSE),1,0) -> 1 | AS26: =IF(J26=VLOOKUP(VALUE(J$1),Questions!$A:$E,5,FALSE),1,0) -> 1 | AT26: =IF(K26=VLOOKUP(VALUE(K$1),Questions!$A:$E,5,FALSE),1,0) -> 1 | AU26: =IF(L26=VLOOKUP(VALUE(L$1),Questions!$A:$E,5,FALSE),1,0) -> 1 | AV26: =IF(M26=VLOOKUP(VALUE(M$1),Questions!$A:$E,5,FALSE),1,0) -> 1 | AW26: =IF(N26=VLOOKUP(VALUE(N$1),Questions!$A:$E,5,FALSE),1,0) -> 0 | ... BQ26: =IF(AH26=VLOOKUP(VALUE(AH$1),Questions!$A:$E,5,FALSE),1,0) -> 0
A27: Kovelsky | B27: 10 | C27: 4 | D27: 26 | G27: 4 | H27: 1 | I27: 3 | J27: 2 | K27: 1 | L27: 3 | M27: 4 | N27: 4 | O27: 1 | P27: 3 | Q27: 1 | R27: 4 | S27: 3 | T27: 2 | U27: 4 | V27: 3 | W27: 4 | X27: 3 | Y27: 1 | Z27: 3 | AA27: 4 | AB27: 2 | AC27: 2 | AD27: 3 | AE27: 1 | AF27: 4 | AG27: 1 | AH27: 2 | AI27: 1 | AJ27: 0 | AK27: 1 | AL27: 1 | AM27: 1 | AN27: 1 | AO27: 1 | AP27: =IF(G27=VLOOKUP(VALUE(G$1),Questions!$A:$E,5,FALSE),1,0) -> 1 | AQ27: =IF(H27=VLOOKUP(VALUE(H$1),Questions!$A:$E,5,FALSE),1,0) -> 1 | AR27: =IF(I27=VLOOKUP(VALUE(I$1),Questions!$A:$E,5,FALSE),1,0) -> 1 | AS27: =IF(J27=VLOOKUP(VALUE(J$1),Questions!$A:$E,5,FALSE),1,0) -> 1 | AT27: =IF(K27=VLOOKUP(VALUE(K$1),Questions!$A:$E,5,FALSE),1,0) -> 1 | AU27: =IF(L27=VLOOKUP(VALUE(L$1),Questions!$A:$E,5,FALSE),1,0) -> 1 | AV27: =IF(M27=VLOOKUP(VALUE(M$1),Questions!$A:$E,5,FALSE),1,0) -> 0 | AW27: =IF(N27=VLOOKUP(VALUE(N$1),Questions!$A:$E,5,FALSE),1,0) -> 0 | ... BQ27: =IF(AH27=VLOOKUP(VALUE(AH$1),Questions!$A:$E,5,FALSE),1,0) -> 1
A28: Kovelsky | B28: 10 | C28: 4 | D28: 27 | AI28: 0 | AJ28: 1 | AK28: 1 | AL28: 1 | AM28: 1 | AN28: 1 | AO28: 1 | AP28: =IF(G28=VLOOKUP(VALUE(G$1),Questions!$A:$E,5,FALSE),1,0) -> 0 | AQ28: =IF(H28=VLOOKUP(VALUE(H$1),Questions!$A:$E,5,FALSE),1,0) -> 0 | AR28: =IF(I28=VLOOKUP(VALUE(I$1),Questions!$A:$E,5,FALSE),1,0) -> 0 | AS28: =IF(J28=VLOOKUP(VALUE(J$1),Questions!$A:$E,5,FALSE),1,0) -> 0 | AT28: =IF(K28=VLOOKUP(VALUE(K$1),Questions!$A:$E,5,FALSE),1,0) -> 0 | AU28: =IF(L28=VLOOKUP(VALUE(L$1),Questions!$A:$E,5,FALSE),1,0) -> 0 | AV28: =IF(M28=VLOOKUP(VALUE(M$1),Questions!$A:$E,5,FALSE),1,0) -> 0 | AW28: =IF(N28=VLOOKUP(VALUE(N$1),Questions!$A:$E,5,FALSE),1,0) -> 0 | ... BQ28: =IF(AH28=VLOOKUP(VALUE(AH$1),Questions!$A:$E,5,FALSE),1,0) -> 0
A29: Kovelsky | B29: 10 | C29: 4 | D29: 28 | G29: 4 | H29: 3 | I29: 4 | J29: 2 | K29: 3 | L29: 3 | M29: 1 | N29: 3 | O29: 1 | P29: 4 | Q29: 1 | R29: 4 | S29: 3 | T29: 2 | U29: 3 | V29: 3 | W29: 4 | X29: 3 | Y29: 1 | Z29: 3 | AA29: 4 | AB29: 2 | AC29: 4 | AD29: 3 | AE29: 1 | AF29: 4 | AG29: 2 | AH29: 2 | AI29: 0 | AJ29: 0 | AK29: 0 | AL29: 0 | AM29: 0 | AN29: 0 | AO29: 0 | AP29: =IF(G29=VLOOKUP(VALUE(G$1),Questions!$A:$E,5,FALSE),1,0) -> 1 | AQ29: =IF(H29=VLOOKUP(VALUE(H$1),Questions!$A:$E,5,FALSE),1,0) -> 0 | AR29: =IF(I29=VLOOKUP(VALUE(I$1),Questions!$A:$E,5,FALSE),1,0) -> 0 | AS29: =IF(J29=VLOOKUP(VALUE(J$1),Questions!$A:$E,5,FALSE),1,0) -> 1 | AT29: =IF(K29=VLOOKUP(VALUE(K$1),Questions!$A:$E,5,FALSE),1,0) -> 0 | AU29: =IF(L29=VLOOKUP(VALUE(L$1),Questions!$A:$E,5,FALSE),1,0) -> 1 | AV29: =IF(M29=VLOOKUP(VALUE(M$1),Questions!$A:$E,5,FALSE),1,0) -> 0 | AW29: =IF(N29=VLOOKUP(VALUE(N$1),Questions!$A:$E,5,FALSE),1,0) -> 1 | ... BQ29: =IF(AH29=VLOOKUP(VALUE(AH$1),Questions!$A:$E,5,FALSE),1,0) -> 1
A30: Kovelsky | B30: 10 | C30: 4 | D30: 29 | G30: 4 | H30: 1 | I30: 2 | J30: 4 | K30: 4 | L30: 3 | M30: 2 | N30: 3 | O30: 1 | P30: 3 | Q30: 4 | R30: 2 | S30: 3 | T30: 1 | U30: 2 | V30: 2 | W30: 1 | X30: 3 | Y30: 1 | Z30: 4 | AA30: 1 | AB30: 4 | AC30: 4 | AD30: 3 | AE30: 3 | AF30: 2 | AG30: 1 | AP30: =IF(G30=VLOOKUP(VALUE(G$1),Questions!$A:$E,5,FALSE),1,0) -> 1 | AQ30: =IF(H30=VLOOKUP(VALUE(H$1),Questions!$A:$E,5,FALSE),1,0) -> 1 | AR30: =IF(I30=VLOOKUP(VALUE(I$1),Questions!$A:$E,5,FALSE),1,0) -> 0 | AS30: =IF(J30=VLOOKUP(VALUE(J$1),Questions!$A:$E,5,FALSE),1,0) -> 0 | AT30: =IF(K30=VLOOKUP(VALUE(K$1),Questions!$A:$E,5,FALSE),1,0) -> 0 | AU30: =IF(L30=VLOOKUP(VALUE(L$1),Questions!$A:$E,5,FALSE),1,0) -> 1 | AV30: =IF(M30=VLOOKUP(VALUE(M$1),Questions!$A:$E,5,FALSE),1,0) -> 1 | AW30: =IF(N30=VLOOKUP(VALUE(N$1),Questions!$A:$E,5,FALSE),1,0) -> 1 | ... BQ30: =IF(AH30=VLOOKUP(VALUE(AH$1),Questions!$A:$E,5,FALSE),1,0) -> 0
A31: Kovelsky | B31: 10 | C31: 4 | D31: 30 | G31: 1 | H31: 1 | I31: 3 | J31: 2 | K31: 3 | L31: 1 | M31: 2 | N31: 4 | O31: 3 | P31: 4 | Q31: 1 | R31: 1 | S31: 3 | T31: 4 | U31: 1 | V31: 2 | W31: 1 | X31: 3 | Y31: 3 | Z31: 4 | AA31: 4 | AB31: 2 | AC31: 3 | AD31: 3 | AE31: 2 | AF31: 4 | AG31: 1 | AH31: 3 | AI31: 0 | AJ31: 1 | AK31: 0 | AL31: 0 | AM31: 0 | AN31: 0 | AO31: 0 | AP31: =IF(G31=VLOOKUP(VALUE(G$1),Questions!$A:$E,5,FALSE),1,0) -> 0 | AQ31: =IF(H31=VLOOKUP(VALUE(H$1),Questions!$A:$E,5,FALSE),1,0) -> 1 | AR31: =IF(I31=VLOOKUP(VALUE(I$1),Questions!$A:$E,5,FALSE),1,0) -> 1 | AS31: =IF(J31=VLOOKUP(VALUE(J$1),Questions!$A:$E,5,FALSE),1,0) -> 1 | AT31: =IF(K31=VLOOKUP(VALUE(K$1),Questions!$A:$E,5,FALSE),1,0) -> 0 | AU31: =IF(L31=VLOOKUP(VALUE(L$1),Questions!$A:$E,5,FALSE),1,0) -> 0 | AV31: =IF(M31=VLOOKUP(VALUE(M$1),Questions!$A:$E,5,FALSE),1,0) -> 1 | AW31: =IF(N31=VLOOKUP(VALUE(N$1),Questions!$A:$E,5,FALSE),1,0) -> 0 | ... BQ31: =IF(AH31=VLOOKUP(VALUE(AH$1),Questions!$A:$E,5,FALSE),1,0) -> 0
A32: Kovelsky | B32: 10 | C32: 4 | D32: 31 | G32: 4 | H32: 1 | I32: 3 | J32: 2 | K32: 1 | L32: 3 | M32: 2 | N32: 1 | O32: 1 | P32: 3 | Q32: 1 | R32: 4 | S32: 3 | T32: 4 | U32: 4 | V32: 3 | W32: 4 | X32: 3 | Y32: 1 | Z32: 3 | AA32: 4 | AB32: 2 | AC32: 3 | AD32: 3 | AE32: 2 | AF32: 4 | AG32: 1 | AH32: 2 | AI32: 1 | AJ32: 1 | AK32: 1 | AL32: 1 | AM32: 1 | AN32: 1 | AO32: 1 | AP32: =IF(G32=VLOOKUP(VALUE(G$1),Questions!$A:$E,5,FALSE),1,0) -> 1 | AQ32: =IF(H32=VLOOKUP(VALUE(H$1),Questions!$A:$E,5,FALSE),1,0) -> 1 | AR32: =IF(I32=VLOOKUP(VALUE(I$1),Questions!$A:$E,5,FALSE),1,0) -> 1 | AS32: =IF(J32=VLOOKUP(VALUE(J$1),Questions!$A:$E,5,FALSE),1,0) -> 1 | AT32: =IF(K32=VLOOKUP(VALUE(K$1),Questions!$A:$E,5,FALSE),1,0) -> 1 | AU32: =IF(L32=VLOOKUP(VALUE(L$1),Questions!$A:$E,5,FALSE),1,0) -> 1 | AV32: =IF(M32=VLOOKUP(VALUE(M$1),Questions!$A:$E,5,FALSE),1,0) -> 1 | AW32: =IF(N32=VLOOKUP(VALUE(N$1),Questions!$A:$E,5,FALSE),1,0) -> 0 | ... BQ32: =IF(AH32=VLOOKUP(VALUE(AH$1),Questions!$A:$E,5,FALSE),1,0) -> 1
A33: Dushin | B33: 10 | C33: 1 | D33: 32 | G33: 4 | H33: 1 | I33: 4 | J33: 2 | K33: 1 | L33: 3 | M33: 2 | N33: 3 | O33: 1 | P33: 3 | Q33: 1 | R33: 4 | S33: 3 | T33: 3 | U33: 4 | V33: 3 | W33: 3 | X33: 4 | Y33: 1 | Z33: 3 | AA33: 4 | AB33: 1 | AC33: 2 | AD33: 3 | AE33: 2 | AF33: 4 | AP33: =IF(G33=VLOOKUP(VALUE(G$1),Questions!$A:$E,5,FALSE),1,0) -> 1 | AQ33: =IF(H33=VLOOKUP(VALUE(H$1),Questions!$A:$E,5,FALSE),1,0) -> 1 | AR33: =IF(I33=VLOOKUP(VALUE(I$1),Questions!$A:$E,5,FALSE),1,0) -> 0 | AS33: =IF(J33=VLOOKUP(VALUE(J$1),Questions!$A:$E,5,FALSE),1,0) -> 1 | AT33: =IF(K33=VLOOKUP(VALUE(K$1),Questions!$A:$E,5,FALSE),1,0) -> 1 | AU33: =IF(L33=VLOOKUP(VALUE(L$1),Questions!$A:$E,5,FALSE),1,0) -> 1 | AV33: =IF(M33=VLOOKUP(VALUE(M$1),Questions!$A:$E,5,FALSE),1,0) -> 1 | AW33: =IF(N33=VLOOKUP(VALUE(N$1),Questions!$A:$E,5,FALSE),1,0) -> 1 | ... BQ33: =IF(AH33=VLOOKUP(VALUE(AH$1),Questions!$A:$E,5,FALSE),1,0) -> 0
A34: Dushin | B34: 10 | C34: 1 | D34: 33 | F34: YES | G34: 3 | H34: 3 | I34: 3 | J34: 2 | K34: 3 | L34: 3 | M34: 2 | N34: 3 | O34: 1 | P34: 3 | Q34: 1 | R34: 4 | S34: 2 | T34: 2 | U34: 3 | V34: 4 | W34: 4 | X34: 1 | Y34: 1 | Z34: 3 | AA34: 4 | AB34: 2 | AC34: 2 | AD34: 3 | AE34: 2 | AF34: 4 | AG34: 1 | AH34: 3 | AI34: 1 | AJ34: 1 | AK34: 1 | AL34: 1 | AM34: 1 | AN34: 1 | AO34: 1 | AP34: =IF(G34=VLOOKUP(VALUE(G$1),Questions!$A:$E,5,FALSE),1,0) -> 0 | AQ34: =IF(H34=VLOOKUP(VALUE(H$1),Questions!$A:$E,5,FALSE),1,0) -> 0 | AR34: =IF(I34=VLOOKUP(VALUE(I$1),Questions!$A:$E,5,FALSE),1,0) -> 1 | AS34: =IF(J34=VLOOKUP(VALUE(J$1),Questions!$A:$E,5,FALSE),1,0) -> 1 | AT34: =IF(K34=VLOOKUP(VALUE(K$1),Questions!$A:$E,5,FALSE),1,0) -> 0 | AU34: =IF(L34=VLOOKUP(VALUE(L$1),Questions!$A:$E,5,FALSE),1,0) -> 1 | AV34: =IF(M34=VLOOKUP(VALUE(M$1),Questions!$A:$E,5,FALSE),1,0) -> 1 | AW34: =IF(N34=VLOOKUP(VALUE(N$1),Questions!$A:$E,5,FALSE),1,0) -> 1 | ... BQ34: =IF(AH34=VLOOKUP(VALUE(AH$1),Questions!$A:$E,5,FALSE),1,0) -> 0
A35: Dushin | B35: 10 | C35: 1 | D35: 34 | G35: 4 | H35: 1 | I35: 3 | J35: 2 | K35: 4 | L35: 2 | M35: 2 | N35: 3 | O35: 3 | P35: 4 | Q35: 1 | R35: 4 | S35: 4 | T35: 2 | U35: 4 | V35: 3 | W35: 4 | X35: 3 | Y35: 1 | Z35: 3 | AA35: 4 | AB35: 2 | AC35: 4 | AD35: 3 | AE35: 2 | AF35: 4 | AG35: 1 | AH35: 3 | AJ35: 1 | AM35: 1 | AP35: =IF(G35=VLOOKUP(VALUE(G$1),Questions!$A:$E,5,FALSE),1,0) -> 1 | AQ35: =IF(H35=VLOOKUP(VALUE(H$1),Questions!$A:$E,5,FALSE),1,0) -> 1 | AR35: =IF(I35=VLOOKUP(VALUE(I$1),Questions!$A:$E,5,FALSE),1,0) -> 1 | AS35: =IF(J35=VLOOKUP(VALUE(J$1),Questions!$A:$E,5,FALSE),1,0) -> 1 | AT35: =IF(K35=VLOOKUP(VALUE(K$1),Questions!$A:$E,5,FALSE),1,0) -> 0 | AU35: =IF(L35=VLOOKUP(VALUE(L$1),Questions!$A:$E,5,FALSE),1,0) -> 0 | AV35: =IF(M35=VLOOKUP(VALUE(M$1),Questions!$A:$E,5,FALSE),1,0) -> 1 | AW35: =IF(N35=VLOOKUP(VALUE(N$1),Questions!$A:$E,5,FALSE),1,0) -> 1 | ... BQ35: =IF(AH35=VLOOKUP(VALUE(AH$1),Questions!$A:$E,5,FALSE),1,0) -> 0
A36: Dushin | B36: 10 | C36: 1 | D36: 35 | F36: YES | G36: 4 | H36: 1 | J36: 2 | K36: 4 | L36: 1 | M36: 2 | N36: 4 | O36: 1 | P36: 3 | Q36: 1 | R36: 4 | S36: 3 | T36: 3 | U36: 1 | V36: 3 | W36: 4 | X36: 4 | Y36: 1 | Z36: 3 | AA36: 3 | AB36: 2 | AC36: 4 | AD36: 3 | AE36: 1 | AF36: 4 | AG36: 3 | AH36: 3 | AI36: 1 | AJ36: 1 | AK36: 1 | AL36: 0 | AM36: 1 | AN36: 0 | AO36: 1 | AP36: =IF(G36=VLOOKUP(VALUE(G$1),Questions!$A:$E,5,FALSE),1,0) -> 1 | AQ36: =IF(H36=VLOOKUP(VALUE(H$1),Questions!$A:$E,5,FALSE),1,0) -> 1 | AR36: =IF(I36=VLOOKUP(VALUE(I$1),Questions!$A:$E,5,FALSE),1,0) -> 0 | AS36: =IF(J36=VLOOKUP(VALUE(J$1),Questions!$A:$E,5,FALSE),1,0) -> 1 | AT36: =IF(K36=VLOOKUP(VALUE(K$1),Questions!$A:$E,5,FALSE),1,0) -> 0 | AU36: =IF(L36=VLOOKUP(VALUE(L$1),Questions!$A:$E,5,FALSE),1,0) -> 0 | AV36: =IF(M36=VLOOKUP(VALUE(M$1),Questions!$A:$E,5,FALSE),1,0) -> 1 | AW36: =IF(N36=VLOOKUP(VALUE(N$1),Questions!$A:$E,5,FALSE),1,0) -> 0 | ... BQ36: =IF(AH36=VLOOKUP(VALUE(AH$1),Questions!$A:$E,5,FALSE),1,0) -> 0
A37: Dushin | B37: 10 | C37: 1 | D37: 36 | G37: 4 | H37: 4 | I37: 1 | J37: 1 | K37: 2 | M37: 2 | N37: 3 | O37: 3 | P37: 4 | Q37: 1 | R37: 2 | S37: 1 | T37: 2 | V37: 4 | AJ37: 0 | AP37: =IF(G37=VLOOKUP(VALUE(G$1),Questions!$A:$E,5,FALSE),1,0) -> 1 | AQ37: =IF(H37=VLOOKUP(VALUE(H$1),Questions!$A:$E,5,FALSE),1,0) -> 0 | AR37: =IF(I37=VLOOKUP(VALUE(I$1),Questions!$A:$E,5,FALSE),1,0) -> 0 | AS37: =IF(J37=VLOOKUP(VALUE(J$1),Questions!$A:$E,5,FALSE),1,0) -> 0 | AT37: =IF(K37=VLOOKUP(VALUE(K$1),Questions!$A:$E,5,FALSE),1,0) -> 0 | AU37: =IF(L37=VLOOKUP(VALUE(L$1),Questions!$A:$E,5,FALSE),1,0) -> 0 | AV37: =IF(M37=VLOOKUP(VALUE(M$1),Questions!$A:$E,5,FALSE),1,0) -> 1 | AW37: =IF(N37=VLOOKUP(VALUE(N$1),Questions!$A:$E,5,FALSE),1,0) -> 1 | ... BQ37: =IF(AH37=VLOOKUP(VALUE(AH$1),Questions!$A:$E,5,FALSE),1,0) -> 0
A38: Dushin | B38: 10 | C38: 1 | D38: 37 | G38: 4 | H38: 3 | I38: 3 | J38: 2 | K38: 1 | L38: 2 | M38: 4 | N38: 3 | O38: 1 | P38: 4 | Q38: 1 | R38: 4 | S38: 3 | T38: 2 | U38: 4 | V38: 3 | W38: 4 | X38: 3 | Y38: 1 | Z38: 3 | AA38: 2 | AB38: 1 | AC38: 2 | AD38: 1 | AE38: 2 | AF38: 4 | AG38: 2 | AH38: 3 | AI38: 1 | AJ38: 1 | AK38: 1 | AL38: 1 | AM38: 1 | AN38: 1 | AO38: 1 | AP38: =IF(G38=VLOOKUP(VALUE(G$1),Questions!$A:$E,5,FALSE),1,0) -> 1 | AQ38: =IF(H38=VLOOKUP(VALUE(H$1),Questions!$A:$E,5,FALSE),1,0) -> 0 | AR38: =IF(I38=VLOOKUP(VALUE(I$1),Questions!$A:$E,5,FALSE),1,0) -> 1 | AS38: =IF(J38=VLOOKUP(VALUE(J$1),Questions!$A:$E,5,FALSE),1,0) -> 1 | AT38: =IF(K38=VLOOKUP(VALUE(K$1),Questions!$A:$E,5,FALSE),1,0) -> 1 | AU38: =IF(L38=VLOOKUP(VALUE(L$1),Questions!$A:$E,5,FALSE),1,0) -> 0 | AV38: =IF(M38=VLOOKUP(VALUE(M$1),Questions!$A:$E,5,FALSE),1,0) -> 0 | AW38: =IF(N38=VLOOKUP(VALUE(N$1),Questions!$A:$E,5,FALSE),1,0) -> 1 | ... BQ38: =IF(AH38=VLOOKUP(VALUE(AH$1),Questions!$A:$E,5,FALSE),1,0) -> 0
A39: Dushin | B39: 10 | C39: 1 | D39: 38 | G39: 4 | H39: 1 | I39: 3 | J39: 1 | K39: 2 | L39: 1 | M39: 2 | N39: 3 | O39: 1 | P39: 4 | Q39: 1 | R39: 4 | S39: 2 | T39: 2 | U39: 4 | V39: 3 | Y39: 1 | Z39: 3 | AP39: =IF(G39=VLOOKUP(VALUE(G$1),Questions!$A:$E,5,FALSE),1,0) -> 1 | AQ39: =IF(H39=VLOOKUP(VALUE(H$1),Questions!$A:$E,5,FALSE),1,0) -> 1 | AR39: =IF(I39=VLOOKUP(VALUE(I$1),Questions!$A:$E,5,FALSE),1,0) -> 1 | AS39: =IF(J39=VLOOKUP(VALUE(J$1),Questions!$A:$E,5,FALSE),1,0) -> 0 | AT39: =IF(K39=VLOOKUP(VALUE(K$1),Questions!$A:$E,5,FALSE),1,0) -> 0 | AU39: =IF(L39=VLOOKUP(VALUE(L$1),Questions!$A:$E,5,FALSE),1,0) -> 0 | AV39: =IF(M39=VLOOKUP(VALUE(M$1),Questions!$A:$E,5,FALSE),1,0) -> 1 | AW39: =IF(N39=VLOOKUP(VALUE(N$1),Questions!$A:$E,5,FALSE),1,0) -> 1 | ... BQ39: =IF(AH39=VLOOKUP(VALUE(AH$1),Questions!$A:$E,5,FALSE),1,0) -> 0
A40: Dushin | B40: 10 | C40: 1 | D40: 39 | E40: YES | F40: YES | G40: 4 | H40: 1 | I40: 3 | J40: 2 | K40: 1 | L40: 1 | M40: 4 | N40: 3 | O40: 1 | P40: 3 | Q40: 1 | R40: 4 | S40: 3 | T40: 4 | U40: 4 | V40: 3 | W40: 4 | X40: 3 | Y40: 1 | Z40: 3 | AA40: 4 | AB40: 2 | AC40: 4 | AD40: 1 | AE40: 3 | AF40: 4 | AG40: 1 | AH40: 2 | AI40: 1 | AJ40: 1 | AK40: 1 | AL40: 1 | AM40: 1 | AN40: 1 | AO40: 1 | AP40: =IF(G40=VLOOKUP(VALUE(G$1),Questions!$A:$E,5,FALSE),1,0) -> 1 | AQ40: =IF(H40=VLOOKUP(VALUE(H$1),Questions!$A:$E,5,FALSE),1,0) -> 1 | AR40: =IF(I40=VLOOKUP(VALUE(I$1),Questions!$A:$E,5,FALSE),1,0) -> 1 | AS40: =IF(J40=VLOOKUP(VALUE(J$1),Questions!$A:$E,5,FALSE),1,0) -> 1 | AT40: =IF(K40=VLOOKUP(VALUE(K$1),Questions!$A:$E,5,FALSE),1,0) -> 1 | AU40: =IF(L40=VLOOKUP(VALUE(L$1),Questions!$A:$E,5,FALSE),1,0) -> 0 | AV40: =IF(M40=VLOOKUP(VALUE(M$1),Questions!$A:$E,5,FALSE),1,0) -> 0 | AW40: =IF(N40=VLOOKUP(VALUE(N$1),Questions!$A:$E,5,FALSE),1,0) -> 1 | ... BQ40: =IF(AH40=VLOOKUP(VALUE(AH$1),Questions!$A:$E,5,FALSE),1,0) -> 1
...

Sheet Questions
A1: # | B1: Part | C1: Stimulus | D1: Question | E1: Answer | F1: Full Answer | G1: Stimulus Type | H1: Source Type | I1: Task Model | J1: Skill | K1: Content | L1: Need OI? | M1: Option 1 | N1: Option 2 | O1: Option 3 | P1: Option 4 | Q1: Pct_correct
A2: 1 | B2: Part I | C2: John W. Dower, “Throwing Off Asia ,” Massachusetts Institute of Technology, 2008 | D2: What claim is best supported by this passage? | E2: 4 | F2: Japan experienced a period of cultural development despite its isolation. | G2: Text-based | H2: Secondary | I2: 4. Claim Validity (Without Outside Information) | J2: A. Gathering, Interpreting, and Using Evidence | K2: 10.01b.1 | L2: No | M2: Japan challenged China for supremacy in Asia. | N2: Japan relied on natural resources for industrial growth. | O2: Japan made great industrial and territorial gains that rivaled world powers. | P2: Japan experienced a period of cultural development despite its isolation. | Q2: =AVERAGE(INDEX(Scores[#Data],0,MATCH("Q"&$A2,Scores[#Headers],0))) -> 0.71153846
A3: 2 | B3: Part I | C3: John W. Dower, “Throwing Off Asia ,” Massachusetts Institute of Technology, 2008 | D3: This passage best describes which development in Japanese history? | E3: 1 | F3: the rule of the Tokugawa Shogunate | G3: Text-based | H3: Secondary | I3: 1. Best Use | J3: A. Gathering, Interpreting, and Using Evidence | K3: 10.01b.1 | L3: Yes | M3: the rule of the Tokugawa Shogunate | N3: the arrival of Commodore Matthew Perry | O3: the Meiji Restoration | P3: the annexation of Korea | Q3: =AVERAGE(INDEX(Scores[#Data],0,MATCH("Q"&$A3,Scores[#Headers],0))) -> 0.70192308
A4: 3 | B4: Part I | C4: Declaration of the Rights of Man and of the Citizen, 1789 | D4: Which group would be most likely to support the ideas presented in this document? | E4: 3 | F4: the Third Estate | G4: Text-based | H4: Primary | I4: 14. Stakeholder Issue | J4: C. Comparison and Contextualization | K4: 10.02c.1 | L4: Yes | M4: the nobility | N4: the clergy | O4: the Third Estate | P4: the royal officials | Q4: =AVERAGE(INDEX(Scores[#Data],0,MATCH("Q"&$A4,Scores[#Headers],0))) -> 0.80769231
A5: 4 | B5: Part I | C5: Declaration of the Rights of Man and of the Citizen, 1789 | D5: Which claim is best supported by this document? | E5: 2 | F5: The rights of all citizens should be respected with fairness and justice. | G5: Text-based | H5: Primary | I5: 4. Claim Validity (Without Outside Information) | J5: A. Gathering, Interpreting, and Using Evidence | K5: 10.02c.1 | L5: No | M5: People arrested should be presumed guilty until proven innocent. | N5: The rights of all citizens should be respected with fairness and justice. | O5: Religious practices should be limited by the government. | P5: Freedom of speech should be restricted for the public good. | Q5: =AVERAGE(INDEX(Scores[#Data],0,MATCH("Q"&$A5,Scores[#Headers],0))) -> 0.83653846
A6: 5 | B6: Part I | C6: Henry Brun et al., Global History and Geography, Amsco, 2004 (adapted) | D6: The situation shown on this map was most infl uenced by the | E6: 1 | F6: French Revolution | G6: Map-based | H6: Secondary | I6: 7. Cause | J6: B. Chronological Reasoning and Causation | K6: 10.02c.2 | L6: Yes | M6: French Revolution | N6: German Unification | O6: Balfour Declaration | P6: Treaty of Versailles | Q6: =AVERAGE(INDEX(Scores[#Data],0,MATCH("Q"&$A6,Scores[#Headers],0))) -> 0.57692308
A7: 6 | B7: Part I | C7: Henry Brun et al., Global History and Geography, Amsco, 2004 (adapted) | D7: Which claim about Latin America is best supported by the information on this map? | E7: 3 | F7: Nationalism became a growing force during the 19th century. | G7: Map-based | H7: Secondary | I7: 13. Interpret Visual Data | J7: A. Gathering, Interpreting, and Using Evidence | K7: 10.02c.2 | L7: No | M7: European countries had control over most of the region until World War I. | N7: Most independence movements occurred in the 20th century. | O7: Nationalism became a growing force during the 19th century. | P7: Most countries gained independence before the Haitian Revolution. | Q7: =AVERAGE(INDEX(Scores[#Data],0,MATCH("Q"&$A7,Scores[#Headers],0))) -> 0.50961538
A8: 7 | B8: Part I | C8: “The Industrial Revolution and the Changing Face of Britain,” The British Museum online | D8: This passage would be most useful for | E8: 2 | F8: explaining the economic benefi ts of the Agricultural Revolution in Britain | G8: Text-based | H8: Secondary | I8: 1. Best Use | J8: A. Gathering, Interpreting, and Using Evidence | K8: 10.03a.1 | L8: Yes | M8: studying how urbanization affected British government policies | N8: explaining the economic benefits of the Agricultural Revolution in Britain | O8: analyzing the distribution of natural resources in Britain | P8: understanding how the Agricultural Revolution led to British imperialism | Q8: =AVERAGE(INDEX(Scores[#Data],0,MATCH("Q"&$A8,Scores[#Headers],0))) -> 0.73076923
A9: 8 | B9: Part I | C9: “The Industrial Revolution and the Changing Face of Britain,” The British Museum online | D9: What was one way British farmers responded to the changes described in this passage? | E9: 3 | F9: Farmers specialized based on their location | G9: Text-based | H9: Secondary | I9: 18. Response to Problem | J9: B. Chronological Reasoning and Causation | K9: 10.03a.1 | L9: No | M9: The enclosure system was eliminated. | N9: Agricultural productivity in Britain decreased. | O9: Farmers specialized based on their location. | P9: Most farmers in the provinces fled to the countryside. | Q9: =AVERAGE(INDEX(Scores[#Data],0,MATCH("Q"&$A9,Scores[#Headers],0))) -> 0.59615385
A10: 9 | B10: Part I | C10: Punch, July 3, 1858 | D10: Which statement best explains the cartoonist’s perspective of conditions in London during this time period? | E10: 1 | F10: Industrialization led to contamination of water supplies and illness. | G10: Visual-based | H10: Primary | I10: 2. POV | J10: A. Gathering, Interpreting, and Using Evidence | K10: 10.09c.3 | L10: No | M10: Industrialization led to contamination of water supplies and illness. | N10: The growth of factories contributed to poor working conditions. | O10: Urbanization caused a scarcity of food and mass starvation. | P10: The church offered support to those living in urban poverty. | Q10: =AVERAGE(INDEX(Scores[#Data],0,MATCH("Q"&$A10,Scores[#Headers],0))) -> 0.74038462
A11: 10 | B11: Part I | C11: Punch, July 3, 1858 | D11: What was the cartoonist’s purpose in creating this illustration? | E11: 3 | F11: to encourage the government to make reforms | G11: Visual-based | H11: Primary | I11: 2. POV | J11: A. Gathering, Interpreting, and Using Evidence | K11: 10.09c.3 | L11: No | M11: to attract people to settle in London | N11: to promote Queen Victoria's humanitarian efforts | O11: to encourage the government to make reforms | P11: to raise public awareness of the impacts of irrigation | Q11: =AVERAGE(INDEX(Scores[#Data],0,MATCH("Q"&$A11,Scores[#Headers],0))) -> 0.43269231
A12: 11 | B12: Part I | C12: Kevin Reilly, Worlds of History, Bedford/St. Martin’s, 2007 (adapted) | D12: Based on this map, which two countries acquired the most foreign territory? | E12: 1 | F12: Great Britain and France | G12: Map-based | H12: Secondary | I12: 13. Interpret Visual Data | J12: A. Gathering, Interpreting, and Using Evidence | K12: 10.04a.2 | L12: No | M12: Great Britain and France | N12: the Netherlands and Belgium | O12: Spain and Portugal | P12: Germany and Italy | Q12: =AVERAGE(INDEX(Scores[#Data],0,MATCH("Q"&$A12,Scores[#Headers],0))) -> 0.84615385
A13: 12 | B13: Part I | C13: Kevin Reilly, Worlds of History, Bedford/St. Martin’s, 2007 (adapted) | D13: The situation shown on this map was caused in part by European nations’ desire to | E13: 4 | F13: obtain raw materials for their industries | G13: Map-based | H13: Secondary | I13: 7. Cause | J13: B. Chronological Reasoning and Causation | K13: 10.04a.2 | L13: Yes | M13: import factory-made goods | N13: encourage immigration into their countries | O13: establish democratic governments worldwide | P13: obtain raw materials for their industries | Q13: =AVERAGE(INDEX(Scores[#Data],0,MATCH("Q"&$A13,Scores[#Headers],0))) -> 0.72115385
... A29: 28 | B29: Part I | C29: Carlotta Gall, “Erdogan’s Plan to Raise a ‘Pious Generation’ Divides Parents in Turkey,” New York Times, June 18, 2018 | D29: Which event led to changes similar to those described in this article? | E29: 2 | F29: the Islamic Revolution of 1979 in Iran | G29: Text-based | H29: Primary | I29: 10. Compare | J29: C. Comparison and Contextualization | K29: 10.08b.1 | L29: Yes | M29: the seizing of the Suez Canal by Gamal Nasser | N29: the Islamic Revolution of 1979 in Iran | O29: the collapse of the Austrian Empire | P29: the partition of India in 1948 | Q29: =AVERAGE(INDEX(Scores[#Data],0,MATCH("Q"&$A29,Scores[#Headers],0))) -> 0.46153846
A30: 29 | B30: Part II | C30: Adam Hochschild, King Leopold’s Ghost, Mariner Books, 1999 | D30: Explain the geographic context for the historical development described in this passage. | G30: Text-based | H30: Secondary | I30: 9. Impact of Setting | K30: 10.04a.1
A31: 30 | B31: Part II | C31: Patrice Lumumba, speech at the ceremony of the proclamation of the Congo’s independence, June 30, 1960 | D31: Based on this passage, explain how the audience affects what Lumumba includes in his speech. | G31: Text-based | H31: Primary | I31: 2. POV | K31: 10.07b.1
A32: 31 | B32: Part II | C32: — | D32: Identify and explain a cause-and-effect relationship between the events and/or ideas found in these documents. Be sure to use evidence from both Documents 1 and 2 in your response.
A33: 32 | B33: Part II | C33: Dr. Sue Gronewold, “The Opium War and Foreign Encroachment,” Asia for Educators, Columbia University | D33: Explain the historical circumstances that led to China’s century of “unequal treaties.” | G33: Text-based | H33: Secondary | I33: 7. Cause | K33: 10.04a.2
A34: 33 | B34: Part II | C34: Wolfgang Lehmacher, “Why China Could Lead the Next Phase of Globalization,” World Economic Forum, November 22, 2016 | D34: Based on this document, identify the author’s point of view regarding China’s economy in the 21st century. | G34: Text-based | H34: Primary | I34: 2. POV | K34: 10.09a.1
A35: 34a | B35: Part II | C35: — | D35: Identify a similarity or a difference in China’s role in the world economy.
A36: 34b | B36: Part II | C36: — | D36: Explain the similarity or difference you identified using evidence from both documents.

Sheet Content Standards
A1: # | B1: Unit / Concept / Content | C1: Unit | D1: Conceptual Understanding | E1: Specifications
A2: 11.01 | B2: Colonial Foundations (1607-1763) | C2: European colonization in North America prompted cultural contact and exchange between diverse peoples; cultural differences and misunderstandings at times led to conflict. A variety of factors contributed to the development of regional differences, including social and racial hierarchies, in colonial America. | D2: European colonization in North America prompted cultural contact and exchange between diverse peoples; cultural differences and misunderstandings at times led to conflict. A variety of factors contributed to the development of regional differences, including social and racial hierarchies, in colonial America.
A3: 10.01 | B3: The World in 1750 | C3: THE WORLD in 1750 | D3: The world in 1750 was marked by powerful Eurasian states and empires, coastal African kingdoms, and growing European maritime empires. The interactions of these states, empires, and kingdoms disrupted regional trade networks and influenced the development of new global trade networks. | E3: The world in 1750 was marked by powerful Eurasian states and empires, coastal African kingdoms, and growing European maritime empires. The interactions of these states, empires, and kingdoms disrupted regional trade networks and influenced the development of new global trade networks.
A4: 10.02 | B4: Enlightenment, Revolution, & Nationalism | C4: ENLIGHTENMENT, REVOLUTION, AND NATIONALISM | D4: The Enlightenment called into question traditional beliefs and inspired widespread political, economic, and social change. This intellectual movement was used to challenge political authorities in Europe and colonial rule in the Americas. These ideals inspired political and social movements. | E4: The Enlightenment called into question traditional beliefs and inspired widespread political, economic, and social change. This intellectual movement was used to challenge political authorities in Europe and colonial rule in the Americas. These ideals inspired political and social movements.
A5: 10.03 | B5: Industrial Revolution | C5: CAUSES AND EFFECTS OF THE INDUSTRIAL REVOLUTION | D5: Innovations in agriculture, production, and transportation led to the Industrial Revolution, which originated in Western Europe and spread over time to Japan and other regions. This led to major population shifts and transformed economic and social systems. | E5: Innovations in agriculture, production, and transportation led to the Industrial Revolution, which originated in Western Europe and spread over time to Japan and other regions. This led to major population shifts and transformed economic and social systems.
A6: 10.04 | B6: Imperialism | C6: IMPERIALISM | D6: Western European interactions with Africa and Asia shifted from limited regional contacts along the coast to greater influence and connections throughout these regions. Competing industrialized states sought to control and transport raw materials and create new markets across the world. | E6: Western European interactions with Africa and Asia shifted from limited regional contacts along the coast to greater influence and connections throughout these regions. Competing industrialized states sought to control and transport raw materials and create new markets across the world.
A7: 10.05 | B7: World Wars (1914-1945) | C7: UNRESOLVED GLOBAL CONFLICT (1914–1945) | D7: World War I and World War II led to geopolitical changes, human and environmental devastation, and attempts to bring stability and peace. | E7: World War I and World War II led to geopolitical changes, human and environmental devastation, and attempts to bring stability and peace.
A8: 10.06 | B8: Cold War (1945-1991) | C8: UNRESOLVED GLOBAL CONFLICT (1945–1991: THE COLD WAR) | D8: The second half of the 20th century was shaped by the Cold War, a legacy of World War II. The United States and the Soviet Union emerged as global superpowers engaged in ideological, political, economic, and military competition. | E8: The second half of the 20th century was shaped by the Cold War, a legacy of World War II. The United States and the Soviet Union emerged as global superpowers engaged in ideological, political, economic, and military competition.
A9: 10.07 | B9: Decolonization & Nationalism (1900's) | C9: DECOLONIZATION AND NATIONALISM (1900–2000) | D9: Nationalist and decolonization movements employed a variety of methods, including nonviolent resistance and armed struggle. Tensions and conflicts often continued after independence as new challenges arose. | E9: Nationalist and decolonization movements employed a variety of methods, including nonviolent resistance and armed struggle. Tensions and conflicts often continued after independence as new challenges arose.
A10: 10.08 | B10: Tradition vs Modernization | C10: TENSIONS BETWEEN TRADITIONAL CULTURES AND MODERNIZATION | D10: Tensions exist between traditional cultures and agents of modernization. Reactions for and against modernization depend on perspective and context. | E10: Tensions exist between traditional cultures and agents of modernization. Reactions for and against modernization depend on perspective and context.
A11: 10.09 | B11: Globalization & Environment | C11: GLOBALIZATION AND A CHANGING GLOBAL ENVIRONMENT (1990–PRESENT) | D11: Technological changes have resulted in a more interconnected world, affecting economic and political relations and in some cases leading to conflict and in others to efforts to cooperate. Globalization and population pressures have led to strains on the environment. | E11: Technological changes have resulted in a more interconnected world, affecting economic and political relations and in some cases leading to conflict and in others to efforts to cooperate. Globalization and population pressures have led to strains on the environment.
A12: 10.1 | B12: Human Rights Violations | C12: HUMAN RIGHTS VIOLATIONS | D12: Since the Holocaust, human rights violations have generated worldwide attention and concern. The United Nations Universal Declaration of Human Rights has provided a set of principles to guide efforts to protect threatened groups Page 27 Grades 9-12 and has served as a lens through which historical occurrences of oppression can be evaluated. | E12: Since the Holocaust, human rights violations have generated worldwide attention and concern. The United Nations Universal Declaration of Human Rights has provided a set of principles to guide efforts to protect threatened groups Page 27 Grades 9-12 and has served as a lens through which historical occurrences of oppression can be evaluated.
A13: 11.02 | B13: Constitutional Foundations (1763–1824) | C13: Growing political and economic tensions led the American colonists to declare their independence from Great Britain. Once independent, the new nation confronted the challenge of creating a stable federal republic. | D13: Growing political and economic tensions led the American colonists to declare their independence from Great Britain. Once independent, the new nation confronted the challenge of creating a stable federal republic.
A14: 10.01a | B14: Eurasian States and Empires ca. 1750 | C14: THE WORLD in 1750 | D14: Powerful Eurasian states and empires faced and responded to challenges ca. 1750. | E14: Powerful Eurasian states and empires faced and responded to challenges ca. 1750.
A15: 10.01a.1 | B15: Mughal & Ottoman (c. 1750) | C15: THE WORLD in 1750 | D15: Powerful Eurasian states and empires faced and responded to challenges ca. 1750. | E15: Students will compare and contrast the Mughal Empire and the Ottoman Empire in 1750 in terms of religious and ethnic tolerance, political organization, and commercial activity.
A16: 10.01a.2 | B16: Tokugawa Shogunate | C16: THE WORLD in 1750 | D16: Powerful Eurasian states and empires faced and responded to challenges ca. 1750. | E16: Students will examine efforts to unify, stabilize, and centralize Japan under the rule of the Tokugawa Shogunate.
A17: 10.01a.3 | B17: Comparing Tokugawa Shogunate & Bourbon Dynasty | C17: THE WORLD in 1750 | D17: Powerful Eurasian states and empires faced and responded to challenges ca. 1750. | E17: Students will compare and contrast the Tokugawa Shogunate in Japan with France under the rule of the Bourbon Dynasty, looking at the role of Edo and Paris/Versailles, attempts to control the daimyo and nobles, and the development of bureaucracies.
A18: 10.01b | B18: Interactions with Outsiders Eurasian States and Empire ca. 1750 | C18: THE WORLD in 1750 | D18: Perceptions of outsiders and interactions with them varied across Eurasia. | E18: Perceptions of outsiders and interactions with them varied across Eurasia.
A19: 10.01b.1 | B19: Tokugawa & Mughal Responses to Outsiders | C19: THE WORLD in 1750 | D19: Perceptions of outsiders and interactions with them varied across Eurasia. | E19: Students will compare and contrast the Tokugawa and Mughal responses to outsiders, with attention to the impacts of those decisions.
A20: 10.01b.2 | B20: Eurasia World Map | C20: THE WORLD in 1750 | D20: Perceptions of outsiders and interactions with them varied across Eurasia. | E20: Students will create a world map showing the extent of European maritime empires, the Russian Empire, the Ottoman Empire, Mughal Empire, China under the Qing Dynasty, Japan under the Tokugawa Shogunate, Ashanti, Benin, and Dahomey ca. 1750.
A21: 10.01b.3 | B21: Comparing Empire's Geography & Power | C21: THE WORLD in 1750 | D21: Perceptions of outsiders and interactions with them varied across Eurasia. | E21: Students will compare the size of these states, empires, and kingdoms relative to the power they wielded in their regions and in the world.
A22: 10.02a | B22: Political Philosophies | C22: ENLIGHTENMENT, REVOLUTION, AND NATIONALISM | D22: Enlightenment thinkers developed political philosophies based on natural laws, which included the concepts of social contract, consent of the governed, and the rights of citizens. | E22: Enlightenment thinkers developed political philosophies based on natural laws, which included the concepts of social contract, consent of the governed, and the rights of citizens.
A23: 10.02a.1 | B23: Political Philosophies | C23: ENLIGHTENMENT, REVOLUTION, AND NATIONALISM | D23: Enlightenment thinkers developed political philosophies based on natural laws, which included the concepts of social contract, consent of the governed, and the rights of citizens. | E23: Students will examine at least three Enlightenment thinkers, including John Locke, Baron de Montesquieu, and Jean-Jacques Rousseau, and key ideas from their written works.
A24: 10.02b | B24: Challenging Tradition | C24: ENLIGHTENMENT, REVOLUTION, AND NATIONALISM | D24: Individuals used Enlightenment ideals to challenge traditional beliefs and secure people’s rights in reform movements, such as women’s rights and abolition; some leaders may be considered enlightened despots. | E24: Individuals used Enlightenment ideals to challenge traditional beliefs and secure people’s rights in reform movements, such as women’s rights and abolition; some leaders may be considered enlightened despots.
A25: 10.02b.1 | B25: Gender & Abolition | C25: ENLIGHTENMENT, REVOLUTION, AND NATIONALISM | D25: Individuals used Enlightenment ideals to challenge traditional beliefs and secure people’s rights in reform movements, such as women’s rights and abolition; some leaders may be considered enlightened despots. | E25: Students will explore the influence of Enlightenment ideals on issues of gender and abolition by examining the ideas of individuals such as Mary Wollstonecraft and William Wilberforce.
