Workbook

Sheet Scores
A1: ID | B1: Grade | C1: Class | D1: ELL | E1: IEP | F1: MC | G1: SEQ | H1: IIIA | I1: IIIB | J1: Final | K1: 1 | L1: 2 | M1: 3 | N1: 4 | O1: 5 | P1: 6 | Q1: 7 | R1: 8 | S1: 9 | T1: 10 | U1: 11 | V1: 12 | W1: 13 | X1: 14 | Y1: 15 | Z1: 16 | AA1: 17 | AB1: 18 | AC1: 19 | AD1: 20 | AE1: 21 | AF1: 22 | AG1: 23 | AH1: 24 | AI1: 25 | AJ1: 26 | AK1: 27 | AL1: 28 | AM1: 29 | AN1: 30 | AO1: 31 | AP1: 32 | AQ1: 33 | AR1: 34 | AS1: 35 | AT1: 36 | AU1: 37 | AV1: Q1 | AW1: Q2 | AX1: Q3 | AY1: Q4 | AZ1: Q5 | BA1: Q6 | BB1: Q7 | BC1: Q8 | BD1: Q9 | BE1: Q10 | BF1: Q11 | BG1: Q12 | BH1: Q13 | BI1: Q14 | BJ1: Q15 | BK1: Q16 | BL1: Q17 | BM1: Q18 | BN1: Q19 | BO1: Q20 | BP1: Q21 | BQ1: Q22 | BR1: Q23 | BS1: Q24 | BT1: Q25 | BU1: Q26 | BV1: Q27 | BW1: Q28 | BX1: Passed? | BY1: Passed*
A2: 1 | B2: 11 | C2: Dushin | D2: FALSE | E2: FALSE | F2: =SUM(Scores[[#This Row],[Q1]:[Q28]]) -> 21 | G2: =SUM(Scores[[#This Row],[29]]:Scores[[#This Row],[30]]) -> 6 | H2: =SUM(Scores[[#This Row],[31]:[36]]) -> 4 | I2: =Scores[[#This Row],[37]] -> 1 | J2: =INDEX('Conversion Chart'!$C$3:$M$47,MATCH(SUM(Scores[[#This Row],[MC]:[IIIA]]),'Conversion Chart'!$B$3:$B$47),MATCH(Scores[[#This Row],[IIIB]],'Conversion Chart'!$C$2:$M$2)) -> 71 | K2: 4 | L2: 2 | N2: 3 | O2: 1 | P2: 4 | Q2: 3 | R2: 1 | S2: 1 | T2: 1 | U2: 2 | V2: 4 | W2: 2 | X2: 4 | Y2: 3 | Z2: 1 | AA2: 1 | AB2: 4 | AC2: 3 | AD2: 4 | AE2: 3 | AF2: 4 | AG2: 3 | AH2: 1 | AI2: 1 | AJ2: 4 | AK2: 4 | AL2: 3 | AM2: 3 | AN2: 3 | AO2: 0 | AP2: 1 | AQ2: 1 | AR2: 0 | AS2: 1 | AT2: 1 | AU2: 1 | AV2: =IF(K2=VLOOKUP(VALUE(K$1),Questions!$A:$E,5,FALSE),1,0) -> 1 | AW2: =IF(L2=VLOOKUP(VALUE(L$1),Questions!$A:$E,5,FALSE),1,0) -> 1 | AX2: =IF(M2=VLOOKUP(VALUE(M$1),Questions!$A:$E,5,FALSE),1,0) -> 0 | AY2: =IF(N2=VLOOKUP(VALUE(N$1),Questions!$A:$E,5,FALSE),1,0) -> 1 | AZ2: =IF(O2=VLOOKUP(VALUE(O$1),Questions!$A:$E,5,FALSE),1,0) -> 1 | BA2: =IF(P2=VLOOKUP(VALUE(P$1),Questions!$A:$E,5,FALSE),1,0) -> 1 | BB2: =IF(Q2=VLOOKUP(VALUE(Q$1),Questions!$A:$E,5,FALSE),1,0) -> 1 | BC2: =IF(R2=VLOOKUP(VALUE(R$1),Questions!$A:$E,5,FALSE),1,0) -> 0 | ... BW2: =IF(AL2=VLOOKUP(VALUE(AL$1),Questions!$A:$E,5,FALSE),1,0) -> 1 | BX2: =IF(Scores[[#This Row],[Final]]>=65,1,0) -> 1 | BY2: =IF(Scores[[#This Row],[Final]]>=IF(Scores[[#This Row],[IEP]],55,65),1,0) -> 1
A3: 2 | B3: 11 | C3: Kovelsky | D3: FALSE | E3: TRUE | F3: =SUM(Scores[[#This Row],[Q1]:[Q28]]) -> 13 | G3: =SUM(Scores[[#This Row],[29]]:Scores[[#This Row],[30]]) -> 4 | H3: =SUM(Scores[[#This Row],[31]:[36]]) -> 6 | I3: =Scores[[#This Row],[37]] -> 1 | J3: =INDEX('Conversion Chart'!$C$3:$M$47,MATCH(SUM(Scores[[#This Row],[MC]:[IIIA]]),'Conversion Chart'!$B$3:$B$47),MATCH(Scores[[#This Row],[IIIB]],'Conversion Chart'!$C$2:$M$2)) -> 61 | K3: 1 | L3: 3 | M3: 3 | N3: 1 | O3: 1 | P3: 3 | Q3: 2 | R3: 2 | S3: 2 | T3: 1 | U3: 2 | V3: 3 | W3: 2 | X3: 3 | Y3: 2 | Z3: 3 | AA3: 3 | AB3: 1 | AC3: 3 | AD3: 2 | AE3: 3 | AF3: 2 | AG3: 3 | AH3: 4 | AI3: 1 | AJ3: 1 | AK3: 1 | AL3: 3 | AM3: 2 | AN3: 2 | AO3: 1 | AP3: 1 | AQ3: 1 | AR3: 1 | AS3: 1 | AT3: 1 | AU3: 1 | AV3: =IF(K3=VLOOKUP(VALUE(K$1),Questions!$A:$E,5,FALSE),1,0) -> 0 | AW3: =IF(L3=VLOOKUP(VALUE(L$1),Questions!$A:$E,5,FALSE),1,0) -> 0 | AX3: =IF(M3=VLOOKUP(VALUE(M$1),Questions!$A:$E,5,FALSE),1,0) -> 1 | AY3: =IF(N3=VLOOKUP(VALUE(N$1),Questions!$A:$E,5,FALSE),1,0) -> 0 | AZ3: =IF(O3=VLOOKUP(VALUE(O$1),Questions!$A:$E,5,FALSE),1,0) -> 1 | BA3: =IF(P3=VLOOKUP(VALUE(P$1),Questions!$A:$E,5,FALSE),1,0) -> 0 | BB3: =IF(Q3=VLOOKUP(VALUE(Q$1),Questions!$A:$E,5,FALSE),1,0) -> 0 | BC3: =IF(R3=VLOOKUP(VALUE(R$1),Questions!$A:$E,5,FALSE),1,0) -> 1 | ... BW3: =IF(AL3=VLOOKUP(VALUE(AL$1),Questions!$A:$E,5,FALSE),1,0) -> 1 | BX3: =IF(Scores[[#This Row],[Final]]>=65,1,0) -> 0 | BY3: =IF(Scores[[#This Row],[Final]]>=IF(Scores[[#This Row],[IEP]],55,65),1,0) -> 1
A4: 3 | B4: 9 | C4: Kovelsky | D4: FALSE | E4: FALSE | F4: =SUM(Scores[[#This Row],[Q1]:[Q28]]) -> 0 | G4: =SUM(Scores[[#This Row],[29]]:Scores[[#This Row],[30]]) -> 0 | H4: =SUM(Scores[[#This Row],[31]:[36]]) -> 0 | I4: =Scores[[#This Row],[37]] -> 0 | J4: =INDEX('Conversion Chart'!$C$3:$M$47,MATCH(SUM(Scores[[#This Row],[MC]:[IIIA]]),'Conversion Chart'!$B$3:$B$47),MATCH(Scores[[#This Row],[IIIB]],'Conversion Chart'!$C$2:$M$2)) -> 0 | AV4: =IF(K4=VLOOKUP(VALUE(K$1),Questions!$A:$E,5,FALSE),1,0) -> 0 | AW4: =IF(L4=VLOOKUP(VALUE(L$1),Questions!$A:$E,5,FALSE),1,0) -> 0 | AX4: =IF(M4=VLOOKUP(VALUE(M$1),Questions!$A:$E,5,FALSE),1,0) -> 0 | AY4: =IF(N4=VLOOKUP(VALUE(N$1),Questions!$A:$E,5,FALSE),1,0) -> 0 | AZ4: =IF(O4=VLOOKUP(VALUE(O$1),Questions!$A:$E,5,FALSE),1,0) -> 0 | BA4: =IF(P4=VLOOKUP(VALUE(P$1),Questions!$A:$E,5,FALSE),1,0) -> 0 | BB4: =IF(Q4=VLOOKUP(VALUE(Q$1),Questions!$A:$E,5,FALSE),1,0) -> 0 | BC4: =IF(R4=VLOOKUP(VALUE(R$1),Questions!$A:$E,5,FALSE),1,0) -> 0 | ... BW4: =IF(AL4=VLOOKUP(VALUE(AL$1),Questions!$A:$E,5,FALSE),1,0) -> 0 | BX4: =IF(Scores[[#This Row],[Final]]>=65,1,0) -> 0 | BY4: =IF(Scores[[#This Row],[Final]]>=IF(Scores[[#This Row],[IEP]],55,65),1,0) -> 0
A5: 4 | B5: 9 | C5: Kovelsky | D5: FALSE | E5: FALSE | F5: =SUM(Scores[[#This Row],[Q1]:[Q28]]) -> 8 | G5: =SUM(Scores[[#This Row],[29]]:Scores[[#This Row],[30]]) -> 0 | H5: =SUM(Scores[[#This Row],[31]:[36]]) -> 6 | I5: =Scores[[#This Row],[37]] -> 0 | J5: =INDEX('Conversion Chart'!$C$3:$M$47,MATCH(SUM(Scores[[#This Row],[MC]:[IIIA]]),'Conversion Chart'!$B$3:$B$47),MATCH(Scores[[#This Row],[IIIB]],'Conversion Chart'!$C$2:$M$2)) -> 40 | K5: 2 | L5: 1 | M5: 3 | N5: 1 | O5: 1 | P5: 4 | Q5: 2 | R5: 3 | S5: 2 | T5: 1 | U5: 3 | V5: 1 | W5: 4 | X5: 2 | Y5: 1 | Z5: 2 | AA5: 2 | AB5: 4 | AC5: 3 | AD5: 4 | AE5: 1 | AF5: 3 | AG5: 2 | AH5: 1 | AI5: 4 | AJ5: 2 | AK5: 4 | AL5: 1 | AM5: 0 | AN5: 0 | AO5: 1 | AP5: 1 | AQ5: 1 | AR5: 1 | AS5: 1 | AT5: 1 | AU5: 0 | AV5: =IF(K5=VLOOKUP(VALUE(K$1),Questions!$A:$E,5,FALSE),1,0) -> 0 | AW5: =IF(L5=VLOOKUP(VALUE(L$1),Questions!$A:$E,5,FALSE),1,0) -> 0 | AX5: =IF(M5=VLOOKUP(VALUE(M$1),Questions!$A:$E,5,FALSE),1,0) -> 1 | AY5: =IF(N5=VLOOKUP(VALUE(N$1),Questions!$A:$E,5,FALSE),1,0) -> 0 | AZ5: =IF(O5=VLOOKUP(VALUE(O$1),Questions!$A:$E,5,FALSE),1,0) -> 1 | BA5: =IF(P5=VLOOKUP(VALUE(P$1),Questions!$A:$E,5,FALSE),1,0) -> 1 | BB5: =IF(Q5=VLOOKUP(VALUE(Q$1),Questions!$A:$E,5,FALSE),1,0) -> 0 | BC5: =IF(R5=VLOOKUP(VALUE(R$1),Questions!$A:$E,5,FALSE),1,0) -> 0 | ... BW5: =IF(AL5=VLOOKUP(VALUE(AL$1),Questions!$A:$E,5,FALSE),1,0) -> 0 | BX5: =IF(Scores[[#This Row],[Final]]>=65,1,0) -> 0 | BY5: =IF(Scores[[#This Row],[Final]]>=IF(Scores[[#This Row],[IEP]],55,65),1,0) -> 0
A6: 5 | B6: 11 | C6: Dushin | D6: FALSE | E6: FALSE | F6: =SUM(Scores[[#This Row],[Q1]:[Q28]]) -> 21 | G6: =SUM(Scores[[#This Row],[29]]:Scores[[#This Row],[30]]) -> 6 | H6: =SUM(Scores[[#This Row],[31]:[36]]) -> 6 | I6: =Scores[[#This Row],[37]] -> 3 | J6: =INDEX('Conversion Chart'!$C$3:$M$47,MATCH(SUM(Scores[[#This Row],[MC]:[IIIA]]),'Conversion Chart'!$B$3:$B$47),MATCH(Scores[[#This Row],[IIIB]],'Conversion Chart'!$C$2:$M$2)) -> 79 | K6: 4 | L6: 2 | M6: 3 | N6: 3 | O6: 1 | P6: 2 | Q6: 3 | R6: 2 | S6: 2 | T6: 1 | U6: 2 | V6: 4 | W6: 2 | X6: 4 | Y6: 1 | Z6: 2 | AA6: 1 | AB6: 4 | AC6: 2 | AD6: 4 | AE6: 2 | AF6: 2 | AG6: 3 | AH6: 3 | AI6: 3 | AJ6: 4 | AK6: 4 | AL6: 2 | AM6: 3 | AN6: 3 | AO6: 1 | AP6: 1 | AQ6: 1 | AR6: 1 | AS6: 1 | AT6: 1 | AU6: 3 | AV6: =IF(K6=VLOOKUP(VALUE(K$1),Questions!$A:$E,5,FALSE),1,0) -> 1 | AW6: =IF(L6=VLOOKUP(VALUE(L$1),Questions!$A:$E,5,FALSE),1,0) -> 1 | AX6: =IF(M6=VLOOKUP(VALUE(M$1),Questions!$A:$E,5,FALSE),1,0) -> 1 | AY6: =IF(N6=VLOOKUP(VALUE(N$1),Questions!$A:$E,5,FALSE),1,0) -> 1 | AZ6: =IF(O6=VLOOKUP(VALUE(O$1),Questions!$A:$E,5,FALSE),1,0) -> 1 | BA6: =IF(P6=VLOOKUP(VALUE(P$1),Questions!$A:$E,5,FALSE),1,0) -> 0 | BB6: =IF(Q6=VLOOKUP(VALUE(Q$1),Questions!$A:$E,5,FALSE),1,0) -> 1 | BC6: =IF(R6=VLOOKUP(VALUE(R$1),Questions!$A:$E,5,FALSE),1,0) -> 1 | ... BW6: =IF(AL6=VLOOKUP(VALUE(AL$1),Questions!$A:$E,5,FALSE),1,0) -> 0 | BX6: =IF(Scores[[#This Row],[Final]]>=65,1,0) -> 1 | BY6: =IF(Scores[[#This Row],[Final]]>=IF(Scores[[#This Row],[IEP]],55,65),1,0) -> 1
A7: 6 | B7: 11 | C7: Dushin | D7: FALSE | E7: FALSE | F7: =SUM(Scores[[#This Row],[Q1]:[Q28]]) -> 15 | G7: =SUM(Scores[[#This Row],[29]]:Scores[[#This Row],[30]]) -> 3 | H7: =SUM(Scores[[#This Row],[31]:[36]]) -> 6 | I7: =Scores[[#This Row],[37]] -> 2 | J7: =INDEX('Conversion Chart'!$C$3:$M$47,MATCH(SUM(Scores[[#This Row],[MC]:[IIIA]]),'Conversion Chart'!$B$3:$B$47),MATCH(Scores[[#This Row],[IIIB]],'Conversion Chart'!$C$2:$M$2)) -> 67 | K7: 4 | L7: 3 | M7: 3 | N7: 1 | O7: 1 | P7: 2 | Q7: 1 | R7: 4 | S7: 3 | T7: 1 | U7: 3 | V7: 4 | W7: 1 | X7: 4 | Y7: 3 | Z7: 1 | AA7: 1 | AB7: 4 | AC7: 3 | AD7: 3 | AE7: 1 | AF7: 2 | AG7: 3 | AH7: 2 | AI7: 3 | AJ7: 4 | AK7: 4 | AL7: 3 | AM7: 2 | AN7: 1 | AO7: 1 | AP7: 1 | AQ7: 1 | AR7: 1 | AS7: 1 | AT7: 1 | AU7: 2 | AV7: =IF(K7=VLOOKUP(VALUE(K$1),Questions!$A:$E,5,FALSE),1,0) -> 1 | AW7: =IF(L7=VLOOKUP(VALUE(L$1),Questions!$A:$E,5,FALSE),1,0) -> 0 | AX7: =IF(M7=VLOOKUP(VALUE(M$1),Questions!$A:$E,5,FALSE),1,0) -> 1 | AY7: =IF(N7=VLOOKUP(VALUE(N$1),Questions!$A:$E,5,FALSE),1,0) -> 0 | AZ7: =IF(O7=VLOOKUP(VALUE(O$1),Questions!$A:$E,5,FALSE),1,0) -> 1 | BA7: =IF(P7=VLOOKUP(VALUE(P$1),Questions!$A:$E,5,FALSE),1,0) -> 0 | BB7: =IF(Q7=VLOOKUP(VALUE(Q$1),Questions!$A:$E,5,FALSE),1,0) -> 0 | BC7: =IF(R7=VLOOKUP(VALUE(R$1),Questions!$A:$E,5,FALSE),1,0) -> 0 | ... BW7: =IF(AL7=VLOOKUP(VALUE(AL$1),Questions!$A:$E,5,FALSE),1,0) -> 1 | BX7: =IF(Scores[[#This Row],[Final]]>=65,1,0) -> 1 | BY7: =IF(Scores[[#This Row],[Final]]>=IF(Scores[[#This Row],[IEP]],55,65),1,0) -> 1
A8: 7 | B8: 11 | C8: Antaky | D8: FALSE | E8: FALSE | F8: =SUM(Scores[[#This Row],[Q1]:[Q28]]) -> 25 | G8: =SUM(Scores[[#This Row],[29]]:Scores[[#This Row],[30]]) -> 6 | H8: =SUM(Scores[[#This Row],[31]:[36]]) -> 6 | I8: =Scores[[#This Row],[37]] -> 4 | J8: =INDEX('Conversion Chart'!$C$3:$M$47,MATCH(SUM(Scores[[#This Row],[MC]:[IIIA]]),'Conversion Chart'!$B$3:$B$47),MATCH(Scores[[#This Row],[IIIB]],'Conversion Chart'!$C$2:$M$2)) -> 86 | K8: 4 | L8: 1 | M8: 3 | N8: 3 | O8: 1 | P8: 4 | Q8: 3 | R8: 2 | S8: 2 | T8: 1 | U8: 2 | V8: 4 | W8: 2 | X8: 4 | Y8: 3 | Z8: 1 | AA8: 1 | AB8: 4 | AC8: 3 | AD8: 1 | AE8: 2 | AF8: 2 | AG8: 3 | AH8: 2 | AI8: 1 | AJ8: 4 | AK8: 1 | AL8: 3 | AM8: 3 | AN8: 3 | AO8: 1 | AP8: 1 | AQ8: 1 | AR8: 1 | AS8: 1 | AT8: 1 | AU8: 4 | AV8: =IF(K8=VLOOKUP(VALUE(K$1),Questions!$A:$E,5,FALSE),1,0) -> 1 | AW8: =IF(L8=VLOOKUP(VALUE(L$1),Questions!$A:$E,5,FALSE),1,0) -> 0 | AX8: =IF(M8=VLOOKUP(VALUE(M$1),Questions!$A:$E,5,FALSE),1,0) -> 1 | AY8: =IF(N8=VLOOKUP(VALUE(N$1),Questions!$A:$E,5,FALSE),1,0) -> 1 | AZ8: =IF(O8=VLOOKUP(VALUE(O$1),Questions!$A:$E,5,FALSE),1,0) -> 1 | BA8: =IF(P8=VLOOKUP(VALUE(P$1),Questions!$A:$E,5,FALSE),1,0) -> 1 | BB8: =IF(Q8=VLOOKUP(VALUE(Q$1),Questions!$A:$E,5,FALSE),1,0) -> 1 | BC8: =IF(R8=VLOOKUP(VALUE(R$1),Questions!$A:$E,5,FALSE),1,0) -> 1 | ... BW8: =IF(AL8=VLOOKUP(VALUE(AL$1),Questions!$A:$E,5,FALSE),1,0) -> 1 | BX8: =IF(Scores[[#This Row],[Final]]>=65,1,0) -> 1 | BY8: =IF(Scores[[#This Row],[Final]]>=IF(Scores[[#This Row],[IEP]],55,65),1,0) -> 1
A9: 8 | B9: 9 | C9: Bermejo | D9: FALSE | E9: FALSE | F9: =SUM(Scores[[#This Row],[Q1]:[Q28]]) -> 21 | G9: =SUM(Scores[[#This Row],[29]]:Scores[[#This Row],[30]]) -> 6 | H9: =SUM(Scores[[#This Row],[31]:[36]]) -> 6 | I9: =Scores[[#This Row],[37]] -> 2 | J9: =INDEX('Conversion Chart'!$C$3:$M$47,MATCH(SUM(Scores[[#This Row],[MC]:[IIIA]]),'Conversion Chart'!$B$3:$B$47),MATCH(Scores[[#This Row],[IIIB]],'Conversion Chart'!$C$2:$M$2)) -> 77 | K9: 3 | L9: 1 | M9: 3 | N9: 3 | O9: 1 | P9: 2 | Q9: 3 | R9: 2 | S9: 2 | T9: 1 | U9: 2 | V9: 4 | W9: 2 | X9: 4 | Y9: 3 | Z9: 1 | AA9: 1 | AB9: 4 | AC9: 3 | AD9: 1 | AE9: 2 | AF9: 2 | AG9: 3 | AH9: 2 | AI9: 3 | AJ9: 4 | AK9: 4 | AL9: 3 | AM9: 3 | AN9: 3 | AO9: 1 | AP9: 1 | AQ9: 1 | AR9: 1 | AS9: 1 | AT9: 1 | AU9: 2 | AV9: =IF(K9=VLOOKUP(VALUE(K$1),Questions!$A:$E,5,FALSE),1,0) -> 0 | AW9: =IF(L9=VLOOKUP(VALUE(L$1),Questions!$A:$E,5,FALSE),1,0) -> 0 | AX9: =IF(M9=VLOOKUP(VALUE(M$1),Questions!$A:$E,5,FALSE),1,0) -> 1 | AY9: =IF(N9=VLOOKUP(VALUE(N$1),Questions!$A:$E,5,FALSE),1,0) -> 1 | AZ9: =IF(O9=VLOOKUP(VALUE(O$1),Questions!$A:$E,5,FALSE),1,0) -> 1 | BA9: =IF(P9=VLOOKUP(VALUE(P$1),Questions!$A:$E,5,FALSE),1,0) -> 0 | BB9: =IF(Q9=VLOOKUP(VALUE(Q$1),Questions!$A:$E,5,FALSE),1,0) -> 1 | BC9: =IF(R9=VLOOKUP(VALUE(R$1),Questions!$A:$E,5,FALSE),1,0) -> 1 | ... BW9: =IF(AL9=VLOOKUP(VALUE(AL$1),Questions!$A:$E,5,FALSE),1,0) -> 1 | BX9: =IF(Scores[[#This Row],[Final]]>=65,1,0) -> 1 | BY9: =IF(Scores[[#This Row],[Final]]>=IF(Scores[[#This Row],[IEP]],55,65),1,0) -> 1
A10: 9 | B10: 11 | C10: Antaky | D10: FALSE | E10: FALSE | F10: =SUM(Scores[[#This Row],[Q1]:[Q28]]) -> 22 | G10: =SUM(Scores[[#This Row],[29]]:Scores[[#This Row],[30]]) -> 6 | H10: =SUM(Scores[[#This Row],[31]:[36]]) -> 6 | I10: =Scores[[#This Row],[37]] -> 2 | J10: =INDEX('Conversion Chart'!$C$3:$M$47,MATCH(SUM(Scores[[#This Row],[MC]:[IIIA]]),'Conversion Chart'!$B$3:$B$47),MATCH(Scores[[#This Row],[IIIB]],'Conversion Chart'!$C$2:$M$2)) -> 77 | K10: 4 | L10: 2 | M10: 4 | N10: 3 | O10: 1 | P10: 4 | Q10: 3 | R10: 3 | S10: 2 | T10: 1 | U10: 2 | V10: 4 | W10: 1 | X10: 4 | Y10: 3 | Z10: 1 | AA10: 1 | AB10: 4 | AC10: 3 | AD10: 1 | AE10: 3 | AF10: 2 | AG10: 3 | AH10: 2 | AI10: 1 | AJ10: 4 | AK10: 1 | AL10: 3 | AM10: 3 | AN10: 3 | AO10: 1 | AP10: 1 | AQ10: 1 | AR10: 1 | AS10: 1 | AT10: 1 | AU10: 2 | AV10: =IF(K10=VLOOKUP(VALUE(K$1),Questions!$A:$E,5,FALSE),1,0) -> 1 | AW10: =IF(L10=VLOOKUP(VALUE(L$1),Questions!$A:$E,5,FALSE),1,0) -> 1 | AX10: =IF(M10=VLOOKUP(VALUE(M$1),Questions!$A:$E,5,FALSE),1,0) -> 0 | AY10: =IF(N10=VLOOKUP(VALUE(N$1),Questions!$A:$E,5,FALSE),1,0) -> 1 | AZ10: =IF(O10=VLOOKUP(VALUE(O$1),Questions!$A:$E,5,FALSE),1,0) -> 1 | BA10: =IF(P10=VLOOKUP(VALUE(P$1),Questions!$A:$E,5,FALSE),1,0) -> 1 | BB10: =IF(Q10=VLOOKUP(VALUE(Q$1),Questions!$A:$E,5,FALSE),1,0) -> 1 | BC10: =IF(R10=VLOOKUP(VALUE(R$1),Questions!$A:$E,5,FALSE),1,0) -> 0 | ... BW10: =IF(AL10=VLOOKUP(VALUE(AL$1),Questions!$A:$E,5,FALSE),1,0) -> 1 | BX10: =IF(Scores[[#This Row],[Final]]>=65,1,0) -> 1 | BY10: =IF(Scores[[#This Row],[Final]]>=IF(Scores[[#This Row],[IEP]],55,65),1,0) -> 1
A11: 10 | B11: 9 | C11: Bermejo | D11: FALSE | E11: FALSE | F11: =SUM(Scores[[#This Row],[Q1]:[Q28]]) -> 0 | G11: =SUM(Scores[[#This Row],[29]]:Scores[[#This Row],[30]]) -> 0 | H11: =SUM(Scores[[#This Row],[31]:[36]]) -> 0 | I11: =Scores[[#This Row],[37]] -> 0 | J11: =INDEX('Conversion Chart'!$C$3:$M$47,MATCH(SUM(Scores[[#This Row],[MC]:[IIIA]]),'Conversion Chart'!$B$3:$B$47),MATCH(Scores[[#This Row],[IIIB]],'Conversion Chart'!$C$2:$M$2)) -> 0 | AV11: =IF(K11=VLOOKUP(VALUE(K$1),Questions!$A:$E,5,FALSE),1,0) -> 0 | AW11: =IF(L11=VLOOKUP(VALUE(L$1),Questions!$A:$E,5,FALSE),1,0) -> 0 | AX11: =IF(M11=VLOOKUP(VALUE(M$1),Questions!$A:$E,5,FALSE),1,0) -> 0 | AY11: =IF(N11=VLOOKUP(VALUE(N$1),Questions!$A:$E,5,FALSE),1,0) -> 0 | AZ11: =IF(O11=VLOOKUP(VALUE(O$1),Questions!$A:$E,5,FALSE),1,0) -> 0 | BA11: =IF(P11=VLOOKUP(VALUE(P$1),Questions!$A:$E,5,FALSE),1,0) -> 0 | BB11: =IF(Q11=VLOOKUP(VALUE(Q$1),Questions!$A:$E,5,FALSE),1,0) -> 0 | BC11: =IF(R11=VLOOKUP(VALUE(R$1),Questions!$A:$E,5,FALSE),1,0) -> 0 | ... BW11: =IF(AL11=VLOOKUP(VALUE(AL$1),Questions!$A:$E,5,FALSE),1,0) -> 0 | BX11: =IF(Scores[[#This Row],[Final]]>=65,1,0) -> 0 | BY11: =IF(Scores[[#This Row],[Final]]>=IF(Scores[[#This Row],[IEP]],55,65),1,0) -> 0
A12: 11 | B12: 9 | C12: Kovelsky | D12: FALSE | E12: TRUE | F12: =SUM(Scores[[#This Row],[Q1]:[Q28]]) -> 8 | G12: =SUM(Scores[[#This Row],[29]]:Scores[[#This Row],[30]]) -> 5 | H12: =SUM(Scores[[#This Row],[31]:[36]]) -> 6 | I12: =Scores[[#This Row],[37]] -> 1 | J12: =INDEX('Conversion Chart'!$C$3:$M$47,MATCH(SUM(Scores[[#This Row],[MC]:[IIIA]]),'Conversion Chart'!$B$3:$B$47),MATCH(Scores[[#This Row],[IIIB]],'Conversion Chart'!$C$2:$M$2)) -> 55 | K12: 4 | L12: 1 | M12: 3 | N12: 2 | O12: 4 | P12: 2 | Q12: 3 | R12: 2 | S12: 3 | T12: 1 | U12: 4 | V12: 2 | W12: 2 | X12: 3 | Y12: 1 | Z12: 4 | AA12: 1 | AB12: 4 | AC12: 2 | AD12: 3 | AE12: 1 | AF12: 4 | AG12: 4 | AH12: 2 | AI12: 3 | AJ12: 1 | AK12: 4 | AL12: 4 | AM12: 3 | AN12: 2 | AO12: 1 | AP12: 1 | AQ12: 1 | AR12: 1 | AS12: 1 | AT12: 1 | AU12: 1 | AV12: =IF(K12=VLOOKUP(VALUE(K$1),Questions!$A:$E,5,FALSE),1,0) -> 1 | AW12: =IF(L12=VLOOKUP(VALUE(L$1),Questions!$A:$E,5,FALSE),1,0) -> 0 | AX12: =IF(M12=VLOOKUP(VALUE(M$1),Questions!$A:$E,5,FALSE),1,0) -> 1 | AY12: =IF(N12=VLOOKUP(VALUE(N$1),Questions!$A:$E,5,FALSE),1,0) -> 0 | AZ12: =IF(O12=VLOOKUP(VALUE(O$1),Questions!$A:$E,5,FALSE),1,0) -> 0 | BA12: =IF(P12=VLOOKUP(VALUE(P$1),Questions!$A:$E,5,FALSE),1,0) -> 0 | BB12: =IF(Q12=VLOOKUP(VALUE(Q$1),Questions!$A:$E,5,FALSE),1,0) -> 1 | BC12: =IF(R12=VLOOKUP(VALUE(R$1),Questions!$A:$E,5,FALSE),1,0) -> 1 | ... BW12: =IF(AL12=VLOOKUP(VALUE(AL$1),Questions!$A:$E,5,FALSE),1,0) -> 0 | BX12: =IF(Scores[[#This Row],[Final]]>=65,1,0) -> 0 | BY12: =IF(Scores[[#This Row],[Final]]>=IF(Scores[[#This Row],[IEP]],55,65),1,0) -> 1
A13: 12 | B13: 11 | C13: Antaky | D13: FALSE | E13: FALSE | F13: =SUM(Scores[[#This Row],[Q1]:[Q28]]) -> 15 | G13: =SUM(Scores[[#This Row],[29]]:Scores[[#This Row],[30]]) -> 4 | H13: =SUM(Scores[[#This Row],[31]:[36]]) -> 6 | I13: =Scores[[#This Row],[37]] -> 2 | J13: =INDEX('Conversion Chart'!$C$3:$M$47,MATCH(SUM(Scores[[#This Row],[MC]:[IIIA]]),'Conversion Chart'!$B$3:$B$47),MATCH(Scores[[#This Row],[IIIB]],'Conversion Chart'!$C$2:$M$2)) -> 68 | K13: 4 | L13: 2 | M13: 3 | N13: 3 | O13: 2 | P13: 2 | Q13: 2 | R13: 2 | S13: 3 | T13: 1 | U13: 2 | V13: 3 | W13: 2 | X13: 4 | Y13: 3 | Z13: 1 | AA13: 4 | AB13: 4 | AC13: 1 | AD13: 2 | AE13: 1 | AF13: 2 | AG13: 3 | AH13: 1 | AI13: 4 | AJ13: 4 | AK13: 3 | AL13: 2 | AM13: 2 | AN13: 2 | AO13: 1 | AP13: 1 | AQ13: 1 | AR13: 1 | AS13: 1 | AT13: 1 | AU13: 2 | AV13: =IF(K13=VLOOKUP(VALUE(K$1),Questions!$A:$E,5,FALSE),1,0) -> 1 | AW13: =IF(L13=VLOOKUP(VALUE(L$1),Questions!$A:$E,5,FALSE),1,0) -> 1 | AX13: =IF(M13=VLOOKUP(VALUE(M$1),Questions!$A:$E,5,FALSE),1,0) -> 1 | AY13: =IF(N13=VLOOKUP(VALUE(N$1),Questions!$A:$E,5,FALSE),1,0) -> 1 | AZ13: =IF(O13=VLOOKUP(VALUE(O$1),Questions!$A:$E,5,FALSE),1,0) -> 0 | BA13: =IF(P13=VLOOKUP(VALUE(P$1),Questions!$A:$E,5,FALSE),1,0) -> 0 | BB13: =IF(Q13=VLOOKUP(VALUE(Q$1),Questions!$A:$E,5,FALSE),1,0) -> 0 | BC13: =IF(R13=VLOOKUP(VALUE(R$1),Questions!$A:$E,5,FALSE),1,0) -> 1 | ... BW13: =IF(AL13=VLOOKUP(VALUE(AL$1),Questions!$A:$E,5,FALSE),1,0) -> 0 | BX13: =IF(Scores[[#This Row],[Final]]>=65,1,0) -> 1 | BY13: =IF(Scores[[#This Row],[Final]]>=IF(Scores[[#This Row],[IEP]],55,65),1,0) -> 1
A14: 13 | B14: 11 | C14: Dushin | D14: FALSE | E14: TRUE | F14: =SUM(Scores[[#This Row],[Q1]:[Q28]]) -> 10 | G14: =SUM(Scores[[#This Row],[29]]:Scores[[#This Row],[30]]) -> 4 | H14: =SUM(Scores[[#This Row],[31]:[36]]) -> 5 | I14: =Scores[[#This Row],[37]] -> 2 | J14: =INDEX('Conversion Chart'!$C$3:$M$47,MATCH(SUM(Scores[[#This Row],[MC]:[IIIA]]),'Conversion Chart'!$B$3:$B$47),MATCH(Scores[[#This Row],[IIIB]],'Conversion Chart'!$C$2:$M$2)) -> 60 | K14: 3 | L14: 1 | M14: 1 | N14: 2 | O14: 1 | P14: 1 | Q14: 4 | R14: 2 | S14: 2 | T14: 3 | U14: 1 | V14: 3 | W14: 4 | X14: 3 | Y14: 2 | Z14: 3 | AA14: 1 | AB14: 4 | AC14: 2 | AD14: 3 | AE14: 3 | AF14: 2 | AG14: 3 | AH14: 3 | AI14: 4 | AJ14: 4 | AK14: 1 | AL14: 4 | AM14: 2 | AN14: 2 | AO14: 1 | AP14: 1 | AQ14: 1 | AR14: 0 | AS14: 1 | AT14: 1 | AU14: 2 | AV14: =IF(K14=VLOOKUP(VALUE(K$1),Questions!$A:$E,5,FALSE),1,0) -> 0 | AW14: =IF(L14=VLOOKUP(VALUE(L$1),Questions!$A:$E,5,FALSE),1,0) -> 0 | AX14: =IF(M14=VLOOKUP(VALUE(M$1),Questions!$A:$E,5,FALSE),1,0) -> 0 | AY14: =IF(N14=VLOOKUP(VALUE(N$1),Questions!$A:$E,5,FALSE),1,0) -> 0 | AZ14: =IF(O14=VLOOKUP(VALUE(O$1),Questions!$A:$E,5,FALSE),1,0) -> 1 | BA14: =IF(P14=VLOOKUP(VALUE(P$1),Questions!$A:$E,5,FALSE),1,0) -> 0 | BB14: =IF(Q14=VLOOKUP(VALUE(Q$1),Questions!$A:$E,5,FALSE),1,0) -> 0 | BC14: =IF(R14=VLOOKUP(VALUE(R$1),Questions!$A:$E,5,FALSE),1,0) -> 1 | ... BW14: =IF(AL14=VLOOKUP(VALUE(AL$1),Questions!$A:$E,5,FALSE),1,0) -> 0 | BX14: =IF(Scores[[#This Row],[Final]]>=65,1,0) -> 0 | BY14: =IF(Scores[[#This Row],[Final]]>=IF(Scores[[#This Row],[IEP]],55,65),1,0) -> 1
A15: 14 | B15: 9 | C15: Bermejo | D15: FALSE | E15: FALSE | F15: =SUM(Scores[[#This Row],[Q1]:[Q28]]) -> 11 | G15: =SUM(Scores[[#This Row],[29]]:Scores[[#This Row],[30]]) -> 3 | H15: =SUM(Scores[[#This Row],[31]:[36]]) -> 5 | I15: =Scores[[#This Row],[37]] -> 1 | J15: =INDEX('Conversion Chart'!$C$3:$M$47,MATCH(SUM(Scores[[#This Row],[MC]:[IIIA]]),'Conversion Chart'!$B$3:$B$47),MATCH(Scores[[#This Row],[IIIB]],'Conversion Chart'!$C$2:$M$2)) -> 55 | K15: 4 | L15: 1 | M15: 3 | N15: 1 | O15: 1 | P15: 2 | Q15: 1 | R15: 2 | S15: 3 | T15: 1 | U15: 2 | V15: 3 | W15: 2 | X15: 3 | Y15: 3 | Z15: 4 | AA15: 2 | AB15: 1 | AC15: 2 | AD15: 4 | AE15: 3 | AF15: 1 | AG15: 4 | AH15: 2 | AI15: 3 | AJ15: 4 | AK15: 4 | AL15: 3 | AM15: 2 | AN15: 1 | AO15: 0 | AP15: 1 | AQ15: 1 | AR15: 1 | AS15: 1 | AT15: 1 | AU15: 1 | AV15: =IF(K15=VLOOKUP(VALUE(K$1),Questions!$A:$E,5,FALSE),1,0) -> 1 | AW15: =IF(L15=VLOOKUP(VALUE(L$1),Questions!$A:$E,5,FALSE),1,0) -> 0 | AX15: =IF(M15=VLOOKUP(VALUE(M$1),Questions!$A:$E,5,FALSE),1,0) -> 1 | AY15: =IF(N15=VLOOKUP(VALUE(N$1),Questions!$A:$E,5,FALSE),1,0) -> 0 | AZ15: =IF(O15=VLOOKUP(VALUE(O$1),Questions!$A:$E,5,FALSE),1,0) -> 1 | BA15: =IF(P15=VLOOKUP(VALUE(P$1),Questions!$A:$E,5,FALSE),1,0) -> 0 | BB15: =IF(Q15=VLOOKUP(VALUE(Q$1),Questions!$A:$E,5,FALSE),1,0) -> 0 | BC15: =IF(R15=VLOOKUP(VALUE(R$1),Questions!$A:$E,5,FALSE),1,0) -> 1 | ... BW15: =IF(AL15=VLOOKUP(VALUE(AL$1),Questions!$A:$E,5,FALSE),1,0) -> 1 | BX15: =IF(Scores[[#This Row],[Final]]>=65,1,0) -> 0 | BY15: =IF(Scores[[#This Row],[Final]]>=IF(Scores[[#This Row],[IEP]],55,65),1,0) -> 0
A16: 15 | B16: 11 | C16: Dushin | D16: FALSE | E16: FALSE | F16: =SUM(Scores[[#This Row],[Q1]:[Q28]]) -> 13 | G16: =SUM(Scores[[#This Row],[29]]:Scores[[#This Row],[30]]) -> 5 | H16: =SUM(Scores[[#This Row],[31]:[36]]) -> 5 | I16: =Scores[[#This Row],[37]] -> 1 | J16: =INDEX('Conversion Chart'!$C$3:$M$47,MATCH(SUM(Scores[[#This Row],[MC]:[IIIA]]),'Conversion Chart'!$B$3:$B$47),MATCH(Scores[[#This Row],[IIIB]],'Conversion Chart'!$C$2:$M$2)) -> 61 | K16: 2 | L16: 2 | M16: 2 | N16: 3 | O16: 1 | P16: 1 | Q16: 2 | R16: 2 | S16: 2 | T16: 1 | U16: 4 | V16: 2 | W16: 3 | X16: 3 | Y16: 2 | Z16: 1 | AA16: 1 | AB16: 4 | AC16: 3 | AD16: 2 | AE16: 4 | AF16: 4 | AG16: 4 | AH16: 2 | AI16: 1 | AJ16: 4 | AK16: 1 | AL16: 4 | AM16: 3 | AN16: 2 | AO16: 0 | AP16: 1 | AQ16: 1 | AR16: 1 | AS16: 1 | AT16: 1 | AU16: 1 | AV16: =IF(K16=VLOOKUP(VALUE(K$1),Questions!$A:$E,5,FALSE),1,0) -> 0 | AW16: =IF(L16=VLOOKUP(VALUE(L$1),Questions!$A:$E,5,FALSE),1,0) -> 1 | AX16: =IF(M16=VLOOKUP(VALUE(M$1),Questions!$A:$E,5,FALSE),1,0) -> 0 | AY16: =IF(N16=VLOOKUP(VALUE(N$1),Questions!$A:$E,5,FALSE),1,0) -> 1 | AZ16: =IF(O16=VLOOKUP(VALUE(O$1),Questions!$A:$E,5,FALSE),1,0) -> 1 | BA16: =IF(P16=VLOOKUP(VALUE(P$1),Questions!$A:$E,5,FALSE),1,0) -> 0 | BB16: =IF(Q16=VLOOKUP(VALUE(Q$1),Questions!$A:$E,5,FALSE),1,0) -> 0 | BC16: =IF(R16=VLOOKUP(VALUE(R$1),Questions!$A:$E,5,FALSE),1,0) -> 1 | ... BW16: =IF(AL16=VLOOKUP(VALUE(AL$1),Questions!$A:$E,5,FALSE),1,0) -> 0 | BX16: =IF(Scores[[#This Row],[Final]]>=65,1,0) -> 0 | BY16: =IF(Scores[[#This Row],[Final]]>=IF(Scores[[#This Row],[IEP]],55,65),1,0) -> 0
A17: 16 | B17: 11 | C17: Dushin | D17: FALSE | E17: FALSE | F17: =SUM(Scores[[#This Row],[Q1]:[Q28]]) -> 26 | G17: =SUM(Scores[[#This Row],[29]]:Scores[[#This Row],[30]]) -> 10 | H17: =SUM(Scores[[#This Row],[31]:[36]]) -> 6 | I17: =Scores[[#This Row],[37]] -> 2.5 | J17: =INDEX('Conversion Chart'!$C$3:$M$47,MATCH(SUM(Scores[[#This Row],[MC]:[IIIA]]),'Conversion Chart'!$B$3:$B$47),MATCH(Scores[[#This Row],[IIIB]],'Conversion Chart'!$C$2:$M$2)) -> 86 | K17: 4 | L17: 2 | M17: 3 | N17: 3 | O17: 1 | P17: 4 | Q17: 3 | R17: 2 | S17: 2 | T17: 1 | U17: 2 | V17: 3 | W17: 2 | X17: 4 | Y17: 3 | Z17: 1 | AA17: 1 | AB17: 4 | AC17: 3 | AD17: 4 | AE17: 2 | AF17: 2 | AG17: 3 | AH17: 3 | AI17: 4 | AJ17: 4 | AK17: 1 | AL17: 3 | AM17: 5 | AN17: 5 | AO17: 1 | AP17: 1 | AQ17: 1 | AR17: 1 | AS17: 1 | AT17: 1 | AU17: 2.5 | AV17: =IF(K17=VLOOKUP(VALUE(K$1),Questions!$A:$E,5,FALSE),1,0) -> 1 | AW17: =IF(L17=VLOOKUP(VALUE(L$1),Questions!$A:$E,5,FALSE),1,0) -> 1 | AX17: =IF(M17=VLOOKUP(VALUE(M$1),Questions!$A:$E,5,FALSE),1,0) -> 1 | AY17: =IF(N17=VLOOKUP(VALUE(N$1),Questions!$A:$E,5,FALSE),1,0) -> 1 | AZ17: =IF(O17=VLOOKUP(VALUE(O$1),Questions!$A:$E,5,FALSE),1,0) -> 1 | BA17: =IF(P17=VLOOKUP(VALUE(P$1),Questions!$A:$E,5,FALSE),1,0) -> 1 | BB17: =IF(Q17=VLOOKUP(VALUE(Q$1),Questions!$A:$E,5,FALSE),1,0) -> 1 | BC17: =IF(R17=VLOOKUP(VALUE(R$1),Questions!$A:$E,5,FALSE),1,0) -> 1 | ... BW17: =IF(AL17=VLOOKUP(VALUE(AL$1),Questions!$A:$E,5,FALSE),1,0) -> 1 | BX17: =IF(Scores[[#This Row],[Final]]>=65,1,0) -> 1 | BY17: =IF(Scores[[#This Row],[Final]]>=IF(Scores[[#This Row],[IEP]],55,65),1,0) -> 1
A18: 17 | B18: 9 | C18: Bermejo | D18: FALSE | E18: FALSE | F18: =SUM(Scores[[#This Row],[Q1]:[Q28]]) -> 13 | G18: =SUM(Scores[[#This Row],[29]]:Scores[[#This Row],[30]]) -> 0 | H18: =SUM(Scores[[#This Row],[31]:[36]]) -> 5 | I18: =Scores[[#This Row],[37]] -> 0 | J18: =INDEX('Conversion Chart'!$C$3:$M$47,MATCH(SUM(Scores[[#This Row],[MC]:[IIIA]]),'Conversion Chart'!$B$3:$B$47),MATCH(Scores[[#This Row],[IIIB]],'Conversion Chart'!$C$2:$M$2)) -> 48 | K18: 4 | L18: 2 | M18: 4 | N18: 1 | O18: 4 | P18: 2 | Q18: 3 | R18: 1 | S18: 4 | T18: 2 | U18: 2 | V18: 4 | W18: 2 | X18: 3 | Y18: 3 | Z18: 1 | AA18: 1 | AB18: 3 | AC18: 2 | AD18: 4 | AE18: 2 | AF18: 2 | AG18: 1 | AH18: 4 | AI18: 2 | AJ18: 3 | AK18: 1 | AL18: 4 | AM18: 0 | AN18: 0 | AO18: 0 | AP18: 1 | AQ18: 1 | AR18: 1 | AS18: 1 | AT18: 1 | AU18: 0 | AV18: =IF(K18=VLOOKUP(VALUE(K$1),Questions!$A:$E,5,FALSE),1,0) -> 1 | AW18: =IF(L18=VLOOKUP(VALUE(L$1),Questions!$A:$E,5,FALSE),1,0) -> 1 | AX18: =IF(M18=VLOOKUP(VALUE(M$1),Questions!$A:$E,5,FALSE),1,0) -> 0 | AY18: =IF(N18=VLOOKUP(VALUE(N$1),Questions!$A:$E,5,FALSE),1,0) -> 0 | AZ18: =IF(O18=VLOOKUP(VALUE(O$1),Questions!$A:$E,5,FALSE),1,0) -> 0 | BA18: =IF(P18=VLOOKUP(VALUE(P$1),Questions!$A:$E,5,FALSE),1,0) -> 0 | BB18: =IF(Q18=VLOOKUP(VALUE(Q$1),Questions!$A:$E,5,FALSE),1,0) -> 1 | BC18: =IF(R18=VLOOKUP(VALUE(R$1),Questions!$A:$E,5,FALSE),1,0) -> 0 | ... BW18: =IF(AL18=VLOOKUP(VALUE(AL$1),Questions!$A:$E,5,FALSE),1,0) -> 0 | BX18: =IF(Scores[[#This Row],[Final]]>=65,1,0) -> 0 | BY18: =IF(Scores[[#This Row],[Final]]>=IF(Scores[[#This Row],[IEP]],55,65),1,0) -> 0
A19: 18 | B19: 11 | C19: Dushin | D19: FALSE | E19: FALSE | F19: =SUM(Scores[[#This Row],[Q1]:[Q28]]) -> 11 | G19: =SUM(Scores[[#This Row],[29]]:Scores[[#This Row],[30]]) -> 3 | H19: =SUM(Scores[[#This Row],[31]:[36]]) -> 5 | I19: =Scores[[#This Row],[37]] -> 1 | J19: =INDEX('Conversion Chart'!$C$3:$M$47,MATCH(SUM(Scores[[#This Row],[MC]:[IIIA]]),'Conversion Chart'!$B$3:$B$47),MATCH(Scores[[#This Row],[IIIB]],'Conversion Chart'!$C$2:$M$2)) -> 55 | K19: 4 | L19: 2 | M19: 2 | N19: 4 | O19: 2 | P19: 4 | Q19: 2 | R19: 3 | S19: 2 | T19: 1 | U19: 3 | V19: 4 | W19: 1 | X19: 1 | Y19: 3 | Z19: 2 | AA19: 4 | AB19: 4 | AC19: 2 | AD19: 3 | AE19: 2 | AF19: 1 | AG19: 2 | AH19: 4 | AI19: 1 | AJ19: 4 | AK19: 2 | AL19: 4 | AM19: 2 | AN19: 1 | AO19: 1 | AP19: 1 | AQ19: 1 | AR19: 1 | AS19: 1 | AT19: 0 | AU19: 1 | AV19: =IF(K19=VLOOKUP(VALUE(K$1),Questions!$A:$E,5,FALSE),1,0) -> 1 | AW19: =IF(L19=VLOOKUP(VALUE(L$1),Questions!$A:$E,5,FALSE),1,0) -> 1 | AX19: =IF(M19=VLOOKUP(VALUE(M$1),Questions!$A:$E,5,FALSE),1,0) -> 0 | AY19: =IF(N19=VLOOKUP(VALUE(N$1),Questions!$A:$E,5,FALSE),1,0) -> 0 | AZ19: =IF(O19=VLOOKUP(VALUE(O$1),Questions!$A:$E,5,FALSE),1,0) -> 0 | BA19: =IF(P19=VLOOKUP(VALUE(P$1),Questions!$A:$E,5,FALSE),1,0) -> 1 | BB19: =IF(Q19=VLOOKUP(VALUE(Q$1),Questions!$A:$E,5,FALSE),1,0) -> 0 | BC19: =IF(R19=VLOOKUP(VALUE(R$1),Questions!$A:$E,5,FALSE),1,0) -> 0 | ... BW19: =IF(AL19=VLOOKUP(VALUE(AL$1),Questions!$A:$E,5,FALSE),1,0) -> 0 | BX19: =IF(Scores[[#This Row],[Final]]>=65,1,0) -> 0 | BY19: =IF(Scores[[#This Row],[Final]]>=IF(Scores[[#This Row],[IEP]],55,65),1,0) -> 0
A20: 19 | B20: 9 | C20: Bermejo | D20: FALSE | E20: FALSE | F20: =SUM(Scores[[#This Row],[Q1]:[Q28]]) -> 6 | G20: =SUM(Scores[[#This Row],[29]]:Scores[[#This Row],[30]]) -> 2 | H20: =SUM(Scores[[#This Row],[31]:[36]]) -> 0 | I20: =Scores[[#This Row],[37]] -> 0 | J20: =INDEX('Conversion Chart'!$C$3:$M$47,MATCH(SUM(Scores[[#This Row],[MC]:[IIIA]]),'Conversion Chart'!$B$3:$B$47),MATCH(Scores[[#This Row],[IIIB]],'Conversion Chart'!$C$2:$M$2)) -> 25 | K20: 2 | L20: 4 | M20: 1 | N20: 1 | O20: 2 | P20: 3 | Q20: 2 | R20: 4 | S20: 3 | T20: 1 | U20: 2 | V20: 4 | W20: 1 | X20: 4 | Y20: 2 | Z20: 3 | AA20: 2 | AB20: 1 | AC20: 4 | AD20: 2 | AE20: 2 | AF20: 1 | AG20: 3 | AH20: 1 | AI20: 3 | AJ20: 2 | AK20: 4 | AL20: 1 | AM20: 1 | AN20: 1 | AO20: 0 | AP20: 0 | AQ20: 0 | AR20: 0 | AS20: 0 | AT20: 0 | AU20: 0 | AV20: =IF(K20=VLOOKUP(VALUE(K$1),Questions!$A:$E,5,FALSE),1,0) -> 0 | AW20: =IF(L20=VLOOKUP(VALUE(L$1),Questions!$A:$E,5,FALSE),1,0) -> 0 | AX20: =IF(M20=VLOOKUP(VALUE(M$1),Questions!$A:$E,5,FALSE),1,0) -> 0 | AY20: =IF(N20=VLOOKUP(VALUE(N$1),Questions!$A:$E,5,FALSE),1,0) -> 0 | AZ20: =IF(O20=VLOOKUP(VALUE(O$1),Questions!$A:$E,5,FALSE),1,0) -> 0 | BA20: =IF(P20=VLOOKUP(VALUE(P$1),Questions!$A:$E,5,FALSE),1,0) -> 0 | BB20: =IF(Q20=VLOOKUP(VALUE(Q$1),Questions!$A:$E,5,FALSE),1,0) -> 0 | BC20: =IF(R20=VLOOKUP(VALUE(R$1),Questions!$A:$E,5,FALSE),1,0) -> 0 | ... BW20: =IF(AL20=VLOOKUP(VALUE(AL$1),Questions!$A:$E,5,FALSE),1,0) -> 0 | BX20: =IF(Scores[[#This Row],[Final]]>=65,1,0) -> 0 | BY20: =IF(Scores[[#This Row],[Final]]>=IF(Scores[[#This Row],[IEP]],55,65),1,0) -> 0
A21: 20 | B21: 9 | C21: Bermejo | D21: FALSE | E21: FALSE | F21: =SUM(Scores[[#This Row],[Q1]:[Q28]]) -> 0 | G21: =SUM(Scores[[#This Row],[29]]:Scores[[#This Row],[30]]) -> 0 | H21: =SUM(Scores[[#This Row],[31]:[36]]) -> 0 | I21: =Scores[[#This Row],[37]] -> 0 | J21: =INDEX('Conversion Chart'!$C$3:$M$47,MATCH(SUM(Scores[[#This Row],[MC]:[IIIA]]),'Conversion Chart'!$B$3:$B$47),MATCH(Scores[[#This Row],[IIIB]],'Conversion Chart'!$C$2:$M$2)) -> 0 | AV21: =IF(K21=VLOOKUP(VALUE(K$1),Questions!$A:$E,5,FALSE),1,0) -> 0 | AW21: =IF(L21=VLOOKUP(VALUE(L$1),Questions!$A:$E,5,FALSE),1,0) -> 0 | AX21: =IF(M21=VLOOKUP(VALUE(M$1),Questions!$A:$E,5,FALSE),1,0) -> 0 | AY21: =IF(N21=VLOOKUP(VALUE(N$1),Questions!$A:$E,5,FALSE),1,0) -> 0 | AZ21: =IF(O21=VLOOKUP(VALUE(O$1),Questions!$A:$E,5,FALSE),1,0) -> 0 | BA21: =IF(P21=VLOOKUP(VALUE(P$1),Questions!$A:$E,5,FALSE),1,0) -> 0 | BB21: =IF(Q21=VLOOKUP(VALUE(Q$1),Questions!$A:$E,5,FALSE),1,0) -> 0 | BC21: =IF(R21=VLOOKUP(VALUE(R$1),Questions!$A:$E,5,FALSE),1,0) -> 0 | ... BW21: =IF(AL21=VLOOKUP(VALUE(AL$1),Questions!$A:$E,5,FALSE),1,0) -> 0 | BX21: =IF(Scores[[#This Row],[Final]]>=65,1,0) -> 0 | BY21: =IF(Scores[[#This Row],[Final]]>=IF(Scores[[#This Row],[IEP]],55,65),1,0) -> 0
A22: 21 | B22: 9 | C22: Bermejo | D22: FALSE | E22: FALSE | F22: =SUM(Scores[[#This Row],[Q1]:[Q28]]) -> 22 | G22: =SUM(Scores[[#This Row],[29]]:Scores[[#This Row],[30]]) -> 2 | H22: =SUM(Scores[[#This Row],[31]:[36]]) -> 5 | I22: =Scores[[#This Row],[37]] -> 2 | J22: =INDEX('Conversion Chart'!$C$3:$M$47,MATCH(SUM(Scores[[#This Row],[MC]:[IIIA]]),'Conversion Chart'!$B$3:$B$47),MATCH(Scores[[#This Row],[IIIB]],'Conversion Chart'!$C$2:$M$2)) -> 72 | K22: 4 | L22: 2 | M22: 3 | N22: 3 | O22: 1 | P22: 3 | Q22: 3 | R22: 2 | S22: 2 | T22: 1 | U22: 2 | V22: 4 | W22: 3 | X22: 4 | Y22: 4 | Z22: 1 | AA22: 1 | AB22: 4 | AC22: 3 | AD22: 2 | AE22: 2 | AF22: 2 | AG22: 3 | AH22: 3 | AI22: 4 | AJ22: 4 | AK22: 1 | AL22: 2 | AM22: 1 | AN22: 1 | AO22: 0 | AP22: 1 | AQ22: 1 | AR22: 1 | AS22: 1 | AT22: 1 | AU22: 2 | AV22: =IF(K22=VLOOKUP(VALUE(K$1),Questions!$A:$E,5,FALSE),1,0) -> 1 | AW22: =IF(L22=VLOOKUP(VALUE(L$1),Questions!$A:$E,5,FALSE),1,0) -> 1 | AX22: =IF(M22=VLOOKUP(VALUE(M$1),Questions!$A:$E,5,FALSE),1,0) -> 1 | AY22: =IF(N22=VLOOKUP(VALUE(N$1),Questions!$A:$E,5,FALSE),1,0) -> 1 | AZ22: =IF(O22=VLOOKUP(VALUE(O$1),Questions!$A:$E,5,FALSE),1,0) -> 1 | BA22: =IF(P22=VLOOKUP(VALUE(P$1),Questions!$A:$E,5,FALSE),1,0) -> 0 | BB22: =IF(Q22=VLOOKUP(VALUE(Q$1),Questions!$A:$E,5,FALSE),1,0) -> 1 | BC22: =IF(R22=VLOOKUP(VALUE(R$1),Questions!$A:$E,5,FALSE),1,0) -> 1 | ... BW22: =IF(AL22=VLOOKUP(VALUE(AL$1),Questions!$A:$E,5,FALSE),1,0) -> 0 | BX22: =IF(Scores[[#This Row],[Final]]>=65,1,0) -> 1 | BY22: =IF(Scores[[#This Row],[Final]]>=IF(Scores[[#This Row],[IEP]],55,65),1,0) -> 1
A23: 22 | B23: 11 | C23: Dushin | D23: FALSE | E23: FALSE | F23: =SUM(Scores[[#This Row],[Q1]:[Q28]]) -> 20 | G23: =SUM(Scores[[#This Row],[29]]:Scores[[#This Row],[30]]) -> 6 | H23: =SUM(Scores[[#This Row],[31]:[36]]) -> 4 | I23: =Scores[[#This Row],[37]] -> 2.5 | J23: =INDEX('Conversion Chart'!$C$3:$M$47,MATCH(SUM(Scores[[#This Row],[MC]:[IIIA]]),'Conversion Chart'!$B$3:$B$47),MATCH(Scores[[#This Row],[IIIB]],'Conversion Chart'!$C$2:$M$2)) -> 75 | K23: 4 | L23: 2 | M23: 3 | N23: 3 | O23: 1 | P23: 3 | Q23: 3 | R23: 2 | S23: 2 | T23: 1 | U23: 2 | V23: 4 | W23: 3 | X23: 3 | Y23: 4 | Z23: 4 | AA23: 1 | AB23: 4 | AC23: 3 | AD23: 2 | AE23: 4 | AF23: 2 | AG23: 3 | AH23: 3 | AI23: 1 | AJ23: 4 | AK23: 1 | AL23: 2 | AM23: 4 | AN23: 2 | AO23: 1 | AP23: 0 | AQ23: 1 | AR23: 1 | AS23: 1 | AT23: 0 | AU23: 2.5 | AV23: =IF(K23=VLOOKUP(VALUE(K$1),Questions!$A:$E,5,FALSE),1,0) -> 1 | AW23: =IF(L23=VLOOKUP(VALUE(L$1),Questions!$A:$E,5,FALSE),1,0) -> 1 | AX23: =IF(M23=VLOOKUP(VALUE(M$1),Questions!$A:$E,5,FALSE),1,0) -> 1 | AY23: =IF(N23=VLOOKUP(VALUE(N$1),Questions!$A:$E,5,FALSE),1,0) -> 1 | AZ23: =IF(O23=VLOOKUP(VALUE(O$1),Questions!$A:$E,5,FALSE),1,0) -> 1 | BA23: =IF(P23=VLOOKUP(VALUE(P$1),Questions!$A:$E,5,FALSE),1,0) -> 0 | BB23: =IF(Q23=VLOOKUP(VALUE(Q$1),Questions!$A:$E,5,FALSE),1,0) -> 1 | BC23: =IF(R23=VLOOKUP(VALUE(R$1),Questions!$A:$E,5,FALSE),1,0) -> 1 | ... BW23: =IF(AL23=VLOOKUP(VALUE(AL$1),Questions!$A:$E,5,FALSE),1,0) -> 0 | BX23: =IF(Scores[[#This Row],[Final]]>=65,1,0) -> 1 | BY23: =IF(Scores[[#This Row],[Final]]>=IF(Scores[[#This Row],[IEP]],55,65),1,0) -> 1
A24: 23 | B24: 9 | C24: Bermejo | D24: FALSE | E24: TRUE | F24: =SUM(Scores[[#This Row],[Q1]:[Q28]]) -> 7 | G24: =SUM(Scores[[#This Row],[29]]:Scores[[#This Row],[30]]) -> 1 | H24: =SUM(Scores[[#This Row],[31]:[36]]) -> 3 | I24: =Scores[[#This Row],[37]] -> 0 | J24: =INDEX('Conversion Chart'!$C$3:$M$47,MATCH(SUM(Scores[[#This Row],[MC]:[IIIA]]),'Conversion Chart'!$B$3:$B$47),MATCH(Scores[[#This Row],[IIIB]],'Conversion Chart'!$C$2:$M$2)) -> 33 | K24: 1 | L24: 2 | M24: 1 | N24: 2 | O24: 1 | P24: 2 | Q24: 3 | R24: 3 | S24: 1 | T24: 1 | U24: 3 | V24: 3 | W24: 4 | X24: 2 | Y24: 1 | Z24: 2 | AA24: 1 | AB24: 4 | AC24: 2 | AD24: 3 | AE24: 1 | AF24: 4 | AG24: 2 | AH24: 1 | AI24: 3 | AJ24: 1 | AK24: 4 | AL24: 3 | AM24: 1 | AN24: 0 | AO24: 0 | AP24: 1 | AQ24: 0 | AR24: 1 | AS24: 0 | AT24: 1 | AU24: 0 | AV24: =IF(K24=VLOOKUP(VALUE(K$1),Questions!$A:$E,5,FALSE),1,0) -> 0 | AW24: =IF(L24=VLOOKUP(VALUE(L$1),Questions!$A:$E,5,FALSE),1,0) -> 1 | AX24: =IF(M24=VLOOKUP(VALUE(M$1),Questions!$A:$E,5,FALSE),1,0) -> 0 | AY24: =IF(N24=VLOOKUP(VALUE(N$1),Questions!$A:$E,5,FALSE),1,0) -> 0 | AZ24: =IF(O24=VLOOKUP(VALUE(O$1),Questions!$A:$E,5,FALSE),1,0) -> 1 | BA24: =IF(P24=VLOOKUP(VALUE(P$1),Questions!$A:$E,5,FALSE),1,0) -> 0 | BB24: =IF(Q24=VLOOKUP(VALUE(Q$1),Questions!$A:$E,5,FALSE),1,0) -> 1 | BC24: =IF(R24=VLOOKUP(VALUE(R$1),Questions!$A:$E,5,FALSE),1,0) -> 0 | ... BW24: =IF(AL24=VLOOKUP(VALUE(AL$1),Questions!$A:$E,5,FALSE),1,0) -> 1 | BX24: =IF(Scores[[#This Row],[Final]]>=65,1,0) -> 0 | BY24: =IF(Scores[[#This Row],[Final]]>=IF(Scores[[#This Row],[IEP]],55,65),1,0) -> 0
A25: 24 | B25: 11 | C25: Dushin | D25: FALSE | E25: FALSE | F25: =SUM(Scores[[#This Row],[Q1]:[Q28]]) -> 18 | G25: =SUM(Scores[[#This Row],[29]]:Scores[[#This Row],[30]]) -> 4 | H25: =SUM(Scores[[#This Row],[31]:[36]]) -> 6 | I25: =Scores[[#This Row],[37]] -> 1 | J25: =INDEX('Conversion Chart'!$C$3:$M$47,MATCH(SUM(Scores[[#This Row],[MC]:[IIIA]]),'Conversion Chart'!$B$3:$B$47),MATCH(Scores[[#This Row],[IIIB]],'Conversion Chart'!$C$2:$M$2)) -> 68 | K25: 3 | L25: 4 | M25: 2 | N25: 3 | O25: 1 | P25: 2 | Q25: 3 | R25: 2 | S25: 2 | T25: 1 | U25: 2 | V25: 1 | W25: 2 | X25: 4 | Y25: 3 | Z25: 4 | AA25: 1 | AB25: 4 | AC25: 3 | AD25: 1 | AE25: 2 | AF25: 2 | AG25: 3 | AH25: 2 | AI25: 3 | AJ25: 4 | AK25: 2 | AL25: 3 | AM25: 2 | AN25: 2 | AO25: 1 | AP25: 1 | AQ25: 1 | AR25: 1 | AS25: 1 | AT25: 1 | AU25: 1 | AV25: =IF(K25=VLOOKUP(VALUE(K$1),Questions!$A:$E,5,FALSE),1,0) -> 0 | AW25: =IF(L25=VLOOKUP(VALUE(L$1),Questions!$A:$E,5,FALSE),1,0) -> 0 | AX25: =IF(M25=VLOOKUP(VALUE(M$1),Questions!$A:$E,5,FALSE),1,0) -> 0 | AY25: =IF(N25=VLOOKUP(VALUE(N$1),Questions!$A:$E,5,FALSE),1,0) -> 1 | AZ25: =IF(O25=VLOOKUP(VALUE(O$1),Questions!$A:$E,5,FALSE),1,0) -> 1 | BA25: =IF(P25=VLOOKUP(VALUE(P$1),Questions!$A:$E,5,FALSE),1,0) -> 0 | BB25: =IF(Q25=VLOOKUP(VALUE(Q$1),Questions!$A:$E,5,FALSE),1,0) -> 1 | BC25: =IF(R25=VLOOKUP(VALUE(R$1),Questions!$A:$E,5,FALSE),1,0) -> 1 | ... BW25: =IF(AL25=VLOOKUP(VALUE(AL$1),Questions!$A:$E,5,FALSE),1,0) -> 1 | BX25: =IF(Scores[[#This Row],[Final]]>=65,1,0) -> 1 | BY25: =IF(Scores[[#This Row],[Final]]>=IF(Scores[[#This Row],[IEP]],55,65),1,0) -> 1
A26: 25 | B26: 11 | C26: Dushin | D26: FALSE | E26: FALSE | F26: =SUM(Scores[[#This Row],[Q1]:[Q28]]) -> 11 | G26: =SUM(Scores[[#This Row],[29]]:Scores[[#This Row],[30]]) -> 3 | H26: =SUM(Scores[[#This Row],[31]:[36]]) -> 4 | I26: =Scores[[#This Row],[37]] -> 1 | J26: =INDEX('Conversion Chart'!$C$3:$M$47,MATCH(SUM(Scores[[#This Row],[MC]:[IIIA]]),'Conversion Chart'!$B$3:$B$47),MATCH(Scores[[#This Row],[IIIB]],'Conversion Chart'!$C$2:$M$2)) -> 54 | K26: 2 | L26: 1 | M26: 2 | N26: 3 | O26: 2 | P26: 2 | Q26: 3 | R26: 2 | S26: 3 | T26: 1 | U26: 2 | V26: 1 | W26: 3 | X26: 4 | Y26: 3 | Z26: 4 | AA26: 1 | AB26: 1 | AC26: 2 | AD26: 2 | AE26: 1 | AF26: 4 | AG26: 3 | AH26: 2 | AI26: 3 | AJ26: 4 | AK26: 4 | AL26: 3 | AM26: 2 | AN26: 1 | AO26: 0 | AP26: 0 | AQ26: 1 | AR26: 1 | AS26: 1 | AT26: 1 | AU26: 1 | AV26: =IF(K26=VLOOKUP(VALUE(K$1),Questions!$A:$E,5,FALSE),1,0) -> 0 | AW26: =IF(L26=VLOOKUP(VALUE(L$1),Questions!$A:$E,5,FALSE),1,0) -> 0 | AX26: =IF(M26=VLOOKUP(VALUE(M$1),Questions!$A:$E,5,FALSE),1,0) -> 0 | AY26: =IF(N26=VLOOKUP(VALUE(N$1),Questions!$A:$E,5,FALSE),1,0) -> 1 | AZ26: =IF(O26=VLOOKUP(VALUE(O$1),Questions!$A:$E,5,FALSE),1,0) -> 0 | BA26: =IF(P26=VLOOKUP(VALUE(P$1),Questions!$A:$E,5,FALSE),1,0) -> 0 | BB26: =IF(Q26=VLOOKUP(VALUE(Q$1),Questions!$A:$E,5,FALSE),1,0) -> 1 | BC26: =IF(R26=VLOOKUP(VALUE(R$1),Questions!$A:$E,5,FALSE),1,0) -> 1 | ... BW26: =IF(AL26=VLOOKUP(VALUE(AL$1),Questions!$A:$E,5,FALSE),1,0) -> 1 | BX26: =IF(Scores[[#This Row],[Final]]>=65,1,0) -> 0 | BY26: =IF(Scores[[#This Row],[Final]]>=IF(Scores[[#This Row],[IEP]],55,65),1,0) -> 0
A27: 26 | B27: 11 | C27: Kovelsky | D27: FALSE | E27: FALSE | F27: =SUM(Scores[[#This Row],[Q1]:[Q28]]) -> 11 | G27: =SUM(Scores[[#This Row],[29]]:Scores[[#This Row],[30]]) -> 0 | H27: =SUM(Scores[[#This Row],[31]:[36]]) -> 6 | I27: =Scores[[#This Row],[37]] -> 2 | J27: =INDEX('Conversion Chart'!$C$3:$M$47,MATCH(SUM(Scores[[#This Row],[MC]:[IIIA]]),'Conversion Chart'!$B$3:$B$47),MATCH(Scores[[#This Row],[IIIB]],'Conversion Chart'!$C$2:$M$2)) -> 57 | K27: 4 | L27: 2 | M27: 4 | N27: 3 | O27: 2 | P27: 2 | Q27: 3 | R27: 2 | S27: 3 | T27: 1 | U27: 2 | V27: 2 | W27: 1 | X27: 4 | Y27: 4 | Z27: 4 | AA27: 2 | AB27: 1 | AC27: 2 | AD27: 3 | AE27: 3 | AF27: 2 | AG27: M | AH27: X | AI27: 3 | AJ27: 4 | AK27: 2 | AL27: 3 | AM27: 0 | AN27: 0 | AO27: 1 | AP27: 1 | AQ27: 1 | AR27: 1 | AS27: 1 | AT27: 1 | AU27: 2 | AV27: =IF(K27=VLOOKUP(VALUE(K$1),Questions!$A:$E,5,FALSE),1,0) -> 1 | AW27: =IF(L27=VLOOKUP(VALUE(L$1),Questions!$A:$E,5,FALSE),1,0) -> 1 | AX27: =IF(M27=VLOOKUP(VALUE(M$1),Questions!$A:$E,5,FALSE),1,0) -> 0 | AY27: =IF(N27=VLOOKUP(VALUE(N$1),Questions!$A:$E,5,FALSE),1,0) -> 1 | AZ27: =IF(O27=VLOOKUP(VALUE(O$1),Questions!$A:$E,5,FALSE),1,0) -> 0 | BA27: =IF(P27=VLOOKUP(VALUE(P$1),Questions!$A:$E,5,FALSE),1,0) -> 0 | BB27: =IF(Q27=VLOOKUP(VALUE(Q$1),Questions!$A:$E,5,FALSE),1,0) -> 1 | BC27: =IF(R27=VLOOKUP(VALUE(R$1),Questions!$A:$E,5,FALSE),1,0) -> 1 | ... BW27: =IF(AL27=VLOOKUP(VALUE(AL$1),Questions!$A:$E,5,FALSE),1,0) -> 1 | BX27: =IF(Scores[[#This Row],[Final]]>=65,1,0) -> 0 | BY27: =IF(Scores[[#This Row],[Final]]>=IF(Scores[[#This Row],[IEP]],55,65),1,0) -> 0
A28: 27 | B28: 11 | C28: Dushin | D28: FALSE | E28: FALSE | F28: =SUM(Scores[[#This Row],[Q1]:[Q28]]) -> 20 | G28: =SUM(Scores[[#This Row],[29]]:Scores[[#This Row],[30]]) -> 5 | H28: =SUM(Scores[[#This Row],[31]:[36]]) -> 4 | I28: =Scores[[#This Row],[37]] -> 1 | J28: =INDEX('Conversion Chart'!$C$3:$M$47,MATCH(SUM(Scores[[#This Row],[MC]:[IIIA]]),'Conversion Chart'!$B$3:$B$47),MATCH(Scores[[#This Row],[IIIB]],'Conversion Chart'!$C$2:$M$2)) -> 69 | K28: 4 | L28: 2 | M28: 3 | N28: 3 | O28: 1 | P28: 3 | Q28: 3 | R28: 2 | S28: 3 | T28: 1 | U28: 2 | V28: 4 | W28: 1 | X28: 4 | Y28: 4 | Z28: 1 | AA28: 1 | AB28: 1 | AC28: 3 | AD28: 1 | AE28: 2 | AF28: 2 | AG28: 3 | AH28: 2 | AI28: 3 | AJ28: 4 | AK28: 1 | AL28: 3 | AM28: 2 | AN28: 3 | AO28: 0 | AP28: 1 | AQ28: 1 | AR28: 1 | AS28: 0 | AT28: 1 | AU28: 1 | AV28: =IF(K28=VLOOKUP(VALUE(K$1),Questions!$A:$E,5,FALSE),1,0) -> 1 | AW28: =IF(L28=VLOOKUP(VALUE(L$1),Questions!$A:$E,5,FALSE),1,0) -> 1 | AX28: =IF(M28=VLOOKUP(VALUE(M$1),Questions!$A:$E,5,FALSE),1,0) -> 1 | AY28: =IF(N28=VLOOKUP(VALUE(N$1),Questions!$A:$E,5,FALSE),1,0) -> 1 | AZ28: =IF(O28=VLOOKUP(VALUE(O$1),Questions!$A:$E,5,FALSE),1,0) -> 1 | BA28: =IF(P28=VLOOKUP(VALUE(P$1),Questions!$A:$E,5,FALSE),1,0) -> 0 | BB28: =IF(Q28=VLOOKUP(VALUE(Q$1),Questions!$A:$E,5,FALSE),1,0) -> 1 | BC28: =IF(R28=VLOOKUP(VALUE(R$1),Questions!$A:$E,5,FALSE),1,0) -> 1 | ... BW28: =IF(AL28=VLOOKUP(VALUE(AL$1),Questions!$A:$E,5,FALSE),1,0) -> 1 | BX28: =IF(Scores[[#This Row],[Final]]>=65,1,0) -> 1 | BY28: =IF(Scores[[#This Row],[Final]]>=IF(Scores[[#This Row],[IEP]],55,65),1,0) -> 1
A29: 28 | B29: 9 | C29: Bermejo | D29: FALSE | E29: FALSE | F29: =SUM(Scores[[#This Row],[Q1]:[Q28]]) -> 16 | G29: =SUM(Scores[[#This Row],[29]]:Scores[[#This Row],[30]]) -> 4 | H29: =SUM(Scores[[#This Row],[31]:[36]]) -> 5 | I29: =Scores[[#This Row],[37]] -> 2.5 | J29: =INDEX('Conversion Chart'!$C$3:$M$47,MATCH(SUM(Scores[[#This Row],[MC]:[IIIA]]),'Conversion Chart'!$B$3:$B$47),MATCH(Scores[[#This Row],[IIIB]],'Conversion Chart'!$C$2:$M$2)) -> 70 | K29: 4 | L29: 2 | M29: 3 | N29: 3 | O29: 1 | P29: 4 | Q29: 3 | R29: 3 | S29: 2 | T29: 1 | U29: 1 | V29: 3 | W29: 2 | X29: 4 | Y29: 4 | Z29: 4 | AA29: 1 | AB29: 3 | AC29: 2 | AD29: 3 | AE29: 2 | AF29: 2 | AG29: 4 | AH29: 2 | AI29: 3 | AJ29: 4 | AK29: 4 | AL29: 3 | AM29: 2 | AN29: 2 | AO29: 0 | AP29: 1 | AQ29: 1 | AR29: 1 | AS29: 1 | AT29: 1 | AU29: 2.5 | AV29: =IF(K29=VLOOKUP(VALUE(K$1),Questions!$A:$E,5,FALSE),1,0) -> 1 | AW29: =IF(L29=VLOOKUP(VALUE(L$1),Questions!$A:$E,5,FALSE),1,0) -> 1 | AX29: =IF(M29=VLOOKUP(VALUE(M$1),Questions!$A:$E,5,FALSE),1,0) -> 1 | AY29: =IF(N29=VLOOKUP(VALUE(N$1),Questions!$A:$E,5,FALSE),1,0) -> 1 | AZ29: =IF(O29=VLOOKUP(VALUE(O$1),Questions!$A:$E,5,FALSE),1,0) -> 1 | BA29: =IF(P29=VLOOKUP(VALUE(P$1),Questions!$A:$E,5,FALSE),1,0) -> 1 | BB29: =IF(Q29=VLOOKUP(VALUE(Q$1),Questions!$A:$E,5,FALSE),1,0) -> 1 | BC29: =IF(R29=VLOOKUP(VALUE(R$1),Questions!$A:$E,5,FALSE),1,0) -> 0 | ... BW29: =IF(AL29=VLOOKUP(VALUE(AL$1),Questions!$A:$E,5,FALSE),1,0) -> 1 | BX29: =IF(Scores[[#This Row],[Final]]>=65,1,0) -> 1 | BY29: =IF(Scores[[#This Row],[Final]]>=IF(Scores[[#This Row],[IEP]],55,65),1,0) -> 1
A30: 29 | B30: 11 | C30: Dushin | D30: FALSE | E30: FALSE | F30: =SUM(Scores[[#This Row],[Q1]:[Q28]]) -> 13 | G30: =SUM(Scores[[#This Row],[29]]:Scores[[#This Row],[30]]) -> 3 | H30: =SUM(Scores[[#This Row],[31]:[36]]) -> 6 | I30: =Scores[[#This Row],[37]] -> 1 | J30: =INDEX('Conversion Chart'!$C$3:$M$47,MATCH(SUM(Scores[[#This Row],[MC]:[IIIA]]),'Conversion Chart'!$B$3:$B$47),MATCH(Scores[[#This Row],[IIIB]],'Conversion Chart'!$C$2:$M$2)) -> 60 | K30: 1 | L30: 1 | M30: 4 | N30: 1 | O30: 1 | P30: 4 | Q30: 2 | R30: 1 | S30: 2 | T30: 1 | U30: 2 | V30: 3 | W30: 1 | X30: 4 | Y30: 4 | Z30: 2 | AA30: 1 | AB30: 4 | AC30: 1 | AD30: 3 | AE30: 4 | AF30: 2 | AG30: 3 | AH30: 2 | AI30: 3 | AJ30: 4 | AK30: 1 | AL30: 3 | AM30: 2 | AN30: 1 | AO30: 1 | AP30: 1 | AQ30: 1 | AR30: 1 | AS30: 1 | AT30: 1 | AU30: 1 | AV30: =IF(K30=VLOOKUP(VALUE(K$1),Questions!$A:$E,5,FALSE),1,0) -> 0 | AW30: =IF(L30=VLOOKUP(VALUE(L$1),Questions!$A:$E,5,FALSE),1,0) -> 0 | AX30: =IF(M30=VLOOKUP(VALUE(M$1),Questions!$A:$E,5,FALSE),1,0) -> 0 | AY30: =IF(N30=VLOOKUP(VALUE(N$1),Questions!$A:$E,5,FALSE),1,0) -> 0 | AZ30: =IF(O30=VLOOKUP(VALUE(O$1),Questions!$A:$E,5,FALSE),1,0) -> 1 | BA30: =IF(P30=VLOOKUP(VALUE(P$1),Questions!$A:$E,5,FALSE),1,0) -> 1 | BB30: =IF(Q30=VLOOKUP(VALUE(Q$1),Questions!$A:$E,5,FALSE),1,0) -> 0 | BC30: =IF(R30=VLOOKUP(VALUE(R$1),Questions!$A:$E,5,FALSE),1,0) -> 0 | ... BW30: =IF(AL30=VLOOKUP(VALUE(AL$1),Questions!$A:$E,5,FALSE),1,0) -> 1 | BX30: =IF(Scores[[#This Row],[Final]]>=65,1,0) -> 0 | BY30: =IF(Scores[[#This Row],[Final]]>=IF(Scores[[#This Row],[IEP]],55,65),1,0) -> 0
A31: 30 | B31: 9 | C31: Bermejo | D31: FALSE | E31: TRUE | F31: =SUM(Scores[[#This Row],[Q1]:[Q28]]) -> 11 | G31: =SUM(Scores[[#This Row],[29]]:Scores[[#This Row],[30]]) -> 3 | H31: =SUM(Scores[[#This Row],[31]:[36]]) -> 5 | I31: =Scores[[#This Row],[37]] -> 1 | J31: =INDEX('Conversion Chart'!$C$3:$M$47,MATCH(SUM(Scores[[#This Row],[MC]:[IIIA]]),'Conversion Chart'!$B$3:$B$47),MATCH(Scores[[#This Row],[IIIB]],'Conversion Chart'!$C$2:$M$2)) -> 55 | K31: 4 | L31: 2 | M31: 3 | N31: 3 | O31: 3 | P31: 2 | Q31: 3 | R31: 3 | S31: 2 | T31: 2 | U31: 2 | V31: 3 | W31: 1 | X31: 2 | Y31: 4 | Z31: 4 | AA31: 1 | AB31: 3 | AC31: 3 | AD31: 1 | AE31: 2 | AF31: 1 | AG31: 4 | AH31: 2 | AI31: 3 | AJ31: 1 | AK31: 4 | AL31: 3 | AM31: 2 | AN31: 1 | AO31: 1 | AP31: 0 | AQ31: 1 | AR31: 1 | AS31: 1 | AT31: 1 | AU31: 1 | AV31: =IF(K31=VLOOKUP(VALUE(K$1),Questions!$A:$E,5,FALSE),1,0) -> 1 | AW31: =IF(L31=VLOOKUP(VALUE(L$1),Questions!$A:$E,5,FALSE),1,0) -> 1 | AX31: =IF(M31=VLOOKUP(VALUE(M$1),Questions!$A:$E,5,FALSE),1,0) -> 1 | AY31: =IF(N31=VLOOKUP(VALUE(N$1),Questions!$A:$E,5,FALSE),1,0) -> 1 | AZ31: =IF(O31=VLOOKUP(VALUE(O$1),Questions!$A:$E,5,FALSE),1,0) -> 0 | BA31: =IF(P31=VLOOKUP(VALUE(P$1),Questions!$A:$E,5,FALSE),1,0) -> 0 | BB31: =IF(Q31=VLOOKUP(VALUE(Q$1),Questions!$A:$E,5,FALSE),1,0) -> 1 | BC31: =IF(R31=VLOOKUP(VALUE(R$1),Questions!$A:$E,5,FALSE),1,0) -> 0 | ... BW31: =IF(AL31=VLOOKUP(VALUE(AL$1),Questions!$A:$E,5,FALSE),1,0) -> 1 | BX31: =IF(Scores[[#This Row],[Final]]>=65,1,0) -> 0 | BY31: =IF(Scores[[#This Row],[Final]]>=IF(Scores[[#This Row],[IEP]],55,65),1,0) -> 1
A32: 31 | B32: 9 | C32: Kovelsky | D32: FALSE | E32: FALSE | F32: =SUM(Scores[[#This Row],[Q1]:[Q28]]) -> 20 | G32: =SUM(Scores[[#This Row],[29]]:Scores[[#This Row],[30]]) -> 2 | H32: =SUM(Scores[[#This Row],[31]:[36]]) -> 6 | I32: =Scores[[#This Row],[37]] -> 1.5 | J32: =INDEX('Conversion Chart'!$C$3:$M$47,MATCH(SUM(Scores[[#This Row],[MC]:[IIIA]]),'Conversion Chart'!$B$3:$B$47),MATCH(Scores[[#This Row],[IIIB]],'Conversion Chart'!$C$2:$M$2)) -> 70 | K32: 4 | L32: 2 | M32: 3 | N32: 3 | O32: 1 | P32: 3 | Q32: 3 | R32: 2 | S32: 3 | T32: 1 | U32: 1 | V32: 4 | W32: 1 | X32: 4 | Y32: 3 | Z32: 1 | AA32: 1 | AB32: 4 | AC32: 3 | AD32: 1 | AE32: 3 | AF32: 2 | AG32: 3 | AH32: 3 | AI32: 1 | AJ32: 1 | AK32: 2 | AL32: 3 | AM32: 2 | AN32: 0 | AO32: 1 | AP32: 1 | AQ32: 1 | AR32: 1 | AS32: 1 | AT32: 1 | AU32: 1.5 | AV32: =IF(K32=VLOOKUP(VALUE(K$1),Questions!$A:$E,5,FALSE),1,0) -> 1 | AW32: =IF(L32=VLOOKUP(VALUE(L$1),Questions!$A:$E,5,FALSE),1,0) -> 1 | AX32: =IF(M32=VLOOKUP(VALUE(M$1),Questions!$A:$E,5,FALSE),1,0) -> 1 | AY32: =IF(N32=VLOOKUP(VALUE(N$1),Questions!$A:$E,5,FALSE),1,0) -> 1 | AZ32: =IF(O32=VLOOKUP(VALUE(O$1),Questions!$A:$E,5,FALSE),1,0) -> 1 | BA32: =IF(P32=VLOOKUP(VALUE(P$1),Questions!$A:$E,5,FALSE),1,0) -> 0 | BB32: =IF(Q32=VLOOKUP(VALUE(Q$1),Questions!$A:$E,5,FALSE),1,0) -> 1 | BC32: =IF(R32=VLOOKUP(VALUE(R$1),Questions!$A:$E,5,FALSE),1,0) -> 1 | ... BW32: =IF(AL32=VLOOKUP(VALUE(AL$1),Questions!$A:$E,5,FALSE),1,0) -> 1 | BX32: =IF(Scores[[#This Row],[Final]]>=65,1,0) -> 1 | BY32: =IF(Scores[[#This Row],[Final]]>=IF(Scores[[#This Row],[IEP]],55,65),1,0) -> 1
A33: 32 | B33: 9 | C33: Bermejo | D33: FALSE | E33: FALSE | F33: =SUM(Scores[[#This Row],[Q1]:[Q28]]) -> 12 | G33: =SUM(Scores[[#This Row],[29]]:Scores[[#This Row],[30]]) -> 3 | H33: =SUM(Scores[[#This Row],[31]:[36]]) -> 6 | I33: =Scores[[#This Row],[37]] -> 1 | J33: =INDEX('Conversion Chart'!$C$3:$M$47,MATCH(SUM(Scores[[#This Row],[MC]:[IIIA]]),'Conversion Chart'!$B$3:$B$47),MATCH(Scores[[#This Row],[IIIB]],'Conversion Chart'!$C$2:$M$2)) -> 58 | K33: 4 | L33: 3 | M33: 1 | N33: 1 | O33: 2 | P33: 1 | Q33: 3 | R33: 1 | S33: 4 | T33: 1 | U33: 2 | V33: 3 | W33: 4 | X33: 2 | Y33: 4 | Z33: 4 | AA33: 1 | AB33: 4 | AC33: 3 | AD33: 4 | AE33: 1 | AF33: 2 | AG33: 3 | AH33: 2 | AI33: 4 | AJ33: 4 | AK33: 2 | AL33: 3 | AM33: 2 | AN33: 1 | AO33: 1 | AP33: 1 | AQ33: 1 | AR33: 1 | AS33: 1 | AT33: 1 | AU33: 1 | AV33: =IF(K33=VLOOKUP(VALUE(K$1),Questions!$A:$E,5,FALSE),1,0) -> 1 | AW33: =IF(L33=VLOOKUP(VALUE(L$1),Questions!$A:$E,5,FALSE),1,0) -> 0 | AX33: =IF(M33=VLOOKUP(VALUE(M$1),Questions!$A:$E,5,FALSE),1,0) -> 0 | AY33: =IF(N33=VLOOKUP(VALUE(N$1),Questions!$A:$E,5,FALSE),1,0) -> 0 | AZ33: =IF(O33=VLOOKUP(VALUE(O$1),Questions!$A:$E,5,FALSE),1,0) -> 0 | BA33: =IF(P33=VLOOKUP(VALUE(P$1),Questions!$A:$E,5,FALSE),1,0) -> 0 | BB33: =IF(Q33=VLOOKUP(VALUE(Q$1),Questions!$A:$E,5,FALSE),1,0) -> 1 | BC33: =IF(R33=VLOOKUP(VALUE(R$1),Questions!$A:$E,5,FALSE),1,0) -> 0 | ... BW33: =IF(AL33=VLOOKUP(VALUE(AL$1),Questions!$A:$E,5,FALSE),1,0) -> 1 | BX33: =IF(Scores[[#This Row],[Final]]>=65,1,0) -> 0 | BY33: =IF(Scores[[#This Row],[Final]]>=IF(Scores[[#This Row],[IEP]],55,65),1,0) -> 0
A34: 33 | B34: 11 | C34: Dushin | D34: FALSE | E34: FALSE | F34: =SUM(Scores[[#This Row],[Q1]:[Q28]]) -> 20 | G34: =SUM(Scores[[#This Row],[29]]:Scores[[#This Row],[30]]) -> 5 | H34: =SUM(Scores[[#This Row],[31]:[36]]) -> 5 | I34: =Scores[[#This Row],[37]] -> 1 | J34: =INDEX('Conversion Chart'!$C$3:$M$47,MATCH(SUM(Scores[[#This Row],[MC]:[IIIA]]),'Conversion Chart'!$B$3:$B$47),MATCH(Scores[[#This Row],[IIIB]],'Conversion Chart'!$C$2:$M$2)) -> 70 | K34: 4 | L34: 2 | M34: 1 | N34: 3 | O34: 2 | P34: 4 | Q34: 2 | R34: 1 | S34: 2 | T34: 1 | U34: 2 | V34: 4 | W34: 2 | X34: 1 | Y34: 3 | Z34: 1 | AA34: 1 | AB34: 4 | AC34: 3 | AD34: 1 | AE34: 2 | AF34: 1 | AG34: 2 | AH34: 3 | AI34: 1 | AJ34: 4 | AK34: 1 | AL34: 3 | AM34: 3 | AN34: 2 | AO34: 0 | AP34: 1 | AQ34: 1 | AR34: 1 | AS34: 1 | AT34: 1 | AU34: 1 | AV34: =IF(K34=VLOOKUP(VALUE(K$1),Questions!$A:$E,5,FALSE),1,0) -> 1 | AW34: =IF(L34=VLOOKUP(VALUE(L$1),Questions!$A:$E,5,FALSE),1,0) -> 1 | AX34: =IF(M34=VLOOKUP(VALUE(M$1),Questions!$A:$E,5,FALSE),1,0) -> 0 | AY34: =IF(N34=VLOOKUP(VALUE(N$1),Questions!$A:$E,5,FALSE),1,0) -> 1 | AZ34: =IF(O34=VLOOKUP(VALUE(O$1),Questions!$A:$E,5,FALSE),1,0) -> 0 | BA34: =IF(P34=VLOOKUP(VALUE(P$1),Questions!$A:$E,5,FALSE),1,0) -> 1 | BB34: =IF(Q34=VLOOKUP(VALUE(Q$1),Questions!$A:$E,5,FALSE),1,0) -> 0 | BC34: =IF(R34=VLOOKUP(VALUE(R$1),Questions!$A:$E,5,FALSE),1,0) -> 0 | ... BW34: =IF(AL34=VLOOKUP(VALUE(AL$1),Questions!$A:$E,5,FALSE),1,0) -> 1 | BX34: =IF(Scores[[#This Row],[Final]]>=65,1,0) -> 1 | BY34: =IF(Scores[[#This Row],[Final]]>=IF(Scores[[#This Row],[IEP]],55,65),1,0) -> 1
A35: 34 | B35: 11 | C35: Antaky | D35: FALSE | E35: FALSE | F35: =SUM(Scores[[#This Row],[Q1]:[Q28]]) -> 20 | G35: =SUM(Scores[[#This Row],[29]]:Scores[[#This Row],[30]]) -> 5 | H35: =SUM(Scores[[#This Row],[31]:[36]]) -> 6 | I35: =Scores[[#This Row],[37]] -> 3 | J35: =INDEX('Conversion Chart'!$C$3:$M$47,MATCH(SUM(Scores[[#This Row],[MC]:[IIIA]]),'Conversion Chart'!$B$3:$B$47),MATCH(Scores[[#This Row],[IIIB]],'Conversion Chart'!$C$2:$M$2)) -> 77 | K35: 4 | L35: 2 | M35: 3 | N35: 4 | O35: 1 | P35: 3 | Q35: 3 | R35: 2 | S35: 2 | T35: 1 | U35: 1 | V35: 4 | W35: 2 | X35: 4 | Y35: 3 | Z35: 2 | AA35: 1 | AB35: 4 | AC35: 1 | AD35: 1 | AE35: 2 | AF35: 2 | AG35: 3 | AH35: 3 | AI35: 4 | AJ35: 4 | AK35: 1 | AL35: 2 | AM35: 2 | AN35: 3 | AO35: 1 | AP35: 1 | AQ35: 1 | AR35: 1 | AS35: 1 | AT35: 1 | AU35: 3 | AV35: =IF(K35=VLOOKUP(VALUE(K$1),Questions!$A:$E,5,FALSE),1,0) -> 1 | AW35: =IF(L35=VLOOKUP(VALUE(L$1),Questions!$A:$E,5,FALSE),1,0) -> 1 | AX35: =IF(M35=VLOOKUP(VALUE(M$1),Questions!$A:$E,5,FALSE),1,0) -> 1 | AY35: =IF(N35=VLOOKUP(VALUE(N$1),Questions!$A:$E,5,FALSE),1,0) -> 0 | AZ35: =IF(O35=VLOOKUP(VALUE(O$1),Questions!$A:$E,5,FALSE),1,0) -> 1 | BA35: =IF(P35=VLOOKUP(VALUE(P$1),Questions!$A:$E,5,FALSE),1,0) -> 0 | BB35: =IF(Q35=VLOOKUP(VALUE(Q$1),Questions!$A:$E,5,FALSE),1,0) -> 1 | BC35: =IF(R35=VLOOKUP(VALUE(R$1),Questions!$A:$E,5,FALSE),1,0) -> 1 | ... BW35: =IF(AL35=VLOOKUP(VALUE(AL$1),Questions!$A:$E,5,FALSE),1,0) -> 0 | BX35: =IF(Scores[[#This Row],[Final]]>=65,1,0) -> 1 | BY35: =IF(Scores[[#This Row],[Final]]>=IF(Scores[[#This Row],[IEP]],55,65),1,0) -> 1
A36: 35 | B36: 9 | C36: Bermejo | D36: FALSE | E36: FALSE | F36: =SUM(Scores[[#This Row],[Q1]:[Q28]]) -> 15 | G36: =SUM(Scores[[#This Row],[29]]:Scores[[#This Row],[30]]) -> 6 | H36: =SUM(Scores[[#This Row],[31]:[36]]) -> 6 | I36: =Scores[[#This Row],[37]] -> 2.5 | J36: =INDEX('Conversion Chart'!$C$3:$M$47,MATCH(SUM(Scores[[#This Row],[MC]:[IIIA]]),'Conversion Chart'!$B$3:$B$47),MATCH(Scores[[#This Row],[IIIB]],'Conversion Chart'!$C$2:$M$2)) -> 72 | K36: 4 | L36: 2 | M36: 3 | N36: 1 | O36: 1 | P36: 2 | Q36: 2 | R36: 2 | S36: 2 | T36: 1 | U36: 2 | V36: 4 | W36: 1 | X36: 2 | Y36: 4 | Z36: 4 | AA36: 3 | AB36: 4 | AC36: 1 | AD36: 4 | AE36: 2 | AF36: 1 | AG36: 3 | AH36: 2 | AI36: 3 | AJ36: 4 | AK36: 4 | AL36: 3 | AM36: 3 | AN36: 3 | AO36: 1 | AP36: 1 | AQ36: 1 | AR36: 1 | AS36: 1 | AT36: 1 | AU36: 2.5 | AV36: =IF(K36=VLOOKUP(VALUE(K$1),Questions!$A:$E,5,FALSE),1,0) -> 1 | AW36: =IF(L36=VLOOKUP(VALUE(L$1),Questions!$A:$E,5,FALSE),1,0) -> 1 | AX36: =IF(M36=VLOOKUP(VALUE(M$1),Questions!$A:$E,5,FALSE),1,0) -> 1 | AY36: =IF(N36=VLOOKUP(VALUE(N$1),Questions!$A:$E,5,FALSE),1,0) -> 0 | AZ36: =IF(O36=VLOOKUP(VALUE(O$1),Questions!$A:$E,5,FALSE),1,0) -> 1 | BA36: =IF(P36=VLOOKUP(VALUE(P$1),Questions!$A:$E,5,FALSE),1,0) -> 0 | BB36: =IF(Q36=VLOOKUP(VALUE(Q$1),Questions!$A:$E,5,FALSE),1,0) -> 0 | BC36: =IF(R36=VLOOKUP(VALUE(R$1),Questions!$A:$E,5,FALSE),1,0) -> 1 | ... BW36: =IF(AL36=VLOOKUP(VALUE(AL$1),Questions!$A:$E,5,FALSE),1,0) -> 1 | BX36: =IF(Scores[[#This Row],[Final]]>=65,1,0) -> 1 | BY36: =IF(Scores[[#This Row],[Final]]>=IF(Scores[[#This Row],[IEP]],55,65),1,0) -> 1
A37: 36 | B37: 11 | C37: Other | D37: FALSE | E37: FALSE | F37: =SUM(Scores[[#This Row],[Q1]:[Q28]]) -> 0 | G37: =SUM(Scores[[#This Row],[29]]:Scores[[#This Row],[30]]) -> 0 | H37: =SUM(Scores[[#This Row],[31]:[36]]) -> 0 | I37: =Scores[[#This Row],[37]] -> 0 | J37: =INDEX('Conversion Chart'!$C$3:$M$47,MATCH(SUM(Scores[[#This Row],[MC]:[IIIA]]),'Conversion Chart'!$B$3:$B$47),MATCH(Scores[[#This Row],[IIIB]],'Conversion Chart'!$C$2:$M$2)) -> 0 | AV37: =IF(K37=VLOOKUP(VALUE(K$1),Questions!$A:$E,5,FALSE),1,0) -> 0 | AW37: =IF(L37=VLOOKUP(VALUE(L$1),Questions!$A:$E,5,FALSE),1,0) -> 0 | AX37: =IF(M37=VLOOKUP(VALUE(M$1),Questions!$A:$E,5,FALSE),1,0) -> 0 | AY37: =IF(N37=VLOOKUP(VALUE(N$1),Questions!$A:$E,5,FALSE),1,0) -> 0 | AZ37: =IF(O37=VLOOKUP(VALUE(O$1),Questions!$A:$E,5,FALSE),1,0) -> 0 | BA37: =IF(P37=VLOOKUP(VALUE(P$1),Questions!$A:$E,5,FALSE),1,0) -> 0 | BB37: =IF(Q37=VLOOKUP(VALUE(Q$1),Questions!$A:$E,5,FALSE),1,0) -> 0 | BC37: =IF(R37=VLOOKUP(VALUE(R$1),Questions!$A:$E,5,FALSE),1,0) -> 0 | ... BW37: =IF(AL37=VLOOKUP(VALUE(AL$1),Questions!$A:$E,5,FALSE),1,0) -> 0 | BX37: =IF(Scores[[#This Row],[Final]]>=65,1,0) -> 0 | BY37: =IF(Scores[[#This Row],[Final]]>=IF(Scores[[#This Row],[IEP]],55,65),1,0) -> 0
A38: 37 | B38: 11 | C38: Other | D38: FALSE | E38: FALSE | F38: =SUM(Scores[[#This Row],[Q1]:[Q28]]) -> 10 | G38: =SUM(Scores[[#This Row],[29]]:Scores[[#This Row],[30]]) -> 3 | H38: =SUM(Scores[[#This Row],[31]:[36]]) -> 3 | I38: =Scores[[#This Row],[37]] -> 0.5 | J38: =INDEX('Conversion Chart'!$C$3:$M$47,MATCH(SUM(Scores[[#This Row],[MC]:[IIIA]]),'Conversion Chart'!$B$3:$B$47),MATCH(Scores[[#This Row],[IIIB]],'Conversion Chart'!$C$2:$M$2)) -> 47 | K38: 4 | L38: 2 | M38: 3 | N38: 1 | O38: 1 | P38: 2 | Q38: 2 | R38: 1 | S38: 4 | T38: 1 | U38: 4 | V38: 3 | W38: 3 | X38: 1 | Y38: 4 | Z38: 4 | AA38: 1 | AB38: 4 | AC38: 1 | AD38: 3 | AE38: 3 | AF38: 2 | AG38: 3 | AH38: 4 | AI38: 3 | AJ38: 4 | AK38: 4 | AL38: 4 | AM38: 2 | AN38: 1 | AO38: 0 | AP38: 1 | AQ38: 0 | AR38: 1 | AS38: 0 | AT38: 1 | AU38: 0.5 | AV38: =IF(K38=VLOOKUP(VALUE(K$1),Questions!$A:$E,5,FALSE),1,0) -> 1 | AW38: =IF(L38=VLOOKUP(VALUE(L$1),Questions!$A:$E,5,FALSE),1,0) -> 1 | AX38: =IF(M38=VLOOKUP(VALUE(M$1),Questions!$A:$E,5,FALSE),1,0) -> 1 | AY38: =IF(N38=VLOOKUP(VALUE(N$1),Questions!$A:$E,5,FALSE),1,0) -> 0 | AZ38: =IF(O38=VLOOKUP(VALUE(O$1),Questions!$A:$E,5,FALSE),1,0) -> 1 | BA38: =IF(P38=VLOOKUP(VALUE(P$1),Questions!$A:$E,5,FALSE),1,0) -> 0 | BB38: =IF(Q38=VLOOKUP(VALUE(Q$1),Questions!$A:$E,5,FALSE),1,0) -> 0 | BC38: =IF(R38=VLOOKUP(VALUE(R$1),Questions!$A:$E,5,FALSE),1,0) -> 0 | ... BW38: =IF(AL38=VLOOKUP(VALUE(AL$1),Questions!$A:$E,5,FALSE),1,0) -> 0 | BX38: =IF(Scores[[#This Row],[Final]]>=65,1,0) -> 0 | BY38: =IF(Scores[[#This Row],[Final]]>=IF(Scores[[#This Row],[IEP]],55,65),1,0) -> 0
A39: 38 | B39: 9 | C39: Bermejo | D39: FALSE | E39: FALSE | F39: =SUM(Scores[[#This Row],[Q1]:[Q28]]) -> 23 | G39: =SUM(Scores[[#This Row],[29]]:Scores[[#This Row],[30]]) -> 9 | H39: =SUM(Scores[[#This Row],[31]:[36]]) -> 6 | I39: =Scores[[#This Row],[37]] -> 2 | J39: =INDEX('Conversion Chart'!$C$3:$M$47,MATCH(SUM(Scores[[#This Row],[MC]:[IIIA]]),'Conversion Chart'!$B$3:$B$47),MATCH(Scores[[#This Row],[IIIB]],'Conversion Chart'!$C$2:$M$2)) -> 81 | K39: 4 | L39: 2 | M39: 3 | N39: 3 | O39: 1 | P39: 4 | Q39: 3 | R39: 2 | S39: 2 | T39: 1 | U39: 2 | V39: 4 | W39: 2 | X39: 2 | Y39: 3 | Z39: 1 | AA39: 1 | AB39: 3 | AC39: 3 | AD39: 4 | AE39: 3 | AF39: 2 | AG39: 3 | AH39: 2 | AI39: 1 | AJ39: 4 | AK39: 4 | AL39: 3 | AM39: 5 | AN39: 4 | AO39: 1 | AP39: 1 | AQ39: 1 | AR39: 1 | AS39: 1 | AT39: 1 | AU39: 2 | AV39: =IF(K39=VLOOKUP(VALUE(K$1),Questions!$A:$E,5,FALSE),1,0) -> 1 | AW39: =IF(L39=VLOOKUP(VALUE(L$1),Questions!$A:$E,5,FALSE),1,0) -> 1 | AX39: =IF(M39=VLOOKUP(VALUE(M$1),Questions!$A:$E,5,FALSE),1,0) -> 1 | AY39: =IF(N39=VLOOKUP(VALUE(N$1),Questions!$A:$E,5,FALSE),1,0) -> 1 | AZ39: =IF(O39=VLOOKUP(VALUE(O$1),Questions!$A:$E,5,FALSE),1,0) -> 1 | BA39: =IF(P39=VLOOKUP(VALUE(P$1),Questions!$A:$E,5,FALSE),1,0) -> 1 | BB39: =IF(Q39=VLOOKUP(VALUE(Q$1),Questions!$A:$E,5,FALSE),1,0) -> 1 | BC39: =IF(R39=VLOOKUP(VALUE(R$1),Questions!$A:$E,5,FALSE),1,0) -> 1 | ... BW39: =IF(AL39=VLOOKUP(VALUE(AL$1),Questions!$A:$E,5,FALSE),1,0) -> 1 | BX39: =IF(Scores[[#This Row],[Final]]>=65,1,0) -> 1 | BY39: =IF(Scores[[#This Row],[Final]]>=IF(Scores[[#This Row],[IEP]],55,65),1,0) -> 1
