Workbook

Sheet Scores
A1: Key | B1: Class | C1: Period | D1: Grade | E1: ELL | F1: IEP | G1: MC | H1: Final | I1: 1 | J1: 2 | K1: 3 | L1: 4 | M1: 5 | N1: 6 | O1: SEQ | P1: Q1 | Q1: Q2 | R1: Q3 | S1: Q4 | T1: Q5 | U1: Q6
A2: BCE87468 | B2: Bermejo | C2: 6 | D2: 9 | E2: FALSE | F2: FALSE | G2: =SUM(P2:U2) -> 5 | I2: 3 | J2: 4 | K2: 3 | L2: 2 | M2: 3 | N2: 2 | O2: 3 | P2: =IF(I2=VLOOKUP(VALUE(I$1),Questions[#All],5,FALSE),1,0) -> 1 | Q2: =IF(J2=VLOOKUP(VALUE(J$1),Questions[#All],5,FALSE),1,0) -> 0 | R2: =IF(K2=VLOOKUP(VALUE(K$1),Questions[#All],5,FALSE),1,0) -> 1 | S2: =IF(L2=VLOOKUP(VALUE(L$1),Questions[#All],5,FALSE),1,0) -> 1 | T2: =IF(M2=VLOOKUP(VALUE(M$1),Questions[#All],5,FALSE),1,0) -> 1 | U2: =IF(N2=VLOOKUP(VALUE(N$1),Questions[#All],5,FALSE),1,0) -> 1
A3: PYD85821 | B3: Bermejo | C3: 6 | D3: 9 | E3: FALSE | F3: FALSE | G3: =SUM(P3:U3) -> 4 | I3: 3 | J3: 1 | K3: 3 | L3: 3 | M3: 3 | N3: 3 | O3: 1 | P3: =IF(I3=VLOOKUP(VALUE(I$1),Questions[#All],5,FALSE),1,0) -> 1 | Q3: =IF(J3=VLOOKUP(VALUE(J$1),Questions[#All],5,FALSE),1,0) -> 1 | R3: =IF(K3=VLOOKUP(VALUE(K$1),Questions[#All],5,FALSE),1,0) -> 1 | S3: =IF(L3=VLOOKUP(VALUE(L$1),Questions[#All],5,FALSE),1,0) -> 0 | T3: =IF(M3=VLOOKUP(VALUE(M$1),Questions[#All],5,FALSE),1,0) -> 1 | U3: =IF(N3=VLOOKUP(VALUE(N$1),Questions[#All],5,FALSE),1,0) -> 0
A4: SPL19463 | B4: Bermejo | C4: 6 | D4: 9 | E4: FALSE | F4: FALSE | G4: =SUM(P4:U4) -> 4 | I4: 3 | J4: 1 | K4: 3 | L4: 2 | M4: 1 | N4: 1 | O4: 2 | P4: =IF(I4=VLOOKUP(VALUE(I$1),Questions[#All],5,FALSE),1,0) -> 1 | Q4: =IF(J4=VLOOKUP(VALUE(J$1),Questions[#All],5,FALSE),1,0) -> 1 | R4: =IF(K4=VLOOKUP(VALUE(K$1),Questions[#All],5,FALSE),1,0) -> 1 | S4: =IF(L4=VLOOKUP(VALUE(L$1),Questions[#All],5,FALSE),1,0) -> 1 | T4: =IF(M4=VLOOKUP(VALUE(M$1),Questions[#All],5,FALSE),1,0) -> 0 | U4: =IF(N4=VLOOKUP(VALUE(N$1),Questions[#All],5,FALSE),1,0) -> 0
A5: TFT96599 | B5: Bermejo | C5: 6 | D5: 9 | E5: FALSE | F5: FALSE | G5: =SUM(P5:U5) -> 6 | I5: 3 | J5: 1 | K5: 3 | L5: 2 | M5: 3 | N5: 2 | O5: 1 | P5: =IF(I5=VLOOKUP(VALUE(I$1),Questions[#All],5,FALSE),1,0) -> 1 | Q5: =IF(J5=VLOOKUP(VALUE(J$1),Questions[#All],5,FALSE),1,0) -> 1 | R5: =IF(K5=VLOOKUP(VALUE(K$1),Questions[#All],5,FALSE),1,0) -> 1 | S5: =IF(L5=VLOOKUP(VALUE(L$1),Questions[#All],5,FALSE),1,0) -> 1 | T5: =IF(M5=VLOOKUP(VALUE(M$1),Questions[#All],5,FALSE),1,0) -> 1 | U5: =IF(N5=VLOOKUP(VALUE(N$1),Questions[#All],5,FALSE),1,0) -> 1
A6: AEA52429 | B6: Bermejo | C6: 6 | D6: 9 | E6: FALSE | F6: FALSE | G6: =SUM(P6:U6) -> 5 | I6: 3 | J6: 1 | K6: 3 | L6: 2 | M6: 1 | N6: 2 | O6: 1 | P6: =IF(I6=VLOOKUP(VALUE(I$1),Questions[#All],5,FALSE),1,0) -> 1 | Q6: =IF(J6=VLOOKUP(VALUE(J$1),Questions[#All],5,FALSE),1,0) -> 1 | R6: =IF(K6=VLOOKUP(VALUE(K$1),Questions[#All],5,FALSE),1,0) -> 1 | S6: =IF(L6=VLOOKUP(VALUE(L$1),Questions[#All],5,FALSE),1,0) -> 1 | T6: =IF(M6=VLOOKUP(VALUE(M$1),Questions[#All],5,FALSE),1,0) -> 0 | U6: =IF(N6=VLOOKUP(VALUE(N$1),Questions[#All],5,FALSE),1,0) -> 1
A7: ONK63527 | B7: Bermejo | C7: 6 | D7: 9 | E7: FALSE | F7: FALSE | G7: =SUM(P7:U7) -> 2 | I7: 3 | J7: 2 | K7: 3 | L7: 1 | M7: 2 | N7: 3 | O7: 1 | P7: =IF(I7=VLOOKUP(VALUE(I$1),Questions[#All],5,FALSE),1,0) -> 1 | Q7: =IF(J7=VLOOKUP(VALUE(J$1),Questions[#All],5,FALSE),1,0) -> 0 | R7: =IF(K7=VLOOKUP(VALUE(K$1),Questions[#All],5,FALSE),1,0) -> 1 | S7: =IF(L7=VLOOKUP(VALUE(L$1),Questions[#All],5,FALSE),1,0) -> 0 | T7: =IF(M7=VLOOKUP(VALUE(M$1),Questions[#All],5,FALSE),1,0) -> 0 | U7: =IF(N7=VLOOKUP(VALUE(N$1),Questions[#All],5,FALSE),1,0) -> 0
A8: MPA54097 | B8: Bermejo | C8: 6 | D8: 9 | E8: FALSE | F8: FALSE | G8: =SUM(P8:U8) -> 3 | I8: 1 | J8: 4 | K8: 3 | L8: 4 | M8: 3 | N8: 2 | O8: 1 | P8: =IF(I8=VLOOKUP(VALUE(I$1),Questions[#All],5,FALSE),1,0) -> 0 | Q8: =IF(J8=VLOOKUP(VALUE(J$1),Questions[#All],5,FALSE),1,0) -> 0 | R8: =IF(K8=VLOOKUP(VALUE(K$1),Questions[#All],5,FALSE),1,0) -> 1 | S8: =IF(L8=VLOOKUP(VALUE(L$1),Questions[#All],5,FALSE),1,0) -> 0 | T8: =IF(M8=VLOOKUP(VALUE(M$1),Questions[#All],5,FALSE),1,0) -> 1 | U8: =IF(N8=VLOOKUP(VALUE(N$1),Questions[#All],5,FALSE),1,0) -> 1
A9: PUZ92475 | B9: Bermejo | C9: 6 | D9: 9 | E9: FALSE | F9: FALSE | G9: =SUM(P9:U9) -> 4 | I9: 3 | J9: 4 | K9: 3 | L9: 2 | M9: 1 | N9: 2 | O9: 1 | P9: =IF(I9=VLOOKUP(VALUE(I$1),Questions[#All],5,FALSE),1,0) -> 1 | Q9: =IF(J9=VLOOKUP(VALUE(J$1),Questions[#All],5,FALSE),1,0) -> 0 | R9: =IF(K9=VLOOKUP(VALUE(K$1),Questions[#All],5,FALSE),1,0) -> 1 | S9: =IF(L9=VLOOKUP(VALUE(L$1),Questions[#All],5,FALSE),1,0) -> 1 | T9: =IF(M9=VLOOKUP(VALUE(M$1),Questions[#All],5,FALSE),1,0) -> 0 | U9: =IF(N9=VLOOKUP(VALUE(N$1),Questions[#All],5,FALSE),1,0) -> 1
A10: BFA12371 | B10: Bermejo | C10: 6 | D10: 9 | E10: FALSE | F10: TRUE | G10: =SUM(P10:U10) -> 3 | I10: 4 | J10: 2 | K10: 3 | L10: 2 | M10: 4 | N10: 2 | O10: 0 | P10: =IF(I10=VLOOKUP(VALUE(I$1),Questions[#All],5,FALSE),1,0) -> 0 | Q10: =IF(J10=VLOOKUP(VALUE(J$1),Questions[#All],5,FALSE),1,0) -> 0 | R10: =IF(K10=VLOOKUP(VALUE(K$1),Questions[#All],5,FALSE),1,0) -> 1 | S10: =IF(L10=VLOOKUP(VALUE(L$1),Questions[#All],5,FALSE),1,0) -> 1 | T10: =IF(M10=VLOOKUP(VALUE(M$1),Questions[#All],5,FALSE),1,0) -> 0 | U10: =IF(N10=VLOOKUP(VALUE(N$1),Questions[#All],5,FALSE),1,0) -> 1
A11: BWX22237 | B11: Bermejo | C11: 6 | D11: 9 | E11: FALSE | F11: FALSE | G11: =SUM(P11:U11) -> 2 | I11: 2 | J11: 1 | K11: 3 | M11: 1 | N11: 3 | O11: 3 | P11: =IF(I11=VLOOKUP(VALUE(I$1),Questions[#All],5,FALSE),1,0) -> 0 | Q11: =IF(J11=VLOOKUP(VALUE(J$1),Questions[#All],5,FALSE),1,0) -> 1 | R11: =IF(K11=VLOOKUP(VALUE(K$1),Questions[#All],5,FALSE),1,0) -> 1 | S11: =IF(L11=VLOOKUP(VALUE(L$1),Questions[#All],5,FALSE),1,0) -> 0 | T11: =IF(M11=VLOOKUP(VALUE(M$1),Questions[#All],5,FALSE),1,0) -> 0 | U11: =IF(N11=VLOOKUP(VALUE(N$1),Questions[#All],5,FALSE),1,0) -> 0
A12: MRQ47886 | B12: Bermejo | C12: 6 | D12: 9 | E12: FALSE | F12: FALSE | G12: =SUM(P12:U12) -> 1 | I12: 2 | J12: 2 | K12: 3 | L12: 3 | M12: 1 | N12: 1 | O12: 1 | P12: =IF(I12=VLOOKUP(VALUE(I$1),Questions[#All],5,FALSE),1,0) -> 0 | Q12: =IF(J12=VLOOKUP(VALUE(J$1),Questions[#All],5,FALSE),1,0) -> 0 | R12: =IF(K12=VLOOKUP(VALUE(K$1),Questions[#All],5,FALSE),1,0) -> 1 | S12: =IF(L12=VLOOKUP(VALUE(L$1),Questions[#All],5,FALSE),1,0) -> 0 | T12: =IF(M12=VLOOKUP(VALUE(M$1),Questions[#All],5,FALSE),1,0) -> 0 | U12: =IF(N12=VLOOKUP(VALUE(N$1),Questions[#All],5,FALSE),1,0) -> 0
A13: DTY88033 | B13: Bermejo | C13: 6 | D13: 9 | E13: FALSE | F13: FALSE | G13: =SUM(P13:U13) -> 6 | I13: 3 | J13: 1 | K13: 3 | L13: 2 | M13: 3 | N13: 2 | O13: 3 | P13: =IF(I13=VLOOKUP(VALUE(I$1),Questions[#All],5,FALSE),1,0) -> 1 | Q13: =IF(J13=VLOOKUP(VALUE(J$1),Questions[#All],5,FALSE),1,0) -> 1 | R13: =IF(K13=VLOOKUP(VALUE(K$1),Questions[#All],5,FALSE),1,0) -> 1 | S13: =IF(L13=VLOOKUP(VALUE(L$1),Questions[#All],5,FALSE),1,0) -> 1 | T13: =IF(M13=VLOOKUP(VALUE(M$1),Questions[#All],5,FALSE),1,0) -> 1 | U13: =IF(N13=VLOOKUP(VALUE(N$1),Questions[#All],5,FALSE),1,0) -> 1
A14: EBH29779 | B14: Bermejo | C14: 6 | D14: 9 | E14: FALSE | F14: TRUE | G14: =SUM(P14:U14) -> 1 | I14: 4 | J14: 2 | K14: 3 | L14: 3 | M14: 4 | N14: 1 | O14: 0 | P14: =IF(I14=VLOOKUP(VALUE(I$1),Questions[#All],5,FALSE),1,0) -> 0 | Q14: =IF(J14=VLOOKUP(VALUE(J$1),Questions[#All],5,FALSE),1,0) -> 0 | R14: =IF(K14=VLOOKUP(VALUE(K$1),Questions[#All],5,FALSE),1,0) -> 1 | S14: =IF(L14=VLOOKUP(VALUE(L$1),Questions[#All],5,FALSE),1,0) -> 0 | T14: =IF(M14=VLOOKUP(VALUE(M$1),Questions[#All],5,FALSE),1,0) -> 0 | U14: =IF(N14=VLOOKUP(VALUE(N$1),Questions[#All],5,FALSE),1,0) -> 0
A15: BJO21212 | B15: Bermejo | C15: 8 | D15: 9 | E15: FALSE | F15: FALSE | G15: =SUM(P15:U15) -> 3 | I15: 4 | J15: 1 | K15: 3 | L15: 2 | M15: 1 | N15: 4 | O15: 1 | P15: =IF(I15=VLOOKUP(VALUE(I$1),Questions[#All],5,FALSE),1,0) -> 0 | Q15: =IF(J15=VLOOKUP(VALUE(J$1),Questions[#All],5,FALSE),1,0) -> 1 | R15: =IF(K15=VLOOKUP(VALUE(K$1),Questions[#All],5,FALSE),1,0) -> 1 | S15: =IF(L15=VLOOKUP(VALUE(L$1),Questions[#All],5,FALSE),1,0) -> 1 | T15: =IF(M15=VLOOKUP(VALUE(M$1),Questions[#All],5,FALSE),1,0) -> 0 | U15: =IF(N15=VLOOKUP(VALUE(N$1),Questions[#All],5,FALSE),1,0) -> 0
A16: JLX21297 | B16: Bermejo | C16: 8 | D16: 9 | E16: FALSE | F16: FALSE | G16: =SUM(P16:U16) -> 6 | I16: 3 | J16: 1 | K16: 3 | L16: 2 | M16: 3 | N16: 2 | O16: 2 | P16: =IF(I16=VLOOKUP(VALUE(I$1),Questions[#All],5,FALSE),1,0) -> 1 | Q16: =IF(J16=VLOOKUP(VALUE(J$1),Questions[#All],5,FALSE),1,0) -> 1 | R16: =IF(K16=VLOOKUP(VALUE(K$1),Questions[#All],5,FALSE),1,0) -> 1 | S16: =IF(L16=VLOOKUP(VALUE(L$1),Questions[#All],5,FALSE),1,0) -> 1 | T16: =IF(M16=VLOOKUP(VALUE(M$1),Questions[#All],5,FALSE),1,0) -> 1 | U16: =IF(N16=VLOOKUP(VALUE(N$1),Questions[#All],5,FALSE),1,0) -> 1
A17: VHW73020 | B17: Bermejo | C17: 8 | D17: 9 | E17: FALSE | F17: FALSE | G17: =SUM(P17:U17) -> 5 | I17: 3 | J17: 1 | K17: 3 | L17: 2 | M17: 1 | N17: 2 | O17: 2 | P17: =IF(I17=VLOOKUP(VALUE(I$1),Questions[#All],5,FALSE),1,0) -> 1 | Q17: =IF(J17=VLOOKUP(VALUE(J$1),Questions[#All],5,FALSE),1,0) -> 1 | R17: =IF(K17=VLOOKUP(VALUE(K$1),Questions[#All],5,FALSE),1,0) -> 1 | S17: =IF(L17=VLOOKUP(VALUE(L$1),Questions[#All],5,FALSE),1,0) -> 1 | T17: =IF(M17=VLOOKUP(VALUE(M$1),Questions[#All],5,FALSE),1,0) -> 0 | U17: =IF(N17=VLOOKUP(VALUE(N$1),Questions[#All],5,FALSE),1,0) -> 1
A18: TXB14318 | B18: Bermejo | C18: 8 | D18: 9 | E18: FALSE | F18: TRUE | G18: =SUM(P18:U18) -> 2 | I18: 2 | J18: 2 | K18: 3 | L18: 1 | M18: 3 | N18: 4 | O18: 3 | P18: =IF(I18=VLOOKUP(VALUE(I$1),Questions[#All],5,FALSE),1,0) -> 0 | Q18: =IF(J18=VLOOKUP(VALUE(J$1),Questions[#All],5,FALSE),1,0) -> 0 | R18: =IF(K18=VLOOKUP(VALUE(K$1),Questions[#All],5,FALSE),1,0) -> 1 | S18: =IF(L18=VLOOKUP(VALUE(L$1),Questions[#All],5,FALSE),1,0) -> 0 | T18: =IF(M18=VLOOKUP(VALUE(M$1),Questions[#All],5,FALSE),1,0) -> 1 | U18: =IF(N18=VLOOKUP(VALUE(N$1),Questions[#All],5,FALSE),1,0) -> 0
A19: ZMS92794 | B19: Bermejo | C19: 8 | D19: 9 | E19: FALSE | F19: TRUE | G19: =SUM(P19:U19) -> 1 | I19: 2 | J19: 3 | K19: 1 | L19: 4 | M19: 4 | N19: 2 | O19: 1 | P19: =IF(I19=VLOOKUP(VALUE(I$1),Questions[#All],5,FALSE),1,0) -> 0 | Q19: =IF(J19=VLOOKUP(VALUE(J$1),Questions[#All],5,FALSE),1,0) -> 0 | R19: =IF(K19=VLOOKUP(VALUE(K$1),Questions[#All],5,FALSE),1,0) -> 0 | S19: =IF(L19=VLOOKUP(VALUE(L$1),Questions[#All],5,FALSE),1,0) -> 0 | T19: =IF(M19=VLOOKUP(VALUE(M$1),Questions[#All],5,FALSE),1,0) -> 0 | U19: =IF(N19=VLOOKUP(VALUE(N$1),Questions[#All],5,FALSE),1,0) -> 1
A20: RQY44411 | B20: Bermejo | C20: 8 | D20: 9 | E20: FALSE | F20: FALSE | G20: =SUM(P20:U20) -> 0 | P20: =IF(I20=VLOOKUP(VALUE(I$1),Questions[#All],5,FALSE),1,0) -> 0 | Q20: =IF(J20=VLOOKUP(VALUE(J$1),Questions[#All],5,FALSE),1,0) -> 0 | R20: =IF(K20=VLOOKUP(VALUE(K$1),Questions[#All],5,FALSE),1,0) -> 0 | S20: =IF(L20=VLOOKUP(VALUE(L$1),Questions[#All],5,FALSE),1,0) -> 0 | T20: =IF(M20=VLOOKUP(VALUE(M$1),Questions[#All],5,FALSE),1,0) -> 0 | U20: =IF(N20=VLOOKUP(VALUE(N$1),Questions[#All],5,FALSE),1,0) -> 0
A21: OTM13405 | B21: Bermejo | C21: 8 | D21: 9 | E21: FALSE | F21: FALSE | G21: =SUM(P21:U21) -> 2 | I21: 3 | J21: 4 | K21: 3 | L21: 3 | M21: 1 | P21: =IF(I21=VLOOKUP(VALUE(I$1),Questions[#All],5,FALSE),1,0) -> 1 | Q21: =IF(J21=VLOOKUP(VALUE(J$1),Questions[#All],5,FALSE),1,0) -> 0 | R21: =IF(K21=VLOOKUP(VALUE(K$1),Questions[#All],5,FALSE),1,0) -> 1 | S21: =IF(L21=VLOOKUP(VALUE(L$1),Questions[#All],5,FALSE),1,0) -> 0 | T21: =IF(M21=VLOOKUP(VALUE(M$1),Questions[#All],5,FALSE),1,0) -> 0 | U21: =IF(N21=VLOOKUP(VALUE(N$1),Questions[#All],5,FALSE),1,0) -> 0
A22: HOT90521 | B22: Bermejo | C22: 8 | D22: 9 | E22: FALSE | F22: FALSE | G22: =SUM(P22:U22) -> 5 | I22: 1 | J22: 1 | K22: 3 | L22: 2 | M22: 3 | N22: 2 | O22: 2 | P22: =IF(I22=VLOOKUP(VALUE(I$1),Questions[#All],5,FALSE),1,0) -> 0 | Q22: =IF(J22=VLOOKUP(VALUE(J$1),Questions[#All],5,FALSE),1,0) -> 1 | R22: =IF(K22=VLOOKUP(VALUE(K$1),Questions[#All],5,FALSE),1,0) -> 1 | S22: =IF(L22=VLOOKUP(VALUE(L$1),Questions[#All],5,FALSE),1,0) -> 1 | T22: =IF(M22=VLOOKUP(VALUE(M$1),Questions[#All],5,FALSE),1,0) -> 1 | U22: =IF(N22=VLOOKUP(VALUE(N$1),Questions[#All],5,FALSE),1,0) -> 1
A23: RTH79332 | B23: Bermejo | C23: 8 | D23: 9 | E23: FALSE | F23: FALSE | G23: =SUM(P23:U23) -> 3 | I23: 4 | J23: 1 | K23: 3 | L23: 3 | M23: 1 | N23: 2 | O23: 1 | P23: =IF(I23=VLOOKUP(VALUE(I$1),Questions[#All],5,FALSE),1,0) -> 0 | Q23: =IF(J23=VLOOKUP(VALUE(J$1),Questions[#All],5,FALSE),1,0) -> 1 | R23: =IF(K23=VLOOKUP(VALUE(K$1),Questions[#All],5,FALSE),1,0) -> 1 | S23: =IF(L23=VLOOKUP(VALUE(L$1),Questions[#All],5,FALSE),1,0) -> 0 | T23: =IF(M23=VLOOKUP(VALUE(M$1),Questions[#All],5,FALSE),1,0) -> 0 | U23: =IF(N23=VLOOKUP(VALUE(N$1),Questions[#All],5,FALSE),1,0) -> 1
A24: XXD85883 | B24: Bermejo | C24: 8 | D24: 9 | E24: FALSE | F24: FALSE | G24: =SUM(P24:U24) -> 4 | I24: 1 | J24: 2 | K24: 3 | L24: 2 | M24: 3 | N24: 2 | O24: 1 | P24: =IF(I24=VLOOKUP(VALUE(I$1),Questions[#All],5,FALSE),1,0) -> 0 | Q24: =IF(J24=VLOOKUP(VALUE(J$1),Questions[#All],5,FALSE),1,0) -> 0 | R24: =IF(K24=VLOOKUP(VALUE(K$1),Questions[#All],5,FALSE),1,0) -> 1 | S24: =IF(L24=VLOOKUP(VALUE(L$1),Questions[#All],5,FALSE),1,0) -> 1 | T24: =IF(M24=VLOOKUP(VALUE(M$1),Questions[#All],5,FALSE),1,0) -> 1 | U24: =IF(N24=VLOOKUP(VALUE(N$1),Questions[#All],5,FALSE),1,0) -> 1
A25: LFK75199 | B25: Bermejo | C25: 8 | D25: 9 | E25: FALSE | F25: TRUE | G25: =SUM(P25:U25) -> 4 | I25: 2 | J25: 1 | K25: 3 | L25: 2 | M25: 3 | N25: 4 | O25: 1 | P25: =IF(I25=VLOOKUP(VALUE(I$1),Questions[#All],5,FALSE),1,0) -> 0 | Q25: =IF(J25=VLOOKUP(VALUE(J$1),Questions[#All],5,FALSE),1,0) -> 1 | R25: =IF(K25=VLOOKUP(VALUE(K$1),Questions[#All],5,FALSE),1,0) -> 1 | S25: =IF(L25=VLOOKUP(VALUE(L$1),Questions[#All],5,FALSE),1,0) -> 1 | T25: =IF(M25=VLOOKUP(VALUE(M$1),Questions[#All],5,FALSE),1,0) -> 1 | U25: =IF(N25=VLOOKUP(VALUE(N$1),Questions[#All],5,FALSE),1,0) -> 0
A26: AZH29276 | B26: Bermejo | C26: 8 | D26: 9 | E26: TRUE | F26: FALSE | G26: =SUM(P26:U26) -> 2 | I26: 3 | J26: 1 | K26: 2 | L26: 3 | M26: 1 | N26: 4 | O26: 1 | P26: =IF(I26=VLOOKUP(VALUE(I$1),Questions[#All],5,FALSE),1,0) -> 1 | Q26: =IF(J26=VLOOKUP(VALUE(J$1),Questions[#All],5,FALSE),1,0) -> 1 | R26: =IF(K26=VLOOKUP(VALUE(K$1),Questions[#All],5,FALSE),1,0) -> 0 | S26: =IF(L26=VLOOKUP(VALUE(L$1),Questions[#All],5,FALSE),1,0) -> 0 | T26: =IF(M26=VLOOKUP(VALUE(M$1),Questions[#All],5,FALSE),1,0) -> 0 | U26: =IF(N26=VLOOKUP(VALUE(N$1),Questions[#All],5,FALSE),1,0) -> 0
A27: JSN75135 | B27: Bermejo | C27: 8 | D27: 9 | E27: FALSE | F27: TRUE | G27: =SUM(P27:U27) -> 1 | I27: 4 | J27: 3 | K27: 2 | L27: 3 | M27: 3 | N27: 1 | O27: 2 | P27: =IF(I27=VLOOKUP(VALUE(I$1),Questions[#All],5,FALSE),1,0) -> 0 | Q27: =IF(J27=VLOOKUP(VALUE(J$1),Questions[#All],5,FALSE),1,0) -> 0 | R27: =IF(K27=VLOOKUP(VALUE(K$1),Questions[#All],5,FALSE),1,0) -> 0 | S27: =IF(L27=VLOOKUP(VALUE(L$1),Questions[#All],5,FALSE),1,0) -> 0 | T27: =IF(M27=VLOOKUP(VALUE(M$1),Questions[#All],5,FALSE),1,0) -> 1 | U27: =IF(N27=VLOOKUP(VALUE(N$1),Questions[#All],5,FALSE),1,0) -> 0
A28: MDS28198 | B28: Bermejo | C28: 8 | D28: 9 | E28: FALSE | F28: FALSE | G28: =SUM(P28:U28) -> 5 | I28: 3 | J28: 1 | K28: 3 | L28: 2 | M28: 1 | N28: 2 | O28: 3 | P28: =IF(I28=VLOOKUP(VALUE(I$1),Questions[#All],5,FALSE),1,0) -> 1 | Q28: =IF(J28=VLOOKUP(VALUE(J$1),Questions[#All],5,FALSE),1,0) -> 1 | R28: =IF(K28=VLOOKUP(VALUE(K$1),Questions[#All],5,FALSE),1,0) -> 1 | S28: =IF(L28=VLOOKUP(VALUE(L$1),Questions[#All],5,FALSE),1,0) -> 1 | T28: =IF(M28=VLOOKUP(VALUE(M$1),Questions[#All],5,FALSE),1,0) -> 0 | U28: =IF(N28=VLOOKUP(VALUE(N$1),Questions[#All],5,FALSE),1,0) -> 1
A29: BBW35809 | B29: Dushin | C29: 3 | D29: 9 | E29: FALSE | F29: FALSE | G29: =SUM(P29:U29) -> 3 | I29: 3 | J29: 2 | K29: 4 | L29: 2 | M29: 1 | N29: 2 | O29: 2 | P29: =IF(I29=VLOOKUP(VALUE(I$1),Questions[#All],5,FALSE),1,0) -> 1 | Q29: =IF(J29=VLOOKUP(VALUE(J$1),Questions[#All],5,FALSE),1,0) -> 0 | R29: =IF(K29=VLOOKUP(VALUE(K$1),Questions[#All],5,FALSE),1,0) -> 0 | S29: =IF(L29=VLOOKUP(VALUE(L$1),Questions[#All],5,FALSE),1,0) -> 1 | T29: =IF(M29=VLOOKUP(VALUE(M$1),Questions[#All],5,FALSE),1,0) -> 0 | U29: =IF(N29=VLOOKUP(VALUE(N$1),Questions[#All],5,FALSE),1,0) -> 1
A30: QJC38094 | B30: Dushin | C30: 3 | D30: 9 | E30: FALSE | F30: FALSE | G30: =SUM(P30:U30) -> 3 | I30: 4 | J30: 1 | K30: 3 | L30: 2 | M30: 1 | O30: 2 | P30: =IF(I30=VLOOKUP(VALUE(I$1),Questions[#All],5,FALSE),1,0) -> 0 | Q30: =IF(J30=VLOOKUP(VALUE(J$1),Questions[#All],5,FALSE),1,0) -> 1 | R30: =IF(K30=VLOOKUP(VALUE(K$1),Questions[#All],5,FALSE),1,0) -> 1 | S30: =IF(L30=VLOOKUP(VALUE(L$1),Questions[#All],5,FALSE),1,0) -> 1 | T30: =IF(M30=VLOOKUP(VALUE(M$1),Questions[#All],5,FALSE),1,0) -> 0 | U30: =IF(N30=VLOOKUP(VALUE(N$1),Questions[#All],5,FALSE),1,0) -> 0
A31: EXL78479 | B31: Dushin | C31: 3 | D31: 9 | E31: TRUE | F31: FALSE | G31: =SUM(P31:U31) -> 5 | I31: 3 | J31: 1 | K31: 3 | L31: 2 | M31: 1 | N31: 2 | O31: 0 | P31: =IF(I31=VLOOKUP(VALUE(I$1),Questions[#All],5,FALSE),1,0) -> 1 | Q31: =IF(J31=VLOOKUP(VALUE(J$1),Questions[#All],5,FALSE),1,0) -> 1 | R31: =IF(K31=VLOOKUP(VALUE(K$1),Questions[#All],5,FALSE),1,0) -> 1 | S31: =IF(L31=VLOOKUP(VALUE(L$1),Questions[#All],5,FALSE),1,0) -> 1 | T31: =IF(M31=VLOOKUP(VALUE(M$1),Questions[#All],5,FALSE),1,0) -> 0 | U31: =IF(N31=VLOOKUP(VALUE(N$1),Questions[#All],5,FALSE),1,0) -> 1
A32: QMV74206 | B32: Dushin | C32: 3 | D32: 9 | E32: FALSE | F32: TRUE | G32: =SUM(P32:U32) -> 3 | I32: 3 | J32: 1 | K32: 2 | L32: 3 | M32: 3 | N32: 4 | P32: =IF(I32=VLOOKUP(VALUE(I$1),Questions[#All],5,FALSE),1,0) -> 1 | Q32: =IF(J32=VLOOKUP(VALUE(J$1),Questions[#All],5,FALSE),1,0) -> 1 | R32: =IF(K32=VLOOKUP(VALUE(K$1),Questions[#All],5,FALSE),1,0) -> 0 | S32: =IF(L32=VLOOKUP(VALUE(L$1),Questions[#All],5,FALSE),1,0) -> 0 | T32: =IF(M32=VLOOKUP(VALUE(M$1),Questions[#All],5,FALSE),1,0) -> 1 | U32: =IF(N32=VLOOKUP(VALUE(N$1),Questions[#All],5,FALSE),1,0) -> 0
A33: CIT87934 | B33: Dushin | C33: 3 | D33: 9 | E33: FALSE | F33: FALSE | G33: =SUM(P33:U33) -> 2 | I33: 2 | J33: 1 | K33: 4 | L33: 2 | M33: 1 | N33: 3 | O33: 2 | P33: =IF(I33=VLOOKUP(VALUE(I$1),Questions[#All],5,FALSE),1,0) -> 0 | Q33: =IF(J33=VLOOKUP(VALUE(J$1),Questions[#All],5,FALSE),1,0) -> 1 | R33: =IF(K33=VLOOKUP(VALUE(K$1),Questions[#All],5,FALSE),1,0) -> 0 | S33: =IF(L33=VLOOKUP(VALUE(L$1),Questions[#All],5,FALSE),1,0) -> 1 | T33: =IF(M33=VLOOKUP(VALUE(M$1),Questions[#All],5,FALSE),1,0) -> 0 | U33: =IF(N33=VLOOKUP(VALUE(N$1),Questions[#All],5,FALSE),1,0) -> 0
A34: CLQ75171 | B34: Dushin | C34: 3 | D34: 9 | E34: TRUE | F34: FALSE | G34: =SUM(P34:U34) -> 3 | I34: 3 | J34: 1 | K34: 3 | L34: 4 | M34: 2 | N34: 1 | O34: 0 | P34: =IF(I34=VLOOKUP(VALUE(I$1),Questions[#All],5,FALSE),1,0) -> 1 | Q34: =IF(J34=VLOOKUP(VALUE(J$1),Questions[#All],5,FALSE),1,0) -> 1 | R34: =IF(K34=VLOOKUP(VALUE(K$1),Questions[#All],5,FALSE),1,0) -> 1 | S34: =IF(L34=VLOOKUP(VALUE(L$1),Questions[#All],5,FALSE),1,0) -> 0 | T34: =IF(M34=VLOOKUP(VALUE(M$1),Questions[#All],5,FALSE),1,0) -> 0 | U34: =IF(N34=VLOOKUP(VALUE(N$1),Questions[#All],5,FALSE),1,0) -> 0
A35: FXD68642 | B35: Dushin | C35: 3 | D35: 9 | E35: FALSE | F35: FALSE | G35: =SUM(P35:U35) -> 3 | I35: 3 | J35: 4 | K35: 1 | L35: 2 | M35: 4 | N35: 2 | O35: 0 | P35: =IF(I35=VLOOKUP(VALUE(I$1),Questions[#All],5,FALSE),1,0) -> 1 | Q35: =IF(J35=VLOOKUP(VALUE(J$1),Questions[#All],5,FALSE),1,0) -> 0 | R35: =IF(K35=VLOOKUP(VALUE(K$1),Questions[#All],5,FALSE),1,0) -> 0 | S35: =IF(L35=VLOOKUP(VALUE(L$1),Questions[#All],5,FALSE),1,0) -> 1 | T35: =IF(M35=VLOOKUP(VALUE(M$1),Questions[#All],5,FALSE),1,0) -> 0 | U35: =IF(N35=VLOOKUP(VALUE(N$1),Questions[#All],5,FALSE),1,0) -> 1
A36: AEU59958 | B36: Dushin | C36: 3 | D36: 9 | E36: FALSE | F36: FALSE | G36: =SUM(P36:U36) -> 2 | I36: 4 | J36: 2 | K36: 3 | L36: 3 | M36: 1 | N36: 2 | O36: 4 | P36: =IF(I36=VLOOKUP(VALUE(I$1),Questions[#All],5,FALSE),1,0) -> 0 | Q36: =IF(J36=VLOOKUP(VALUE(J$1),Questions[#All],5,FALSE),1,0) -> 0 | R36: =IF(K36=VLOOKUP(VALUE(K$1),Questions[#All],5,FALSE),1,0) -> 1 | S36: =IF(L36=VLOOKUP(VALUE(L$1),Questions[#All],5,FALSE),1,0) -> 0 | T36: =IF(M36=VLOOKUP(VALUE(M$1),Questions[#All],5,FALSE),1,0) -> 0 | U36: =IF(N36=VLOOKUP(VALUE(N$1),Questions[#All],5,FALSE),1,0) -> 1
A37: JXA20997 | B37: Dushin | C37: 3 | D37: 9 | E37: FALSE | F37: FALSE | G37: =SUM(P37:U37) -> 3 | I37: 2 | J37: 4 | K37: 3 | L37: 2 | M37: 1 | N37: 2 | P37: =IF(I37=VLOOKUP(VALUE(I$1),Questions[#All],5,FALSE),1,0) -> 0 | Q37: =IF(J37=VLOOKUP(VALUE(J$1),Questions[#All],5,FALSE),1,0) -> 0 | R37: =IF(K37=VLOOKUP(VALUE(K$1),Questions[#All],5,FALSE),1,0) -> 1 | S37: =IF(L37=VLOOKUP(VALUE(L$1),Questions[#All],5,FALSE),1,0) -> 1 | T37: =IF(M37=VLOOKUP(VALUE(M$1),Questions[#All],5,FALSE),1,0) -> 0 | U37: =IF(N37=VLOOKUP(VALUE(N$1),Questions[#All],5,FALSE),1,0) -> 1
A38: LOB72239 | B38: Dushin | C38: 3 | D38: 9 | E38: FALSE | F38: FALSE | G38: =SUM(P38:U38) -> 2 | I38: 4 | J38: 3 | K38: 3 | L38: 3 | M38: 1 | N38: 2 | O38: 3 | P38: =IF(I38=VLOOKUP(VALUE(I$1),Questions[#All],5,FALSE),1,0) -> 0 | Q38: =IF(J38=VLOOKUP(VALUE(J$1),Questions[#All],5,FALSE),1,0) -> 0 | R38: =IF(K38=VLOOKUP(VALUE(K$1),Questions[#All],5,FALSE),1,0) -> 1 | S38: =IF(L38=VLOOKUP(VALUE(L$1),Questions[#All],5,FALSE),1,0) -> 0 | T38: =IF(M38=VLOOKUP(VALUE(M$1),Questions[#All],5,FALSE),1,0) -> 0 | U38: =IF(N38=VLOOKUP(VALUE(N$1),Questions[#All],5,FALSE),1,0) -> 1
A39: MND12981 | B39: Dushin | C39: 3 | D39: 9 | E39: FALSE | F39: FALSE | G39: =SUM(P39:U39) -> 4 | I39: 4 | J39: 1 | K39: 3 | L39: 2 | M39: 4 | N39: 2 | O39: 1 | P39: =IF(I39=VLOOKUP(VALUE(I$1),Questions[#All],5,FALSE),1,0) -> 0 | Q39: =IF(J39=VLOOKUP(VALUE(J$1),Questions[#All],5,FALSE),1,0) -> 1 | R39: =IF(K39=VLOOKUP(VALUE(K$1),Questions[#All],5,FALSE),1,0) -> 1 | S39: =IF(L39=VLOOKUP(VALUE(L$1),Questions[#All],5,FALSE),1,0) -> 1 | T39: =IF(M39=VLOOKUP(VALUE(M$1),Questions[#All],5,FALSE),1,0) -> 0 | U39: =IF(N39=VLOOKUP(VALUE(N$1),Questions[#All],5,FALSE),1,0) -> 1
A40: DTP58821 | B40: Dushin | C40: 3 | D40: 9 | E40: FALSE | F40: FALSE | G40: =SUM(P40:U40) -> 3 | I40: 2 | J40: 1 | K40: 3 | L40: 2 | M40: 4 | N40: 1 | O40: 2 | P40: =IF(I40=VLOOKUP(VALUE(I$1),Questions[#All],5,FALSE),1,0) -> 0 | Q40: =IF(J40=VLOOKUP(VALUE(J$1),Questions[#All],5,FALSE),1,0) -> 1 | R40: =IF(K40=VLOOKUP(VALUE(K$1),Questions[#All],5,FALSE),1,0) -> 1 | S40: =IF(L40=VLOOKUP(VALUE(L$1),Questions[#All],5,FALSE),1,0) -> 1 | T40: =IF(M40=VLOOKUP(VALUE(M$1),Questions[#All],5,FALSE),1,0) -> 0 | U40: =IF(N40=VLOOKUP(VALUE(N$1),Questions[#All],5,FALSE),1,0) -> 0
...

Sheet Questions
A1: # | B1: Part | C1: Stimulus | D1: Question | E1: Key | F1: Option_1 | G1: Option_2 | H1: Option_3 | I1: Option_4 | J1: Stimulus_type | K1: Source_type | L1: Task_model | M1: Skill_standard | N1: Need_OI? | O1: Content_standard | P1: Pct_Correct | Q1: Point_Biserial
A2: 1 | B2: Part I | C2: Excerpt from John Robinson's Farewell Address to the Pilgrims (1620) | D2: Based on this excerpt, what is the author’s point of view about the role of government in the Plymouth Colony? | E2: 3 | F2: Separate leaders for church and state should be elected. | G2: People have the right to rebel against the government. | H2: The power to govern belongs to the people. | I2: Rulers must be given absolute authority to govern. | J2: Text-based | K2: Primary | L2: 2. POV | M2: A.3: Sourcing & Point of View | N2: No | O2: 11.01c.2: Colonial Democracy & Key Documents | P2: {=AVERAGE(INDEX(Scores!$B$2:$U$140,0,MATCH("Q"&$A2,Scores!$B$1:$U$1,0)))} -> 0.52517986
A3: 2 | B3: Part I | C3: Excerpt from John Robinson's Farewell Address to the Pilgrims (1620) | D3: Which document most closely reflects the ideas about government expressed by John Robinson in this address? | E3: 1 | F3: Mayflower Compact | G3: Maryland Toleration Act | H3: Stamp Act | I3: Townshend Acts | J3: Text-based | K3: Primary | L3: 10. Compare | M3: C.3: Comparing Developments | N3: Yes | O3: 11.01c.2: Colonial Democracy & Key Documents | P3: {=AVERAGE(INDEX(Scores!$B$2:$U$140,0,MATCH("Q"&$A3,Scores!$B$1:$U$1,0)))} -> 0.49640288
A4: 3 | B4: Part I | C4: Passage from John Josselyn's account of New England (1638) | D4: The events described in this account could be considered a turning point in history because | E4: 3 | F4: The author of this account went on to become a powerful English Lord. | G4: Native American societies grew strong again after contracting European diseases, resulting in an increase in Native populations at this time. | H4: Native Americans in the British colonies experienced a drastic decline in population due to disease and war brought by Europeans. | I4: New England colonists repaired relationships with Native Americans soon after the incidents described. | J4: Text-based | K4: Primary | L4: 5. Turning Point | M4: B.5: Continuity & Change | N4: Yes | O4: 11.01a.2: Colonization Impact on Native Americans | P4: {=AVERAGE(INDEX(Scores!$B$2:$U$140,0,MATCH("Q"&$A4,Scores!$B$1:$U$1,0)))} -> 0.79856115
A5: 4 | B5: Part I | C5: Passage from John Josselyn's account of New England (1638) | D5: Based on the information provided in this account, which claim is most plausible? | E5: 2 | F5: Native American peoples were welcoming to European colonists who settled in North America. | G5: Native American populations were susceptible to diseases to which they had no previous exposure. | H5: European colonists poisoned Native peoples intentionally, decimating their population. | I5: Native American civilization was far inferior to European civilization | J5: Text-based | K5: Primary | L5: 4. Claim Validity (Without Outside Information) | M5: A.5: Inferences & Conclusions | N5: No | O5: 11.01a.2: Colonization Impact on Native Americans | P5: {=AVERAGE(INDEX(Scores!$B$2:$U$140,0,MATCH("Q"&$A5,Scores!$B$1:$U$1,0)))} -> 0.73381295
A6: 5 | B6: Part I | C6: Excerpt on colonial slavery (Engerman, Sutch & Wright, 2003) and an image | D6: Based on both the excerpt and the image, which is most likely responsible for the action shown in the image? | E6: 3 | F6: The decline of the institution of slavery in England by the early 17th century. | G6: Increased 19th century demand for cotton grown in the deep southern U.S. | H6: Increased 18th century demand for tobacco grown in the Chesapeake region of the U.S. | I6: Increased demand for white indentured servants in the Southern states. | J6: Multiple | K6: Secondary | L6: 7. Cause | M6: B.2: Cause & Effect | N6: Yes | O6: 11.01b.3: Colonial Slavery | P6: {=AVERAGE(INDEX(Scores!$B$2:$U$140,0,MATCH("Q"&$A6,Scores!$B$1:$U$1,0)))} -> 0.34532374
A7: 6 | B7: Part I | C7: Excerpt on colonial slavery (Engerman, Sutch & Wright, 2003) and an image | D7: Which statement best describes a result of the historical events referenced in the excerpt and the image? | E7: 2 | F7: Southern planters relied more heavily on white indentured servants to produce cotton. | G7: Generations of people with African ancestry were legally subjected to lifetime enslavement. | H7: Southern planters began to cultivate tobacco during the 18th century. | I7: White indentured servants increasingly joined with black workers to fight for their rights. | J7: Multiple | K7: Secondary | L7: 8. Effect | M7: B.2: Cause & Effect | N7: No | O7: 11.01b.3: Colonial Slavery | P7: {=AVERAGE(INDEX(Scores!$B$2:$U$140,0,MATCH("Q"&$A7,Scores!$B$1:$U$1,0)))} -> 0.67625899
A8: 7 | B8: Part II | C8: Two documents: Miantonomo's plea for unity (1642) and John Lawson's A New Voyage to Carolina (1709) | D8: Read and analyze the documents. In a short essay: (1) describe the historical context surrounding Documents 1 and 2; (2) analyze Document 1 and explain how audience, purpose, bias, or point of view affects its use as a reliable source of evidence. | J8: Text-based | O8: 11.01a.2: Colonization Impact on Native Americans

Sheet Task Models
A1: Model | B1: Detail
A2: 1. Best Use | B2: Students are given a stimulus and asked to evaluate and classify (identify) best use.
A3: 2. POV | B3: Students are given a stimulus and asked to identify point of view, purpose, context, bias, format of source, location of source in time and/or place, and/or intended audience of sources using background knowledge.
A4: 3. Claim Validity (With Outside Information) | B4: Students are given a stimulus and asked to identify support for a claim found in the stimulus (bound in the same timeframe/event/space). It must require students to draw on their knowledge rather than on straight comprehension of text.
A5: 4. Claim Validity (Without Outside Information) | B5: Students are given a stimulus and asked to select a plausible claim that logically follows from evidence presented.
A6: 5. Turning Point | B6: Students are given a stimulus and asked to identify the significance of a turning point in history.
A7: 6. Change Over Time | B7: Students are given a stimulus and asked to identify significance of an event, action, idea, or development as part of change or part of continuity in history.
A8: 7. Cause | B8: Students are given a stimulus and asked to identify a central cause of the described phenomenon.
A9: 8. Effect | B9: Students are given a stimulus and asked to identify a central effect of the described phenomenon.
A10: 9. Impact of Setting | B10: Students are given a stimulus and asked to identify the impact of time and place on an issue or event linked to that stimulus.
A11: 10. Compare | B11: Students are given one stimulus or two stimuli and asked to identify a similarity in the described phenomenon (historical development, historical event, geographic setting, economic situation, individual’s action/belief) (implicit comparison).
A12: 11. Contrast | B12: Students are given one/two stimuli and asked to identify a difference in the described phenomenon (historical development, historical event, geographic setting, economic situation, individual’s action/belief) (implicit comparison).
... A19: 18. Response to Problem | B19: Students are given one stimulus or two stimuli and asked to identify a response to a problem (issue).

Sheet Skill Standards
A1: Standard | B1: Concept | C1: Specification
A2: A. Gathering, Interpreting, and Using Evidence | B2: A.1: Framing Questions & Hypotheses | C2: Define and frame questions about events and the world in which we live, form hypotheses as potential answers to these questions, use evidence to answer these questions, and consider and analyze counter-hypotheses.
A3: A. Gathering, Interpreting, and Using Evidence | B3: A.2: Evaluating Sources | C3: Identify, describe, and evaluate evidence about events from diverse sources (including written documents, works of art, photographs, charts and graphs, artifacts, oral traditions, and other primary and secondary sources).
A4: A. Gathering, Interpreting, and Using Evidence | B4: A.3: Sourcing & Point of View | C4: Analyze evidence in terms of content, authorship, point of view, bias, purpose, format, and audience.
A5: A. Gathering, Interpreting, and Using Evidence | B5: A.4: Evaluating Arguments | C5: Describe, analyze, and evaluate arguments of others.
A6: A. Gathering, Interpreting, and Using Evidence | B6: A.5: Inferences & Conclusions | C6: Make inferences and draw conclusions from evidence.
A7: A. Gathering, Interpreting, and Using Evidence | B7: A.6: Constructing Arguments | C7: Deconstruct and construct plausible and persuasive arguments, using evidence.
A8: A. Gathering, Interpreting, and Using Evidence | B8: A.7: Synthesizing Evidence | C8: Create meaningful and persuasive understandings of the past by fusing disparate and relevant evidence from primary and secondary sources and drawing connections to the present.
A9: B. Chronological Reasoning and Causation | B9: B.1: Chronological Relationships | C9: Articulate how events are related chronologically to one another in time and explain the ways in which earlier ideas and events may influence subsequent ideas and events.
A10: B. Chronological Reasoning and Causation | B10: B.2: Cause & Effect | C10: Identify causes and effects using examples from different time periods and courses of study across several grade levels.
A11: B. Chronological Reasoning and Causation | B11: B.3: Multiple Causes & Effects | C11: Identify, analyze, and evaluate the relationship between multiple causes and effects
A12: B. Chronological Reasoning and Causation | B12: B.4: Long-Term vs. Immediate Causes | C12: Distinguish between long-term and immediate causes and multiple effects (time, continuity, and change).
... A42: F. Civic Participation | B42: F.8: Civic Responsibility | C42: Fulfill social and political responsibilities associated with citizenship in a democratic society and interdependent global community by developing awareness of and/or engaging in the political process.

Sheet Content Standards
A1: # | B1: Framework | C1: Specifications | D1: Concatenated
A2: 10.01a.1 | B2: Mughal & Ottoman (c. 1750) | C2: Students will compare and contrast the Mughal Empire and the Ottoman Empire in 1750 in terms of religious and ethnic tolerance, political organization, and commercial activity. | D2: =_xlfn.CONCAT(Table3[[#This Row],['#]],": ",Table3[[#This Row],[Framework]]) -> 10.01a.1: Mughal & Ottoman (c. 1750)
A3: 10.01a.2 | B3: Tokugawa Shogunate | C3: Students will examine efforts to unify, stabilize, and centralize Japan under the rule of the Tokugawa Shogunate. | D3: =_xlfn.CONCAT(Table3[[#This Row],['#]],": ",Table3[[#This Row],[Framework]]) -> 10.01a.2: Tokugawa Shogunate
A4: 10.01a.3 | B4: Comparing Tokugawa Shogunate & Bourbon Dynasty | C4: Students will compare and contrast the Tokugawa Shogunate in Japan with France under the rule of the Bourbon Dynasty, looking at the role of Edo and Paris/Versailles, attempts to control the daimyo and nobles, and the development of bureaucracies. | D4: =_xlfn.CONCAT(Table3[[#This Row],['#]],": ",Table3[[#This Row],[Framework]]) -> 10.01a.3: Comparing Tokugawa Shogunate & Bourbon Dynasty
A5: 10.01b.1 | B5: Tokugawa & Mughal Responses to Outsiders | C5: Students will compare and contrast the Tokugawa and Mughal responses to outsiders, with attention to the impacts of those decisions. | D5: =_xlfn.CONCAT(Table3[[#This Row],['#]],": ",Table3[[#This Row],[Framework]]) -> 10.01b.1: Tokugawa & Mughal Responses to Outsiders
A6: 10.01b.2 | B6: Eurasia World Map | C6: Students will create a world map showing the extent of European maritime empires, the Russian Empire, the Ottoman Empire, Mughal Empire, China under the Qing Dynasty, Japan under the Tokugawa Shogunate, Ashanti, Benin, and Dahomey ca. 1750. | D6: =_xlfn.CONCAT(Table3[[#This Row],['#]],": ",Table3[[#This Row],[Framework]]) -> 10.01b.2: Eurasia World Map
A7: 10.01b.3 | B7: Comparing Empire's Geography & Power | C7: Students will compare the size of these states, empires, and kingdoms relative to the power they wielded in their regions and in the world. | D7: =_xlfn.CONCAT(Table3[[#This Row],['#]],": ",Table3[[#This Row],[Framework]]) -> 10.01b.3: Comparing Empire's Geography & Power
A8: 10.02a.1 | B8: Political Philosophies | C8: Students will examine at least three Enlightenment thinkers, including John Locke, Baron de Montesquieu, and Jean-Jacques Rousseau, and key ideas from their written works. | D8: =_xlfn.CONCAT(Table3[[#This Row],['#]],": ",Table3[[#This Row],[Framework]]) -> 10.02a.1: Political Philosophies
A9: 10.02b.1 | B9: Gender & Abolition | C9: Students will explore the influence of Enlightenment ideals on issues of gender and abolition by examining the ideas of individuals such as Mary Wollstonecraft and William Wilberforce. | D9: =_xlfn.CONCAT(Table3[[#This Row],['#]],": ",Table3[[#This Row],[Framework]]) -> 10.02b.1: Gender & Abolition
A10: 10.02b.2 | B10: Enlightened Despots | C10: Students will examine enlightened despots including Catherine the Great. | D10: =_xlfn.CONCAT(Table3[[#This Row],['#]],": ",Table3[[#This Row],[Framework]]) -> 10.02b.2: Enlightened Despots
A11: 10.02c.1 | B11: French Revolutions | C11: Students will examine evidence related to the preconditions of the French Revolution and the course of the revolution, noting the roles of Olympe de Gouges, Maximilien Robespierre, and Napoleon Bonaparte. | D11: =_xlfn.CONCAT(Table3[[#This Row],['#]],": ",Table3[[#This Row],[Framework]]) -> 10.02c.1: French Revolutions
A12: 10.02c.2 | B12: Latin American Revolutions | C12: Students will examine the evidence related to the impacts of the French Revolution on resistance and revolutionary movements, noting the roles of Toussaint L'Ouverture and Simon Bolivar. | D12: =_xlfn.CONCAT(Table3[[#This Row],['#]],": ",Table3[[#This Row],[Framework]]) -> 10.02c.2: Latin American Revolutions
A13: 10.02d.1 | B13: Italy, Germany & Ottoman, Austrian | C13: Students will investigate the role of cultural identity and nationalism in the unification of Italy and Germany and in the dissolution of the Ottoman and Austrian Empires. | D13: =_xlfn.CONCAT(Table3[[#This Row],['#]],": ",Table3[[#This Row],[Framework]]) -> 10.02d.1: Italy, Germany & Ottoman, Austrian
... A178: 11.11c.3 | B178: US vs China Rivalry | C178: Students will examine the economic relationship and the strategic rivalry between the United States and China. | D178: =_xlfn.CONCAT(Table3[[#This Row],['#]],": ",Table3[[#This Row],[Framework]]) -> 11.11c.3: US vs China Rivalry
